Workbook

Sheet チェック対象管理
A1: チェック | B1: シート名 | C1: マッピング | D1: マスターURL | E1: 最終チェック日時 | F1: 結果
A2: FALSE | B2: 1話 | C2: マッピング設定シート_new | D2: https://docs.google.com/spreadsheets/d/1TS8YjnOCA1QWgrPJa5HzzKVS7WefPnRxDbr5XFhNQ5o/edit?gid=1350936069#gid=1350936069 | E2: 46027.683 | F2: ✅ OK
A3: FALSE | B3: 2話 | C3: マッピング設定シート_new | D3: https://docs.google.com/spreadsheets/d/1TS8YjnOCA1QWgrPJa5HzzKVS7WefPnRxDbr5XFhNQ5o/edit?gid=1350936069#gid=1350936069 | E3: 46027.683 | F3: ✅ OK
A4: FALSE | B4: 3話 | C4: マッピング設定シート_new | D4: https://docs.google.com/spreadsheets/d/1TS8YjnOCA1QWgrPJa5HzzKVS7WefPnRxDbr5XFhNQ5o/edit?gid=1350936069#gid=1350936069 | E4: 46027.683 | F4: ✅ OK
A5: TRUE | B5: 4話 | C5: マッピング設定シート_new | D5: https://docs.google.com/spreadsheets/d/1TS8YjnOCA1QWgrPJa5HzzKVS7WefPnRxDbr5XFhNQ5o/edit?gid=1350936069#gid=1350936069 | E5: 46027.684 | F5: ✅ OK
A6: FALSE
A7: FALSE
A8: FALSE
A9: FALSE
A10: FALSE
A11: FALSE
A12: FALSE
A13: FALSE
A14: FALSE
A15: FALSE
A16: FALSE
A17: FALSE
... A19: FALSE

Sheet MstAutoPlayerSequence
A1: シート名 | B1: id | C1: sequence_set_id | D1: sequence_group_id | E1: sequence_element_id | F1: priority_sequence_element_id | G1: condition_type | H1: condition_value | I1: action_type | J1: action_value | K1: action_value2 | L1: summon_count | M1: summon_interval | N1: summon_animation_type | O1: summon_position | P1: move_start_condition_type | Q1: move_start_condition_value | R1: move_stop_condition_type | S1: move_stop_condition_value | T1: move_restart_condition_type | U1: move_restart_condition_value | V1: move_loop_count | W1: is_summon_unit_outpost_damage_invalidation | X1: last_boss_trigger | Y1: aura_type | Z1: death_type | AA1: enemy_hp_coef | AB1: enemy_attack_coef | AC1: enemy_speed_coef | AD1: override_drop_battle_point | AE1: defeated_score | AF1: action_delay | AG1: deactivation_condition_type | AH1: deactivation_condition_value | AI1: release_key
A2: 4話 | C2: event_jig1_challenge01_00004 | E2: 1 | G2: InitialSummon | H2: 0 | I2: SummonEnemy | J2: c_jig_00001_jig1_challenge_Boss_Red | L2: 1 | N2: None | O2: 2.75 | P2: ElapsedTime | Q2: 1200 | R2: None | T2: None | W2: TRUE | Y2: Boss | Z2: Normal | AA2: 3.1 | AB2: 6.3 | AC2: 1 | AE2: 0 | AG2: None | AI2: 202601010
A3: 4話 | C3: event_jig1_challenge01_00004 | E3: 2 | G3: InitialSummon | H3: 0 | I3: SummonEnemy | J3: c_jig_00101_jig1_challenge_Boss_Red | L3: 1 | N3: None | O3: 1.6 | P3: Damage | Q3: 1 | R3: None | T3: None | W3: FALSE | Y3: Boss | Z3: Normal | AA3: 4.9 | AB3: 5.3 | AC3: 1 | AE3: 0 | AG3: None | AI3: 202601010
A4: 4話 | C4: event_jig1_challenge01_00004 | E4: 3 | G4: FriendUnitDead | H4: 1 | I4: SummonEnemy | J4: c_jig_00001_jig1_challenge_Boss_Red | L4: 1 | N4: None | P4: None | R4: None | T4: None | W4: TRUE | Y4: Boss | Z4: Normal | AA4: 6.1 | AB4: 7.7 | AC4: 1.2 | AE4: 0 | AG4: None | AI4: 202601010
A5: 4話 | C5: event_jig1_challenge01_00004 | E5: 4 | G5: ElapsedTime | H5: 1100 | I5: SummonEnemy | J5: e_jig_00401_jig1_challenge02_Normal_Red | L5: 1 | N5: None | P5: None | R5: None | T5: None | W5: FALSE | Y5: Default | Z5: Normal | AA5: 1.6 | AB5: 0.8 | AC5: 1 | AE5: 0 | AG5: None | AI5: 202601010
A6: 4話 | C6: event_jig1_challenge01_00004 | E6: 5 | G6: ElapsedTime | H6: 300 | I6: SummonEnemy | J6: e_jig_00401_jig1_challenge02_Normal_Red | L6: 3 | M6: 800 | N6: None | P6: None | R6: None | T6: None | W6: FALSE | Y6: Default | Z6: Normal | AA6: 1.2 | AB6: 1.8 | AC6: 1 | AE6: 0 | AG6: None | AI6: 202601010
A7: 4話 | C7: event_jig1_challenge01_00004 | E7: 6 | G7: ElapsedTime | H7: 900 | I7: SummonEnemy | J7: e_jig_00401_jig1_challenge_Normal_Colorless | L7: 3 | M7: 1200 | N7: None | P7: None | R7: None | T7: None | W7: FALSE | Y7: Default | Z7: Normal | AA7: 1.3 | AB7: 1.2 | AC7: 1 | AE7: 0 | AG7: None | AI7: 202601010
A8: 4話 | C8: event_jig1_challenge01_00004 | E8: 7 | G8: ElapsedTime | H8: 1500 | I8: SummonEnemy | J8: e_jig_00401_jig1_challenge02_Normal_Red | L8: 10 | M8: 1300 | N8: None | P8: None | R8: None | T8: None | W8: FALSE | Y8: Default | Z8: Normal | AA8: 0.8 | AB8: 1 | AC8: 1 | AE8: 0 | AG8: None | AI8: 202601010
A9: 4話 | C9: event_jig1_challenge01_00004 | E9: 8 | G9: ElapsedTime | H9: 900 | I9: SummonEnemy | J9: e_jig_00401_jig1_challenge_Normal_Colorless | L9: 7 | M9: 2500 | N9: None | P9: None | R9: None | T9: None | W9: FALSE | Y9: Default | Z9: Normal | AA9: 1 | AB9: 1 | AC9: 1 | AE9: 0 | AG9: None | AI9: 202601010
A10: 4話 | C10: event_jig1_challenge01_00004 | E10: 9 | G10: ElapsedTime | H10: 1000 | I10: SummonEnemy | J10: e_jig_00401_jig1_challenge02_Normal_Red | L10: 15 | M10: 3000 | N10: None | P10: None | R10: None | T10: None | W10: FALSE | Y10: Default | Z10: Normal | AA10: 1.1 | AB10: 1.1 | AC10: 1 | AE10: 0 | AG10: None | AI10: 202601010
A11: 4話 | C11: event_jig1_challenge01_00004 | E11: 10 | G11: FriendUnitDead | H11: 1 | I11: SummonEnemy | J11: e_jig_00401_jig1_challenge02_Normal_Red | L11: 3 | M11: 500 | N11: None | P11: None | R11: None | T11: None | W11: FALSE | Y11: Default | Z11: Normal | AA11: 1.6 | AB11: 1.1 | AC11: 1 | AE11: 0 | AG11: None | AI11: 202601010
A12: 4話 | C12: event_jig1_challenge01_00004 | E12: 11 | G12: FriendUnitDead | H12: 1 | I12: SummonEnemy | J12: e_jig_00401_jig1_challenge_Normal_Colorless | L12: 1 | N12: None | P12: None | R12: None | T12: None | W12: FALSE | Y12: Default | Z12: Normal | AA12: 1.6 | AB12: 1 | AC12: 1.1 | AE12: 0 | AG12: None | AI12: 202601010
A13: 4話 | C13: event_jig1_challenge01_00004 | E13: 12 | G13: FriendUnitDead | H13: 1 | I13: SummonEnemy | J13: e_jig_00401_jig1_challenge_Normal_Colorless | L13: 5 | M13: 900 | N13: None | P13: None | R13: None | T13: None | W13: FALSE | Y13: Default | Z13: Normal | AA13: 1 | AB13: 0.3 | AC13: 1.3 | AE13: 0 | AG13: None | AI13: 202601010
A14: 3話 | C14: event_jig1_challenge01_00003 | E14: 1 | G14: FriendUnitDead | H14: 3 | I14: SummonEnemy | J14: c_jig_00401_jig1_challenge_Boss_Colorless | L14: 1 | N14: None | P14: None | R14: None | T14: None | W14: FALSE | Y14: Boss | Z14: Normal | AA14: 4.4 | AB14: 7.5 | AC14: 1 | AE14: 0 | AG14: None | AI14: 202601010
A15: 3話 | C15: event_jig1_challenge01_00003 | E15: 2 | G15: FriendUnitDead | H15: 3 | I15: SummonEnemy | J15: c_jig_00501_jig1_challenge_Boss_Green | L15: 1 | N15: None | P15: None | R15: None | T15: None | W15: FALSE | Y15: Boss | Z15: Normal | AA15: 4 | AB15: 5.5 | AC15: 1 | AE15: 0 | AG15: None | AI15: 202601010
A16: 3話 | C16: event_jig1_challenge01_00003 | E16: 3 | G16: InitialSummon | H16: 0 | I16: SummonEnemy | J16: e_jig_00301_jig1_challenge_Normal_Yellow | L16: 1 | N16: None | O16: 1.5 | P16: EnterTargetKoma | Q16: 2 | R16: None | T16: None | W16: FALSE | Y16: Default | Z16: Normal | AA16: 3.3 | AB16: 2 | AC16: 1 | AE16: 0 | AG16: None | AI16: 202601010
A17: 3話 | C17: event_jig1_challenge01_00003 | E17: 4 | G17: InitialSummon | H17: 0 | I17: SummonEnemy | J17: e_jig_00301_jig1_challenge_Normal_Yellow | L17: 1 | N17: None | O17: 1.2 | P17: Damage | Q17: 1 | R17: None | T17: None | W17: FALSE | Y17: Default | Z17: Normal | AA17: 2.4 | AB17: 1.8 | AC17: 1 | AE17: 0 | AG17: None | AI17: 202601010
A18: 3話 | C18: event_jig1_challenge01_00003 | E18: 5 | G18: InitialSummon | H18: 0 | I18: SummonEnemy | J18: e_jig_00301_jig1_challenge_Normal_Yellow | L18: 1 | N18: None | O18: 0.85 | P18: Damage | Q18: 1 | R18: None | T18: None | W18: FALSE | Y18: Default | Z18: Normal | AA18: 2.4 | AB18: 1.8 | AC18: 1 | AE18: 0 | AG18: None | AI18: 202601010
A19: 3話 | C19: event_jig1_challenge01_00003 | E19: 6 | G19: ElapsedTime | H19: 1000 | I19: SummonEnemy | J19: e_jig_00301_jig1_challenge_Normal_Red | L19: 6 | M19: 1200 | N19: None | P19: None | R19: None | T19: None | W19: FALSE | Y19: Default | Z19: Normal | AA19: 1.8 | AB19: 1.2 | AC19: 1 | AE19: 0 | AG19: None | AI19: 202601010
A20: 3話 | C20: event_jig1_challenge01_00003 | E20: 7 | G20: ElapsedTime | H20: 300 | I20: SummonEnemy | J20: e_jig_00401_jig1_challenge_Normal_Colorless | L20: 15 | M20: 800 | N20: None | P20: None | R20: None | T20: None | W20: FALSE | Y20: Default | Z20: Normal | AA20: 1 | AB20: 1.8 | AC20: 1 | AE20: 0 | AG20: None | AI20: 202601010
A21: 3話 | C21: event_jig1_challenge01_00003 | E21: 8 | G21: ElapsedTime | H21: 500 | I21: SummonEnemy | J21: e_jig_00401_jig1_challenge_Normal_Colorless | L21: 10 | M21: 1600 | N21: None | P21: None | R21: None | T21: None | W21: FALSE | Y21: Default | Z21: Normal | AA21: 0.4 | AB21: 1 | AC21: 1 | AE21: 0 | AG21: None | AI21: 202601010
A22: 2話 | C22: event_jig1_challenge01_00002 | E22: 1 | G22: OutpostDamage | H22: 1 | I22: SummonEnemy | J22: c_jig_00201_jig1_challenge_Boss_Green | L22: 1 | N22: None | P22: None | R22: None | T22: None | W22: FALSE | Y22: Boss | Z22: Normal | AA22: 3.3 | AB22: 6.4 | AC22: 1 | AE22: 0 | AG22: None | AI22: 202601010
A23: 2話 | C23: event_jig1_challenge01_00002 | E23: 2 | G23: OutpostDamage | H23: 1 | I23: SummonEnemy | J23: c_jig_00301_jig1_challenge_Boss_Green | L23: 1 | N23: None | P23: None | R23: None | T23: None | W23: FALSE | Y23: Boss | Z23: Normal | AA23: 4.2 | AB23: 4.1 | AC23: 1 | AE23: 0 | AG23: None | AI23: 202601010
A24: 2話 | C24: event_jig1_challenge01_00002 | E24: 3 | G24: ElapsedTime | H24: 900 | I24: SummonEnemy | J24: e_jig_00301_jig1_challenge_Normal_Yellow | L24: 1 | N24: None | P24: None | R24: None | T24: None | W24: FALSE | Y24: Default | Z24: Normal | AA24: 2.8 | AB24: 1.8 | AC24: 1 | AE24: 0 | AG24: None | AI24: 202601010
A25: 2話 | C25: event_jig1_challenge01_00002 | E25: 4 | G25: ElapsedTime | H25: 200 | I25: SummonEnemy | J25: e_jig_00401_jig1_challenge_Normal_Yellow | L25: 4 | M25: 1700 | N25: None | P25: None | R25: None | T25: None | W25: FALSE | Y25: Default | Z25: Normal | AA25: 0.6 | AB25: 0.8 | AC25: 1 | AE25: 0 | AG25: None | AI25: 202601010
A26: 2話 | C26: event_jig1_challenge01_00002 | E26: 5 | G26: ElapsedTime | H26: 1100 | I26: SummonEnemy | J26: e_jig_00401_jig1_challenge_Normal_Colorless | L26: 12 | M26: 1400 | N26: None | P26: None | R26: None | T26: None | W26: FALSE | Y26: Default | Z26: Normal | AA26: 1 | AB26: 1.4 | AC26: 1 | AE26: 0 | AG26: None | AI26: 202601010
A27: 2話 | C27: event_jig1_challenge01_00002 | E27: 6 | G27: OutpostDamage | H27: 1 | I27: SummonEnemy | J27: e_jig_00401_jig1_challenge_Normal_Colorless | L27: 1 | N27: None | P27: None | R27: None | T27: None | W27: FALSE | Y27: Default | Z27: Normal | AA27: 1.2 | AB27: 1.6 | AC27: 1 | AE27: 0 | AG27: None | AI27: 202601010
A28: 1話 | C28: event_jig1_challenge01_00001 | E28: 1 | G28: FriendUnitDead | H28: 2 | I28: SummonEnemy | J28: e_jig_00501_jig1_challenge_Boss_Colorless | L28: 1 | M28: 0 | N28: None | P28: None | R28: None | T28: None | W28: FALSE | Y28: Boss | Z28: Normal | AA28: 4.6 | AB28: 2.8 | AC28: 1 | AE28: 0 | AG28: None | AI28: 202601010
A29: 1話 | C29: event_jig1_challenge01_00001 | E29: 2 | G29: InitialSummon | H29: 0 | I29: SummonEnemy | J29: e_jig_00301_jig1_challenge_Normal_Yellow | L29: 1 | M29: 0 | N29: None | O29: 0.87 | P29: FoeEnterSameKoma | R29: None | T29: None | W29: FALSE | Y29: Default | Z29: Normal | AA29: 4.4 | AB29: 1.8 | AC29: 1 | AE29: 0 | AG29: None | AI29: 202601010
A30: 1話 | C30: event_jig1_challenge01_00001 | E30: 3 | G30: ElapsedTime | H30: 300 | I30: SummonEnemy | J30: e_jig_00401_jig1_challenge_Normal_Yellow | L30: 12 | M30: 800 | N30: None | P30: None | R30: None | T30: None | W30: FALSE | Y30: Default | Z30: Normal | AA30: 1.3 | AB30: 1.5 | AC30: 1 | AE30: 0 | AG30: None | AI30: 202601010
A31: 1話 | C31: event_jig1_challenge01_00001 | E31: 4 | G31: ElapsedTime | H31: 80 | I31: SummonEnemy | J31: e_jig_00401_jig1_challenge_Normal_Colorless | L31: 8 | M31: 1600 | N31: None | P31: None | R31: None | T31: None | W31: FALSE | Y31: Default | Z31: Normal | AA31: 0.6 | AB31: 1.1 | AC31: 1 | AE31: 0 | AG31: None | AI31: 202601010
A32: 1話 | C32: event_jig1_challenge01_00001 | E32: 5 | G32: ElapsedTime | H32: 500 | I32: SummonEnemy | J32: e_jig_00401_jig1_challenge_Normal_Colorless | L32: 5 | M32: 2000 | N32: None | P32: None | R32: None | T32: None | W32: FALSE | Y32: Default | Z32: Normal | AA32: 1 | AB32: 0.4 | AC32: 1 | AE32: 0 | AG32: None | AI32: 202601010

Sheet master_config
A1: master名 | B1: startRow | C1: startCol
A2: MstAutoPlayerSequence | B2: 3 | C2: 2

Sheet マッピング設定シート_new
A1: 項目名 | B1: 方向 | C1: マスター名 | D1: チェック無視 | E1: マスター列名 | F1: ユニークキー | G1: 展開タイプ | H1: 空白無視
B2: ▼ | C2: MstAutoPlayerSequence | D2: TRUE | E2: id | F2: TRUE | G2: 通常 | H2: TRUE
A3: 敵ゲートID | B3: ▼ | C3: MstAutoPlayerSequence | D3: FALSE | E3: sequence_set_id | G3: 下方継承 | H3: FALSE
A4: sequence_group_id | B4: ▼ | C4: MstAutoPlayerSequence | D4: FALSE | E4: sequence_group_id | G4: 通常 | H4: FALSE
A5: sequence_element_id | B5: ▼ | C5: MstAutoPlayerSequence | D5: FALSE | E5: sequence_element_id | F5: TRUE | G5: 通常 | H5: TRUE
A6: priority_sequence_element_id | B6: ▼ | C6: MstAutoPlayerSequence | D6: FALSE | E6: priority_sequence_element_id | G6: 通常 | H6: FALSE
A7: condition_type | B7: ▼ | C7: MstAutoPlayerSequence | D7: FALSE | E7: condition_type | G7: 通常 | H7: FALSE
A8: condition_value | B8: ▼ | C8: MstAutoPlayerSequence | D8: FALSE | E8: condition_value | G8: 通常 | H8: FALSE
A9: action_type | B9: ▼ | C9: MstAutoPlayerSequence | D9: FALSE | E9: action_type | G9: 通常 | H9: FALSE
A10: action_value | B10: ▼ | C10: MstAutoPlayerSequence | D10: FALSE | E10: action_value | G10: 通常 | H10: FALSE
A11: action_value2 | B11: ▼ | C11: MstAutoPlayerSequence | D11: FALSE | E11: action_value2 | G11: 通常 | H11: FALSE
A12: summon_count | B12: ▼ | C12: MstAutoPlayerSequence | D12: FALSE | E12: summon_count | G12: 通常 | H12: FALSE
A13: summon_interval | B13: ▼ | C13: MstAutoPlayerSequence | D13: FALSE | E13: summon_interval | G13: 通常 | H13: FALSE
A14: summon_animation_type | B14: ▼ | C14: MstAutoPlayerSequence | D14: FALSE | E14: summon_animation_type | G14: 通常 | H14: FALSE
A15: summon_position | B15: ▼ | C15: MstAutoPlayerSequence | D15: FALSE | E15: summon_position | G15: 通常 | H15: FALSE
A16: move_start_condition_type | B16: ▼ | C16: MstAutoPlayerSequence | D16: FALSE | E16: move_start_condition_type | G16: 通常 | H16: FALSE
A17: move_start_condition_value | B17: ▼ | C17: MstAutoPlayerSequence | D17: FALSE | E17: move_start_condition_value | G17: 通常 | H17: FALSE
... A35: リリースキー | B35: ▼ | C35: MstAutoPlayerSequence | D35: FALSE | E35: release_key | G35: 下方継承 | H35: FALSE

Sheet ステージ概要temp
B2: 作成開始日 | E2: 担当者 | P2: クエストフレーバーテキスト（最大18文字×8行） | AA2: 文字数
B3: 46006 | E3: 平野 | AA3: =len(P3) -> 0
AA4: =len(P4) -> 0
AA5: =len(P5) -> 0
B6: クエスト名 | E6: =iferror(VLOOKUP(E7,'クエストID_管理'!F:G,2,false),"クエストIDを入力してください,又はクエストID_管理シートの関数を有効化してください") -> 死罪人と首切り役人 | AA6: =len(P6) -> 0
B7: クエストID | E7: quest_event_jig1_challenge01 | AA7: =len(P7) -> 0
B8: クエスト種類 | E8: イベントクエスト | AA8: =len(P8) -> 0
B9: リリースキー | E9: 202601010 | AA9: =len(P9) -> 0
AA10: =len(P10) -> 0
P11: ※!（エクスクラメーションマーク）は半角で
B12: 開催期間
B13: 開始日時 | D13: 46038 | G13: 0.625 | J13: から
B14: 終了日時 | D14: 46069 | G14: 0.45832176 | J14: 終了
B16: クエストトップ表示キャラID | E16: キャラ名 | H16: セリフ1 | K16: セリフ2 | N16: セリフ3
B17: chara_jig_00201 | E17: {=iferror(INDEX('キャラID_管理'!F:F,MATCH(B17,'キャラID_管理'!D:D,0),0),"error")} -> 杠 | H17: ありったけ試してあげる♡
B18: chara_jig_00301 | E18: {=iferror(INDEX('キャラID_管理'!F:F,MATCH(B18,'キャラID_管理'!D:D,0),0),"error")} -> 山田浅ェ門 仙汰 | H18: 先立つものはまず情報ですから
E19: {=iferror(INDEX('キャラID_管理'!F:F,MATCH(B19,'キャラID_管理'!D:D,0),0),"error")} -> error

Sheet 早見表
B1: 元シート | C1: GLOW_クエストレギュレーション
B2: 推奨PTLv | C2: 難易度 | D2: 雑魚HP RPG系 | G2: 雑魚ATK※バフ考慮外 | J2: ボスHP | M2: ボスATK※バフ考慮外 | P2: ゲートHP | Q2: 備考
D3: ディフェンス | E3: アタック / テクニカル | F3: サポート | G3: ディフェンス | H3: アタック / テクニカル | I3: サポート | J3: ディフェンス | K3: アタック / テクニカル | L3: サポート | M3: ディフェンス | N3: アタック / テクニカル | O3: サポート | P3: 各ステージ毎に調整
B4: Lv1~/星1 | C4: Normal 1 | D4: 5600 | E4: 1050 | F4: 2450 | G4: 21 | H4: 70 | I4: 35 | J4: 56000 | K4: 10500 | L4: 24500 | M4: 56 | N4: 140 | O4: 84 | P4: 5000
B5: Lv2~/星1 | C5: Normal 2 | D5: 6300 | E5: 1400 | F5: 2800 | G5: 28 | H5: 84 | I5: 49 | J5: 63000 | K5: 14000 | L5: 28000 | M5: 56 | N5: 140 | O5: 84 | P5: 5000
B6: Lv3~/星1 | C6: Normal 3 | D6: 7000 | E6: 2450 | F6: 3150 | G6: 49 | H6: 119 | I6: 70 | J6: 70000 | K6: 24500 | L6: 31500 | M6: 84 | N6: 175 | O6: 105 | P6: 5000
B7: Lv5~/星1 | C7: Normal 4 | D7: 8400 | E7: 3150 | F7: 3500 | G7: 70 | H7: 140 | I7: 91 | J7: 84000 | K7: 31500 | L7: 35000 | M7: 84 | N7: 175 | O7: 105 | P7: 15000
B8: Lv7~/星1 | C8: Normal 5 | D8: 9800 | E8: 3850 | F8: 3850 | G8: 84 | H8: 175 | I8: 105 | J8: 98000 | K8: 38500 | L8: 38500 | M8: 98 | N8: 210 | O8: 126 | P8: 15000
B9: Lv10~/星1 | C9: Normal 6 | D9: 11900 | E9: 4900 | F9: 5600 | G9: 105 | H9: 210 | I9: 140 | J9: 119000 | K9: 49000 | L9: 56000 | M9: 119 | N9: 350 | O9: 210 | P9: 25000
B10: Lv15~/星1 | C10: Normal 7 | D10: 15400 | E10: 6650 | F10: 7000 | G10: 140 | H10: 280 | I10: 210 | J10: 154000 | K10: 66500 | L10: 70000 | M10: 140 | N10: 420 | O10: 280 | P10: 25000
B11: Lv20~/星1 | C11: Normal 8 | D11: 18900 | E11: 8400 | F11: 9100 | G11: 210 | H11: 350 | I11: 245 | J11: 189000 | K11: 84000 | L11: 91000 | M11: 210 | N11: 490 | O11: 350 | P11: 25000
B12: Lv25~/星1 | C12: Normal 9 | D12: 22400 | E12: 10150 | F12: 11900 | G12: 280 | H12: 420 | I12: 245 | J12: 224000 | K12: 101500 | L12: 119000 | M12: 280 | N12: 560 | O12: 420 | P12: 30000
B13: Lv30~/星1 | C13: Normal 10 | D13: 26600 | E13: 11900 | F13: 14700 | G13: 350 | H13: 560 | I13: 350 | J13: 266000 | K13: 119000 | L13: 147000 | M13: 350 | N13: 770 | O13: 490 | P13: 30000
B14: Lv35~/星1 | C14: Normal 11 | D14: 31500 | E14: 14000 | F14: 17500 | G14: 350 | H14: 700 | I14: 420 | J14: 315000 | K14: 140000 | L14: 175000 | M14: 420 | N14: 840 | O14: 560 | P14: 30000
B15: Lv40~/星1 | C15: Normal 12,13 Hard ~3 | D15: 38500 | E15: 16800 | F15: 20300 | G15: 420 | H15: 840 | I15: 490 | J15: 350000 | K15: 175000 | L15: 231000 | M15: 490 | N15: 980 | O15: 700 | P15: 50000
... B17: Lv50~/星1 | C17: Normal 16 Hard ~6 | D17: 49000 | E17: 21000 | F17: 26600 | G17: 490 | H17: 1120 | I17: 630 | J17: 490000 | K17: 245000 | L17: 315000 | M17: 630 | N17: 1260 | O17: 910 | P17: 50000
B18: Lv55~/星1 | D18: 56000 | E18: 24500 | F18: 30100 | G18: 490 | H18: 1260 | I18: 700 | J18: 560000 | K18: 280000 | L18: 350000 | M18: 700 | N18: 1400 | O18: 910 | P18: 50000
B19: Lv60~/星1 | C19: Hard ~9 | D19: 63000 | E19: 28000 | F19: 33600 | G19: 560 | H19: 1400 | I19: 770 | J19: 630000 | K19: 350000 | L19: 420000 | M19: 770 | N19: 1540 | O19: 1050 | P19: 75000
B20: Lv65~/星1 | D20: 70000 | E20: 31500 | F20: 37100 | G20: 560 | H20: 1540 | I20: 840 | J20: 770000 | K20: 420000 | L20: 560000 | M20: 840 | N20: 1750 | O20: 1120 | P20: 75000
B21: Lv70~/星1 | C21: Hard ~13 | D21: 77000 | E21: 35000 | F21: 43400 | G21: 630 | H21: 1680 | I21: 910 | J21: 980000 | K21: 560000 | L21: 700000 | M21: 910 | N21: 1960 | O21: 1260 | P21: 75000
B22: Lv75~/星1 | D22: 84000 | E22: 38500 | F22: 49700 | G22: 630 | H22: 1820 | I22: 980 | J22: 1190000 | K22: 700000 | L22: 910000 | M22: 980 | N22: 2170 | O22: 1260 | P22: 100000
B23: Lv80~/星1 | C23: Hard ~16 | D23: 91000 | E23: 42000 | F23: 56000 | G23: 700 | H23: 1960 | I23: 1050 | J23: 1400000 | K23: 840000 | L23: 1050000 | M23: 1120 | N23: 2380 | O23: 1400 | P23: 100000
B24: Lv60~/星3 | C24: Ex main ~5 | D24: 75600 | E24: 33600 | F24: 40320 | G24: 672 | H24: 1680 | I24: 924 | J24: 756000 | K24: 420000 | L24: 504000 | M24: 924 | N24: 1848 | O24: 1260 | P24: 150000
B25: Lv60~/星5 | C25: Ex | D25: 88200 | E25: 39200 | F25: 47040 | G25: 784 | H25: 1960 | I25: 1078 | J25: 882000 | K25: 490000 | L25: 588000 | M25: 1078 | N25: 2156 | O25: 1470 | P25: 150000
B26: Lv70~/星3 | C26: Ex main ~10 | D26: 100100 | E26: 45500 | F26: 56420 | G26: 819 | H26: 2184 | I26: 1183 | J26: 1274000 | K26: 728000 | L26: 910000 | M26: 1183 | N26: 2548 | O26: 1638 | P26: 150000
B27: Lv70~/星5 | C27: Ex | D27: 115500 | E27: 52500 | F27: 65100 | G27: 945 | H27: 2520 | I27: 1365 | J27: 1470000 | K27: 840000 | L27: 1050000 | M27: 1365 | N27: 2940 | O27: 1890 | P27: 200000
B28: Lv80~/星3 | C28: Ex main ~16 | D28: 118300 | E28: 54600 | F28: 72800 | G28: 910 | H28: 2548 | I28: 1365 | J28: 1820000 | K28: 1092000 | L28: 1365000 | M28: 1456 | N28: 3094 | O28: 1820 | P28: 200000
B29: Lv80~/星5 | C29: Ex | D29: 136500 | E29: 63000 | F29: 84000 | G29: 1050 | H29: 2940 | I29: 1575 | J29: 2100000 | K29: 1260000 | L29: 1575000 | M29: 1680 | N29: 3570 | O29: 2100 | P29: 300000
B30: any | C30: 1日1回 | J30: 210000 | M30: 21 | N30: 70 | O30: 35 | P30: 1000
B31: Lv1~/星1 | C31: ストーリー1話 | D31: 5600 | E31: 1050 | F31: 2450 | G31: 21 | H31: 70 | I31: 35 | J31: 56000 | K31: 10500 | L31: 24500 | M31: 56 | N31: 140 | O31: 84 | P31: 5000
B32: Lv3~/星1 | C32: ストーリー2話 | D32: 7000 | E32: 2450 | F32: 3150 | G32: 49 | H32: 119 | I32: 70 | J32: 70000 | K32: 24500 | L32: 31500 | M32: 84 | N32: 175 | O32: 105 | P32: 5000
B33: Lv5~/星1 | C33: ストーリー3話,4話 | D33: 8400 | E33: 3150 | F33: 3500 | G33: 70 | H33: 140 | I33: 91 | J33: 84000 | K33: 31500 | L33: 35000 | M33: 84 | N33: 175 | O33: 105 | P33: 15000
B34: Lv10~/星1 | C34: ストーリー5話,6話 | D34: 11900 | E34: 4900 | F34: 5600 | G34: 105 | H34: 210 | I34: 140 | J34: 119000 | K34: 49000 | L34: 56000 | M34: 119 | N34: 350 | O34: 210 | P34: 25000
B35: Lv15~/星1 | C35: ストーリー7話 | D35: 15400 | E35: 6650 | F35: 7000 | G35: 140 | H35: 280 | I35: 210 | J35: 154000 | K35: 6650 | L35: 70000 | M35: 140 | N35: 420 | O35: 280 | P35: 25000
B36: Lv20~/星1 | C36: ストーリー8話 | D36: 18900 | E36: 8400 | F36: 9100 | G36: 210 | H36: 350 | I36: 245 | J36: 189000 | K36: 84000 | L36: 91000 | M36: 210 | N36: 490 | O36: 350 | P36: 25000
B37: Lv30~/星1 | C37: チャレンジ1話 | D37: 26600 | E37: 11900 | F37: 14700 | G37: 350 | H37: 560 | I37: 350 | J37: 266000 | K37: 119000 | L37: 147000 | M37: 350 | N37: 770 | O37: 490 | P37: 30000
B38: Lv30~/星1 | C38: チャレンジ2話 | D38: 26600 | E38: 11900 | F38: 14700 | G38: 350 | H38: 560 | I38: 350 | J38: 266000 | K38: 119000 | L38: 147000 | M38: 350 | N38: 770 | O38: 490 | P38: 30000
B39: Lv40~/星1 | C39: チャレンジ3話 | D39: 38500 | E39: 16800 | F39: 20300 | G39: 420 | H39: 840 | I39: 490 | J39: 350000 | K39: 175000 | L39: 231000 | M39: 490 | N39: 980 | O39: 700 | P39: 50000
B40: Lv50~/星1 | C40: チャレンジ4話 | D40: 49000 | E40: 21000 | F40: 26600 | G40: 490 | H40: 1120 | I40: 630 | J40: 490000 | K40: 245000 | L40: 315000 | M40: 630 | N40: 1260 | O40: 910 | P40: 50000
B41: Lv70~/星1 | C41: 高難度ver1 1話 | D41: 77000 | E41: 35000 | F41: 43400 | G41: 630 | H41: 1680 | I41: 910 | J41: 980000 | K41: 560000 | L41: 700000 | M41: 910 | N41: 1960 | O41: 1260 | P41: 150000
...

Sheet ステージ設計▶︎

Sheet 1話
B2: ■基礎情報
B4: ステージコンセプト | S4: ステージ情報詳細
B5: 地獄蝶から毒あり 雑魚敵は黄属性がいるので緑属性で有利に戦える 原作でがびまる達が囲まれた際に助けに来た二人(杠、仙太)なら毒軽減、緑属性で活躍の場ができる 竈神 魚を倒すとボス登場 無属性ボスなので推奨レベル超えていないと時間が掛かる | S5: 【属性情報】 黄属性の敵が登場するので緑属性のキャラは有利に戦うこともできるぞ! さらに、無属性の敵も登場するぞ! 【ギミック情報】 毒攻撃をしてくる敵が登場するぞ! 特性で毒ダメージ軽減を持っているキャラを編成しよう! 特定の敵を倒すと、強敵の『山田浅ェ門 源嗣』が出現するぞ! また、このステージではスピードアタックルールがあるぞ! 早くクリアすると報酬ゲット!
B9: ステージ名（最大20文字） | G9: 文字数 | I9: スタミナ | K9: 難易度 | N9: 推奨PTLv | Q9: 通常BGM | V9: ボスBGM
B10: 1話 | G10: =len(B10) -> 2 | I10: 10 | K10: イベント全般 | N10: 30 | Q10: SSE_SBG_003_003 | V10: SSE_SBG_003_004
B12: 味方ゲートID | E12: 敵ゲートID | H12: 敵ゲートasset | K12: 敵ゲートHP | N12: リリースキー
B13: default | E13: event_jig1_challenge01_00001 | H13: event_jig_0001 | K13: 30000 | N13: 202601010
B15: ■報酬設計
B17: クリアコイン | E17: リーダーEXP | H17: 原画のかけら確率 | K17: 原画のかけら種
B18: =iferror(I10*ifs(K10="イベント全般",15,K10="イベント高難度",25),"-") -> 150 | E18: =I10*10 -> 100
B20: ドロップ区分 | E20: リソースtype | G20: アイテムID | J20: アイテム名 | R20: ドロップ数 | T20: ドロップ率
B21: FirstClear | E21: =if(J21="プリズム","FreeDiamond","item") -> item | G21: {=iferror(INDEX('アイテムID_管理'!E:E,MATCH(J21,'アイテムID_管理'!H:H,0),0),"error")} -> ticket_glo_00003 | J21: ピックアップガシャチケット | S21: 1 | U21: 100
E23: =if(J23="プリズム","FreeDiamond","Item") -> Item | G23: {=iferror(INDEX('アイテムID_管理'!E:E,MATCH(J23,'アイテムID_管理'!H:H,0),0),"none")} -> none
B24: タイムスコア報酬 | E24: =if(J24="プリズム","FreeDiamond","item") -> FreeDiamond | G24: {=iferror(INDEX('アイテムID_管理'!E:E,MATCH(J24,'アイテムID_管理'!H:H,0),0),"none")} -> prism_glo_00001 | J24: プリズム | R24: 20 | T24: 140秒
B25: タイムスコア報酬 | E25: =if(J25="プリズム","FreeDiamond","item") -> FreeDiamond | G25: {=iferror(INDEX('アイテムID_管理'!E:E,MATCH(J25,'アイテムID_管理'!H:H,0),0),"none")} -> prism_glo_00001 | J25: プリズム | R25: 20 | T25: 200秒
B26: タイムスコア報酬 | E26: =if(J26="プリズム","FreeDiamond","item") -> FreeDiamond | G26: {=iferror(INDEX('アイテムID_管理'!E:E,MATCH(J26,'アイテムID_管理'!H:H,0),0),"none")} -> prism_glo_00001 | J26: プリズム | R26: 20 | T26: 300秒
B28: ■コマ設計
B30: 行数 | D30: 行パターンID | F30: コマ数 | H30: コマ高さ | J30: コマ幅1 | L30: コマ幅2 | N30: コマ幅3 | P30: コマ幅4 | R30: コマ背景 | U30: コマ効果1 | Z30: 効果時間 | AB30: 効果数値 | AD30: コマ効果2 | AI30: 効果時間 | AK30: 効果数値 | AM30: コマ効果3 | AR30: 効果時間 | AT30: 効果数値 | AV30: コマ効果4 | BA30: 効果時間 | BC30: 効果数値
B31: 1行目 | D31: 3 | F31: =iferror(vlookup(D31,'行パターン'!$A$2:$C62,2,false),"error") -> 2コマ | H31: 0.55 | J31: {=iferror(INDEX('行パターン'!D:D,MATCH(D31,'行パターン'!A:A,0),0),"error")} -> 0.4 | L31: {=iferror(if(sum(J31)=1,"none",INDEX('行パターン'!E:E,MATCH($D31,'行パターン'!$A:$A,0),0)),"")} -> 0.6 | N31: {=iferror(if(sum(J31:M31)=1,"none",INDEX('行パターン'!F:F,MATCH($D31,'行パターン'!$A:$A,0),0)),"")} -> none | P31: {=iferror(if(sum(J31:O31)=1,"none",INDEX('行パターン'!G:G,MATCH($D31,'行パターン'!$A:$A,0),0)),"")} -> none | R31: jig_00003
B32: 2行目 | D32: 4 | F32: =iferror(vlookup(D32,'行パターン'!$A$2:$C62,2,false),"error") -> 2コマ | H32: 0.55 | J32: {=iferror(INDEX('行パターン'!D:D,MATCH(D32,'行パターン'!A:A,0),0),"error")} -> 0.75 | L32: {=iferror(if(sum(J32)=1,"none",INDEX('行パターン'!E:E,MATCH($D32,'行パターン'!$A:$A,0),0)),"")} -> 0.25 | N32: {=iferror(if(sum(J32:M32)=1,"none",INDEX('行パターン'!F:F,MATCH($D32,'行パターン'!$A:$A,0),0)),"")} -> none | P32: {=iferror(if(sum(J32:O32)=1,"none",INDEX('行パターン'!G:G,MATCH($D32,'行パターン'!$A:$A,0),0)),"")} -> none | R32: jig_00003
B33: 3行目 | F33: =iferror(vlookup(D33,'行パターン'!$A$2:$C62,2,false)," ") | J33: {=iferror(INDEX('行パターン'!D:D,MATCH(D33,'行パターン'!A:A,0),0)," ")} | L33: {=iferror(if(sum(J33)=1,"none",INDEX('行パターン'!E:E,MATCH($D33,'行パターン'!$A:$A,0),0)),"")} | N33: {=iferror(if(sum(J33:M33)=1,"none",INDEX('行パターン'!F:F,MATCH($D33,'行パターン'!$A:$A,0),0)),"")} | P33: {=iferror(if(sum(J33:O33)=1,"none",INDEX('行パターン'!H:H,MATCH($D33,'行パターン'!$A:$A,0),0)),"")}
B34: 4行目 | F34: =iferror(vlookup(D34,'行パターン'!$A$2:$C62,2,false)," ") | J34: {=iferror(INDEX('行パターン'!D:D,MATCH(D34,'行パターン'!A:A,0),0)," ")} | L34: {=iferror(if(sum(J34)=1,"none",INDEX('行パターン'!E:E,MATCH($D34,'行パターン'!$A:$A,0),0)),"")} | N34: {=iferror(if(sum(J34:M34)=1,"none",INDEX('行パターン'!F:F,MATCH($D34,'行パターン'!$A:$A,0),0)),"")} | P34: {=iferror(if(sum(J34:O34)=1,"none",INDEX('行パターン'!G:G,MATCH($D34,'行パターン'!$A:$A,0),0)),"")}
B35: 5行目 | F35: =iferror(vlookup(D35,'行パターン'!$A$2:$C62,2,false)," ") | J35: {=iferror(INDEX('行パターン'!D:D,MATCH(D35,'行パターン'!A:A,0),0)," ")} | L35: {=iferror(if(sum(J35)=1,"none",INDEX('行パターン'!E:E,MATCH($D35,'行パターン'!$A:$A,0),0)),"")} | N35: {=iferror(if(sum(J35:M35)=1,"none",INDEX('行パターン'!F:F,MATCH($D35,'行パターン'!$A:$A,0),0)),"")} | P35: {=iferror(if(sum(J35:O35)=1,"none",INDEX('行パターン'!G:G,MATCH($D35,'行パターン'!$A:$A,0),0)),"")}
B37: ■Enemyシーケンス | F37: ※コピペして使用
B39: sequence _group_id | D39: sequence_ element_id | F39: priority_sequence_element_id | H39: Enemy_ID | L39: ファントム名 | P39: unit_kind | R39: 属性 | T39: ロール | V39: オーラタイプ | X39: 死亡タイプ | Z39: 必殺ワザ有無 | AB39: 体力 | AD39: 体力係数 | AF39: 攻撃力 | AH39: 攻撃係数 | AJ39: 通常攻撃F | AL39: 通常攻撃CDF | AN39: 通常攻撃DPS | AP39: 通常攻撃備考 | AT39: 必殺技内容 | AY39: 必殺発動回数 | BA39: 必殺技F(秒) | BC39: 特性 | BE39: 移動速度 | BG39: well_distance | BI39: start_range | BK39: end_range | BM39: 攻撃範囲 | BO39: KB回数 | BQ39: 撃破p | BS39: 上書き撃破p | BU39: 変身先ID | BW39: 変身条件1 | BY39: 変身条件2 | CA39: 出撃条件 condition_type | CE39: 出撃開始値 condition_value | CG39: 出撃感覚値 summon_interval | CI39: 召喚回数 summon_count | CK39: アクション遅延 action_delay | CM39: 出撃 アニメーション | CO39: 召喚pos summon_position | CQ39: 移動開始条件 move_start_condition_type | CU39: 移動開始値 condition_value | CW39: 移動停止条件 move_stop_condition_type | DA39: 移動停止値 | DC39: 移動再スタート条件 move_restart_condition_type | DG39: 移動再スタート値 | DI39: 再スタート回数 move_loop_count | DK39: ゲート無敵化 | DM39: 出現停止条件 | DQ39: 停止条件値 | DS39: 備考 | EA39: sequence_group_id | EB39: sequence_element_id | EC39: priority_sequence_element_id | ED39: condition_type | EE39: condition_value | EF39: action_type | EG39: action_value | EH39: action_value2 | EI39: summon_count | EJ39: summon_interval | EK39: summon_animation_type | EL39: summon_position | EM39: move_start_condition_type | EN39: move_start_condition_value | EO39: move_stop_condition_type | EP39: move_stop_condition_value | EQ39: move_restart_condition_type | ER39: move_restart_condition_value | ES39: move_loop_count | ET39: is_summon_unit_outpost_damage_invalidation | EV39: aura_type | EW39: death_type | EX39: enemy_hp_coef | EY39: enemy_attack_coef | EZ39: enemy_speed_coef | FA39: override_drop_battle_point | FB39: defeated_score | FC39: action_delay | FD39: deactivation_condition_type | FE39: deactivation_condition_value
D40: 1 | H40: e_jig_00501_jig1_challenge_Boss_Colorless | L40: {=iferror(INDEX('ファントムマスター_イベント'!F:F,MATCH(H40,'ファントムマスター_イベント'!D:D,0),0),"none")} -> 山田浅ェ門 源嗣 | P40: {=iferror(INDEX('ファントムマスター_イベント'!H:H,MATCH(H40,'ファントムマスター_イベント'!D:D,0),0),"none")} -> Boss | R40: {=iferror(INDEX('ファントムマスター_イベント'!J:J,MATCH(H40,'ファントムマスター_イベント'!D:D,0),0),"none")} -> Colorless | T40: {=iferror(INDEX('ファントムマスター_イベント'!I:I,MATCH(H40,'ファントムマスター_イベント'!D:D,0),0),"none")} -> Defense | V40: Boss | X40: Normal | Z40: なし | AB40: {=iferror(INDEX('ファントムマスター_イベント'!K:K,MATCH(H40,'ファントムマスター_イベント'!D:D,0),0)*AD40,"none")} -> 230000 | AD40: 4.6 | AF40: {=iferror(INDEX('ファントムマスター_イベント'!O:O,MATCH(H40,'ファントムマスター_イベント'!D:D,0),0)*AH40,"none")} -> 840 | AH40: 2.8 | AJ40: {=iferror(right(INDEX('ファントムマスター_イベント'!T:T,MATCH(H40,'ファントムマスター_イベント'!D:D,0),0),4)*50,"none")} -> 71.5 | AL40: {=iferror(right(INDEX('ファントムマスター_イベント'!V:V,MATCH(H40,'ファントムマスター_イベント'!D:D,0),0),4),"none")} | AN40: =iferror(AF40*(50/(AJ40+AL40)),"攻撃力に数値を入力") -> 587.41259 | AP40: {=iferror(INDEX('ファントムマスター_イベント'!AC:AC,MATCH(H40,'ファントムマスター_イベント'!D:D,0),0),"none")} | AT40: {=iferror(INDEX('ファントムマスター_イベント'!Y:Y,MATCH(H40,'ファントムマスター_イベント'!D:D,0),0),"none")} | AY40: {=iferror(INDEX('ファントムマスター_イベント'!Z:Z,MATCH(H40,'ファントムマスター_イベント'!D:D,0),0),"none")} -> - | BA40: {=iferror(INDEX('ファントムマスター_イベント'!W:W,MATCH(H40,'ファントムマスター_イベント'!D:D,0),0)*50,"none")} -> none | BC40: {=iferror(INDEX('ファントムマスター_イベント'!AA:AA,MATCH(H40,'ファントムマスター_イベント'!D:D,0),0),"none")} | BE40: {=iferror(INDEX('ファントムマスター_イベント'!M:M,MATCH(H40,'ファントムマスター_イベント'!D:D,0),0),"none")} -> 32 | BG40: {=iferror(INDEX('ファントムマスター_イベント'!N:N,MATCH(H40,'ファントムマスター_イベント'!D:D,0),0),"none")} -> 0.22 | BI40: {=iferror(INDEX('ファントムマスター_イベント'!P:P,MATCH(H40,'ファントムマスター_イベント'!D:D,0),0),"none")} -> 0 | BK40: {=iferror(INDEX('ファントムマスター_イベント'!Q:Q,MATCH(H40,'ファントムマスター_イベント'!D:D,0),0),"none")} -> 0.23 | BM40: {=iferror(INDEX('ファントムマスター_イベント'!R:R,MATCH(H40,'ファントムマスター_イベント'!D:D,0),0),"none")} -> 1 | BO40: {=iferror(INDEX('ファントムマスター_イベント'!L:L,MATCH(H40,'ファントムマスター_イベント'!D:D,0),0),"none")} -> 3 | BQ40: {=iferror(INDEX('ファントムマスター_イベント'!S:S,MATCH(H40,'ファントムマスター_イベント'!D:D,0),0),"none")} -> 300 | CA40: FriendUnitDead | CE40: 2 | CG40: 0 | CI40: 1 | CM40: None | CQ40: None | CW40: None | DC40: None | DK40: FALSE | DM40: None | EA40: =B40 | EB40: =D40 -> 1 | EC40: =F40 | ED40: =CA40 -> FriendUnitDead | EE40: =CE40 -> 2 | EF40: ="SummonEnemy" -> SummonEnemy | EG40: =H40 -> e_jig_00501_jig1_challenge_Boss_Colorless | EI40: =CI40 -> 1 | EJ40: =CG40 -> 0 | EK40: =CM40 -> None | EL40: =CO40 | EM40: =CQ40 -> None | EN40: =CU40 | EO40: =CW40 -> None | EP40: =DA40 | EQ40: =DC40 -> None | ER40: =DG40 | ES40: =DI40 | ET40: =DK40 -> FALSE | EV40: =V40 -> Boss | EW40: =X40 -> Normal | EX40: =AD40 -> 4.6 | EY40: =AH40 -> 2.8 | EZ40: ="1" -> 1 | FA40: =BS40 | FB40: 0 | FC40: =CK40 | FD40: =DM40 -> None | FE40: =DQ40
D41: 2 | H41: e_jig_00301_jig1_challenge_Normal_Yellow | L41: {=iferror(INDEX('ファントムマスター_イベント'!F:F,MATCH(H41,'ファントムマスター_イベント'!D:D,0),0),"none")} -> 竈神 魚 | P41: {=iferror(INDEX('ファントムマスター_イベント'!H:H,MATCH(H41,'ファントムマスター_イベント'!D:D,0),0),"none")} -> Normal | R41: {=iferror(INDEX('ファントムマスター_イベント'!J:J,MATCH(H41,'ファントムマスター_イベント'!D:D,0),0),"none")} -> Yellow | T41: {=iferror(INDEX('ファントムマスター_イベント'!I:I,MATCH(H41,'ファントムマスター_イベント'!D:D,0),0),"none")} -> Attack | V41: Default | X41: Normal | Z41: なし | AB41: {=iferror(INDEX('ファントムマスター_イベント'!K:K,MATCH(H41,'ファントムマスター_イベント'!D:D,0),0)*AD41,"none")} -> 44000 | AD41: 4.4 | AF41: {=iferror(INDEX('ファントムマスター_イベント'!O:O,MATCH(H41,'ファントムマスター_イベント'!D:D,0),0)*AH41,"none")} -> 180 | AH41: 1.8 | AJ41: {=iferror(right(INDEX('ファントムマスター_イベント'!T:T,MATCH(H41,'ファントムマスター_イベント'!D:D,0),0),4)*50,"none")} -> 75 | AL41: {=iferror(right(INDEX('ファントムマスター_イベント'!V:V,MATCH(H41,'ファントムマスター_イベント'!D:D,0),0),4),"none")} -> 10 | AN41: =iferror(AF41*(50/(AJ41+AL41)),"攻撃力に数値を入力") -> 105.88235 | AT41: {=iferror(INDEX('ファントムマスター_イベント'!Y:Y,MATCH(H41,'ファントムマスター_イベント'!D:D,0),0),"none")} | AY41: {=iferror(INDEX('ファントムマスター_イベント'!Z:Z,MATCH(H41,'ファントムマスター_イベント'!D:D,0),0),"none")} -> - | BA41: {=iferror(INDEX('ファントムマスター_イベント'!W:W,MATCH(H41,'ファントムマスター_イベント'!D:D,0),0)*50,"none")} -> none | BC41: {=iferror(INDEX('ファントムマスター_イベント'!AA:AA,MATCH(H41,'ファントムマスター_イベント'!D:D,0),0),"none")} | BE41: {=iferror(INDEX('ファントムマスター_イベント'!M:M,MATCH(H41,'ファントムマスター_イベント'!D:D,0),0),"none")} -> 37 | BG41: {=iferror(INDEX('ファントムマスター_イベント'!N:N,MATCH(H41,'ファントムマスター_イベント'!D:D,0),0),"none")} -> 0.22 | BI41: {=iferror(INDEX('ファントムマスター_イベント'!P:P,MATCH(H41,'ファントムマスター_イベント'!D:D,0),0),"none")} -> 0 | BK41: {=iferror(INDEX('ファントムマスター_イベント'!Q:Q,MATCH(H41,'ファントムマスター_イベント'!D:D,0),0),"none")} -> 0.23 | BM41: {=iferror(INDEX('ファントムマスター_イベント'!R:R,MATCH(H41,'ファントムマスター_イベント'!D:D,0),0),"none")} -> 1 | BO41: {=iferror(INDEX('ファントムマスター_イベント'!L:L,MATCH(H41,'ファントムマスター_イベント'!D:D,0),0),"none")} -> 3 | BQ41: {=iferror(INDEX('ファントムマスター_イベント'!S:S,MATCH(H41,'ファントムマスター_イベント'!D:D,0),0),"none")} -> 100 | CA41: InitialSummon | CE41: 0 | CG41: 0 | CI41: 1 | CM41: None | CO41: 0.87 | CQ41: FoeEnterSameKoma | CW41: None | DC41: None | DK41: FALSE | DM41: None | EA41: =B41 | EB41: =D41 -> 2 | EC41: =F41 | ED41: =CA41 -> InitialSummon | EE41: =CE41 -> 0 | EF41: ="SummonEnemy" -> SummonEnemy | EG41: =H41 -> e_jig_00301_jig1_challenge_Normal_Yellow | EI41: =CI41 -> 1 | EJ41: =CG41 -> 0 | EK41: =CM41 -> None | EL41: =CO41 -> 0.87 | EM41: =CQ41 -> FoeEnterSameKoma | EN41: =CU41 | EO41: =CW41 -> None | EP41: =DA41 | EQ41: =DC41 -> None | ER41: =DG41 | ES41: =DI41 | ET41: =DK41 -> FALSE | EV41: =V41 -> Default | EW41: =X41 -> Normal | EX41: =AD41 -> 4.4 | EY41: =AH41 -> 1.8 | EZ41: ="1" -> 1 | FA41: =BS41 | FB41: 0 | FC41: =CK41 | FD41: =DM41 -> None | FE41: =DQ41
D42: 3 | H42: e_jig_00401_jig1_challenge_Normal_Yellow | L42: {=iferror(INDEX('ファントムマスター_イベント'!F:F,MATCH(H42,'ファントムマスター_イベント'!D:D,0),0),"none")} -> 極楽蝶 | P42: {=iferror(INDEX('ファントムマスター_イベント'!H:H,MATCH(H42,'ファントムマスター_イベント'!D:D,0),0),"none")} -> Normal | R42: {=iferror(INDEX('ファントムマスター_イベント'!J:J,MATCH(H42,'ファントムマスター_イベント'!D:D,0),0),"none")} -> Yellow | T42: {=iferror(INDEX('ファントムマスター_イベント'!I:I,MATCH(H42,'ファントムマスター_イベント'!D:D,0),0),"none")} -> Attack | V42: Default | X42: Normal | Z42: なし | AB42: {=iferror(INDEX('ファントムマスター_イベント'!K:K,MATCH(H42,'ファントムマスター_イベント'!D:D,0),0)*AD42,"none")} -> 13000 | AD42: 1.3 | AF42: {=iferror(INDEX('ファントムマスター_イベント'!O:O,MATCH(H42,'ファントムマスター_イベント'!D:D,0),0)*AH42,"none")} -> 150 | AH42: 1.5 | AJ42: {=iferror(right(INDEX('ファントムマスター_イベント'!T:T,MATCH(H42,'ファントムマスター_イベント'!D:D,0),0),4)*50,"none")} -> 65 | AL42: {=iferror(right(INDEX('ファントムマスター_イベント'!V:V,MATCH(H42,'ファントムマスター_イベント'!D:D,0),0),4),"none")} -> 125 | AN42: =iferror(AF42*(50/(AJ42+AL42)),"攻撃力に数値を入力") -> 39.473684 | AT42: {=iferror(INDEX('ファントムマスター_イベント'!Y:Y,MATCH(H42,'ファントムマスター_イベント'!D:D,0),0),"none")} | AY42: {=iferror(INDEX('ファントムマスター_イベント'!Z:Z,MATCH(H42,'ファントムマスター_イベント'!D:D,0),0),"none")} -> - | BA42: {=iferror(INDEX('ファントムマスター_イベント'!W:W,MATCH(H42,'ファントムマスター_イベント'!D:D,0),0)*50,"none")} -> none | BC42: {=iferror(INDEX('ファントムマスター_イベント'!AA:AA,MATCH(H42,'ファントムマスター_イベント'!D:D,0),0),"none")} | BE42: {=iferror(INDEX('ファントムマスター_イベント'!M:M,MATCH(H42,'ファントムマスター_イベント'!D:D,0),0),"none")} -> 33 | BG42: {=iferror(INDEX('ファントムマスター_イベント'!N:N,MATCH(H42,'ファントムマスター_イベント'!D:D,0),0),"none")} -> 0.24 | BI42: {=iferror(INDEX('ファントムマスター_イベント'!P:P,MATCH(H42,'ファントムマスター_イベント'!D:D,0),0),"none")} -> 0 | BK42: {=iferror(INDEX('ファントムマスター_イベント'!Q:Q,MATCH(H42,'ファントムマスター_イベント'!D:D,0),0),"none")} -> 0.25 | BM42: {=iferror(INDEX('ファントムマスター_イベント'!R:R,MATCH(H42,'ファントムマスター_イベント'!D:D,0),0),"none")} -> 1 | BO42: {=iferror(INDEX('ファントムマスター_イベント'!L:L,MATCH(H42,'ファントムマスター_イベント'!D:D,0),0),"none")} -> 1 | BQ42: {=iferror(INDEX('ファントムマスター_イベント'!S:S,MATCH(H42,'ファントムマスター_イベント'!D:D,0),0),"none")} -> 50 | CA42: ElapsedTime | CE42: 300 | CG42: 800 | CI42: 12 | CM42: None | CQ42: None | CW42: None | DC42: None | DK42: FALSE | DM42: None | EA42: =B42 | EB42: =D42 -> 3 | EC42: =F42 | ED42: =CA42 -> ElapsedTime | EE42: =CE42 -> 300 | EF42: ="SummonEnemy" -> SummonEnemy | EG42: =H42 -> e_jig_00401_jig1_challenge_Normal_Yellow | EI42: =CI42 -> 12 | EJ42: =CG42 -> 800 | EK42: =CM42 -> None | EL42: =CO42 | EM42: =CQ42 -> None | EN42: =CU42 | EO42: =CW42 -> None | EP42: =DA42 | EQ42: =DC42 -> None | ER42: =DG42 | ES42: =DI42 | ET42: =DK42 -> FALSE | EV42: =V42 -> Default | EW42: =X42 -> Normal | EX42: =AD42 -> 1.3 | EY42: =AH42 -> 1.5 | EZ42: ="1" -> 1 | FA42: =BS42 | FB42: 0 | FC42: =CK42 | FD42: =DM42 -> None | FE42: =DQ42
D43: 4 | H43: e_jig_00401_jig1_challenge_Normal_Colorless | L43: {=iferror(INDEX('ファントムマスター_イベント'!F:F,MATCH(H43,'ファントムマスター_イベント'!D:D,0),0),"none")} -> 極楽蝶 | P43: {=iferror(INDEX('ファントムマスター_イベント'!H:H,MATCH(H43,'ファントムマスター_イベント'!D:D,0),0),"none")} -> Normal | R43: {=iferror(INDEX('ファントムマスター_イベント'!J:J,MATCH(H43,'ファントムマスター_イベント'!D:D,0),0),"none")} -> Colorless | T43: {=iferror(INDEX('ファントムマスター_イベント'!I:I,MATCH(H43,'ファントムマスター_イベント'!D:D,0),0),"none")} -> Attack | V43: Default | X43: Normal | Z43: なし | AB43: {=iferror(INDEX('ファントムマスター_イベント'!K:K,MATCH(H43,'ファントムマスター_イベント'!D:D,0),0)*AD43,"none")} -> 6000 | AD43: 0.6 | AF43: {=iferror(INDEX('ファントムマスター_イベント'!O:O,MATCH(H43,'ファントムマスター_イベント'!D:D,0),0)*AH43,"none")} -> 110 | AH43: 1.1 | AJ43: {=iferror(right(INDEX('ファントムマスター_イベント'!T:T,MATCH(H43,'ファントムマスター_イベント'!D:D,0),0),4)*50,"none")} -> 65 | AL43: {=iferror(right(INDEX('ファントムマスター_イベント'!V:V,MATCH(H43,'ファントムマスター_イベント'!D:D,0),0),4),"none")} -> 125 | AN43: =iferror(AF43*(50/(AJ43+AL43)),"攻撃力に数値を入力") -> 28.947368 | AT43: {=iferror(INDEX('ファントムマスター_イベント'!Y:Y,MATCH(H43,'ファントムマスター_イベント'!D:D,0),0),"none")} | AY43: {=iferror(INDEX('ファントムマスター_イベント'!Z:Z,MATCH(H43,'ファントムマスター_イベント'!D:D,0),0),"none")} -> - | BA43: {=iferror(INDEX('ファントムマスター_イベント'!W:W,MATCH(H43,'ファントムマスター_イベント'!D:D,0),0)*50,"none")} -> none | BC43: {=iferror(INDEX('ファントムマスター_イベント'!AA:AA,MATCH(H43,'ファントムマスター_イベント'!D:D,0),0),"none")} | BE43: {=iferror(INDEX('ファントムマスター_イベント'!M:M,MATCH(H43,'ファントムマスター_イベント'!D:D,0),0),"none")} -> 33 | BG43: {=iferror(INDEX('ファントムマスター_イベント'!N:N,MATCH(H43,'ファントムマスター_イベント'!D:D,0),0),"none")} -> 0.24 | BI43: {=iferror(INDEX('ファントムマスター_イベント'!P:P,MATCH(H43,'ファントムマスター_イベント'!D:D,0),0),"none")} -> 0 | BK43: {=iferror(INDEX('ファントムマスター_イベント'!Q:Q,MATCH(H43,'ファントムマスター_イベント'!D:D,0),0),"none")} -> 0.25 | BM43: {=iferror(INDEX('ファントムマスター_イベント'!R:R,MATCH(H43,'ファントムマスター_イベント'!D:D,0),0),"none")} -> 100 | BO43: {=iferror(INDEX('ファントムマスター_イベント'!L:L,MATCH(H43,'ファントムマスター_イベント'!D:D,0),0),"none")} -> 1 | BQ43: {=iferror(INDEX('ファントムマスター_イベント'!S:S,MATCH(H43,'ファントムマスター_イベント'!D:D,0),0),"none")} -> 50 | CA43: ElapsedTime | CE43: 80 | CG43: 1600 | CI43: 8 | CM43: None | CQ43: None | CW43: None | DC43: None | DK43: FALSE | DM43: None | EA43: =B43 | EB43: =D43 -> 4 | EC43: =F43 | ED43: =CA43 -> ElapsedTime | EE43: =CE43 -> 80 | EF43: ="SummonEnemy" -> SummonEnemy | EG43: =H43 -> e_jig_00401_jig1_challenge_Normal_Colorless | EI43: =CI43 -> 8 | EJ43: =CG43 -> 1600 | EK43: =CM43 -> None | EL43: =CO43 | EM43: =CQ43 -> None | EN43: =CU43 | EO43: =CW43 -> None | EP43: =DA43 | EQ43: =DC43 -> None | ER43: =DG43 | ES43: =DI43 | ET43: =DK43 -> FALSE | EV43: =V43 -> Default | EW43: =X43 -> Normal | EX43: =AD43 -> 0.6 | EY43: =AH43 -> 1.1 | EZ43: ="1" -> 1 | FA43: =BS43 | FB43: 0 | FC43: =CK43 | FD43: =DM43 -> None | FE43: =DQ43
D44: 5 | H44: e_jig_00401_jig1_challenge_Normal_Colorless | L44: {=iferror(INDEX('ファントムマスター_イベント'!F:F,MATCH(H44,'ファントムマスター_イベント'!D:D,0),0),"none")} -> 極楽蝶 | P44: {=iferror(INDEX('ファントムマスター_イベント'!H:H,MATCH(H44,'ファントムマスター_イベント'!D:D,0),0),"none")} -> Normal | R44: {=iferror(INDEX('ファントムマスター_イベント'!J:J,MATCH(H44,'ファントムマスター_イベント'!D:D,0),0),"none")} -> Colorless | T44: {=iferror(INDEX('ファントムマスター_イベント'!I:I,MATCH(H44,'ファントムマスター_イベント'!D:D,0),0),"none")} -> Attack | V44: Default | X44: Normal | Z44: なし | AB44: {=iferror(INDEX('ファントムマスター_イベント'!K:K,MATCH(H44,'ファントムマスター_イベント'!D:D,0),0)*AD44,"none")} -> 10000 | AD44: 1 | AF44: {=iferror(INDEX('ファントムマスター_イベント'!O:O,MATCH(H44,'ファントムマスター_イベント'!D:D,0),0)*AH44,"none")} -> 40 | AH44: 0.4 | AJ44: {=iferror(right(INDEX('ファントムマスター_イベント'!T:T,MATCH(H44,'ファントムマスター_イベント'!D:D,0),0),4)*50,"none")} -> 65 | AL44: {=iferror(right(INDEX('ファントムマスター_イベント'!V:V,MATCH(H44,'ファントムマスター_イベント'!D:D,0),0),4),"none")} -> 125 | AN44: =iferror(AF44*(50/(AJ44+AL44)),"攻撃力に数値を入力") -> 10.526316 | AT44: {=iferror(INDEX('ファントムマスター_イベント'!Y:Y,MATCH(H44,'ファントムマスター_イベント'!D:D,0),0),"none")} | AY44: {=iferror(INDEX('ファントムマスター_イベント'!Z:Z,MATCH(H44,'ファントムマスター_イベント'!D:D,0),0),"none")} -> - | BA44: {=iferror(INDEX('ファントムマスター_イベント'!W:W,MATCH(H44,'ファントムマスター_イベント'!D:D,0),0)*50,"none")} -> none | BC44: {=iferror(INDEX('ファントムマスター_イベント'!AA:AA,MATCH(H44,'ファントムマスター_イベント'!D:D,0),0),"none")} | BE44: {=iferror(INDEX('ファントムマスター_イベント'!M:M,MATCH(H44,'ファントムマスター_イベント'!D:D,0),0),"none")} -> 33 | BG44: {=iferror(INDEX('ファントムマスター_イベント'!N:N,MATCH(H44,'ファントムマスター_イベント'!D:D,0),0),"none")} -> 0.24 | BI44: {=iferror(INDEX('ファントムマスター_イベント'!P:P,MATCH(H44,'ファントムマスター_イベント'!D:D,0),0),"none")} -> 0 | BK44: {=iferror(INDEX('ファントムマスター_イベント'!Q:Q,MATCH(H44,'ファントムマスター_イベント'!D:D,0),0),"none")} -> 0.25 | BM44: {=iferror(INDEX('ファントムマスター_イベント'!R:R,MATCH(H44,'ファントムマスター_イベント'!D:D,0),0),"none")} -> 100 | BO44: {=iferror(INDEX('ファントムマスター_イベント'!L:L,MATCH(H44,'ファントムマスター_イベント'!D:D,0),0),"none")} -> 1 | BQ44: {=iferror(INDEX('ファントムマスター_イベント'!S:S,MATCH(H44,'ファントムマスター_イベント'!D:D,0),0),"none")} -> 50 | CA44: ElapsedTime | CE44: 500 | CG44: 2000 | CI44: 5 | CM44: None | CQ44: None | CW44: None | DC44: None | DK44: FALSE | DM44: None | EA44: =B44 | EB44: =D44 -> 5 | EC44: =F44 | ED44: =CA44 -> ElapsedTime | EE44: =CE44 -> 500 | EF44: ="SummonEnemy" -> SummonEnemy | EG44: =H44 -> e_jig_00401_jig1_challenge_Normal_Colorless | EI44: =CI44 -> 5 | EJ44: =CG44 -> 2000 | EK44: =CM44 -> None | EL44: =CO44 | EM44: =CQ44 -> None | EN44: =CU44 | EO44: =CW44 -> None | EP44: =DA44 | EQ44: =DC44 -> None | ER44: =DG44 | ES44: =DI44 | ET44: =DK44 -> FALSE | EV44: =V44 -> Default | EW44: =X44 -> Normal | EX44: =AD44 -> 1 | EY44: =AH44 -> 0.4 | EZ44: ="1" -> 1 | FA44: =BS44 | FB44: 0 | FC44: =CK44 | FD44: =DM44 -> None | FE44: =DQ44
L45: {=iferror(INDEX('ファントムマスター_イベント'!F:F,MATCH(H45,'ファントムマスター_イベント'!D:D,0),0),"none")} -> none | P45: {=iferror(INDEX('ファントムマスター_イベント'!H:H,MATCH(H45,'ファントムマスター_イベント'!D:D,0),0),"none")} -> none | R45: {=iferror(INDEX('ファントムマスター_イベント'!J:J,MATCH(H45,'ファントムマスター_イベント'!D:D,0),0),"none")} -> none | T45: {=iferror(INDEX('ファントムマスター_イベント'!I:I,MATCH(H45,'ファントムマスター_イベント'!D:D,0),0),"none")} -> none | V45: Default | X45: Normal | AB45: {=iferror(INDEX('ファントムマスター_イベント'!K:K,MATCH(H45,'ファントムマスター_イベント'!D:D,0),0)*AD45,"none")} -> none | AD45: 1 | AF45: {=iferror(INDEX('ファントムマスター_イベント'!O:O,MATCH(H45,'ファントムマスター_イベント'!D:D,0),0)*AH45,"none")} -> none | AH45: 1 | AJ45: {=iferror(right(INDEX('ファントムマスター_イベント'!T:T,MATCH(H45,'ファントムマスター_イベント'!D:D,0),0),4)*50,"none")} -> none | AL45: {=iferror(right(INDEX('ファントムマスター_イベント'!V:V,MATCH(H45,'ファントムマスター_イベント'!D:D,0),0),4),"none")} -> none | AN45: =iferror(AF45*(50/(AJ45+AL45)),"攻撃力に数値を入力") -> 攻撃力に数値を入力 | AT45: {=iferror(INDEX('ファントムマスター_イベント'!Y:Y,MATCH(H45,'ファントムマスター_イベント'!D:D,0),0),"none")} -> none | AY45: {=iferror(INDEX('ファントムマスター_イベント'!Z:Z,MATCH(H45,'ファントムマスター_イベント'!D:D,0),0),"none")} -> none | BA45: {=iferror(INDEX('ファントムマスター_イベント'!W:W,MATCH(H45,'ファントムマスター_イベント'!D:D,0),0)*50,"none")} -> none | BC45: {=iferror(INDEX('ファントムマスター_イベント'!AA:AA,MATCH(H45,'ファントムマスター_イベント'!D:D,0),0),"none")} -> none | BE45: {=iferror(INDEX('ファントムマスター_イベント'!M:M,MATCH(H45,'ファントムマスター_イベント'!D:D,0),0),"none")} -> none | BG45: {=iferror(INDEX('ファントムマスター_イベント'!N:N,MATCH(H45,'ファントムマスター_イベント'!D:D,0),0),"none")} -> none | BI45: {=iferror(INDEX('ファントムマスター_イベント'!P:P,MATCH(H45,'ファントムマスター_イベント'!D:D,0),0),"none")} -> none | BK45: {=iferror(INDEX('ファントムマスター_イベント'!Q:Q,MATCH(H45,'ファントムマスター_イベント'!D:D,0),0),"none")} -> none | BM45: {=iferror(INDEX('ファントムマスター_イベント'!R:R,MATCH(H45,'ファントムマスター_イベント'!D:D,0),0),"none")} -> none | BO45: {=iferror(INDEX('ファントムマスター_イベント'!L:L,MATCH(H45,'ファントムマスター_イベント'!D:D,0),0),"none")} -> none | BQ45: {=iferror(INDEX('ファントムマスター_イベント'!S:S,MATCH(H45,'ファントムマスター_イベント'!D:D,0),0),"none")} -> none | CA45: 未入力 | CM45: None | CQ45: None | CW45: None | DC45: None | DK45: FALSE | DM45: None | EA45: =B45 | EB45: =D45 | EC45: =F45 | ED45: =CA45 -> 未入力 | EE45: =CE45 | EF45: ="SummonEnemy" -> SummonEnemy | EG45: =H45 | EI45: =CI45 | EJ45: =CG45 | EK45: =CM45 -> None | EL45: =CO45 | EM45: =CQ45 -> None | EN45: =CU45 | EO45: =CW45 -> None | EP45: =DA45 | EQ45: =DC45 -> None | ER45: =DG45 | ES45: =DI45 | ET45: =DK45 -> FALSE | EV45: =V45 -> Default | EW45: =X45 -> Normal | EX45: =AD45 -> 1 | EY45: =AH45 -> 1 | EZ45: ="1" -> 1 | FA45: =BS45 | FB45: 0 | FC45: =CK45 | FD45: =DM45 -> None | FE45: =DQ45
L46: {=iferror(INDEX('ファントムマスター_イベント'!F:F,MATCH(H46,'ファントムマスター_イベント'!D:D,0),0),"none")} -> none | P46: {=iferror(INDEX('ファントムマスター_イベント'!H:H,MATCH(H46,'ファントムマスター_イベント'!D:D,0),0),"none")} -> none | R46: {=iferror(INDEX('ファントムマスター_イベント'!J:J,MATCH(H46,'ファントムマスター_イベント'!D:D,0),0),"none")} -> none | T46: {=iferror(INDEX('ファントムマスター_イベント'!I:I,MATCH(H46,'ファントムマスター_イベント'!D:D,0),0),"none")} -> none | V46: Default | X46: Normal | AB46: {=iferror(INDEX('ファントムマスター_イベント'!K:K,MATCH(H46,'ファントムマスター_イベント'!D:D,0),0)*AD46,"none")} -> none | AD46: 1 | AF46: {=iferror(INDEX('ファントムマスター_イベント'!O:O,MATCH(H46,'ファントムマスター_イベント'!D:D,0),0)*AH46,"none")} -> none | AH46: 1 | AJ46: {=iferror(right(INDEX('ファントムマスター_イベント'!T:T,MATCH(H46,'ファントムマスター_イベント'!D:D,0),0),4)*50,"none")} -> none | AL46: {=iferror(right(INDEX('ファントムマスター_イベント'!V:V,MATCH(H46,'ファントムマスター_イベント'!D:D,0),0),4),"none")} -> none | AN46: =iferror(AF46*(50/(AJ46+AL46)),"攻撃力に数値を入力") -> 攻撃力に数値を入力 | AT46: {=iferror(INDEX('ファントムマスター_イベント'!Y:Y,MATCH(H46,'ファントムマスター_イベント'!D:D,0),0),"none")} -> none | AY46: {=iferror(INDEX('ファントムマスター_イベント'!Z:Z,MATCH(H46,'ファントムマスター_イベント'!D:D,0),0),"none")} -> none | BA46: {=iferror(INDEX('ファントムマスター_イベント'!W:W,MATCH(H46,'ファントムマスター_イベント'!D:D,0),0)*50,"none")} -> none | BC46: {=iferror(INDEX('ファントムマスター_イベント'!AA:AA,MATCH(H46,'ファントムマスター_イベント'!D:D,0),0),"none")} -> none | BE46: {=iferror(INDEX('ファントムマスター_イベント'!M:M,MATCH(H46,'ファントムマスター_イベント'!D:D,0),0),"none")} -> none | BG46: {=iferror(INDEX('ファントムマスター_イベント'!N:N,MATCH(H46,'ファントムマスター_イベント'!D:D,0),0),"none")} -> none | BI46: {=iferror(INDEX('ファントムマスター_イベント'!P:P,MATCH(H46,'ファントムマスター_イベント'!D:D,0),0),"none")} -> none | BK46: {=iferror(INDEX('ファントムマスター_イベント'!Q:Q,MATCH(H46,'ファントムマスター_イベント'!D:D,0),0),"none")} -> none | BM46: {=iferror(INDEX('ファントムマスター_イベント'!R:R,MATCH(H46,'ファントムマスター_イベント'!D:D,0),0),"none")} -> none | BO46: {=iferror(INDEX('ファントムマスター_イベント'!L:L,MATCH(H46,'ファントムマスター_イベント'!D:D,0),0),"none")} -> none | BQ46: {=iferror(INDEX('ファントムマスター_イベント'!S:S,MATCH(H46,'ファントムマスター_イベント'!D:D,0),0),"none")} -> none | CA46: 未入力 | CM46: None | CQ46: None | CW46: None | DC46: None | DK46: FALSE | DM46: None | EA46: =B46 | EB46: =D46 | EC46: =F46 | ED46: =CA46 -> 未入力 | EE46: =CE46 | EF46: ="SummonEnemy" -> SummonEnemy | EG46: =H46 | EI46: =CI46 | EJ46: =CG46 | EK46: =CM46 -> None | EL46: =CO46 | EM46: =CQ46 -> None | EN46: =CU46 | EO46: =CW46 -> None | EP46: =DA46 | EQ46: =DC46 -> None | ER46: =DG46 | ES46: =DI46 | ET46: =DK46 -> FALSE | EV46: =V46 -> Default | EW46: =X46 -> Normal | EX46: =AD46 -> 1 | EY46: =AH46 -> 1 | EZ46: ="1" -> 1 | FA46: =BS46 | FB46: 0 | FC46: =CK46 | FD46: =DM46 -> None | FE46: =DQ46
L47: {=iferror(INDEX('ファントムマスター_イベント'!F:F,MATCH(H47,'ファントムマスター_イベント'!D:D,0),0),"none")} -> none | P47: {=iferror(INDEX('ファントムマスター_イベント'!H:H,MATCH(H47,'ファントムマスター_イベント'!D:D,0),0),"none")} -> none | R47: {=iferror(INDEX('ファントムマスター_イベント'!J:J,MATCH(H47,'ファントムマスター_イベント'!D:D,0),0),"none")} -> none | T47: {=iferror(INDEX('ファントムマスター_イベント'!I:I,MATCH(H47,'ファントムマスター_イベント'!D:D,0),0),"none")} -> none | V47: Default | X47: Normal | AB47: {=iferror(INDEX('ファントムマスター_イベント'!K:K,MATCH(H47,'ファントムマスター_イベント'!D:D,0),0)*AD47,"none")} -> none | AD47: 1 | AF47: {=iferror(INDEX('ファントムマスター_イベント'!O:O,MATCH(H47,'ファントムマスター_イベント'!D:D,0),0)*AH47,"none")} -> none | AH47: 1 | AJ47: {=iferror(right(INDEX('ファントムマスター_イベント'!T:T,MATCH(H47,'ファントムマスター_イベント'!D:D,0),0),4)*50,"none")} -> none | AL47: {=iferror(right(INDEX('ファントムマスター_イベント'!V:V,MATCH(H47,'ファントムマスター_イベント'!D:D,0),0),4),"none")} -> none | AN47: =iferror(AF47*(50/(AJ47+AL47)),"攻撃力に数値を入力") -> 攻撃力に数値を入力 | AT47: {=iferror(INDEX('ファントムマスター_イベント'!Y:Y,MATCH(H47,'ファントムマスター_イベント'!D:D,0),0),"none")} -> none | AY47: {=iferror(INDEX('ファントムマスター_イベント'!Z:Z,MATCH(H47,'ファントムマスター_イベント'!D:D,0),0),"none")} -> none | BA47: {=iferror(INDEX('ファントムマスター_イベント'!W:W,MATCH(H47,'ファントムマスター_イベント'!D:D,0),0)*50,"none")} -> none | BC47: {=iferror(INDEX('ファントムマスター_イベント'!AA:AA,MATCH(H47,'ファントムマスター_イベント'!D:D,0),0),"none")} -> none | BE47: {=iferror(INDEX('ファントムマスター_イベント'!M:M,MATCH(H47,'ファントムマスター_イベント'!D:D,0),0),"none")} -> none | BG47: {=iferror(INDEX('ファントムマスター_イベント'!N:N,MATCH(H47,'ファントムマスター_イベント'!D:D,0),0),"none")} -> none | BI47: {=iferror(INDEX('ファントムマスター_イベント'!P:P,MATCH(H47,'ファントムマスター_イベント'!D:D,0),0),"none")} -> none | BK47: {=iferror(INDEX('ファントムマスター_イベント'!Q:Q,MATCH(H47,'ファントムマスター_イベント'!D:D,0),0),"none")} -> none | BM47: {=iferror(INDEX('ファントムマスター_イベント'!R:R,MATCH(H47,'ファントムマスター_イベント'!D:D,0),0),"none")} -> none | BO47: {=iferror(INDEX('ファントムマスター_イベント'!L:L,MATCH(H47,'ファントムマスター_イベント'!D:D,0),0),"none")} -> none | BQ47: {=iferror(INDEX('ファントムマスター_イベント'!S:S,MATCH(H47,'ファントムマスター_イベント'!D:D,0),0),"none")} -> none | CA47: 未入力 | CM47: None | CQ47: None | CW47: None | DC47: None | DK47: FALSE | DM47: None | EA47: =B47 | EB47: =D47 | EC47: =F47 | ED47: =CA47 -> 未入力 | EE47: =CE47 | EF47: ="SummonEnemy" -> SummonEnemy | EG47: =H47 | EI47: =CI47 | EJ47: =CG47 | EK47: =CM47 -> None | EL47: =CO47 | EM47: =CQ47 -> None | EN47: =CU47 | EO47: =CW47 -> None | EP47: =DA47 | EQ47: =DC47 -> None | ER47: =DG47 | ES47: =DI47 | ET47: =DK47 -> FALSE | EV47: =V47 -> Default | EW47: =X47 -> Normal | EX47: =AD47 -> 1 | EY47: =AH47 -> 1 | EZ47: ="1" -> 1 | FA47: =BS47 | FB47: 0 | FC47: =CK47 | FD47: =DM47 -> None | FE47: =DQ47
L48: {=iferror(INDEX('ファントムマスター_イベント'!F:F,MATCH(H48,'ファントムマスター_イベント'!D:D,0),0),"none")} -> none | P48: {=iferror(INDEX('ファントムマスター_イベント'!H:H,MATCH(H48,'ファントムマスター_イベント'!D:D,0),0),"none")} -> none | R48: {=iferror(INDEX('ファントムマスター_イベント'!J:J,MATCH(H48,'ファントムマスター_イベント'!D:D,0),0),"none")} -> none | T48: {=iferror(INDEX('ファントムマスター_イベント'!I:I,MATCH(H48,'ファントムマスター_イベント'!D:D,0),0),"none")} -> none | V48: Default | X48: Normal | AB48: {=iferror(INDEX('ファントムマスター_イベント'!K:K,MATCH(H48,'ファントムマスター_イベント'!D:D,0),0)*AD48,"none")} -> none | AD48: 1 | AF48: {=iferror(INDEX('ファントムマスター_イベント'!O:O,MATCH(H48,'ファントムマスター_イベント'!D:D,0),0)*AH48,"none")} -> none | AH48: 1 | AJ48: {=iferror(right(INDEX('ファントムマスター_イベント'!T:T,MATCH(H48,'ファントムマスター_イベント'!D:D,0),0),4)*50,"none")} -> none | AL48: {=iferror(right(INDEX('ファントムマスター_イベント'!V:V,MATCH(H48,'ファントムマスター_イベント'!D:D,0),0),4),"none")} -> none | AN48: =iferror(AF48*(50/(AJ48+AL48)),"攻撃力に数値を入力") -> 攻撃力に数値を入力 | AT48: {=iferror(INDEX('ファントムマスター_イベント'!Y:Y,MATCH(H48,'ファントムマスター_イベント'!D:D,0),0),"none")} -> none | AY48: {=iferror(INDEX('ファントムマスター_イベント'!Z:Z,MATCH(H48,'ファントムマスター_イベント'!D:D,0),0),"none")} -> none | BA48: {=iferror(INDEX('ファントムマスター_イベント'!W:W,MATCH(H48,'ファントムマスター_イベント'!D:D,0),0)*50,"none")} -> none | BC48: {=iferror(INDEX('ファントムマスター_イベント'!AA:AA,MATCH(H48,'ファントムマスター_イベント'!D:D,0),0),"none")} -> none | BE48: {=iferror(INDEX('ファントムマスター_イベント'!M:M,MATCH(H48,'ファントムマスター_イベント'!D:D,0),0),"none")} -> none | BG48: {=iferror(INDEX('ファントムマスター_イベント'!N:N,MATCH(H48,'ファントムマスター_イベント'!D:D,0),0),"none")} -> none | BI48: {=iferror(INDEX('ファントムマスター_イベント'!P:P,MATCH(H48,'ファントムマスター_イベント'!D:D,0),0),"none")} -> none | BK48: {=iferror(INDEX('ファントムマスター_イベント'!Q:Q,MATCH(H48,'ファントムマスター_イベント'!D:D,0),0),"none")} -> none | BM48: {=iferror(INDEX('ファントムマスター_イベント'!R:R,MATCH(H48,'ファントムマスター_イベント'!D:D,0),0),"none")} -> none | BO48: {=iferror(INDEX('ファントムマスター_イベント'!L:L,MATCH(H48,'ファントムマスター_イベント'!D:D,0),0),"none")} -> none | BQ48: {=iferror(INDEX('ファントムマスター_イベント'!S:S,MATCH(H48,'ファントムマスター_イベント'!D:D,0),0),"none")} -> none | CA48: 未入力 | CM48: None | CQ48: None | CW48: None | DC48: None | DK48: FALSE | DM48: None | EA48: =B48 | EB48: =D48 | EC48: =F48 | ED48: =CA48 -> 未入力 | EE48: =CE48 | EF48: ="SummonEnemy" -> SummonEnemy | EG48: =H48 | EI48: =CI48 | EJ48: =CG48 | EK48: =CM48 -> None | EL48: =CO48 | EM48: =CQ48 -> None | EN48: =CU48 | EO48: =CW48 -> None | EP48: =DA48 | EQ48: =DC48 -> None | ER48: =DG48 | ES48: =DI48 | ET48: =DK48 -> FALSE | EV48: =V48 -> Default | EW48: =X48 -> Normal | EX48: =AD48 -> 1 | EY48: =AH48 -> 1 | EZ48: ="1" -> 1 | FA48: =BS48 | FB48: 0 | FC48: =CK48 | FD48: =DM48 -> None | FE48: =DQ48
L49: {=iferror(INDEX('ファントムマスター_イベント'!F:F,MATCH(H49,'ファントムマスター_イベント'!D:D,0),0),"none")} -> none | P49: {=iferror(INDEX('ファントムマスター_イベント'!H:H,MATCH(H49,'ファントムマスター_イベント'!D:D,0),0),"none")} -> none | R49: {=iferror(INDEX('ファントムマスター_イベント'!J:J,MATCH(H49,'ファントムマスター_イベント'!D:D,0),0),"none")} -> none | T49: {=iferror(INDEX('ファントムマスター_イベント'!I:I,MATCH(H49,'ファントムマスター_イベント'!D:D,0),0),"none")} -> none | V49: Default | X49: Normal | AB49: {=iferror(INDEX('ファントムマスター_イベント'!K:K,MATCH(H49,'ファントムマスター_イベント'!D:D,0),0)*AD49,"none")} -> none | AD49: 1 | AF49: {=iferror(INDEX('ファントムマスター_イベント'!O:O,MATCH(H49,'ファントムマスター_イベント'!D:D,0),0)*AH49,"none")} -> none | AH49: 1 | AJ49: {=iferror(right(INDEX('ファントムマスター_イベント'!T:T,MATCH(H49,'ファントムマスター_イベント'!D:D,0),0),4)*50,"none")} -> none | AL49: {=iferror(right(INDEX('ファントムマスター_イベント'!V:V,MATCH(H49,'ファントムマスター_イベント'!D:D,0),0),4),"none")} -> none | AN49: =iferror(AF49*(50/(AJ49+AL49)),"攻撃力に数値を入力") -> 攻撃力に数値を入力 | AT49: {=iferror(INDEX('ファントムマスター_イベント'!Y:Y,MATCH(H49,'ファントムマスター_イベント'!D:D,0),0),"none")} -> none | AY49: {=iferror(INDEX('ファントムマスター_イベント'!Z:Z,MATCH(H49,'ファントムマスター_イベント'!D:D,0),0),"none")} -> none | BA49: {=iferror(INDEX('ファントムマスター_イベント'!W:W,MATCH(H49,'ファントムマスター_イベント'!D:D,0),0)*50,"none")} -> none | BC49: {=iferror(INDEX('ファントムマスター_イベント'!AA:AA,MATCH(H49,'ファントムマスター_イベント'!D:D,0),0),"none")} -> none | BE49: {=iferror(INDEX('ファントムマスター_イベント'!M:M,MATCH(H49,'ファントムマスター_イベント'!D:D,0),0),"none")} -> none | BG49: {=iferror(INDEX('ファントムマスター_イベント'!N:N,MATCH(H49,'ファントムマスター_イベント'!D:D,0),0),"none")} -> none | BI49: {=iferror(INDEX('ファントムマスター_イベント'!P:P,MATCH(H49,'ファントムマスター_イベント'!D:D,0),0),"none")} -> none | BK49: {=iferror(INDEX('ファントムマスター_イベント'!Q:Q,MATCH(H49,'ファントムマスター_イベント'!D:D,0),0),"none")} -> none | BM49: {=iferror(INDEX('ファントムマスター_イベント'!R:R,MATCH(H49,'ファントムマスター_イベント'!D:D,0),0),"none")} -> none | BO49: {=iferror(INDEX('ファントムマスター_イベント'!L:L,MATCH(H49,'ファントムマスター_イベント'!D:D,0),0),"none")} -> none | BQ49: {=iferror(INDEX('ファントムマスター_イベント'!S:S,MATCH(H49,'ファントムマスター_イベント'!D:D,0),0),"none")} -> none | CA49: 未入力 | CM49: None | CQ49: None | CW49: None | DC49: None | DK49: FALSE | DM49: None | EA49: =B49 | EB49: =D49 | EC49: =F49 | ED49: =CA49 -> 未入力 | EE49: =CE49 | EF49: ="SummonEnemy" -> SummonEnemy | EG49: =H49 | EI49: =CI49 | EJ49: =CG49 | EK49: =CM49 -> None | EL49: =CO49 | EM49: =CQ49 -> None | EN49: =CU49 | EO49: =CW49 -> None | EP49: =DA49 | EQ49: =DC49 -> None | ER49: =DG49 | ES49: =DI49 | ET49: =DK49 -> FALSE | EV49: =V49 -> Default | EW49: =X49 -> Normal | EX49: =AD49 -> 1 | EY49: =AH49 -> 1 | EZ49: ="1" -> 1 | FA49: =BS49 | FB49: 0 | FC49: =CK49 | FD49: =DM49 -> None | FE49: =DQ49
L50: {=iferror(INDEX('ファントムマスター_イベント'!F:F,MATCH(H50,'ファントムマスター_イベント'!D:D,0),0),"none")} -> none | P50: {=iferror(INDEX('ファントムマスター_イベント'!H:H,MATCH(H50,'ファントムマスター_イベント'!D:D,0),0),"none")} -> none | R50: {=iferror(INDEX('ファントムマスター_イベント'!J:J,MATCH(H50,'ファントムマスター_イベント'!D:D,0),0),"none")} -> none | T50: {=iferror(INDEX('ファントムマスター_イベント'!I:I,MATCH(H50,'ファントムマスター_イベント'!D:D,0),0),"none")} -> none | V50: Default | X50: Normal | AB50: {=iferror(INDEX('ファントムマスター_イベント'!K:K,MATCH(H50,'ファントムマスター_イベント'!D:D,0),0)*AD50,"none")} -> none | AD50: 1 | AF50: {=iferror(INDEX('ファントムマスター_イベント'!O:O,MATCH(H50,'ファントムマスター_イベント'!D:D,0),0)*AH50,"none")} -> none | AH50: 1 | AJ50: {=iferror(right(INDEX('ファントムマスター_イベント'!T:T,MATCH(H50,'ファントムマスター_イベント'!D:D,0),0),4)*50,"none")} -> none | AL50: {=iferror(right(INDEX('ファントムマスター_イベント'!V:V,MATCH(H50,'ファントムマスター_イベント'!D:D,0),0),4),"none")} -> none | AN50: =iferror(AF50*(50/(AJ50+AL50)),"攻撃力に数値を入力") -> 攻撃力に数値を入力 | AT50: {=iferror(INDEX('ファントムマスター_イベント'!Y:Y,MATCH(H50,'ファントムマスター_イベント'!D:D,0),0),"none")} -> none | AY50: {=iferror(INDEX('ファントムマスター_イベント'!Z:Z,MATCH(H50,'ファントムマスター_イベント'!D:D,0),0),"none")} -> none | BA50: {=iferror(INDEX('ファントムマスター_イベント'!W:W,MATCH(H50,'ファントムマスター_イベント'!D:D,0),0)*50,"none")} -> none | BC50: {=iferror(INDEX('ファントムマスター_イベント'!AA:AA,MATCH(H50,'ファントムマスター_イベント'!D:D,0),0),"none")} -> none | BE50: {=iferror(INDEX('ファントムマスター_イベント'!M:M,MATCH(H50,'ファントムマスター_イベント'!D:D,0),0),"none")} -> none | BG50: {=iferror(INDEX('ファントムマスター_イベント'!N:N,MATCH(H50,'ファントムマスター_イベント'!D:D,0),0),"none")} -> none | BI50: {=iferror(INDEX('ファントムマスター_イベント'!P:P,MATCH(H50,'ファントムマスター_イベント'!D:D,0),0),"none")} -> none | BK50: {=iferror(INDEX('ファントムマスター_イベント'!Q:Q,MATCH(H50,'ファントムマスター_イベント'!D:D,0),0),"none")} -> none | BM50: {=iferror(INDEX('ファントムマスター_イベント'!R:R,MATCH(H50,'ファントムマスター_イベント'!D:D,0),0),"none")} -> none | BO50: {=iferror(INDEX('ファントムマスター_イベント'!L:L,MATCH(H50,'ファントムマスター_イベント'!D:D,0),0),"none")} -> none | BQ50: {=iferror(INDEX('ファントムマスター_イベント'!S:S,MATCH(H50,'ファントムマスター_イベント'!D:D,0),0),"none")} -> none | CA50: 未入力 | CM50: None | CQ50: None | CW50: None | DC50: None | DK50: FALSE | DM50: None | EA50: =B50 | EB50: =D50 | EC50: =F50 | ED50: =CA50 -> 未入力 | EE50: =CE50 | EF50: ="SummonEnemy" -> SummonEnemy | EG50: =H50 | EI50: =CI50 | EJ50: =CG50 | EK50: =CM50 -> None | EL50: =CO50 | EM50: =CQ50 -> None | EN50: =CU50 | EO50: =CW50 -> None | EP50: =DA50 | EQ50: =DC50 -> None | ER50: =DG50 | ES50: =DI50 | ET50: =DK50 -> FALSE | EV50: =V50 -> Default | EW50: =X50 -> Normal | EX50: =AD50 -> 1 | EY50: =AH50 -> 1 | EZ50: ="1" -> 1 | FA50: =BS50 | FB50: 0 | FC50: =CK50 | FD50: =DM50 -> None | FE50: =DQ50
