Workbook
Name 使用画面ID: 'プルダウンメニュー (SE用)'!$F$2:$F$34
Name SEステータス: 'プルダウンメニュー (SE用)'!$A$2:$A$8
Name BGM発注: 'プルダウンメニュー (SE用)'!$B$2:$B$7
Name 使用画面: 'プルダウンメニュー (SE用)'!$E$2:$E$34

Sheet ID割り振りルール
A2: ■ID設定ルールについて
C3: 番号以外も指定可能になった ※万が一作品IDなどで被りが生まれるなどイレギュラーがありましたら、別途ルール追加いただいて問題ございません。 ただし、関係各所への共有を忘れないこと！！
C4: カテゴリー | D4: ID付与ルール | E4: 最大ID桁数
C5: 作品 | D5: 作品のローマ字表記の先頭3文字からとったものとする。 小文字表記。 例）『SPY×FAMILY』ならspyとなる。 | E5: 3桁
C6: キャラ | D6: キャラクターIDは接頭語(chara)+作品ID3桁+5桁のIDで管理する。 敵キャラの場合は接頭語がenemyとなる。 例）アーニャの場合、chara_spy_00001、2体目（別のアーニャ）はchara_spy_00002となる。 同じ作品のロイドは、chara_spy_00100となる。1IPの1キャラにつき99番のIDを割り振れる。 敵キャラも同様のルール 同時期かつ同名キャラに関して、別IDを取得する 例）極楽蝶（遠） enemy_jig_00401 極楽蝶（近） enemy_jig_00402 | E6: 15桁
C7: アバターアイコン | D7: キャラと同じルール。 接頭語がcharaからiconになったのみ。 例）スパイファミリーのキャラで00001のアーニャのアイコンの場合は、下記となる。 unit_icon_chara_spy_00001 もしエネミーのアバターアイコンを配布など割り振りが必要な場合は、charaの箇所をenemyに変更してIDを採番する。 | E7: 25桁
C8: クエスト | D8: 接頭語(quest)+クエストの難易度+クエストカテゴリー+作品ID3桁+5桁のIDで管理する。 クエストの難易度設定がないものに関しては、nullとなる。クエストカテゴリーは、メインクエスト、特集祭などのイベントなどがある。 例）メインクエストのノーマルの難易度のダンダダンのクエストの場合は、下記となる。 quest_main_normal_dan_00001 | E8: 32桁
C9: アイテム | D9: 接頭語(各カテゴリー)+作品ID3桁+5桁のIDで管理する。 それぞれカテゴリー別で接頭語が決まっているので注意すること。 例）プリズムであれば、下記となる。 prism_glo_00001 | E9: 19桁
C10: 図鑑 | D10: 接頭語(book)+作品ID3桁+5桁のIDで管理する。 例）スパイファミリーの図鑑の場合は、下記となる。 book_spy_00001 | E10: 14桁
C11: エンブレム | D11: 接頭語(emblem)+エンブレムカテゴリー+作品ID3桁+5桁のIDで管理する。 例）ダンダダンの特集祭で入手できるエンブレムの場合は、下記となる。 emblem_event_spy_00001 | E11: 24桁
C12: 背景 | D12: 接頭語(background)+作品ID3桁+5桁のIDで管理する。 作品毎の背景で最大99999番まで割り振ることが可能。 また、汎用背景に関しては、作品IDをgloとして管理する。 例）スパイファミリーの背景の場合は、下記となる。 background_spy_00001 | E12: 20桁
C13: コンテンツ | D13: 接頭語(contents)+コンテンツカテゴリー+作品ID3桁+5桁のIDで管理する。 コンテンツカテゴリーには、event、training、duel、raid、limitedがある。 例）ラーメン赤猫の大特集祭の場合は、下記となる。 contents_event_aha_00001 | E13: 24桁
C14: BGM | D14: BGMは画面遷移図の大分類の管理番号+サウンド数で管理する。 例）タイトル画面であれば下記となる SBG_011_001 | E14: 11桁
C15: キャラアイコン | D15: キャラの頭にさらに接頭語を追加します。 接頭語がcharaの頭にpicon or eiconをつけるのみ。 例）スパイファミリーのキャラで00001のアーニャのアイコンの場合は、下記となる。 picon_chara_spy_00001、eicon_chara_spy_00001 敵onlyのキャラはeiconのみで良い eicon_enemy_spy_00001 | E15: 21桁
C16: ゲート | D16: ゲートIDは接頭語(outpost)+作品ID3桁+5桁のIDで管理する。 敵キャラの場合は接頭語がenemyとなる。 例）姫+エクスの場合、outpost_gom_00001、2個目（別の姫）はoutpost_gom_00002となる。 同じ作品について別キャラであっても実装順に連番とする。エクスのみを実装したい場合outpost_gom_00003となる。最大で99999番のID割り振りが可能。 敵ゲートは、enemy_gom_00001から連番で使用するので、99999番のID割り振りが可能。 | E16: 17桁

Sheet 作品
A1: 作品_ID | B1: 作品バナーID | C1: 作品ロゴID | D1: 作品名 | E1: 連載曜日 | F1: サブタイトル | G1: サブタイトルの位置 | H1: タイトル合成 | I1: display_order | J1: 設定ID | K1: left1 | L1: left2 | M1: left3 | N1: メインサムネ1画像AssetKey | O1: メインサムネ2画像AssetKey | P1: メインサムネ3画像AssetKey | Q1: メインサムネ3画像AssetKey | R1: BGMジャンル(通常) | S1: BGMジャンル(ボス) | T1: デプロイ | U1: リリース監状況
A2: spy | B2: =CONCATENATE("series_banner_",A2) -> series_banner_spy | C2: series_logo_spy | D2: SPY×FAMILY | E2: 月曜日 | F2: - | H2: =if(G2="",D2,if(G2="後ろ",D2&" "&F2,F2&" "&D2)) -> SPY×FAMILY | I2: 001 | J2: spy | K2: =left(J2,1) -> s | L2: =left(J2,2) -> sp | M2: =left(J2,3) -> spy | N2: ="quest_image_"&A2&"_"&"01" -> quest_image_spy_01 | R2: 日常・ギャグ | S2: 強敵/ボス登場時2 （高難度）
A3: aka | B3: =CONCATENATE("series_banner_",A3) -> series_banner_aka | C3: series_logo_aka | D3: ラーメン赤猫 | E3: 月曜日 | F3: - | H3: =if(G3="",D3,if(G3="後ろ",D3&" "&F3,F3&" "&D3)) -> ラーメン赤猫 | I3: 002 | J3: akaneko | K3: =left(J3,1) -> a | L3: =left(J3,2) -> ak | M3: =left(J3,3) -> aka | N3: ="quest_image_"&A3&"_"&"01" -> quest_image_aka_01 | R3: バトル系2 | S3: 強敵/ボス登場時2 （高難度）
A4: rik | B4: =CONCATENATE("series_banner_",A4) -> series_banner_rik | C4: series_logo_rik | D4: トマトイプーのリコピン | E4: 月曜日 | F4: - | H4: =if(G4="",D4,if(G4="後ろ",D4&" "&F4,F4&" "&D4)) -> トマトイプーのリコピン | I4: 003 | J4: rikopin | K4: =left(J4,1) -> r | L4: =left(J4,2) -> ri | M4: =left(J4,3) -> rik | N4: ="quest_image_"&A4&"_"&"01" -> quest_image_rik_01 | R4: 日常・ギャグ | S4: 強敵/ボス登場時2 （高難度）
A5: dan | B5: =CONCATENATE("series_banner_",A5) -> series_banner_dan | C5: series_logo_dan | D5: ダンダダン | E5: 火曜日 | F5: - | H5: =if(G5="",D5,if(G5="後ろ",D5&" "&F5,F5&" "&D5)) -> ダンダダン | I5: 004 | J5: dan | K5: =left(J5,1) -> d | L5: =left(J5,2) -> da | M5: =left(J5,3) -> dan | N5: ="quest_image_"&A5&"_"&"01" -> quest_image_dan_01 | R5: バトル系1 | S5: 強敵/ボスバトル1
A6: gom | B6: =CONCATENATE("series_banner_",A6) -> series_banner_gom | C6: series_logo_gom | D6: 姫様“拷問”の時間です | E6: 火曜日 | F6: - | H6: =if(G6="",D6,if(G6="後ろ",D6&" "&F6,F6&" "&D6)) -> 姫様“拷問”の時間です | I6: 005 | J6: gomon | K6: =left(J6,1) -> g | L6: =left(J6,2) -> go | M6: =left(J6,3) -> gom | N6: ="quest_image_"&A6&"_"&"01" -> quest_image_gom_01 | R6: バトル系2 | S6: 強敵/ボス登場時2 （高難度）
A7: chi | B7: =CONCATENATE("series_banner_",A7) -> series_banner_chi | C7: series_logo_chi | D7: チェンソーマン | E7: 水曜日 | F7: - | H7: =if(G7="",D7,if(G7="後ろ",D7&" "&F7,F7&" "&D7)) -> チェンソーマン | I7: 006 | J7: chienso | K7: =left(J7,1) -> c | L7: =left(J7,2) -> ch | M7: =left(J7,3) -> chi | N7: ="quest_image_"&A7&"_"&"01" -> quest_image_chi_01 | R7: バトル系1 | S7: 強敵/ボスバトル1
A8: mag | B8: =CONCATENATE("series_banner_",A8) -> series_banner_mag | C8: series_logo_mag | D8: 株式会社マジルミエ | E8: 水曜日 | F8: - | H8: =if(G8="",D8,if(G8="後ろ",D8&" "&F8,F8&" "&D8)) -> 株式会社マジルミエ | I8: 007 | J8: magirumie | K8: =left(J8,1) -> m | L8: =left(J8,2) -> ma | M8: mag | N8: ="quest_image_"&A8&"_"&"01" -> quest_image_mag_01 | R8: バトル系1 | S8: 強敵/ボスバトル1
A9: dos | B9: =CONCATENATE("series_banner_",A9) -> series_banner_dos | C9: series_logo_dos | D9: 道産子ギャルはなまらめんこい | E9: 水曜日 | F9: - | H9: =if(G9="",D9,if(G9="後ろ",D9&" "&F9,F9&" "&D9)) -> 道産子ギャルはなまらめんこい | I9: 008 | J9: dosanko | K9: =left(J9,1) -> d | L9: =left(J9,2) -> do | M9: =left(J9,3) -> dos | N9: ="quest_image_"&A9&"_"&"01" -> quest_image_dos_01 | R9: ラブコメ2 | S9: 強敵/ボス登場時2 （高難度）
A10: bat | B10: =CONCATENATE("series_banner_",A10) -> series_banner_bat | C10: series_logo_bat | D10: 忘却バッテリー | E10: 木曜日 | F10: - | H10: =if(G10="",D10,if(G10="後ろ",D10&" "&F10,F10&" "&D10)) -> 忘却バッテリー | I10: 009 | J10: batteri | K10: =left(J10,1) -> b | L10: =left(J10,2) -> ba | M10: =left(J10,3) -> bat | N10: ="quest_image_"&A10&"_"&"01" -> quest_image_bat_01 | R10: バトル系1 | S10: 強敵/ボス登場時2 （高難度）
A11: kai | B11: =CONCATENATE("series_banner_",A11) -> series_banner_kai | C11: series_logo_kai | D11: 怪獣８号 | E11: 金曜日 | F11: - | H11: =if(G11="",D11,if(G11="後ろ",D11&" "&F11,F11&" "&D11)) -> 怪獣８号 | I11: 010 | J11: kaiju | K11: =left(J11,1) -> k | L11: =left(J11,2) -> ka | M11: =left(J11,3) -> kai | N11: ="quest_image_"&A11&"_"&"01" -> quest_image_kai_01 | R11: バトル系1 | S11: 強敵/ボスバトル1
A12: yuw | B12: =CONCATENATE("series_banner_",A12) -> series_banner_yuw | C12: series_logo_yuw | D12: 2.5次元の誘惑 | E12: 土曜日 | F12: - | H12: =if(G12="",D12,if(G12="後ろ",D12&" "&F12,F12&" "&D12)) -> 2.5次元の誘惑 | I12: 011 | J12: yuwaku | K12: =left(J12,1) -> y | L12: =left(J12,2) -> yu | M12: =left(J12,3) -> yuw | N12: ="quest_image_"&A12&"_"&"01" -> quest_image_yuw_01 | R12: バトル系2 | S12: 強敵/ボス登場時2 （高難度）
A13: sur | B13: =CONCATENATE("series_banner_",A13) -> series_banner_sur | C13: series_logo_sur | D13: 魔都精兵のスレイブ | E13: 土曜日 | F13: - | H13: =if(G13="",D13,if(G13="後ろ",D13&" "&F13,F13&" "&D13)) -> 魔都精兵のスレイブ | I13: 012 | J13: sureibu | K13: =left(J13,1) -> s | L13: =left(J13,2) -> su | M13: =left(J13,3) -> sur | N13: ="quest_image_"&A13&"_"&"01" -> quest_image_sur_01 | R13: バトル系1 | S13: 強敵/ボスバトル1
A14: ron | B14: =CONCATENATE("series_banner_",A14) -> series_banner_ron | C14: series_logo_ron | D14: 鴨乃橋ロンの禁断推理 | E14: 日曜日 | F14: - | H14: =if(G14="",D14,if(G14="後ろ",D14&" "&F14,F14&" "&D14)) -> 鴨乃橋ロンの禁断推理 | I14: 013 | J14: ron | K14: =left(J14,1) -> r | L14: =left(J14,2) -> ro | M14: =left(J14,3) -> ron | N14: ="quest_image_"&A14&"_"&"01" -> quest_image_ron_01 | R14: シリアス | S14: 強敵/ボス登場時2 （高難度）
A15: aha | B15: =CONCATENATE("series_banner_",A15) -> series_banner_aha | C15: series_logo_aha | D15: 阿波連さんははかれない | E15: - | F15: - | H15: =if(G15="",D15,if(G15="後ろ",D15&" "&F15,F15&" "&D15)) -> 阿波連さんははかれない | I15: 014 | J15: aharen | K15: =left(J15,1) -> a | L15: =left(J15,2) -> ah | M15: =left(J15,3) -> aha | N15: ="quest_image_"&A15&"_"&"01" -> quest_image_aha_01 | R15: バトル系2 | S15: 強敵/ボス登場時2 （高難度）
A16: sum | B16: =CONCATENATE("series_banner_",A16) -> series_banner_sum | C16: series_logo_sum | D16: サマータイムレンダ | E16: - | F16: - | H16: =if(G16="",D16,if(G16="後ろ",D16&" "&F16,F16&" "&D16)) -> サマータイムレンダ | I16: 015 | J16: summer | K16: =left(J16,1) -> s | L16: =left(J16,2) -> su | M16: =left(J16,3) -> sum | N16: ="quest_image_"&A16&"_"&"01" -> quest_image_sum_01 | R16: シリアス | S16: 強敵/ボスバトル1
A17: jig | B17: =CONCATENATE("series_banner_",A17) -> series_banner_jig | C17: series_logo_jig | D17: 地獄楽 | E17: - | F17: - | H17: =if(G17="",D17,if(G17="後ろ",D17&" "&F17,F17&" "&D17)) -> 地獄楽 | I17: 016 | J17: jigoku | K17: =left(J17,1) -> j | L17: =left(J17,2) -> ji | M17: =left(J17,3) -> jig | N17: ="quest_image_"&A17&"_"&"01" -> quest_image_jig_01 | R17: シリアス | S17: 強敵/ボスバトル1
A18: tak | B18: =CONCATENATE("series_banner_",A18) -> series_banner_tak | C18: series_logo_tak | D18: タコピーの原罪 | E18: - | F18: - | H18: =if(G18="",D18,if(G18="後ろ",D18&" "&F18,F18&" "&D18)) -> タコピーの原罪 | I18: 017 | J18: takopi | K18: =left(J18,1) -> t | L18: =left(J18,2) -> ta | M18: =left(J18,3) -> tak | N18: ="quest_image_"&A18&"_"&"01" -> quest_image_tak_01 | R18: 日常・ギャグ | S18: 強敵/ボス登場時2 （高難度）
A19: osh | B19: =CONCATENATE("series_banner_",A19) -> series_banner_osh | C19: series_logo_tak | D19: 【推しの子】 | E19: - | F19: - | H19: =if(G19="",D19,if(G19="後ろ",D19&" "&F19,F19&" "&D19)) -> 【推しの子】 | I19: 018 | J19: oshinoko | K19: =left(J19,1) -> o | L19: =left(J19,2) -> os | M19: =left(J19,3) -> osh | N19: ="quest_image_"&A19&"_"&"01" -> quest_image_osh_01 | R19: ラブコメ2 | S19: 強敵/ボス登場時2 （高難度）
A20: you | B20: =CONCATENATE("series_banner_",A20) -> series_banner_you | C20: series_logo_tak | D20: 幼稚園WARS | E20: 木曜日 | F20: - | H20: =if(G20="",D20,if(G20="後ろ",D20&" "&F20,F20&" "&D20)) -> 幼稚園WARS | I20: 019 | J20: youchien | K20: =left(J20,1) -> y | L20: =left(J20,2) -> yo | M20: =left(J20,3) -> you | N20: ="quest_image_"&A20&"_"&"01" -> quest_image_you_01 | R20: バトル系2 | S20: 強敵/ボスバトル1
A21: kim | B21: =CONCATENATE("series_banner_",A21) -> series_banner_kim | C21: series_logo_tak | D21: 君のことが大大大大大好きな100人の彼女 | E21: 木曜日 | H21: =if(G21="",D21,if(G21="後ろ",D21&" "&F21,F21&" "&D21)) -> 君のことが大大大大大好きな100人の彼女 | I21: 020 | J21: kimino | K21: k | L21: ki | M21: kim | N21: ="quest_image_"&A21&"_"&"01" -> quest_image_kim_01 | R21: ラブコメ2 | S21: 強敵/ボス登場時2 （高難度）
A22: hut | B22: =CONCATENATE("series_banner_",A22) -> series_banner_hut | C22: series_logo_hut | D22: ふつうの軽音部 | E22: 日曜日 | F22: - | H22: ふつうの軽音部 | I22: 021 | J22: hutuu | K22: h | L22: hu | M22: hut | N22: ="quest_image_"&A22&"_"&"01" -> quest_image_hut_01 | R22: 日常・ギャグ | S22: 強敵/ボスバトル1
A23: rur | B23: =CONCATENATE("series_banner_",A23) -> series_banner_rur | C23: series_logo_rur | D23: ルリドラゴン | E23: - | F23: - | H23: ルリドラゴン | I23: 022 | J23: rurid | K23: r | L23: ru | M23: rur | N23: ="quest_image_"&A23&"_"&"01" -> quest_image_rur_01 | R23: 日常・ギャグ | S23: 強敵/ボスバトル1
A24: hyp | B24: =CONCATENATE("series_banner_",A24) -> series_banner_hyp | C24: series_logo_hyp | D24: ハイパーインフレーション | E24: - | F24: - | H24: ハイパーインフレーション | I24: 023 | J24: hyper | K24: h | L24: hy | M24: hyp | N24: ="quest_image_"&A24&"_"&"01" -> quest_image_hyp_01 | R24: シリアス | S24: 強敵/ボスバトル1
A25: gam | B25: =CONCATENATE("series_banner_",A25) -> series_banner_gam | C25: series_logo_gam | D25: ゲーミングお嬢様 | H25: ゲーミングお嬢様 | I25: 024 | J25: gamin | K25: g | L25: ga | M25: gam | N25: ="quest_image_"&A25&"_"&"01" -> quest_image_gam_01
A26: ara | B26: =CONCATENATE("series_banner_",A26) -> series_banner_ara | C26: series_logo_ara | D26: アラガネの子 | H26: アラガネの子 | I26: 025 | J26: aragane | K26: a | L26: ar | M26: ara | N26: ="quest_image_"&A26&"_"&"01" -> quest_image_ara_01
A27: aya | B27: =CONCATENATE("series_banner_",A27) -> series_banner_aya | C27: =CONCATENATE("series_logo_",A27) -> series_logo_aya | D27: あやかしトライアングル | H27: あやかしトライアングル | I27: 026 | J27: ayakasi | K27: a | L27: ay | M27: aya | N27: ="quest_image_"&A27&"_"&"01" -> quest_image_aya_01
A28: mar | B28: =CONCATENATE("series_banner_",A28) -> series_banner_mar | C28: =CONCATENATE("series_logo_",A28) -> series_logo_mar | D28: マリッジトキシン | H28: マリッジトキシン | I28: 027 | J28: marriage | K28: m | L28: ma | M28: mar | N28: ="quest_image_"&A28&"_"&"01" -> quest_image_mar_01
A29: sib | B29: =CONCATENATE("series_banner_",A29) -> series_banner_sib | C29: =CONCATENATE("series_logo_",A29) -> series_logo_sib | D29: シバつき物件 | H29: シバつき物件 | I29: 028 | J29: siba | K29: s | L29: si | M29: sib | N29: ="quest_image_"&A29&"_"&"01" -> quest_image_sib_01
A30: nek | B30: =CONCATENATE("series_banner_",A30) -> series_banner_nek | C30: =CONCATENATE("series_logo_",A30) -> series_logo_nek | D30: 猫田びより | H30: 猫田びより | I30: 029 | J30: neko | K30: n | L30: ne | M30: nek | N30: ="quest_image_"&A30&"_"&"01" -> quest_image_nek_01
A31: mad | B31: =CONCATENATE("series_banner_",A31) -> series_banner_mad | C31: =CONCATENATE("series_logo_",A31) -> series_logo_mad | D31: MAD | H31: MAD | I31: 030 | J31: mad | K31: m | L31: ma | M31: mad | N31: ="quest_image_"&A31&"_"&"01" -> quest_image_mad_01
A32: syu | B32: =CONCATENATE("series_banner_",A32) -> series_banner_syu | C32: =CONCATENATE("series_logo_",A32) -> series_logo_syu | D32: 終末のハーレム | H32: 終末のハーレム | I32: 031 | J32: syuumatu | K32: s | L32: sy | M32: syu | N32: ="quest_image_"&A32&"_"&"01" -> quest_image_syu_01
A33: aft | B33: =CONCATENATE("series_banner_",A33) -> series_banner_aft | C33: =CONCATENATE("series_logo_",A33) -> series_logo_aft | D33: 終末のハーレム After World | H33: 終末のハーレム After World | I33: 032 | J33: after | K33: a | L33: af | M33: aft | N33: ="quest_image_"&A33&"_"&"01" -> quest_image_aft_01
A34: fan | B34: =CONCATENATE("series_banner_",A34) -> series_banner_fan | C34: =CONCATENATE("series_logo_",A34) -> series_logo_fan | D34: 終末のハーレム ファンタジア | H34: 終末のハーレム ファンタジア | I34: 033 | J34: fantasia | K34: f | L34: fa | M34: fan | N34: ="quest_image_"&A34&"_"&"01" -> quest_image_fan_01
A35: kut | B35: =CONCATENATE("series_banner_",A35) -> series_banner_kut | C35: =CONCATENATE("series_logo_",A35) -> series_logo_kut | D35: 口が裂けても君には | H35: 口が裂けても君には | I35: 034 | J35: kuti | K35: k | L35: ku | M35: kut | N35: ="quest_image_"&A35&"_"&"01" -> quest_image_kut_01
A36: san | B36: =CONCATENATE("series_banner_",A36) -> series_banner_san | C36: =CONCATENATE("series_logo_",A36) -> series_logo_san | D36: サンキューピッチ | H36: サンキューピッチ | I36: 035 | J36: sankyuu | K36: s | L36: sa | M36: san | N36: ="quest_image_"&A36&"_"&"01" -> quest_image_san_01
A37: kus | B37: =CONCATENATE("series_banner_",A37) -> series_banner_kus | C37: =CONCATENATE("series_logo_",A37) -> series_logo_kus | D37: クソ女に幸あれ | H37: クソ女に幸あれ | I37: 036 | J37: kuso | K37: k | L37: ku | M37: kus | N37: ="quest_image_"&A37&"_"&"01" -> quest_image_kus_01
A38: han | B38: =CONCATENATE("series_banner_",A38) -> series_banner_han | C38: =CONCATENATE("series_logo_",A38) -> series_logo_han | D38: 半人前の恋人 | H38: 半人前の恋人 | I38: 037 | J38: hanninmae | K38: h | L38: ha | M38: han | N38: ="quest_image_"&A38&"_"&"01" -> quest_image_han_01
... A41: kaw | B41: =CONCATENATE("series_banner_",A41) -> series_banner_kaw | C41: =CONCATENATE("series_logo_",A41) -> series_logo_kaw | D41: カワイスギクライシス | H41: カワイスギクライシス | I41: 040 | J41: kawaisugi | K41: k | L41: ka | M41: kaw | N41: ="quest_image_"&A41&"_"&"01" -> quest_image_kaw_01
A42: c8m | B42: =CONCATENATE("series_banner_",A42) -> series_banner_c8m | C42: =CONCATENATE("series_logo_",A42) -> series_logo_c8m | D42: ちえりの恋は8メートル
...

Sheet キャラpng素材
A1: 作品ID | B1: 作品名 | C1: 立ち絵png_ID | D1: キャラ名（仮） | E1: キャラ名（監修FIX） | F1: valid_start_date | G1: valid_end_date | H1: デプロイ | I1: 補足
A2: spy | B2: SPY×FAMILY | C2: unit_stand_image_spy_00001 | D2: アーニャ・フォージャー | F2: 45658 | G2: 390812.5
A3: spy | B3: SPY×FAMILY | C3: unit_stand_image_spy_00002 | D3: イーデン校の生徒 アーニャ | F3: 45658 | G3: 390812.5
A4: spy | B4: SPY×FAMILY | C4: unit_stand_image_spy_00101 | D4: ロイド・フォージャー | F4: 45658 | G4: 390812.5
A5: spy | B5: SPY×FAMILY | C5: unit_stand_image_spy_00201 | D5: ヨル・フォージャー | F5: 45658 | G5: 390812.5
A6: spy | B6: SPY×FAMILY | C6: unit_stand_image_spy_00301 | D6: ダミアン・デズモンド | F6: 45658 | G6: 390812.5
A7: spy | B7: SPY×FAMILY | C7: unit_stand_image_spy_00401 | D7: フランキー・フランクリン | F7: 45658 | G7: 390812.5
A8: aka | B8: ラーメン赤猫 | C8: unit_stand_image_aka_00001 | D8: 佐々木 | F8: 45658 | G8: 390812.5
A9: aka | B9: ラーメン赤猫 | C9: unit_stand_image_aka_00101 | D9: 文蔵 | F9: 45658 | G9: 390812.5
A10: rik | B10: トマトイプーのリコピン | C10: unit_stand_image_rik_00001 | D10: リコピン | F10: 45658 | G10: 390812.5
A11: rik | B11: トマトイプーのリコピン | C11: unit_stand_image_rik_00101 | D11: 甘戸 めめ | F11: 45658 | G11: 390812.5
A12: rik | B12: トマトイプーのリコピン | C12: unit_stand_image_rik_00201 | D12: チアミン | F12: 45658 | G12: 390812.5
A13: dan | B13: ダンダダン | C13: unit_stand_image_dan_00001 | D13: オカルン （制服着用） | F13: 45658 | G13: 390812.5
... A51: sum | B51: サマータイムレンダ | C51: unit_stand_image_sum_00201 | D51: 小舟 澪 | F51: 45658 | G51: 390812.5

Sheet ゲート
A1: 作品ID | B1: 作品名 | C1: ゲート_ID | D1: asset_key | E1: ゲート名（管理用） | F1: ゲート位置 | G1: 制作番号 | H1: valid_start_date | I1: valid_end_date | J1: デプロイ | K1: 補足
A2: gom | B2: 姫様“拷問”の時間です | C2: =CONCATENATE("outpost_",A2,"_",F2,"_",text(G2,"0000")) -> outpost_gom_ally_0001 | D2: =CONCATENATE(A2,"_",F2,"_",text(G2,"0000")) -> gom_ally_0001 | E2: 姫+エクス | F2: ally | G2: 1
A3: gom | B3: 姫様“拷問”の時間です | C3: =CONCATENATE("outpost_",A3,"_",F3,"_",text(G3,"0000")) -> outpost_gom_enemy_0001 | D3: =CONCATENATE(A3,"_",F3,"_",text(G3,"0000")) -> gom_enemy_0001 | E3: トーチャー（ピック）+アイアンメイデン | F3: enemy | G3: 1
A4: gom | B4: 姫様“拷問”の時間です | C4: =CONCATENATE("outpost_",A4,"_",F4,"_",text(G4,"0000")) -> outpost_gom_enemy_0002 | D4: =CONCATENATE(A4,"_",F4,"_",text(G4,"0000")) -> gom_enemy_0002 | E4: トーチャー（ゴリラ） | F4: enemy | G4: 2
A5: gom | B5: 姫様“拷問”の時間です | C5: =CONCATENATE("outpost_",A5,"_",F5,"_",text(G5,"0000")) -> outpost_gom_enemy_0003 | D5: =CONCATENATE(A5,"_",F5,"_",text(G5,"0000")) -> gom_enemy_0003 | E5: クロル | F5: enemy | G5: 3
A6: kim | B6: {=iferror(INDEX('作品'!D:D,MATCH(A6,'作品'!A:A,0),0),"error")} -> 君のことが大大大大大好きな100人の彼女 | C6: =CONCATENATE("outpost_",A6,"_",F6,"_",text(G6,"0000")) -> outpost_kim_enemy_0001 | D6: =CONCATENATE(A6,"_",F6,"_",text(G6,"0000")) -> kim_enemy_0001 | E6: 愛城恋太郎 | F6: enemy | G6: 1
A7: glo | B7: GLOW | C7: =CONCATENATE("outpost_",A7,"_",F7,"_",text(G7,"0000")) -> outpost_glo_enemy_0001 | D7: =CONCATENATE(A7,"_",F7,"_",text(G7,"0000")) -> glo_enemy_0001 | E7: 宝箱 | F7: enemy | G7: 1
A8: sample | B8: サンプル1 | C8: =CONCATENATE("outpost_",A8,"_",F8,"_",text(G8,"0000")) -> outpost_sample_ally_0001 | D8: =CONCATENATE(A8,"_",F8,"_",text(G8,"0000")) -> sample_ally_0001 | E8: ID発行イメージサンプル | F8: ally | G8: 1 | K8: 命名規則： outpost_作品ID_ゲート位置_制作番号4桁
A9: sample | B9: サンプル2 | C9: =CONCATENATE("outpost_",A9,"_",F9,"_",text(G9,"0000")) -> outpost_sample_ally_0002 | D9: =CONCATENATE(A9,"_",F9,"_",text(G9,"0000")) -> sample_ally_0002 | E9: ID発行イメージサンプル | F9: ally | G9: 2
A10: sample | B10: サンプル3 | C10: =CONCATENATE("outpost_",A10,"_",F10,"_",text(G10,"0000")) -> outpost_sample_enemy_0001 | D10: =CONCATENATE(A10,"_",F10,"_",text(G10,"0000")) -> sample_enemy_0001 | E10: ID発行イメージサンプル | F10: enemy | G10: 1

Sheet 原画のかけら原画
A1: 作品_ID | B1: 作品名 | C1: 接頭語（カテゴリー） | D1: アイテム_ID | E1: assetKey | F1: drop_ID | G1: アイテム名 | H1: レアリティ | I1: 最大所持数 | J1: フレーバーテキスト | K1: アイテム備考 | L1: start_date | M1: リリースキー
A2: 原画のかけら1枚原画完成ダイアログ用（524*524）ID 解像度高い方
A3: spy | B3: {=iferror(INDEX('作品'!D:D,MATCH(A3,'作品'!A:A,0),0),"error")} -> SPY×FAMILY | C3: artwork | D3: =$C$15&"_"&$A3&"_"&TEXT(countif($A3:A$3,A3),"0000") -> artwork_spy_0001 | E3: =D3 -> artwork_spy_0001 | G3: 秘密の家族 | H3: - | I3: 1 | J3: 父はスパイ、母は殺し屋、娘は超能力者！？ 全員が秘密を抱えた家族生活が始まる！ | K3: ノーマル | L3: 45924.625 | M3: 202509010
A4: spy | B4: {=iferror(INDEX('作品'!D:D,MATCH(A4,'作品'!A:A,0),0),"error")} -> SPY×FAMILY | C4: artwork | D4: =$C$15&"_"&$A4&"_"&TEXT(countif($A$3:A4,A4),"0000") -> artwork_spy_0002 | E4: =D4 -> artwork_spy_0002 | G4: 素敵な家族 | H4: - | I4: 1 | J4: 共通認識を深めるために出かけた3人は、 協力してひったくりを捕まえる。 | K4: ハード | L4: 45924.625 | M4: 202509010
A5: spy | B5: {=iferror(INDEX('作品'!D:D,MATCH(A5,'作品'!A:A,0),0),"error")} -> SPY×FAMILY | C5: artwork | D5: =$C$15&"_"&$A5&"_"&TEXT(countif($A$3:A5,A5),"0000") -> artwork_spy_0003 | E5: =D5 -> artwork_spy_0003 | G5: 明るい未来に！！ | H5: - | I5: 1 | J5: イーデンでの面接試験の後、 落ち込むロイドを励ますために お茶で乾杯！ | K5: Ex | L5: 45924.625 | M5: 202509010
A7: gom | B7: {=iferror(INDEX('作品'!D:D,MATCH(A7,'作品'!A:A,0),0),"error")} -> 姫様“拷問”の時間です | C7: artwork | D7: =$C$15&"_"&$A7&"_"&TEXT(countif($A$3:A7,A7),"0000") -> artwork_gom_0001 | E7: =D7 -> artwork_gom_0001 | G7: 決して屈しない! | H7: - | I7: 1 | J7: 国王軍第三騎士団”騎士団長”にして王女の姫様は、魔王軍からの”拷問”に抵抗する! | K7: ノーマル | L7: 45924.625 | M7: 202509010
A8: gom | B8: {=iferror(INDEX('作品'!D:D,MATCH(A8,'作品'!A:A,0),0),"error")} -> 姫様“拷問”の時間です | C8: artwork | D8: =$C$15&"_"&$A8&"_"&TEXT(countif($A$3:A8,A8),"0000") -> artwork_gom_0002 | E8: =D8 -> artwork_gom_0002 | G8: 姫様”拷問”の時間です | H8: - | I8: 1 | J8: 魔王軍 最高位拷問官のトーチャーは、どのような拷問をするのか・・・ | K8: ハード | L8: 45924.625 | M8: 202509010
A9: gom | B9: {=iferror(INDEX('作品'!D:D,MATCH(A9,'作品'!A:A,0),0),"error")} -> 姫様“拷問”の時間です | C9: artwork | D9: =$C$15&"_"&$A9&"_"&TEXT(countif($A$3:A9,A9),"0000") -> artwork_gom_0003 | E9: =D9 -> artwork_gom_0003 | G9: 姫様と最高位拷問官 | H9: - | I9: 1 | J9: 拷問が終われば、立場を気にせずにパーティーだ! | K9: Ex | L9: 45924.625 | M9: 202509010
A11: aka | B11: {=iferror(INDEX('作品'!D:D,MATCH(A11,'作品'!A:A,0),0),"error")} -> ラーメン赤猫 | C11: artwork | D11: =$C$15&"_"&$A11&"_"&TEXT(countif($A$3:A11,A11),"0000") -> artwork_aka_0001 | E11: =D11 -> artwork_aka_0001 | G11: 新メニューの試食 | H11: - | I11: 1 | J11: 早起きした珠子に試食を頼む文蔵。​ もしかして、新メニュー！？ | K11: ノーマル | L11: 45924.625 | M11: 202509010
A12: aka | B12: {=iferror(INDEX('作品'!D:D,MATCH(A12,'作品'!A:A,0),0),"error")} -> ラーメン赤猫 | C12: artwork | D12: =$C$15&"_"&$A12&"_"&TEXT(countif($A$3:A12,A12),"0000") -> artwork_aka_0002 | E12: =D12 -> artwork_aka_0002 | G12: 話は聞かせてもらった！ | H12: - | I12: 1 | J12: 新メニュー開発に挑戦する文蔵。​ ラーメン赤猫のみんなで新メニュー開発だ！ | K12: ハード | L12: 45924.625 | M12: 202509010
A13: aka | B13: {=iferror(INDEX('作品'!D:D,MATCH(A13,'作品'!A:A,0),0),"error")} -> ラーメン赤猫 | C13: artwork | D13: =$C$15&"_"&$A13&"_"&TEXT(countif($A$3:A13,A13),"0000") -> artwork_aka_0003 | E13: =D13 -> artwork_aka_0003 | G13: みんなでお昼寝 | H13: - | I13: 1 | J13: 昼営業と夜営業の間の休憩時間。​ 至福のお昼寝タイム！ | K13: Ex | L13: 45924.625 | M13: 202509010
A15: dan | B15: {=iferror(INDEX('作品'!D:D,MATCH(A15,'作品'!A:A,0),0),"error")} -> ダンダダン | C15: artwork | D15: =$C$15&"_"&$A15&"_"&TEXT(countif($A$3:A15,A15),"0000") -> artwork_dan_0001 | E15: =D15 -> artwork_dan_0001 | G15: オカルトの話しよーぜ | H15: - | I15: 1 | J15: 度重なる危機を乗り越え、 なんだか友達になれそうな二人。 | K15: ノーマル | L15: 45924.625 | M15: 202509010
A16: dan | B16: {=iferror(INDEX('作品'!D:D,MATCH(A16,'作品'!A:A,0),0),"error")} -> ダンダダン | C16: artwork | D16: =$C$15&"_"&$A16&"_"&TEXT(countif($A$3:A16,A16),"0000") -> artwork_dan_0002 | E16: =D16 -> artwork_dan_0002 | G16: ターボババアをぶっ飛ばそう | H16: - | I16: 1 | J16: オカルンの呪いを解くために、トンネルで再びターボババアと対峙する。 | K16: ハード | L16: 45924.625 | M16: 202509010
A17: dan | B17: {=iferror(INDEX('作品'!D:D,MATCH(A17,'作品'!A:A,0),0),"error")} -> ダンダダン | C17: artwork | D17: =$C$15&"_"&$A17&"_"&TEXT(countif($A$3:A17,A17),"0000") -> artwork_dan_0003 | E17: =D17 -> artwork_dan_0003 | G17: 力が溢れてくるぜ・・・!! | H17: - | I17: 1 | J17: ターボババアの呪いを解放した「オカルン」。超スピードで移動できるが、ネガティブになってしまう。 | K17: Ex | L17: 45924.625 | M17: 202509010
A19: jig | B19: {=iferror(INDEX('作品'!D:D,MATCH(A19,'作品'!A:A,0),0),"error")} -> 地獄楽 | C19: artwork | D19: =$C$15&"_"&$A19&"_"&TEXT(countif($A$3:A19,A19),"0000") -> artwork_jig_0001 | E19: =D19 -> artwork_jig_0001 | G19: 必ず生きて帰る 君のために・・・!! | H19: - | I19: 1 | J19: 帰りを待つ愛する人のために、決意する。 | K19: ノーマル | L19: 45924.625 | M19: 202509010
... A29: chi | B29: {=iferror(INDEX('作品'!D:D,MATCH(A29,'作品'!A:A,0),0),"error")} -> チェンソーマン | C29: artwork | D29: =$C$15&"_"&$A29&"_"&TEXT(countif($A$3:A29,A29),"0000") -> artwork_chi_0003 | E29: =D29 -> artwork_chi_0003 | G29: 公安対魔特異４課 | H29: - | I29: 1 | J29: 公安に悪魔の駆除要請。​ 公安対魔特異４課６人、全員集合！​ | K29: Ex | L29: 45924.625 | M29: 202509010
H30: - | I30: 1 | J30: -
A31: kai | B31: {=iferror(INDEX('作品'!D:D,MATCH(A31,'作品'!A:A,0),0),"error")} -> 怪獣８号 | C31: artwork | D31: =$C$15&"_"&$A31&"_"&TEXT(countif($A$3:A31,A31),"0000") -> artwork_kai_0001 | E31: =D31 -> artwork_kai_0001 | G31: 戦力解放！！ | H31: - | I31: 1 | J31: 怪獣襲来！ 解放戦力１％になった、 今までとは違うカフカを見せてやる！ | K31: ノーマル | L31: 45924.625 | M31: 202509010
A32: kai | B32: {=iferror(INDEX('作品'!D:D,MATCH(A32,'作品'!A:A,0),0),"error")} -> 怪獣８号 | C32: artwork | D32: =$C$15&"_"&$A32&"_"&TEXT(countif($A$3:A32,A32),"0000") -> artwork_kai_0002 | E32: =D32 -> artwork_kai_0002 | G32: 取るべき行動 | H32: - | I32: 1 | J32: 防衛隊員選別試験二次最終審査開始！ 攻撃能力の低いカフカとレノの取るべき行動は…！？ | K32: ハード | L32: 45924.625 | M32: 202509010
A33: kai | B33: {=iferror(INDEX('作品'!D:D,MATCH(A33,'作品'!A:A,0),0),"error")} -> 怪獣８号 | C33: artwork | D33: =$C$15&"_"&$A33&"_"&TEXT(countif($A$3:A33,A33),"0000") -> artwork_kai_0003 | E33: =D33 -> artwork_kai_0003 | G33: あとは俺に任せろ | H33: - | I33: 1 | J33: 防衛隊入隊試験中に現れた謎の大怪獣。 他の受験者を避難させる為に足止めをするキコルの前に、 怪獣8号が現れる…！！ | K33: Ex | L33: 45924.625 | M33: 202509010
H34: - | J34: -
A35: sur | B35: {=iferror(INDEX('作品'!D:D,MATCH(A35,'作品'!A:A,0),0),"error")} -> 魔都精兵のスレイブ | C35: artwork | D35: =$C$15&"_"&$A35&"_"&TEXT(countif($A$3:A35,A35),"0000") -> artwork_sur_0001 | E35: =D35 -> artwork_sur_0001 | G35: お前を私の奴隷にする | H35: - | I35: 1 | J35: 魔都に迷い込んだ和倉 優希を助けた 魔防隊七番組組長、羽前 京香は、 突然奴隷にすると言い出し…！？ | K35: ノーマル | L35: 45924.625 | M35: 202509010
A36: sur | B36: {=iferror(INDEX('作品'!D:D,MATCH(A36,'作品'!A:A,0),0),"error")} -> 魔都精兵のスレイブ | C36: artwork | D36: =$C$15&"_"&$A36&"_"&TEXT(countif($A$3:A36,A36),"0000") -> artwork_sur_0002 | E36: =D36 -> artwork_sur_0002 | G36: 無窮の鎖 | H36: - | I36: 1 | J36: 無窮の鎖となった優希は、 驚異的な力を発揮する！ | K36: ハード | L36: 45924.625 | M36: 202509010
A37: sur | B37: {=iferror(INDEX('作品'!D:D,MATCH(A37,'作品'!A:A,0),0),"error")} -> 魔都精兵のスレイブ | C37: artwork | D37: =$C$15&"_"&$A37&"_"&TEXT(countif($A$3:A37,A37),"0000") -> artwork_sur_0003 | E37: =D37 -> artwork_sur_0003 | G37: 魔都精兵七番隊 | H37: - | I37: 1 | J37: 京香の奴隷となった優希は、 七番隊組寮の管理人となる！ | K37: Ex | L37: 45924.625 | M37: 202509010
H38: - | I38: 1 | J38: -
A39: rik | B39: {=iferror(INDEX('作品'!D:D,MATCH(A39,'作品'!A:A,0),0),"error")} -> トマトイプーのリコピン | C39: artwork | D39: =$C$15&"_"&$A39&"_"&TEXT(countif($A$3:A39,A39),"0000") -> artwork_rik_0001 | E39: =D39 -> artwork_rik_0001 | G39: フワフワ乗り物の雲 | H39: - | I39: 1 | J39: リコピンのパパが設計をしたフワフワ乗り物の雲！ 他にも食べられる雲やインテリア雲があるぞ！ | K39: ノーマル | L39: 45924.625 | M39: 202509010
A40: rik | B40: {=iferror(INDEX('作品'!D:D,MATCH(A40,'作品'!A:A,0),0),"error")} -> トマトイプーのリコピン | C40: artwork | D40: =$C$15&"_"&$A40&"_"&TEXT(countif($A$3:A40,A40),"0000") -> artwork_rik_0002 | E40: =D40 -> artwork_rik_0002 | G40: めめちゃんの世界へようこそ | H40: - | I40: 1 | J40: めめちゃんの世界に来てしまったリコピン！ 洗濯をしたり、不燃ごみをまとめたり…！？ | K40: ハード | L40: 45924.625 | M40: 202509010
A41: rik | B41: {=iferror(INDEX('作品'!D:D,MATCH(A41,'作品'!A:A,0),0),"error")} -> トマトイプーのリコピン | C41: artwork | D41: =$C$15&"_"&$A41&"_"&TEXT(countif($A$3:A41,A41),"0000") -> artwork_rik_0003 | E41: =D41 -> artwork_rik_0003 | G41: はじめましてぼくリコピン | H41: - | I41: 1 | J41: リコピンはトマトの苗から生まれたトイプードル！ トマトイプーの3さいの男の子なんだよ！ | K41: Ex | L41: 45924.625 | M41: 202509010
H42: - | I42: 1 | J42: -
A43: mag | B43: {=iferror(INDEX('作品'!D:D,MATCH(A43,'作品'!A:A,0),0),"error")} -> 株式会社マジルミエ | C43: artwork | D43: =$C$15&"_"&$A43&"_"&TEXT(countif($A$3:A43,A43),"0000") -> artwork_mag_0001 | E43: =D43 -> artwork_mag_0001 | G43: 初めての変身 | H43: - | I43: 1 | J43: 魔法少女としての初仕事！​ 出動前に変身だ！ | K43: ノーマル | L43: 45924.625 | M43: 202509010
A44: mag | B44: {=iferror(INDEX('作品'!D:D,MATCH(A44,'作品'!A:A,0),0),"error")} -> 株式会社マジルミエ | C44: artwork | D44: =$C$15&"_"&$A44&"_"&TEXT(countif($A$3:A44,A44),"0000") -> artwork_mag_0002 | E44: =D44 -> artwork_mag_0002 | G44: 業務完了！ | H44: - | I44: 1 | J44: 面接中に現れた怪異に対応すべく現れた​ 魔法少女・越谷 仁美。 | K44: ハード | L44: 45924.625 | M44: 202509010
A45: mag | B45: {=iferror(INDEX('作品'!D:D,MATCH(A45,'作品'!A:A,0),0),"error")} -> 株式会社マジルミエ | C45: artwork | D45: =$C$15&"_"&$A45&"_"&TEXT(countif($A$3:A45,A45),"0000") -> artwork_mag_0003 | E45: =D45 -> artwork_mag_0003 | G45: 飛ばすよ！ | H45: - | I45: 1 | J45: 初めての仕事、初めてのホーキ、初めての魔法！ 初めてでももう立派な魔法少女。 | K45: Ex | L45: 45924.625 | M45: 202509010
H46: - | I46: 1 | J46: -
A47: sum | B47: {=iferror(INDEX('作品'!D:D,MATCH(A47,'作品'!A:A,0),0),"error")} -> サマータイムレンダ | C47: artwork | D47: =$C$15&"_"&$A47&"_"&TEXT(countif($A$3:A47,A47),"0000") -> artwork_sum_0001 | E47: =D47 -> artwork_sum_0001 | G47: 言うてる場合かっ！！！ | H47: - | I47: 1 | J47: 見つからないように人混みの中を駆け抜ける 慎平と潮。 | K47: ノーマル | L47: 45924.625 | M47: 202509010
A48: sum | B48: {=iferror(INDEX('作品'!D:D,MATCH(A48,'作品'!A:A,0),0),"error")} -> サマータイムレンダ | C48: artwork | D48: =$C$15&"_"&$A48&"_"&TEXT(countif($A$3:A48,A48),"0000") -> artwork_sum_0002 | E48: =D48 -> artwork_sum_0002 | G48: ちゃんと見つけてよ | H48: - | I48: 1 | J48: 夏祭りの人混みで潮を見かけたような気がして 向かった先の浜辺には潮の姿が…！？ | K48: ハード | L48: 45924.625 | M48: 202509010
A49: sum | B49: {=iferror(INDEX('作品'!D:D,MATCH(A49,'作品'!A:A,0),0),"error")} -> サマータイムレンダ | C49: artwork | D49: =$C$15&"_"&$A49&"_"&TEXT(countif($A$3:A49,A49),"0000") -> artwork_sum_0003 | E49: =D49 -> artwork_sum_0003 | G49: 言おうと思てたことあんねん | H49: - | I49: 1 | J49: 浜辺で再会した、死んだはずの幼馴染潮。 彼女は、慎平に再会できたら 言おうと思っていたことがあるという。 | K49: Ex | L49: 45924.625 | M49: 202509010
H50: -
A51: glo | B51: {=iferror(INDEX('作品'!D:D,MATCH(A51,'作品'!A:A,0),0),"error")} -> GLOW | C51: artwork | D51: artwork_tutorial_0001 | E51: =D51 -> artwork_tutorial_0001 | G51: 希望のコマ | H51: - | I51: 1 | K51: チュートリアル初期設定。最初から持ち物に所持。 | L51: 45924.625 | M51: 202509010 ※チュートリアル使用
A52: glo | B52: {=iferror(INDEX('作品'!D:D,MATCH(A52,'作品'!A:A,0),0),"error")} -> GLOW | C52: artwork | D52: =$C$15&"_"&$A52&"_"&TEXT(countif($A$3:A52,A52),"0000") -> artwork_glo_0002 | E52: =D52 -> artwork_glo_0002 | G52: ジャンプラバースファントム侵攻 | H52: - | I52: 1 | J52: 侵略されたジャンプラバースの画像 | K52: エネミー専用のゲート原画 | L52: 45924.625 | M52: 202509010 ※チュートリアル使用
A54: osh | B54: {=iferror(INDEX('作品'!D:D,MATCH(A54,'作品'!A:A,0),0),"error")} -> 【推しの子】 | C54: artwork | D54: =$C$15&"_"&$A54&"_"&TEXT(countif($A$3:A54,A54),"0000") -> artwork_osh_0001 | E54: =D54 -> artwork_osh_0001 | G54: 激バズ！本能のヲタ芸！ | H54: - | I54: 1 | J54: 推しへの愛が高まりすぎた双子の赤ちゃんが ヲタ芸を打つという異常事態に思わずアイドルも個レス！ | K54: ノーマル | L54: 45658 | M54: 202512020
...

Sheet キャラ
A1: 作品ID | B1: 作品名 | C1: 識別ID | D1: キャラ_ID | E1: キャラ名（仮） | F1: キャラ名（監修FIX） | G1: 必殺ワザ名（監修FIX） | H1: レアリティ | I1: ラベル | J1: 属性 | K1: キャラ立ち位置 | L1: ロール | M1: 通常攻撃モーション | N1: 攻撃射程 | O1: 必殺ワザモーション | P1: 必殺ワザ発動有無 | Q1: 通常攻撃モーション | R1: 通常攻撃発生 | S1: 必殺攻撃モーション | T1: 必殺攻撃発生 | U1: valid_start_date | V1: valid_end_date | W1: catch_copy_image_filename | X1: ノーマル敵専用アイコン_ID | Y1: BOSS専用アイコン_ID | Z1: 通常攻撃Asset | AA1: 必殺ワザAsset | AB1: デプロイ | AC1: プランナー監修状況 | AD1: 全て監修状況 | AE1: 補足 | AF1: 発注依頼書状況 | AG1: リリースキー
A2: spy | B2: {=iferror(INDEX('作品'!D:D,MATCH(A2,'作品'!A:A,0),0),"error")} -> SPY×FAMILY | C2: 00001 | D2: =K2&"_"&A2&"_"&C2 -> chara_spy_00001 | E2: わくわく アーニャ | F2: わくわく アーニャ | G2: せいふくのアーニャかわいい？ | H2: UR | I2: PremiumUR | J2: 無 | K2: chara | L2: スペシャル | M2: - | N2: ー | O2: - | P2: =RIGHT(D2,5) -> 00001 | Q2: - | R2: - | S2: 3.44 | T2: 0 | U2: 45922.458 | V2: 390812.5 | W2: ="catchcopy_character_"&text(D2,"000000")&".png" -> catchcopy_character_chara_spy_00001.png | X2: ="enemy_icon_"&K2&"_"&A2&"_"&C2 -> enemy_icon_chara_spy_00001 | Y2: ="boss_icon_"&K2&"_"&A2&"_"&C2 -> boss_icon_chara_spy_00001 | AA2: chara_spy_00001_special | AB2: リリース時 | AC2: 監修通過 | AE2: ▼フレーバーなど下記のシートに記載 GLOW_キャラ名称＆キャラセリフ資料 | AF2: 未 | AG2: 202509010_リリース
A3: spy | B3: {=iferror(INDEX('作品'!D:D,MATCH(A3,'作品'!A:A,0),0),"error")} -> SPY×FAMILY | C3: 00002 | D3: =K3&"_"&A3&"_"&C3 -> chara_spy_00002 | F3: 選定中 | G3: （未FIX）アーニャがんばるます！ | H3: SSR | I3: DropSSR | J3: 無 | K3: chara | L3: スペシャル | M3: - | N3: ー | O3: - | P3: =RIGHT(D3,5) -> 00002 | Q3: - | R3: - | S3: 2.4 | T3: stop無:1.03 | U3: 実装未定 | V3: 390812.5 | W3: ="catchcopy_character_"&text(D3,"000000")&".png" -> catchcopy_character_chara_spy_00002.png | X3: ="enemy_icon_"&K3&"_"&A3&"_"&C3 -> enemy_icon_chara_spy_00002 | Y3: ="boss_icon_"&K3&"_"&A3&"_"&C3 -> boss_icon_chara_spy_00002 | AB3: 1周年 | AC3: 監修中 | AG3: 999999999_リリースキー未定
A4: spy | B4: {=iferror(INDEX('作品'!D:D,MATCH(A4,'作品'!A:A,0),0),"error")} -> SPY×FAMILY | C4: 00101 | D4: =K4&"_"&A4&"_"&C4 -> chara_spy_00101 | E4: <黄昏> ロイド | F4: <黄昏> ロイド | G4: 終わりにしよう | H4: UR | I4: PremiumUR | J4: 黄 | K4: chara | L4: アタック | M4: shageki_1 | N4: Long | O4: shageki_1 | P4: =RIGHT(D4,5) -> 00101 | Q4: 1.64 | R4: 0.83 | S4: 2.50 | T4: 1.33 | U4: 45922.458 | V4: 390812.5 | W4: ="catchcopy_character_"&text(D4,"000000")&".png" -> catchcopy_character_chara_spy_00101.png | X4: ="enemy_icon_"&K4&"_"&A4&"_"&C4 -> enemy_icon_chara_spy_00101 | Y4: ="boss_icon_"&K4&"_"&A4&"_"&C4 -> boss_icon_chara_spy_00101 | Z4: chara_spy_00101_normal | AA4: chara_spy_00101_special | AB4: リリース時 | AC4: 監修通過 | AE4: ▼フレーバーなど下記のシートに記載 GLOW_キャラ名称＆キャラセリフ資料 | AF4: 未 | AG4: 202509010_リリース
A5: spy | B5: {=iferror(INDEX('作品'!D:D,MATCH(A5,'作品'!A:A,0),0),"error")} -> SPY×FAMILY | C5: 00201 | D5: =K5&"_"&A5&"_"&C5 -> chara_spy_00201 | E5: <いばら姫> ヨル | F5: <いばら姫> ヨル | G5: この手が血で汚れても構わない | H5: UR | I5: PremiumUR | J5: 赤 | K5: chara | L5: アタック | M5: zangeki_1 | N5: Middle | O5: dageki_1 | P5: =RIGHT(D5,5) -> 00201 | Q5: 1.42 | R5: stop無:1回目 0.61 | S5: 2.50 | T5: stop有:1回目 0.73 | U5: 45922.458 | V5: 390812.5 | W5: ="catchcopy_character_"&text(D5,"000000")&".png" -> catchcopy_character_chara_spy_00201.png | X5: ="enemy_icon_"&K5&"_"&A5&"_"&C5 -> enemy_icon_chara_spy_00201 | Y5: ="boss_icon_"&K5&"_"&A5&"_"&C5 -> boss_icon_chara_spy_00201 | Z5: chara_spy_00201_normal | AA5: chara_spy_00201_special | AB5: リリース時 | AC5: 監修通過 | AE5: ▼フレーバーなど下記のシートに記載 GLOW_キャラ名称＆キャラセリフ資料 | AF5: 未 | AG5: 202509010_リリース
A6: spy | B6: {=iferror(INDEX('作品'!D:D,MATCH(A6,'作品'!A:A,0),0),"error")} -> SPY×FAMILY | C6: 00301 | D6: =K6&"_"&A6&"_"&C6 -> chara_spy_00301 | E6: ダミアン・デズモンド | F6: ダミアン・デズモンド | G6: いい気になるなよ | H6: SR | I6: DropSR | J6: 無 | K6: chara | L6: スペシャル | M6: - | N6: ー | O6: - | P6: =RIGHT(D6,5) -> 00301 | Q6: - | R6: - | S6: 2.10 | T6: 0 | U6: 45936.625 | V6: 390812.5 | W6: ="catchcopy_character_"&text(D6,"000000")&".png" -> catchcopy_character_chara_spy_00301.png | X6: ="enemy_icon_"&K6&"_"&A6&"_"&C6 -> enemy_icon_chara_spy_00301 | Y6: ="boss_icon_"&K6&"_"&A6&"_"&C6 -> boss_icon_chara_spy_00301 | AA6: chara_spy_00301_special | AB6: SPY×FAMILYいいジャン祭 | AC6: 監修通過 | AE6: ▼フレーバーなど下記のシートに記載 GLOW_キャラ名称＆キャラセリフ資料 | AF6: 未 | AG6: 202510010_SPY×FAMILY
A7: spy | B7: {=iferror(INDEX('作品'!D:D,MATCH(A7,'作品'!A:A,0),0),"error")} -> SPY×FAMILY | C7: 00401 | D7: =K7&"_"&A7&"_"&C7 -> chara_spy_00401 | E7: フランキー・フランクリン | F7: フランキー・フランクリン | G7: 超人外骨格！！ | H7: SR | I7: DropSR | J7: 緑 | K7: chara | L7: ディフェンス | M7: dageki_2 | N7: Short | O7: dageki_2 | P7: =RIGHT(D7,5) -> 00401 | Q7: 1.20 | R7: 0.50 | S7: 2.75 | T7: 1.34 | U7: 45936.625 | V7: 390812.5 | W7: ="catchcopy_character_"&text(D7,"000000")&".png" -> catchcopy_character_chara_spy_00401.png | X7: ="enemy_icon_"&K7&"_"&A7&"_"&C7 -> enemy_icon_chara_spy_00401 | Y7: ="boss_icon_"&K7&"_"&A7&"_"&C7 -> boss_icon_chara_spy_00401 | Z7: chara_spy_00401_normal | AA7: chara_spy_00401_special | AB7: リリース時 | AC7: 監修通過 | AE7: ▼フレーバーなど下記のシートに記載 GLOW_キャラ名称＆キャラセリフ資料 | AF7: 未 | AG7: 202509010_リリース
A8: spy | B8: {=iferror(INDEX('作品'!D:D,MATCH(A8,'作品'!A:A,0),0),"error")} -> SPY×FAMILY | C8: 00501 | D8: =K8&"_"&A8&"_"&C8 -> chara_spy_00501 | E8: ユーリ・ブライア | F8: 姉を想う盲愛 ユーリ・ブライア | G8: 姉さぁーーーん♡ | H8: UR | I8: PremiumUR | J8: 青 | K8: chara | L8: ディフェンス | M8: dageki_1 | N8: Short | O8: - | P8: =RIGHT(D8,5) -> 00501 | Q8: 1.13 | R8: stop有:1回目 0.33 | S8: 2.33 | T8: stop無:1回目 1.17 | U8: 45936.625 | V8: 390812.5 | W8: ="catchcopy_character_"&text(D8,"000000")&".png" -> catchcopy_character_chara_spy_00501.png | X8: ="enemy_icon_"&K8&"_"&A8&"_"&C8 -> enemy_icon_chara_spy_00501 | Y8: ="boss_icon_"&K8&"_"&A8&"_"&C8 -> boss_icon_chara_spy_00501 | AA8: chara_spy_00501_special | AB8: SPY×FAMILYいいジャン祭 | AC8: 監修通過 | AE8: ▼フレーバーなど下記のシートに記載 GLOW_キャラ名称＆キャラセリフ資料 | AF8: 未 | AG8: 202510010_SPY×FAMILY
A9: aka | B9: {=iferror(INDEX('作品'!D:D,MATCH(A9,'作品'!A:A,0),0),"error")} -> ラーメン赤猫 | C9: 00001 | D9: =K9&"_"&A9&"_"&C9 -> chara_aka_00001 | E9: 佐々木 | F9: 佐々木 | G9: ハチワレの猫の佐々木さん | H9: R | I9: PremiumR | J9: 赤 | K9: chara | L9: ディフェンス | M9: dageki_1 | N9: Short | O9: zangeki_1 | P9: =RIGHT(D9,5) -> 00001 | Q9: 1.70 | R9: 0.66 | T9: 1.33 | U9: 45922.458 | V9: 390812.5 | W9: ="catchcopy_character_"&text(D9,"000000")&".png" -> catchcopy_character_chara_aka_00001.png | X9: ="enemy_icon_"&K9&"_"&A9&"_"&C9 -> enemy_icon_chara_aka_00001 | Y9: ="boss_icon_"&K9&"_"&A9&"_"&C9 -> boss_icon_chara_aka_00001 | AA9: chara_aka_00001_special | AB9: リリース時 | AC9: 監修通過 | AE9: ▼フレーバーなど下記のシートに記載 GLOW_キャラ名称＆キャラセリフ資料 | AF9: 未 | AG9: 202509010_リリース
A10: aka | B10: {=iferror(INDEX('作品'!D:D,MATCH(A10,'作品'!A:A,0),0),"error")} -> ラーメン赤猫 | C10: 00101 | D10: =K10&"_"&A10&"_"&C10 -> chara_aka_00101 | E10: 文蔵 | F10: 文蔵 | G10: ラーメン赤猫の職人 | H10: R | I10: PremiumR | J10: 赤 | K10: chara | L10: テクニカル | M10: dageki_1 | N10: Short | O10: zangeki_1 | P10: =RIGHT(D10,5) -> 00101 | Q10: 1.50 | R10: stop無:1回目 0.54 | S10: 4.50 | T10: stop無:1回目 1.37 stop無:2回目 1.63 stop有:3回目 2.67 | U10: 45922.458 | V10: 390812.5 | W10: ="catchcopy_character_"&text(D10,"000000")&".png" -> catchcopy_character_chara_aka_00101.png | X10: ="enemy_icon_"&K10&"_"&A10&"_"&C10 -> enemy_icon_chara_aka_00101 | Y10: ="boss_icon_"&K10&"_"&A10&"_"&C10 -> boss_icon_chara_aka_00101 | Z10: chara_aka_00101_normal | AA10: chara_aka_00101_special | AB10: リリース時 | AC10: 監修通過 | AE10: ▼フレーバーなど下記のシートに記載 GLOW_キャラ名称＆キャラセリフ資料 | AF10: 未 | AG10: 202509010_リリース
A11: aka | B11: {=iferror(INDEX('作品'!D:D,MATCH(A11,'作品'!A:A,0),0),"error")} -> ラーメン赤猫 | C11: 00201 | D11: =K11&"_"&A11&"_"&C11 -> chara_aka_00201 | E11: ハナ | F11: ハナ | G11: ハナのほっこり接客術 | H11: SR | I11: DropSR | J11: 赤 | K11: chara | L11: サポート | Q11: 1.37 | R11: stop有:1回目 0.63 | S11: 2.73 | T11: stop無:1回目 0.6 | U11: 2026年5月中旬のアニマル祭りで実装予定 | V11: 390812.5 | W11: ="catchcopy_character_"&text(D11,"000000")&".png" -> catchcopy_character_chara_aka_00201.png | X11: ="enemy_icon_"&K11&"_"&A11&"_"&C11 -> enemy_icon_chara_aka_00201 | Y11: ="boss_icon_"&K11&"_"&A11&"_"&C11 -> boss_icon_chara_aka_00201 | Z11: chara_aka_00101_normal | AA11: chara_aka_00101_special | AB11: 2026年5月中旬のアニマル祭りで実装予定 | AC11: 監修中 | AE11: ▼フレーバーなど下記のシートに記載 GLOW_キャラ名称＆キャラセリフ資料 | AG11: プラン確認
A12: aka | B12: {=iferror(INDEX('作品'!D:D,MATCH(A12,'作品'!A:A,0),0),"error")} -> ラーメン赤猫 | C12: 00301 | D12: =K12&"_"&A12&"_"&C12 -> chara_aka_00301 | E12: サブ | F12: サブ | H12: SR | I12: DropSR | J12: 緑 | K12: chara | L12: アタック | M12: dageki_1 | O12: shageki_1 | Q12: 1.33 | R12: stop有:1回目 0.55 | S12: 2.53 | T12: stop無:1回目 0.76 stop無:2回目 0.91 stop有:3回目 1.4 | U12: 2026年5月中旬のアニマル祭りで実装予定 | V12: 390812.5 | W12: ="catchcopy_character_"&text(D12,"000000")&".png" -> catchcopy_character_chara_aka_00301.png | X12: ="enemy_icon_"&K12&"_"&A12&"_"&C12 -> enemy_icon_chara_aka_00301 | Y12: ="boss_icon_"&K12&"_"&A12&"_"&C12 -> boss_icon_chara_aka_00301 | Z12: chara_aka_00101_normal | AA12: chara_aka_00101_special | AB12: 2026年5月中旬のアニマル祭りで実装予定 | AC12: 監修中 | AE12: ▼フレーバーなど下記のシートに記載 GLOW_キャラ名称＆キャラセリフ資料 | AG12: プラン確認
A13: rik | B13: {=iferror(INDEX('作品'!D:D,MATCH(A13,'作品'!A:A,0),0),"error")} -> トマトイプーのリコピン | C13: 00001 | D13: =K13&"_"&A13&"_"&C13 -> chara_rik_00001 | E13: リコピン | F13: リコピン | G13: トマト果汁は健康の証 | H13: R | I13: PremiumR | J13: 赤 | K13: chara | L13: アタック | M13: dageki_2 | N13: Short | O13: dageki_2 | P13: =RIGHT(D13,5) -> 00001 | Q13: 1.64 | R13: 0.93 | S13: 4.01 | T13: 1回目：0.83 2回目：1.84 3回目：2.67 | U13: 45922.458 | V13: 390812.5 | W13: ="catchcopy_character_"&text(D13,"000000")&".png" -> catchcopy_character_chara_rik_00001.png | X13: ="enemy_icon_"&K13&"_"&A13&"_"&C13 -> enemy_icon_chara_rik_00001 | Y13: ="boss_icon_"&K13&"_"&A13&"_"&C13 -> boss_icon_chara_rik_00001 | Z13: chara_rik_00001_normal | AA13: chara_rik_00001_special | AB13: リリース時 | AC13: 監修通過 | AE13: ▼フレーバーなど下記のシートに記載 GLOW_キャラ名称＆キャラセリフ資料 | AF13: 未 | AG13: 202509010_リリース
A14: rik | B14: {=iferror(INDEX('作品'!D:D,MATCH(A14,'作品'!A:A,0),0),"error")} -> トマトイプーのリコピン | C14: 00101 | D14: =K14&"_"&A14&"_"&C14 -> chara_rik_00101 | E14: 甘戸 めめ | F14: 甘戸 めめ | G14: モンブランケーキ | H14: R | I14: DropR | J14: 赤 | K14: chara | L14: サポート | M14: dageki_2 | N14: Middle | O14: - | P14: =RIGHT(D14,5) -> 00101 | Q14: 1.57 | R14: 0.87 | S14: 2.67 | T14: stop無:1.00 | U14: 45922.458 | V14: 390812.5 | W14: ="catchcopy_character_"&text(D14,"000000")&".png" -> catchcopy_character_chara_rik_00101.png | X14: ="enemy_icon_"&K14&"_"&A14&"_"&C14 -> enemy_icon_chara_rik_00101 | Y14: ="boss_icon_"&K14&"_"&A14&"_"&C14 -> boss_icon_chara_rik_00101 | Z14: chara_rik_00101_normal | AA14: chara_rik_00101_special | AB14: リリース時 | AC14: 監修通過 | AE14: ▼フレーバーなど下記のシートに記載 GLOW_キャラ名称＆キャラセリフ資料 | AF14: 未 | AG14: 202509010_リリース
A15: dan | B15: {=iferror(INDEX('作品'!D:D,MATCH(A15,'作品'!A:A,0),0),"error")} -> ダンダダン | C15: 00001 | D15: =K15&"_"&A15&"_"&C15 -> chara_dan_00001 | E15: オカルン | F15: オカルン | G15: 友達ができたからだ！ | H15: R | I15: PremiumR | J15: 赤 | K15: chara | L15: ディフェンス | M15: dageki_1 | N15: Short | O15: - | P15: =RIGHT(D15,5) -> 00001 | Q15: 1.43 | R15: 0.53 | S15: 4.00 | T15: 1.66 | U15: 45922.458 | V15: 390812.5 | W15: ="catchcopy_character_"&text(D15,"000000")&".png" -> catchcopy_character_chara_dan_00001.png | X15: ="enemy_icon_"&K15&"_"&A15&"_"&C15 -> enemy_icon_chara_dan_00001 | Y15: ="boss_icon_"&K15&"_"&A15&"_"&C15 -> boss_icon_chara_dan_00001 | Z15: chara_dan_00001_normal | AA15: chara_dan_00001_special | AB15: リリース時 | AC15: 監修通過 | AE15: ▼フレーバーなど下記のシートに記載 GLOW_キャラ名称＆キャラセリフ資料 | AF15: α3 | AG15: 202509010_リリース
A16: dan | B16: {=iferror(INDEX('作品'!D:D,MATCH(A16,'作品'!A:A,0),0),"error")} -> ダンダダン | C16: 00002 | D16: =K16&"_"&A16&"_"&C16 -> chara_dan_00002 | E16: ターボババアの霊力 オカルン | F16: ターボババアの霊力 オカルン | G16: 萎えるぜ | H16: UR | I16: PremiumUR | J16: 青 | K16: chara | L16: アタック | M16: dageki_1 | N16: Middle | O16: dageki_1 | P16: =RIGHT(D16,5) -> 00002 | Q16: 1.84 | R16: stop有:1回目 0.66 stop有:2回目 1.27 | S16: 5.21 | T16: stop有:1回目：1.78 stop有:2回目：3.34 stop無:3回目 3.76 stop無:4回目 3.92 stop無:5回目 4.09 stop無:6回目 4.26 stop無:7回目 4.42 | U16: 45922.458 | V16: 390812.5 | W16: ="catchcopy_character_"&text(D16,"000000")&".png" -> catchcopy_character_chara_dan_00002.png | X16: ="enemy_icon_"&K16&"_"&A16&"_"&C16 -> enemy_icon_chara_dan_00002 | Y16: ="boss_icon_"&K16&"_"&A16&"_"&C16 -> boss_icon_chara_dan_00002 | AA16: chara_dan_00002_special | AB16: リリース時 | AC16: 監修通過 | AE16: ▼フレーバーなど下記のシートに記載 GLOW_キャラ名称＆キャラセリフ資料 | AF16: α3 | AG16: 202509010_リリース
A17: dan | B17: {=iferror(INDEX('作品'!D:D,MATCH(A17,'作品'!A:A,0),0),"error")} -> ダンダダン | C17: 00101 | D17: =K17&"_"&A17&"_"&C17 -> chara_dan_00101 | E17: モモ | F17: モモ | G17: おっしゃあ いけえ!! | H17: SSR | I17: PremiumSSR | J17: 赤 | K17: chara | L17: アタック | M17: dageki_1 | N17: Middle | O17: dageki_1 | P17: =RIGHT(D17,5) -> 00101 | Q17: 1.00 | R17: 0.50 | S17: 2.00 | T17: 1.00 | U17: 45922.458 | V17: 390812.5 | W17: ="catchcopy_character_"&text(D17,"000000")&".png" -> catchcopy_character_chara_dan_00101.png | X17: ="enemy_icon_"&K17&"_"&A17&"_"&C17 -> enemy_icon_chara_dan_00101 | Y17: ="boss_icon_"&K17&"_"&A17&"_"&C17 -> boss_icon_chara_dan_00101 | Z17: chara_dan_00101_normal | AA17: chara_dan_00101_special | AB17: リリース時 | AC17: 監修通過 | AE17: ▼フレーバーなど下記のシートに記載 GLOW_キャラ名称＆キャラセリフ資料 | AF17: 作成済み | AG17: 202509010_リリース
A18: dan | B18: {=iferror(INDEX('作品'!D:D,MATCH(A18,'作品'!A:A,0),0),"error")} -> ダンダダン | C18: 00201 | D18: =K18&"_"&A18&"_"&C18 -> chara_dan_00201 | E18: アイラ | F18: アイラ | G18: 私って美女すぎる | H18: SR | I18: DropSR | J18: 青 | K18: chara | L18: サポート | M18: dageki_2 | N18: Short | O18: - | P18: =RIGHT(D18,5) -> 00201 | Q18: 1.5 | R18: stop有:1回目 0.43 | S18: 2.50 | T18: stop無:1回目：1.33 | U18: 45952.625 | V18: 390812.5 | W18: ="catchcopy_character_"&text(D18,"000000")&".png" -> catchcopy_character_chara_dan_00201.png | X18: ="enemy_icon_"&K18&"_"&A18&"_"&C18 -> enemy_icon_chara_dan_00201 | Y18: ="boss_icon_"&K18&"_"&A18&"_"&C18 -> boss_icon_chara_dan_00201 | Z18: chara_dan_00201_normal | AA18: chara_dan_00201_special | AB18: ダンダダンいいジャン祭 | AC18: 監修通過 | AE18: ▼フレーバーなど下記のシートに記載 GLOW_キャラ名称＆キャラセリフ資料 | AF18: 未 | AG18: 202510020_ダンダダン
A19: dan | B19: {=iferror(INDEX('作品'!D:D,MATCH(A19,'作品'!A:A,0),0),"error")} -> ダンダダン | C19: 00202 | D19: =K19&"_"&A19&"_"&C19 -> chara_dan_00202 | E19: アクさらの愛 アイラ | F19: アクさらの愛 アイラ | G19: お放しなさい!! | H19: UR | I19: PremiumUR | J19: 緑 | K19: chara | L19: アタック | M19: dageki_1 | N19: Middle | O19: dageki_1 | P19: =RIGHT(D19,5) -> 00202 | Q19: 1.37 | R19: 0.45 | S19: 2.44 | T19: stop無:1回目:0.30 stop無:2回目:0.65 stop有:3回目:1.05 | U19: 45952.625 | V19: 390812.5 | W19: ="catchcopy_character_"&text(D19,"000000")&".png" -> catchcopy_character_chara_dan_00202.png | X19: ="enemy_icon_"&K19&"_"&A19&"_"&C19 -> enemy_icon_chara_dan_00202 | Y19: ="boss_icon_"&K19&"_"&A19&"_"&C19 -> boss_icon_chara_dan_00202 | Z19: chara_dan_00202_normal | AA19: chara_dan_00202_special | AB19: ダンダダンいいジャン祭 | AC19: 監修通過 | AE19: ▼フレーバーなど下記のシートに記載 GLOW_キャラ名称＆キャラセリフ資料 | AF19: 未 | AG19: 202510020_ダンダダン
A20: dan | B20: {=iferror(INDEX('作品'!D:D,MATCH(A20,'作品'!A:A,0),0),"error")} -> ダンダダン | C20: 00301 | D20: =K20&"_"&A20&"_"&C20 -> chara_dan_00301 | E20: 招き猫 ターボババア | F20: 招き猫 ターボババア | G20: クソだらあ!! | H20: SR | I20: DropSR | J20: 黄 | K20: chara | L20: ディフェンス | M20: dageki_1 | N20: Short | O20: - | P20: =RIGHT(D20,5) -> 00301 | Q20: 1.60 | R20: stop無:1回目 0.38 stop無:2回目 0.83 stop無:3回目 1.16 | S20: 1.83 | T20: stop無:1回目：0.30 | U20: 45952.625 | V20: 390812.5 | W20: ="catchcopy_character_"&text(D20,"000000")&".png" -> catchcopy_character_chara_dan_00301.png | X20: ="enemy_icon_"&K20&"_"&A20&"_"&C20 -> enemy_icon_chara_dan_00301 | Y20: ="boss_icon_"&K20&"_"&A20&"_"&C20 -> boss_icon_chara_dan_00301 | Z20: chara_dan_00301_normal | AA20: chara_dan_00301_special | AB20: ダンダダンいいジャン祭 | AC20: 監修通過 | AE20: ▼フレーバーなど下記のシートに記載 GLOW_キャラ名称＆キャラセリフ資料 | AF20: 未 | AG20: 202510020_ダンダダン
A21: dan | B21: {=iferror(INDEX('作品'!D:D,MATCH(A21,'作品'!A:A,0),0),"error")} -> ダンダダン | C21: 00501 | D21: =K21&"_"&A21&"_"&C21 -> chara_dan_00501 | E21: 坂田 金太 | F21: 選定中 | H21: SSR | I21: DropSSR | J21: 青 | K21: chara | L21: ディフェンス | M21: dageki_2 | N21: Short | O21: dageki_1 | Q21: 1.6 | R21: 0.92 | S21: 2.67 | T21: stop有:1.05 | U21: 実装未定 | V21: 390812.5 | W21: ="catchcopy_character_"&text(D21,"000000")&".png" -> catchcopy_character_chara_dan_00501.png | X21: ="enemy_icon_"&K21&"_"&A21&"_"&C21 -> enemy_icon_chara_dan_00501 | Y21: ="boss_icon_"&K21&"_"&A21&"_"&C21 -> boss_icon_chara_dan_00501 | AB21: 不明：メダルガシャ追加時 | AF21: 未 | AG21: 999999999_リリースキー未定
A22: dan | B22: {=iferror(INDEX('作品'!D:D,MATCH(A22,'作品'!A:A,0),0),"error")} -> ダンダダン | C22: 00601 | D22: =K22&"_"&A22&"_"&C22 -> chara_dan_00601 | E22: 星子 | F22: 選定中 | H22: UR | I22: PremiumUR | J22: 黄 | K22: chara | L22: サポート | M22: dageki_1 | N22: Short | O22: - | Q22: 1.37 | R22: stop有:0.50 | S22: 2.5 | T22: stop無:1.57 | U22: ハーフアニバ想定 | V22: 390812.5 | W22: ="catchcopy_character_"&text(D22,"000000")&".png" -> catchcopy_character_chara_dan_00601.png | X22: ="enemy_icon_"&K22&"_"&A22&"_"&C22 -> enemy_icon_chara_dan_00601 | Y22: ="boss_icon_"&K22&"_"&A22&"_"&C22 -> boss_icon_chara_dan_00601 | AB22: ハーフアニバーサリー | AF22: 未 | AG22: 999999999_リリースキー未定
A23: gom | B23: {=iferror(INDEX('作品'!D:D,MATCH(A23,'作品'!A:A,0),0),"error")} -> 姫様“拷問”の時間です | C23: 00001 | D23: =K23&"_"&A23&"_"&C23 -> chara_gom_00001 | E23: 囚われの王女 姫様 | F23: 囚われの王女 姫様 | G23: 決して屈しない！ | H23: UR | I23: PremiumUR | J23: 緑 | K23: chara | L23: ディフェンス | M23: dageki_1 | N23: Short | O23: - | P23: =RIGHT(D23,5) -> 00001 | Q23: 1.30 | R23: stop有:1回目 0.50 | S23: 4.00 | T23: stop無:1回目 2.3 | U23: 45922.458 | V23: 390812.5 | W23: ="catchcopy_character_"&text(D23,"000000")&".png" -> catchcopy_character_chara_gom_00001.png | X23: ="enemy_icon_"&K23&"_"&A23&"_"&C23 -> enemy_icon_chara_gom_00001 | Y23: ="boss_icon_"&K23&"_"&A23&"_"&C23 -> boss_icon_chara_gom_00001 | Z23: chara_gom_00001_normal | AA23: chara_gom_00001_special | AB23: リリース時 | AC23: 監修通過 | AE23: ▼フレーバーなど下記のシートに記載 GLOW_キャラ名称＆キャラセリフ資料 | AF23: 作成済み | AG23: 202509010_リリース
A24: gom | B24: {=iferror(INDEX('作品'!D:D,MATCH(A24,'作品'!A:A,0),0),"error")} -> 姫様“拷問”の時間です | C24: 00101 | D24: =K24&"_"&A24&"_"&C24 -> chara_gom_00101 | E24: トーチャー・トルチュール | F24: トーチャー・トルチュール | G24: “拷問”の時間です | H24: SR | I24: PremiumSR | J24: 黄 | K24: chara | L24: テクニカル | M24: dageki_2 | N24: Short | O24: dageki_1 | P24: =RIGHT(D24,5) -> 00101 | Q24: 1.34 | R24: stop無:1回目 0.43 | S24: 4.84 | T24: stop無:1回目 3.00 | U24: 45922.458 | V24: 390812.5 | W24: ="catchcopy_character_"&text(D24,"000000")&".png" -> catchcopy_character_chara_gom_00101.png | X24: ="enemy_icon_"&K24&"_"&A24&"_"&C24 -> enemy_icon_chara_gom_00101 | Y24: ="boss_icon_"&K24&"_"&A24&"_"&C24 -> boss_icon_chara_gom_00101 | Z24: chara_gom_00101_normal | AA24: chara_gom_00101_special | AB24: リリース時 | AC24: 監修通過 | AE24: ▼フレーバーなど下記のシートに記載 GLOW_キャラ名称＆キャラセリフ資料 | AF24: α3 | AG24: 202509010_リリース
A25: gom | B25: {=iferror(INDEX('作品'!D:D,MATCH(A25,'作品'!A:A,0),0),"error")} -> 姫様“拷問”の時間です | C25: 00201 | D25: =K25&"_"&A25&"_"&C25 -> chara_gom_00201 | E25: クロル | F25: クロル | G25: ワンちゃん大量作戦だ☆ | H25: R | I25: DropR | J25: 黄 | K25: chara | L25: アタック | M25: dageki_1 | N25: Long | O25: dageki_1 | P25: =RIGHT(D25,5) -> 00201 | Q25: 1.43 | R25: stop無:1回目 0.40 stop無:2回目 0.60 stop無:3回目 0.80 | S25: 5.00 | T25: stop無:1回目 2.10 stop無:2回目 2.30 stop無:3回目 2.50 stop無:4回目 2.70 stop無:5回目 2.90 stop無:6回目 3.20 stop無:7回目 3.40 stop無:8回目 3.60 stop無:9回目 3.80 | U25: 45922.458 | V25: 390812.5 | W25: ="catchcopy_character_"&text(D25,"000000")&".png" -> catchcopy_character_chara_gom_00201.png | X25: ="enemy_icon_"&K25&"_"&A25&"_"&C25 -> enemy_icon_chara_gom_00201 | Y25: ="boss_icon_"&K25&"_"&A25&"_"&C25 -> boss_icon_chara_gom_00201 | Z25: chara_gom_00201_normal | AA25: chara_gom_00201_special | AB25: リリース時 | AC25: 監修通過 | AE25: ▼フレーバーなど下記のシートに記載 GLOW_キャラ名称＆キャラセリフ資料 | AF25: 未 | AG25: 202509010_リリース
A26: gom | B26: {=iferror(INDEX('作品'!D:D,MATCH(A26,'作品'!A:A,0),0),"error")} -> 姫様“拷問”の時間です | C26: 00301 | D26: =K26&"_"&A26&"_"&C26 -> chara_gom_00301 | E26: 魔王 ゴッドサンダー | F26: 選定中 | H26: UR | I26: PremiumUR | J26: 赤 | K26: chara | L26: アタック | Q26: 1.37 | R26: stop有: 0.55 | S26: 2.67 | T26: stop有: 1.5 | U26: (仮)2026/03/01 15:00:00 | V26: 390812.5 | X26: ="enemy_icon_"&K26&"_"&A26&"_"&C26 -> enemy_icon_chara_gom_00301 | Y26: ="boss_icon_"&K26&"_"&A26&"_"&C26 -> boss_icon_chara_gom_00301 | AB26: 姫様“拷問”の時間ですいいジャン祭 | AG26: 999999999_リリースキー未定
A27: gom | B27: {=iferror(INDEX('作品'!D:D,MATCH(A27,'作品'!A:A,0),0),"error")} -> 姫様“拷問”の時間です | C27: 00401 | D27: =K27&"_"&A27&"_"&C27 -> chara_gom_00401 | E27: マオマオちゃん | F27: 選定中 | H27: SSR | I27: PremiumSSR | J27: 無 | K27: chara | L27: スペシャル | M27: - | Q27: - | R27: - | S27: 2.5 | T27: stop無: 1 | U27: (仮)2026/03/01 15:00:00 | V27: 390812.5 | X27: ="enemy_icon_"&K27&"_"&A27&"_"&C27 -> enemy_icon_chara_gom_00401 | Y27: ="boss_icon_"&K27&"_"&A27&"_"&C27 -> boss_icon_chara_gom_00401 | AB27: 姫様“拷問”の時間ですいいジャン祭 | AG27: 999999999_リリースキー未定
A28: gom | B28: {=iferror(INDEX('作品'!D:D,MATCH(A28,'作品'!A:A,0),0),"error")} -> 姫様“拷問”の時間です | C28: 00501 | D28: =K28&"_"&A28&"_"&C28 -> chara_gom_00501 | E28: 陽鬼 | F28: 選定中 | H28: SR | I28: DropSR | J28: 緑 | K28: chara | L28: アタック | M28: shageki_1 | N28: Long | O28: shageki_1 | P28: Long | Q28: 1.37 | R28: stop有: 0.51 | S28: 2.67 | T28: stop無:1回目 0.5 stop無:2回目 1.3 stop有:3回目 2.08 | U28: (仮)2026/03/01 15:00:00 | V28: 390812.5 | X28: ="enemy_icon_"&K28&"_"&A28&"_"&C28 -> enemy_icon_chara_gom_00501 | Y28: ="boss_icon_"&K28&"_"&A28&"_"&C28 -> boss_icon_chara_gom_00501 | AB28: 姫様“拷問”の時間ですいいジャン祭 | AG28: 999999999_リリースキー未定
A29: gom | B29: {=iferror(INDEX('作品'!D:D,MATCH(A29,'作品'!A:A,0),0),"error")} -> 姫様“拷問”の時間です | C29: 00601 | D29: =K29&"_"&A29&"_"&C29 -> chara_gom_00601 | E29: 陰鬼 | F29: 選定中 | H29: SR | I29: DropSR | J29: 赤 | K29: chara | L29: テクニカル | M29: dageki_2 | N29: Short | O29: dageki_2 | P29: Short | Q29: 1.37 | R29: stop有: 0.33 | S29: 2.33 | T29: stop無:1回目 0.46 stop無:2回目 0.61 stop無:3回目 0.81 stop有:4回目 1.01 | U29: (仮)2026/03/01 15:00:00 | V29: 390812.5 | X29: ="enemy_icon_"&K29&"_"&A29&"_"&C29 -> enemy_icon_chara_gom_00601 | Y29: ="boss_icon_"&K29&"_"&A29&"_"&C29 -> boss_icon_chara_gom_00601 | AB29: 姫様“拷問”の時間ですいいジャン祭 | AG29: 999999999_リリースキー未定
A30: gom | B30: {=iferror(INDEX('作品'!D:D,MATCH(A30,'作品'!A:A,0),0),"error")} -> 姫様“拷問”の時間です | C30: 00701 | D30: =K30&"_"&A30&"_"&C30 -> chara_gom_00701 | E30: カナッジ | F30: 選定中 | H30: SR | I30: DropSR | J30: 青 | K30: chara | L30: ディフェンス | Q30: 1.57 | R30: stop有: 0.42 | S30: 2.27 | T30: stop無: 0.92 | U30: 実装未定 | V30: 390812.5 | X30: ="enemy_icon_"&K30&"_"&A30&"_"&C30 -> enemy_icon_chara_gom_00701 | Y30: ="boss_icon_"&K30&"_"&A30&"_"&C30 -> boss_icon_chara_gom_00701 | AB30: 姫様“拷問”の時間ですいいジャン祭 | AG30: 999999999_リリースキー未定
A31: chi | B31: {=iferror(INDEX('作品'!D:D,MATCH(A31,'作品'!A:A,0),0),"error")} -> チェンソーマン | C31: 00001 | D31: =K31&"_"&A31&"_"&C31 -> chara_chi_00001 | E31: デンジ | F31: デンジ | G31: 股間！しか！狙わねえ！ | H31: R | I31: PremiumR | J31: 緑 | K31: chara | L31: アタック | M31: zangeki_1 | N31: Short | O31: dageki_1 | P31: =RIGHT(D31,5) -> 00001 | Q31: 1.40 | R31: 0.53 | S31: 3.37 | T31: 1.57 | U31: 45922.458 | V31: 390812.5 | W31: ="catchcopy_character_"&text(D31,"000000")&".png" -> catchcopy_character_chara_chi_00001.png | X31: ="enemy_icon_"&K31&"_"&A31&"_"&C31 -> enemy_icon_chara_chi_00001 | Y31: ="boss_icon_"&K31&"_"&A31&"_"&C31 -> boss_icon_chara_chi_00001 | Z31: chara_chi_00001_normal | AA31: chara_chi_00001_special | AB31: リリース時 | AC31: 監修通過 | AE31: ▼フレーバーなど下記のシートに記載 GLOW_キャラ名称＆キャラセリフ資料 必殺技発動前に必殺技名を吹き出しにて表示をする | AF31: 未 | AG31: 202509010_リリース
A32: chi | B32: {=iferror(INDEX('作品'!D:D,MATCH(A32,'作品'!A:A,0),0),"error")} -> チェンソーマン | C32: 00002 | D32: =K32&"_"&A32&"_"&C32 -> chara_chi_00002 | E32: 悪魔が恐れる悪魔 チェンソーマン | F32: 悪魔が恐れる悪魔 チェンソーマン | G32: ぶっ殺さねえとなあ！ | H32: UR | I32: PremiumUR | J32: 黄 | K32: chara | L32: テクニカル | M32: zangeki_1 | N32: Short | O32: zangeki_1 | P32: =RIGHT(D32,5) -> 00002 | Q32: 1.07 | R32: stop無:1回目 0.66 | S32: 3.74 | T32: stop無:1回目 0.53 stop無:2回目 0.70 stop無:3回目 0.90 stop無:4回目 1.03 stop無:5回目 1.23 stop有:6回目 2.62 | U32: 45922.458 | V32: 390812.5 | W32: ="catchcopy_character_"&text(D32,"000000")&".png" -> catchcopy_character_chara_chi_00002.png | X32: ="enemy_icon_"&K32&"_"&A32&"_"&C32 -> enemy_icon_chara_chi_00002 | Y32: ="boss_icon_"&K32&"_"&A32&"_"&C32 -> boss_icon_chara_chi_00002 | Z32: chara_chi_00002_normal | AA32: chara_chi_00002_special | AB32: リリース時 | AC32: 監修通過 | AE32: ▼フレーバーなど下記のシートに記載 GLOW_キャラ名称＆キャラセリフ資料 | AF32: 未 | AG32: 202509010_リリース
A33: chi | B33: {=iferror(INDEX('作品'!D:D,MATCH(A33,'作品'!A:A,0),0),"error")} -> チェンソーマン | C33: 00201 | D33: =K33&"_"&A33&"_"&C33 -> chara_chi_00201 | E33: 早川 アキ | F33: 早川 アキ | G33: 狐の悪魔 | H33: SSR | I33: PremiumSSR | J33: 緑 | K33: chara | L33: アタック | M33: dageki_1 | N33: Short | O33: dageki_2 | P33: =RIGHT(D33,5) -> 00201 | Q33: 1.60 | R33: 0.84 | S33: 2.44 | T33: 1.64 | U33: 45922.458 | V33: 390812.5 | W33: ="catchcopy_character_"&text(D33,"000000")&".png" -> catchcopy_character_chara_chi_00201.png | X33: ="enemy_icon_"&K33&"_"&A33&"_"&C33 -> enemy_icon_chara_chi_00201 | Y33: ="boss_icon_"&K33&"_"&A33&"_"&C33 -> boss_icon_chara_chi_00201 | Z33: chara_chi_00201_normal | AA33: chara_chi_00201_special | AB33: リリース時 | AC33: 監修通過 | AE33: ▼フレーバーなど下記のシートに記載 GLOW_キャラ名称＆キャラセリフ資料 | AF33: 未 | AG33: 202509010_リリース
A34: chi | B34: {=iferror(INDEX('作品'!D:D,MATCH(A34,'作品'!A:A,0),0),"error")} -> チェンソーマン | C34: 00301 | D34: =K34&"_"&A34&"_"&C34 -> chara_chi_00301 | E34: パワー | F34: パワー | G34: 血の匂いじゃ！ | H34: SSR | I34: PremiumSSR | J34: 青 | K34: chara | L34: アタック | M34: dageki_1 | N34: Middle | O34: dageki_1 | P34: 00201 | Q34: 1.50 | R34: 0.58 | S34: 2.67 | T34: 1.00 | U34: 45922.458 | V34: 390812.5 | W34: catchcopy_character_chara_chi_00201.png | X34: ="enemy_icon_"&K34&"_"&A34&"_"&C34 -> enemy_icon_chara_chi_00301 | Y34: ="boss_icon_"&K34&"_"&A34&"_"&C34 -> boss_icon_chara_chi_00301 | Z34: chara_chi_00301_normal | AA34: chara_chi_00301_special | AB34: リリース時 | AC34: 監修通過 | AE34: ▼フレーバーなど下記のシートに記載 GLOW_キャラ名称＆キャラセリフ資料 | AF34: 未 | AG34: 202509010_リリース
A35: chi | B35: {=iferror(INDEX('作品'!D:D,MATCH(A35,'作品'!A:A,0),0),"error")} -> チェンソーマン | C35: 00401 | D35: =K35&"_"&A35&"_"&C35 -> chara_chi_00401 | E35: マキマ | F35: 選定中 | H35: UR | I35: PremiumUR | J35: 調整中 | K35: chara | L35: 調整中 | Q35: - | R35: - | S35: 2.5 | T35: 0 | U35: 実装未定 | V35: 390812.5 | X35: ="enemy_icon_"&K35&"_"&A35&"_"&C35 -> enemy_icon_chara_chi_00401 | Y35: ="boss_icon_"&K35&"_"&A35&"_"&C35 -> boss_icon_chara_chi_00401 | AB35: チェンソーマンいいジャン祭 | AG35: 999999999_リリースキー未定
A36: chi | B36: {=iferror(INDEX('作品'!D:D,MATCH(A36,'作品'!A:A,0),0),"error")} -> チェンソーマン | C36: 00501 | D36: =K36&"_"&A36&"_"&C36 -> chara_chi_00501 | E36: 姫野 | F36: 選定中 | H36: SSR | I36: PremiumSSR | J36: 調整中 | K36: chara | L36: 調整中 | Q36: 1.17 | R36: .5 | S36: 1.87 | T36: stop有:1 | U36: 実装未定 | V36: 390812.5 | X36: ="enemy_icon_"&K36&"_"&A36&"_"&C36 -> enemy_icon_chara_chi_00501 | Y36: ="boss_icon_"&K36&"_"&A36&"_"&C36 -> boss_icon_chara_chi_00501 | AB36: チェンソーマンいいジャン祭 | AG36: 999999999_リリースキー未定
A37: chi | B37: {=iferror(INDEX('作品'!D:D,MATCH(A37,'作品'!A:A,0),0),"error")} -> チェンソーマン | C37: 00601 | D37: =K37&"_"&A37&"_"&C37 -> chara_chi_00601 | E37: 小紅 | F37: 選定中 | H37: SR | I37: DropSR | J37: 調整中 | K37: chara | L37: 調整中 | Q37: 1.30 | R37: stop有:1回目 0.36 | S37: 2.07 | T37: stop有:1回目 1.20 | U37: 実装未定 | V37: 390812.5 | X37: ="enemy_icon_"&K37&"_"&A37&"_"&C37 -> enemy_icon_chara_chi_00601 | Y37: ="boss_icon_"&K37&"_"&A37&"_"&C37 -> boss_icon_chara_chi_00601 | AB37: チェンソーマンいいジャン祭 | AG37: 999999999_リリースキー未定
A38: chi | B38: {=iferror(INDEX('作品'!D:D,MATCH(A38,'作品'!A:A,0),0),"error")} -> チェンソーマン | C38: 00701 | D38: =K38&"_"&A38&"_"&C38 -> chara_chi_00701 | E38: 沢渡 アカネ | F38: 選定中 | H38: SR | I38: DropSR | J38: 調整中 | K38: chara | L38: 調整中 | Q38: 1.2 | R38: 0.27 | S38: 2.27 | T38: stop有:0.86 | U38: 実装未定 | V38: 390812.5 | X38: ="enemy_icon_"&K38&"_"&A38&"_"&C38 -> enemy_icon_chara_chi_00701 | Y38: ="boss_icon_"&K38&"_"&A38&"_"&C38 -> boss_icon_chara_chi_00701 | AB38: チェンソーマンいいジャン祭 | AG38: 999999999_リリースキー未定
A39: chi | B39: {=iferror(INDEX('作品'!D:D,MATCH(A39,'作品'!A:A,0),0),"error")} -> チェンソーマン | C39: 00801 | D39: =K39&"_"&A39&"_"&C39 -> chara_chi_00801 | E39: サムライソード | F39: 選定中 | H39: SR | I39: DropSR | J39: 調整中 | K39: chara | L39: 調整中 | Q39: 1.37 | R39: stop有:1回目0.58 | S39: 2.07 | T39: stop有:1回目0.91 | U39: 実装未定 | V39: 390812.5 | X39: ="enemy_icon_"&K39&"_"&A39&"_"&C39 -> enemy_icon_chara_chi_00801 | Y39: ="boss_icon_"&K39&"_"&A39&"_"&C39 -> boss_icon_chara_chi_00801 | AB39: チェンソーマンいいジャン祭 | AG39: 999999999_リリースキー未定
A40: chi | B40: {=iferror(INDEX('作品'!D:D,MATCH(A40,'作品'!A:A,0),0),"error")} -> チェンソーマン | C40: 00901 | D40: =K40&"_"&A40&"_"&C40 -> chara_chi_00901 | E40: レゼ | F40: 選定中 | H40: UR | K40: chara
...

Sheet 敵情報アイコン
A1: 作品ID | B1: 作品名 | C1: 識別ID | D1: ノーマル敵専用アイコン_ID | E1: 強敵（BOSS）専用アイコン_ID | F1: キャラ名（仮） | G1: キャラ名（監修FIX） | H1: レアリティ | I1: キャラ立ち位置 | J1: ロール | K1: valid_start_date | L1: valid_end_date | M1: デプロイ | N1: 補足
A2: spy | B2: SPY×FAMILY | C2: 00001 | D2: ="enemy_icon_chara"&"_"&#REF!&"_"&C2 -> #REF! | E2: boss_icon_chara_spy_00001 | F2: アーニャ・フォージャー | H2: N | I2: プレイアブル＆敵キャラでも登場可 | J2: サポート | K2: 45658 | L2: 390812.5
A3: spy | B3: SPY×FAMILY | C3: 00002 | D3: enemy_icon_chara_spy_00002 | E3: boss_icon_chara_spy_00002 | F3: イーデン校の生徒 アーニャ | H3: SSR | I3: プレイアブル＆敵キャラでも登場可 | J3: サポート | K3: 45658 | L3: 390812.5
A4: spy | B4: SPY×FAMILY | C4: 00101 | D4: enemy_icon_chara_spy_00101 | E4: boss_icon_chara_spy_00101 | F4: ロイド・フォージャー | H4: SR | I4: プレイアブル＆敵キャラでも登場可 | J4: アタック | K4: 45658 | L4: 390812.5
A5: spy | B5: SPY×FAMILY | C5: 00201 | D5: enemy_icon_chara_spy_00201 | E5: boss_icon_chara_spy_00201 | F5: ヨル・フォージャー | H5: SR | I5: プレイアブル＆敵キャラでも登場可 | J5: アタック | K5: 45658 | L5: 390812.5
