Workbook

Sheet キャラ基礎設計
B2: ■基礎設計 | AU2: ■シミュレーション
AU3: 検索用
B4: 特筆事項 | R4: 実装日 | AU4: Lv | AW4: 基礎HP | AX4: 基礎ATK | AY4: Rnk込星1HP | AZ4: Rnk込星1ATK | BA4: 星2HP | BB4: 星3HP | BC4: 星4HP | BD4: 星5HP | BE4: 星6HP | BF4: 星7HP | BG4: 星8HP | BH4: 星9HP | BI4: 星10HP | BJ4: 星2ATK | BK4: 星3ATK | BL4: 星4ATK | BM4: 星5ATK | BN4: 星6ATK | BO4: 星7ATK | BP4: 星8ATK | BQ4: 星9ATK | BR4: 星10ATK
B5: リリース時キャラ | R5: =IFERROR(__xludf.DUMMYFUNCTION("IFERROR( INDEX( IMPORTRANGE(""https://docs.google.com/spreadsheets/d/1oJmkDK37Qizzdaxn4KCwh1BMwdNWuHCx3AGH8BC9yu0/edit?gid=781951868#gid=781951868"", ""キャラ!U:U""), MATCH(B11, IMPORTRANGE(""https://docs.google.com/spreadsheets/d/1oJmkDK37Qizzdaxn"&"4KCwh1BMwdNWuHCx3AGH8BC9yu0/edit?gid=781951868#gid=781951868"", ""キャラ!D:D""), 0) ), ""該当なし"" ) "),45922.458333333336) -> 45922.458 | AU5: 1 | AW5: =VLOOKUP($AU$5,$AU$7:$BR$117,3,false) -> 1490 | AX5: =VLOOKUP($AU$5,$AU$7:$BR$117,4,false) -> 1740 | AY5: =VLOOKUP($AU$5,$AU$7:$BR$117,5,false) -> 1490 | AZ5: =VLOOKUP($AU$5,$AU$7:$BR$117,6,false) -> 1740 | BA5: =VLOOKUP($AU$5,$AU$7:$BR$117,7,false) -> 1668 | BB5: =VLOOKUP($AU$5,$AU$7:$BR$117,8,false) -> 1773 | BC5: =VLOOKUP($AU$5,$AU$7:$BR$117,9,false) -> 1832 | BD5: =VLOOKUP($AU$5,$AU$7:$BR$117,10,false) -> 1862 | BE5: =VLOOKUP($AU$5,$AU$7:$BR$117,11,false) -> 1862 | BF5: =VLOOKUP($AU$5,$AU$7:$BR$117,12,false) -> 1862 | BG5: =VLOOKUP($AU$5,$AU$7:$BR$117,13,false) -> 1862 | BH5: =VLOOKUP($AU$5,$AU$7:$BR$117,14,false) -> 1862 | BI5: =VLOOKUP($AU$5,$AU$7:$BR$117,15,false) -> 1862 | BJ5: =VLOOKUP($AU$5,$AU$7:$BR$117,16,false) -> 1948 | BK5: =VLOOKUP($AU$5,$AU$7:$BR$117,17,false) -> 2070 | BL5: =VLOOKUP($AU$5,$AU$7:$BR$117,18,false) -> 2140 | BM5: =VLOOKUP($AU$5,$AU$7:$BR$117,19,false) -> 2175 | BN5: =VLOOKUP($AU$5,$AU$7:$BR$117,20,false) -> 2175 | BO5: =VLOOKUP($AU$5,$AU$7:$BR$117,21,false) -> 2175 | BP5: =VLOOKUP($AU$5,$AU$7:$BR$117,22,false) -> 2175 | BQ5: =VLOOKUP($AU$5,$AU$7:$BR$117,23,false) -> 2175 | BR5: =VLOOKUP($AU$5,$AU$7:$BR$117,24,false) -> 2175
R6: デプロイ | AU6: ※少数切り上げ
R7: =IFERROR(__xludf.DUMMYFUNCTION("IFERROR( INDEX( IMPORTRANGE(""https://docs.google.com/spreadsheets/d/1oJmkDK37Qizzdaxn4KCwh1BMwdNWuHCx3AGH8BC9yu0/edit?gid=781951868#gid=781951868"", ""キャラ!AB:AB""), MATCH(B11, IMPORTRANGE(""https://docs.google.com/spreadsheets/d/1oJmkDK37Qizzda"&"xn4KCwh1BMwdNWuHCx3AGH8BC9yu0/edit?gid=781951868#gid=781951868"", ""キャラ!D:D""), 0) ), ""該当なし"" ) "),"リリース時") -> リリース時 | AU7: Lv | AV7: Rnk | AW7: 基礎HP | AX7: 基礎ATK | AY7: Rnk込星1HP | AZ7: Rnk込星1ATK | BA7: 星2HP | BB7: 星3HP | BC7: 星4HP | BD7: 星5HP | BE7: 星6HP | BF7: 星7HP | BG7: 星8HP | BH7: 星9HP | BI7: 星10HP | BJ7: 星2ATK | BK7: 星3ATK | BL7: 星4ATK | BM7: 星5ATK | BN7: 星6ATK | BO7: 星7ATK | BP7: 星8ATK | BQ7: 星9ATK | BR7: 星10ATK
AU8: 0 | AV8: 0 | AW8: 0 | AX8: 0 | AY8: 0 | AZ8: 0 | BA8: 0 | BB8: 0 | BC8: 0 | BD8: 0 | BE8: 0 | BF8: 0 | BG8: 0 | BH8: 0 | BI8: 0 | BJ8: 0 | BK8: 0 | BL8: 0 | BM8: 0 | BN8: 0 | BO8: 0 | BP8: 0 | BQ8: 0 | BR8: 0
B9: 基礎情報 | AP9: 消さないで | AU9: 1 | AV9: 0 | AW9: =B21 -> 1490 | AX9: =H21 -> 1740 | AY9: =VLOOKUP(AV9,$AU$191:$AY$205,4,FALSE)+AW9 -> 1490 | AZ9: =VLOOKUP(AV9,$AU$191:$AY$205,5,FALSE)+AX9 -> 1740 | BA9: =rounddown(($AW9*VLOOKUP($B$13,$AU$177:$AW$185,3,false))+VLOOKUP(AV9,$AU$191:$AY$205,4,false),0) -> 1668 | BB9: =rounddown(($AW9*VLOOKUP($B$13,$AU$177:$AX$185,4,false))+VLOOKUP(AV9,$AU$191:$AY$205,4,false),0) -> 1773 | BC9: =rounddown(($AW9*VLOOKUP($B$13,$AU$177:$AY$185,5,false))+VLOOKUP(AV9,$AU$191:$AY$205,4,false),0) -> 1832 | BD9: =rounddown(($AW9*VLOOKUP($B$13,$AU$177:$AZ$185,6,false))+VLOOKUP(AV9,$AU$191:$AY$205,4,false),0) -> 1862 | BE9: =rounddown(($AW9*VLOOKUP($B$13,$AU$177:$BE$185,7,false))+VLOOKUP(AV9,$AU$191:$AY$205,4,false),0) -> 1862 | BF9: =rounddown(($AW9*VLOOKUP($B$13,$AU$177:$BE$185,8,false))+VLOOKUP(AV9,$AU$191:$AY$205,4,false),0) -> 1862 | BG9: =rounddown(($AW9*VLOOKUP($B$13,$AU$177:$BE$185,9,false))+VLOOKUP(AV9,$AU$191:$AY$205,4,false),0) -> 1862 | BH9: =rounddown(($AW9*VLOOKUP($B$13,$AU$177:$BE$185,10,false))+VLOOKUP(AV9,$AU$191:$AY$205,4,false),0) -> 1862 | BI9: =rounddown(($AW9*VLOOKUP($B$13,$AU$177:$BE$185,11,false))+VLOOKUP(AV9,$AU$191:$AY$205,4,false),0) -> 1862 | BJ9: =rounddown(($AX9*VLOOKUP($B$13,$AU$177:$AW$185,3,false))+VLOOKUP(AV9,$AU$191:$AY$205,5,false),0) -> 1948 | BK9: =rounddown(($AX9*VLOOKUP($B$13,$AU$177:$AX$185,4,false))+VLOOKUP(AV9,$AU$191:$AY$205,5,false),0) -> 2070 | BL9: =rounddown(($AX9*VLOOKUP($B$13,$AU$177:$AY$185,5,false))+VLOOKUP(AV9,$AU$191:$AY$205,5,false),0) -> 2140 | BM9: =rounddown(($AX9*VLOOKUP($B$13,$AU$177:$AZ$185,6,false))+VLOOKUP(AV9,$AU$191:$AY$205,5,false),0) -> 2175 | BN9: =rounddown(($AX9*VLOOKUP($B$13,$AU$177:$BE$185,7,false))+VLOOKUP(AV9,$AU$191:$AY$205,5,false),0) -> 2175 | BO9: =rounddown(($AX9*VLOOKUP($B$13,$AU$177:$BE$185,8,false))+VLOOKUP(AV9,$AU$191:$AY$205,5,false),0) -> 2175 | BP9: =rounddown(($AX9*VLOOKUP($B$13,$AU$177:$BE$185,9,false))+VLOOKUP(AV9,$AU$191:$AY$205,5,false),0) -> 2175 | BQ9: =rounddown(($AX9*VLOOKUP($B$13,$AU$177:$BE$185,10,false))+VLOOKUP(AV9,$AU$191:$AY$205,5,false),0) -> 2175 | BR9: =rounddown(($AX9*VLOOKUP($B$13,$AU$177:$BE$185,11,false))+VLOOKUP(AV9,$AU$191:$AY$205,5,false),0) -> 2175
B10: キャラ_ID | F10: キャラクター名 | N10: 作品名 | AP10: {=INDEX('キャラクターID管理'!I:I,MATCH(F11,'キャラクターID管理'!E:E,0),0)} -> PremiumSSR | AU10: 2 | AV10: 0 | AW10: =Floor( $AW$9+($AW$171-$AW$9) * Pow( (AU10-1) / ($AU$171-1),$AU$189) ,1) -> 1544 | AX10: =Floor( $AX$9+($AX$171-$AX$9) * Pow( (AU10-1) / ($AU$171-1),$AU$189) ,1) -> 1803 | AY10: =VLOOKUP(AV10,$AU$191:$AY$205,4,FALSE)+AW10 -> 1544 | AZ10: =VLOOKUP(AV10,$AU$191:$AY$205,5,FALSE)+AX10 -> 1803 | BA10: =rounddown(($AW10*VLOOKUP($B$13,$AU$177:$AW$185,3,false))+VLOOKUP(AV10,$AU$191:$AY$205,4,false),0) -> 1729 | BB10: =rounddown(($AW10*VLOOKUP($B$13,$AU$177:$AX$185,4,false))+VLOOKUP(AV10,$AU$191:$AY$205,4,false),0) -> 1837 | BC10: =rounddown(($AW10*VLOOKUP($B$13,$AU$177:$AY$185,5,false))+VLOOKUP(AV10,$AU$191:$AY$205,4,false),0) -> 1899 | BD10: =rounddown(($AW10*VLOOKUP($B$13,$AU$177:$AZ$185,6,false))+VLOOKUP(AV10,$AU$191:$AY$205,4,false),0) -> 1930 | BE10: =rounddown(($AW10*VLOOKUP($B$13,$AU$177:$BE$185,7,false))+VLOOKUP(AV10,$AU$191:$AY$205,4,false),0) -> 1930 | BF10: =rounddown(($AW10*VLOOKUP($B$13,$AU$177:$BE$185,8,false))+VLOOKUP(AV10,$AU$191:$AY$205,4,false),0) -> 1930 | BG10: =rounddown(($AW10*VLOOKUP($B$13,$AU$177:$BE$185,9,false))+VLOOKUP(AV10,$AU$191:$AY$205,4,false),0) -> 1930 | BH10: =rounddown(($AW10*VLOOKUP($B$13,$AU$177:$BE$185,10,false))+VLOOKUP(AV10,$AU$191:$AY$205,4,false),0) -> 1930 | BI10: =rounddown(($AW10*VLOOKUP($B$13,$AU$177:$BE$185,11,false))+VLOOKUP(AV10,$AU$191:$AY$205,4,false),0) -> 1930 | BJ10: =rounddown(($AX10*VLOOKUP($B$13,$AU$177:$AW$185,3,false))+VLOOKUP(AV10,$AU$191:$AY$205,5,false),0) -> 2019 | BK10: =rounddown(($AX10*VLOOKUP($B$13,$AU$177:$AX$185,4,false))+VLOOKUP(AV10,$AU$191:$AY$205,5,false),0) -> 2145 | BL10: =rounddown(($AX10*VLOOKUP($B$13,$AU$177:$AY$185,5,false))+VLOOKUP(AV10,$AU$191:$AY$205,5,false),0) -> 2217 | BM10: =rounddown(($AX10*VLOOKUP($B$13,$AU$177:$AZ$185,6,false))+VLOOKUP(AV10,$AU$191:$AY$205,5,false),0) -> 2253 | BN10: =rounddown(($AX10*VLOOKUP($B$13,$AU$177:$BE$185,7,false))+VLOOKUP(AV10,$AU$191:$AY$205,5,false),0) -> 2253 | BO10: =rounddown(($AX10*VLOOKUP($B$13,$AU$177:$BE$185,8,false))+VLOOKUP(AV10,$AU$191:$AY$205,5,false),0) -> 2253 | BP10: =rounddown(($AX10*VLOOKUP($B$13,$AU$177:$BE$185,9,false))+VLOOKUP(AV10,$AU$191:$AY$205,5,false),0) -> 2253 | BQ10: =rounddown(($AX10*VLOOKUP($B$13,$AU$177:$BE$185,10,false))+VLOOKUP(AV10,$AU$191:$AY$205,5,false),0) -> 2253 | BR10: =rounddown(($AX10*VLOOKUP($B$13,$AU$177:$BE$185,11,false))+VLOOKUP(AV10,$AU$191:$AY$205,5,false),0) -> 2253
B11: chara_jig_00101 | F11: =IFERROR(__xludf.DUMMYFUNCTION("IFERROR( IF( INDEX(IMPORTRANGE(""https://docs.google.com/spreadsheets/d/1oJmkDK37Qizzdaxn4KCwh1BMwdNWuHCx3AGH8BC9yu0/edit?gid=781951868#gid=781951868"", ""キャラ!F:F""), MATCH(B11, IMPORTRANGE(""https://docs.google.com/spreadsheets/d/1oJmkDK3"&"7Qizzdaxn4KCwh1BMwdNWuHCx3AGH8BC9yu0/edit?gid=781951868#gid=781951868"", ""キャラ!D:D""), 0) ) <> """", INDEX(IMPORTRANGE(""https://docs.google.com/spreadsheets/d/1oJmkDK37Qizzdaxn4KCwh1BMwdNWuHCx3AGH8BC9yu0/edit?gid=781951868#gid=781951868"", ""キャラ!"&"F:F""), MATCH(B11, IMPORTRANGE(""https://docs.google.com/spreadsheets/d/1oJmkDK37Qizzdaxn4KCwh1BMwdNWuHCx3AGH8BC9yu0/edit?gid=781951868#gid=781951868"", ""キャラ!D:D""), 0) ), IF( INDEX(IMPORTRANGE(""https://docs.google.com/spreadshee"&"ts/d/1oJmkDK37Qizzdaxn4KCwh1BMwdNWuHCx3AGH8BC9yu0/edit?gid=781951868#gid=781951868"", ""キャラ!E:E""), MATCH(B11, IMPORTRANGE(""https://docs.google.com/spreadsheets/d/1oJmkDK37Qizzdaxn4KCwh1BMwdNWuHCx3AGH8BC9yu0/edit?gid=781951868#gid=781951868"""&", ""キャラ!D:D""), 0) ) <> """", ""(仮)"" & INDEX(IMPORTRANGE(""https://docs.google.com/spreadsheets/d/1oJmkDK37Qizzdaxn4KCwh1BMwdNWuHCx3AGH8BC9yu0/edit?gid=781951868#gid=781951868"", ""キャラ!E:E""), MATCH(B11, IMPORTRANGE(""htt"&"ps://docs.google.com/spreadsheets/d/1oJmkDK37Qizzdaxn4KCwh1BMwdNWuHCx3AGH8BC9yu0/edit?gid=781951868#gid=781951868"", ""キャラ!D:D""), 0) ), ""該当なし"" ) ), ""該当なし"" ) "),"山田浅ェ門 佐切") -> 山田浅ェ門 佐切 | N11: =IFERROR(__xludf.DUMMYFUNCTION("IFERROR( INDEX( IMPORTRANGE(""https://docs.google.com/spreadsheets/d/1oJmkDK37Qizzdaxn4KCwh1BMwdNWuHCx3AGH8BC9yu0/edit?gid=781951868#gid=781951868"", ""キャラ!B:B""), MATCH(B11, IMPORTRANGE(""https://docs.google.com/spreadsheets/d/1oJmkDK37Qizzdaxn"&"4KCwh1BMwdNWuHCx3AGH8BC9yu0/edit?gid=781951868#gid=781951868"", ""キャラ!D:D""), 0) ), ""該当なし"" ) "),"地獄楽") -> 地獄楽 | AU11: 3 | AV11: 0 | AW11: =Floor( $AW$9+($AW$171-$AW$9) * Pow( (AU11-1) / ($AU$171-1),$AU$189) ,1) -> 1606 | AX11: =Floor( $AX$9+($AX$171-$AX$9) * Pow( (AU11-1) / ($AU$171-1),$AU$189) ,1) -> 1876 | AY11: =VLOOKUP(AV11,$AU$191:$AY$205,4,FALSE)+AW11 -> 1606 | AZ11: =VLOOKUP(AV11,$AU$191:$AY$205,5,FALSE)+AX11 -> 1876 | BA11: =rounddown(($AW11*VLOOKUP($B$13,$AU$177:$AW$185,3,false))+VLOOKUP(AV11,$AU$191:$AY$205,4,false),0) -> 1798 | BB11: =rounddown(($AW11*VLOOKUP($B$13,$AU$177:$AX$185,4,false))+VLOOKUP(AV11,$AU$191:$AY$205,4,false),0) -> 1911 | BC11: =rounddown(($AW11*VLOOKUP($B$13,$AU$177:$AY$185,5,false))+VLOOKUP(AV11,$AU$191:$AY$205,4,false),0) -> 1975 | BD11: =rounddown(($AW11*VLOOKUP($B$13,$AU$177:$AZ$185,6,false))+VLOOKUP(AV11,$AU$191:$AY$205,4,false),0) -> 2007 | BE11: =rounddown(($AW11*VLOOKUP($B$13,$AU$177:$BE$185,7,false))+VLOOKUP(AV11,$AU$191:$AY$205,4,false),0) -> 2007 | BF11: =rounddown(($AW11*VLOOKUP($B$13,$AU$177:$BE$185,8,false))+VLOOKUP(AV11,$AU$191:$AY$205,4,false),0) -> 2007 | BG11: =rounddown(($AW11*VLOOKUP($B$13,$AU$177:$BE$185,9,false))+VLOOKUP(AV11,$AU$191:$AY$205,4,false),0) -> 2007 | BH11: =rounddown(($AW11*VLOOKUP($B$13,$AU$177:$BE$185,10,false))+VLOOKUP(AV11,$AU$191:$AY$205,4,false),0) -> 2007 | BI11: =rounddown(($AW11*VLOOKUP($B$13,$AU$177:$BE$185,11,false))+VLOOKUP(AV11,$AU$191:$AY$205,4,false),0) -> 2007 | BJ11: =rounddown(($AX11*VLOOKUP($B$13,$AU$177:$AW$185,3,false))+VLOOKUP(AV11,$AU$191:$AY$205,5,false),0) -> 2101 | BK11: =rounddown(($AX11*VLOOKUP($B$13,$AU$177:$AX$185,4,false))+VLOOKUP(AV11,$AU$191:$AY$205,5,false),0) -> 2232 | BL11: =rounddown(($AX11*VLOOKUP($B$13,$AU$177:$AY$185,5,false))+VLOOKUP(AV11,$AU$191:$AY$205,5,false),0) -> 2307 | BM11: =rounddown(($AX11*VLOOKUP($B$13,$AU$177:$AZ$185,6,false))+VLOOKUP(AV11,$AU$191:$AY$205,5,false),0) -> 2345 | BN11: =rounddown(($AX11*VLOOKUP($B$13,$AU$177:$BE$185,7,false))+VLOOKUP(AV11,$AU$191:$AY$205,5,false),0) -> 2345 | BO11: =rounddown(($AX11*VLOOKUP($B$13,$AU$177:$BE$185,8,false))+VLOOKUP(AV11,$AU$191:$AY$205,5,false),0) -> 2345 | BP11: =rounddown(($AX11*VLOOKUP($B$13,$AU$177:$BE$185,9,false))+VLOOKUP(AV11,$AU$191:$AY$205,5,false),0) -> 2345 | BQ11: =rounddown(($AX11*VLOOKUP($B$13,$AU$177:$BE$185,10,false))+VLOOKUP(AV11,$AU$191:$AY$205,5,false),0) -> 2345 | BR11: =rounddown(($AX11*VLOOKUP($B$13,$AU$177:$BE$185,11,false))+VLOOKUP(AV11,$AU$191:$AY$205,5,false),0) -> 2345
B12: ラベル | E12: ロール | H12: 属性 | K12: 攻撃射程 | AU12: 4 | AV12: 0 | AW12: =Floor( $AW$9+($AW$171-$AW$9) * Pow( (AU12-1) / ($AU$171-1),$AU$189) ,1) -> 1672 | AX12: =Floor( $AX$9+($AX$171-$AX$9) * Pow( (AU12-1) / ($AU$171-1),$AU$189) ,1) -> 1953 | AY12: =VLOOKUP(AV12,$AU$191:$AY$205,4,FALSE)+AW12 -> 1672 | AZ12: =VLOOKUP(AV12,$AU$191:$AY$205,5,FALSE)+AX12 -> 1953 | BA12: =rounddown(($AW12*VLOOKUP($B$13,$AU$177:$AW$185,3,false))+VLOOKUP(AV12,$AU$191:$AY$205,4,false),0) -> 1872 | BB12: =rounddown(($AW12*VLOOKUP($B$13,$AU$177:$AX$185,4,false))+VLOOKUP(AV12,$AU$191:$AY$205,4,false),0) -> 1989 | BC12: =rounddown(($AW12*VLOOKUP($B$13,$AU$177:$AY$185,5,false))+VLOOKUP(AV12,$AU$191:$AY$205,4,false),0) -> 2056 | BD12: =rounddown(($AW12*VLOOKUP($B$13,$AU$177:$AZ$185,6,false))+VLOOKUP(AV12,$AU$191:$AY$205,4,false),0) -> 2090 | BE12: =rounddown(($AW12*VLOOKUP($B$13,$AU$177:$BE$185,7,false))+VLOOKUP(AV12,$AU$191:$AY$205,4,false),0) -> 2090 | BF12: =rounddown(($AW12*VLOOKUP($B$13,$AU$177:$BE$185,8,false))+VLOOKUP(AV12,$AU$191:$AY$205,4,false),0) -> 2090 | BG12: =rounddown(($AW12*VLOOKUP($B$13,$AU$177:$BE$185,9,false))+VLOOKUP(AV12,$AU$191:$AY$205,4,false),0) -> 2090 | BH12: =rounddown(($AW12*VLOOKUP($B$13,$AU$177:$BE$185,10,false))+VLOOKUP(AV12,$AU$191:$AY$205,4,false),0) -> 2090 | BI12: =rounddown(($AW12*VLOOKUP($B$13,$AU$177:$BE$185,11,false))+VLOOKUP(AV12,$AU$191:$AY$205,4,false),0) -> 2090 | BJ12: =rounddown(($AX12*VLOOKUP($B$13,$AU$177:$AW$185,3,false))+VLOOKUP(AV12,$AU$191:$AY$205,5,false),0) -> 2187 | BK12: =rounddown(($AX12*VLOOKUP($B$13,$AU$177:$AX$185,4,false))+VLOOKUP(AV12,$AU$191:$AY$205,5,false),0) -> 2324 | BL12: =rounddown(($AX12*VLOOKUP($B$13,$AU$177:$AY$185,5,false))+VLOOKUP(AV12,$AU$191:$AY$205,5,false),0) -> 2402 | BM12: =rounddown(($AX12*VLOOKUP($B$13,$AU$177:$AZ$185,6,false))+VLOOKUP(AV12,$AU$191:$AY$205,5,false),0) -> 2441 | BN12: =rounddown(($AX12*VLOOKUP($B$13,$AU$177:$BE$185,7,false))+VLOOKUP(AV12,$AU$191:$AY$205,5,false),0) -> 2441 | BO12: =rounddown(($AX12*VLOOKUP($B$13,$AU$177:$BE$185,8,false))+VLOOKUP(AV12,$AU$191:$AY$205,5,false),0) -> 2441 | BP12: =rounddown(($AX12*VLOOKUP($B$13,$AU$177:$BE$185,9,false))+VLOOKUP(AV12,$AU$191:$AY$205,5,false),0) -> 2441 | BQ12: =rounddown(($AX12*VLOOKUP($B$13,$AU$177:$BE$185,10,false))+VLOOKUP(AV12,$AU$191:$AY$205,5,false),0) -> 2441 | BR12: =rounddown(($AX12*VLOOKUP($B$13,$AU$177:$BE$185,11,false))+VLOOKUP(AV12,$AU$191:$AY$205,5,false),0) -> 2441
B13: =IFERROR(__xludf.DUMMYFUNCTION("IFERROR( INDEX( IMPORTRANGE(""https://docs.google.com/spreadsheets/d/1oJmkDK37Qizzdaxn4KCwh1BMwdNWuHCx3AGH8BC9yu0/edit?gid=781951868#gid=781951868"", ""キャラ!I:I""), MATCH(B11, IMPORTRANGE(""https://docs.google.com/spreadsheets/d/1oJmkDK37Qizzdaxn"&"4KCwh1BMwdNWuHCx3AGH8BC9yu0/edit?gid=781951868#gid=781951868"", ""キャラ!D:D""), 0) ), ""該当なし"" ) "),"PremiumSSR") -> PremiumSSR | E13: =IFERROR(__xludf.DUMMYFUNCTION("IFERROR( INDEX( IMPORTRANGE(""https://docs.google.com/spreadsheets/d/1oJmkDK37Qizzdaxn4KCwh1BMwdNWuHCx3AGH8BC9yu0/edit?gid=781951868#gid=781951868"", ""キャラ!L:L""), MATCH(B11, IMPORTRANGE(""https://docs.google.com/spreadsheets/d/1oJmkDK37Qizzdaxn"&"4KCwh1BMwdNWuHCx3AGH8BC9yu0/edit?gid=781951868#gid=781951868"", ""キャラ!D:D""), 0) ), ""該当なし"" ) "),"アタック") -> アタック | H13: =IFERROR(__xludf.DUMMYFUNCTION("IFERROR( INDEX( IMPORTRANGE(""https://docs.google.com/spreadsheets/d/1oJmkDK37Qizzdaxn4KCwh1BMwdNWuHCx3AGH8BC9yu0/edit?gid=781951868#gid=781951868"", ""キャラ!J:J""), MATCH(B11, IMPORTRANGE(""https://docs.google.com/spreadsheets/d/1oJmkDK37Qizzdaxn"&"4KCwh1BMwdNWuHCx3AGH8BC9yu0/edit?gid=781951868#gid=781951868"", ""キャラ!D:D""), 0) ), ""該当なし"" ) "),"赤") -> 赤 | K13: =IFERROR(__xludf.DUMMYFUNCTION("IFERROR( INDEX( IMPORTRANGE(""https://docs.google.com/spreadsheets/d/1oJmkDK37Qizzdaxn4KCwh1BMwdNWuHCx3AGH8BC9yu0/edit?gid=781951868#gid=781951868"", ""キャラ!N:N""), MATCH(B11, IMPORTRANGE(""https://docs.google.com/spreadsheets/d/1oJmkDK37Qizzdaxn"&"4KCwh1BMwdNWuHCx3AGH8BC9yu0/edit?gid=781951868#gid=781951868"", ""キャラ!D:D""), 0) ), ""該当なし"" ) "),"Short") -> Short | AP13: 消さないで | AU13: 5 | AV13: 0 | AW13: =Floor( $AW$9+($AW$171-$AW$9) * Pow( (AU13-1) / ($AU$171-1),$AU$189) ,1) -> 1740 | AX13: =Floor( $AX$9+($AX$171-$AX$9) * Pow( (AU13-1) / ($AU$171-1),$AU$189) ,1) -> 2032 | AY13: =VLOOKUP(AV13,$AU$191:$AY$205,4,FALSE)+AW13 -> 1740 | AZ13: =VLOOKUP(AV13,$AU$191:$AY$205,5,FALSE)+AX13 -> 2032 | BA13: =rounddown(($AW13*VLOOKUP($B$13,$AU$177:$AW$185,3,false))+VLOOKUP(AV13,$AU$191:$AY$205,4,false),0) -> 1948 | BB13: =rounddown(($AW13*VLOOKUP($B$13,$AU$177:$AX$185,4,false))+VLOOKUP(AV13,$AU$191:$AY$205,4,false),0) -> 2070 | BC13: =rounddown(($AW13*VLOOKUP($B$13,$AU$177:$AY$185,5,false))+VLOOKUP(AV13,$AU$191:$AY$205,4,false),0) -> 2140 | BD13: =rounddown(($AW13*VLOOKUP($B$13,$AU$177:$AZ$185,6,false))+VLOOKUP(AV13,$AU$191:$AY$205,4,false),0) -> 2175 | BE13: =rounddown(($AW13*VLOOKUP($B$13,$AU$177:$BE$185,7,false))+VLOOKUP(AV13,$AU$191:$AY$205,4,false),0) -> 2175 | BF13: =rounddown(($AW13*VLOOKUP($B$13,$AU$177:$BE$185,8,false))+VLOOKUP(AV13,$AU$191:$AY$205,4,false),0) -> 2175 | BG13: =rounddown(($AW13*VLOOKUP($B$13,$AU$177:$BE$185,9,false))+VLOOKUP(AV13,$AU$191:$AY$205,4,false),0) -> 2175 | BH13: =rounddown(($AW13*VLOOKUP($B$13,$AU$177:$BE$185,10,false))+VLOOKUP(AV13,$AU$191:$AY$205,4,false),0) -> 2175 | BI13: =rounddown(($AW13*VLOOKUP($B$13,$AU$177:$BE$185,11,false))+VLOOKUP(AV13,$AU$191:$AY$205,4,false),0) -> 2175 | BJ13: =rounddown(($AX13*VLOOKUP($B$13,$AU$177:$AW$185,3,false))+VLOOKUP(AV13,$AU$191:$AY$205,5,false),0) -> 2275 | BK13: =rounddown(($AX13*VLOOKUP($B$13,$AU$177:$AX$185,4,false))+VLOOKUP(AV13,$AU$191:$AY$205,5,false),0) -> 2418 | BL13: =rounddown(($AX13*VLOOKUP($B$13,$AU$177:$AY$185,5,false))+VLOOKUP(AV13,$AU$191:$AY$205,5,false),0) -> 2499 | BM13: =rounddown(($AX13*VLOOKUP($B$13,$AU$177:$AZ$185,6,false))+VLOOKUP(AV13,$AU$191:$AY$205,5,false),0) -> 2540 | BN13: =rounddown(($AX13*VLOOKUP($B$13,$AU$177:$BE$185,7,false))+VLOOKUP(AV13,$AU$191:$AY$205,5,false),0) -> 2540 | BO13: =rounddown(($AX13*VLOOKUP($B$13,$AU$177:$BE$185,8,false))+VLOOKUP(AV13,$AU$191:$AY$205,5,false),0) -> 2540 | BP13: =rounddown(($AX13*VLOOKUP($B$13,$AU$177:$BE$185,9,false))+VLOOKUP(AV13,$AU$191:$AY$205,5,false),0) -> 2540 | BQ13: =rounddown(($AX13*VLOOKUP($B$13,$AU$177:$BE$185,10,false))+VLOOKUP(AV13,$AU$191:$AY$205,5,false),0) -> 2540 | BR13: =rounddown(($AX13*VLOOKUP($B$13,$AU$177:$BE$185,11,false))+VLOOKUP(AV13,$AU$191:$AY$205,5,false),0) -> 2540
B14: ※キャラクター名：Glow_ID_管理のFIX名称を参照。未記入の場合(仮)名称を参照。 | AP14: =IFS(and(E13="ディフェンス",G17<=0.59),"遠距離以外",and(E13="アタック",G17<=0.59),"遠距離以外",and(E13="サポート",G17<=0.59),"遠距離以外",and(E13="テクニカル",G17<=0.59),"遠距離以外",TRUE,"遠距離") -> 遠距離以外 | AU14: 6 | AV14: 0 | AW14: =Floor( $AW$9+($AW$171-$AW$9) * Pow( (AU14-1) / ($AU$171-1),$AU$189) ,1) -> 1810 | AX14: =Floor( $AX$9+($AX$171-$AX$9) * Pow( (AU14-1) / ($AU$171-1),$AU$189) ,1) -> 2114 | AY14: =VLOOKUP(AV14,$AU$191:$AY$205,4,FALSE)+AW14 -> 1810 | AZ14: =VLOOKUP(AV14,$AU$191:$AY$205,5,FALSE)+AX14 -> 2114 | BA14: =rounddown(($AW14*VLOOKUP($B$13,$AU$177:$AW$185,3,false))+VLOOKUP(AV14,$AU$191:$AY$205,4,false),0) -> 2027 | BB14: =rounddown(($AW14*VLOOKUP($B$13,$AU$177:$AX$185,4,false))+VLOOKUP(AV14,$AU$191:$AY$205,4,false),0) -> 2153 | BC14: =rounddown(($AW14*VLOOKUP($B$13,$AU$177:$AY$185,5,false))+VLOOKUP(AV14,$AU$191:$AY$205,4,false),0) -> 2226 | BD14: =rounddown(($AW14*VLOOKUP($B$13,$AU$177:$AZ$185,6,false))+VLOOKUP(AV14,$AU$191:$AY$205,4,false),0) -> 2262 | BE14: =rounddown(($AW14*VLOOKUP($B$13,$AU$177:$BE$185,7,false))+VLOOKUP(AV14,$AU$191:$AY$205,4,false),0) -> 2262 | BF14: =rounddown(($AW14*VLOOKUP($B$13,$AU$177:$BE$185,8,false))+VLOOKUP(AV14,$AU$191:$AY$205,4,false),0) -> 2262 | BG14: =rounddown(($AW14*VLOOKUP($B$13,$AU$177:$BE$185,9,false))+VLOOKUP(AV14,$AU$191:$AY$205,4,false),0) -> 2262 | BH14: =rounddown(($AW14*VLOOKUP($B$13,$AU$177:$BE$185,10,false))+VLOOKUP(AV14,$AU$191:$AY$205,4,false),0) -> 2262 | BI14: =rounddown(($AW14*VLOOKUP($B$13,$AU$177:$BE$185,11,false))+VLOOKUP(AV14,$AU$191:$AY$205,4,false),0) -> 2262 | BJ14: =rounddown(($AX14*VLOOKUP($B$13,$AU$177:$AW$185,3,false))+VLOOKUP(AV14,$AU$191:$AY$205,5,false),0) -> 2367 | BK14: =rounddown(($AX14*VLOOKUP($B$13,$AU$177:$AX$185,4,false))+VLOOKUP(AV14,$AU$191:$AY$205,5,false),0) -> 2515 | BL14: =rounddown(($AX14*VLOOKUP($B$13,$AU$177:$AY$185,5,false))+VLOOKUP(AV14,$AU$191:$AY$205,5,false),0) -> 2600 | BM14: =rounddown(($AX14*VLOOKUP($B$13,$AU$177:$AZ$185,6,false))+VLOOKUP(AV14,$AU$191:$AY$205,5,false),0) -> 2642 | BN14: =rounddown(($AX14*VLOOKUP($B$13,$AU$177:$BE$185,7,false))+VLOOKUP(AV14,$AU$191:$AY$205,5,false),0) -> 2642 | BO14: =rounddown(($AX14*VLOOKUP($B$13,$AU$177:$BE$185,8,false))+VLOOKUP(AV14,$AU$191:$AY$205,5,false),0) -> 2642 | BP14: =rounddown(($AX14*VLOOKUP($B$13,$AU$177:$BE$185,9,false))+VLOOKUP(AV14,$AU$191:$AY$205,5,false),0) -> 2642 | BQ14: =rounddown(($AX14*VLOOKUP($B$13,$AU$177:$BE$185,10,false))+VLOOKUP(AV14,$AU$191:$AY$205,5,false),0) -> 2642 | BR14: =rounddown(($AX14*VLOOKUP($B$13,$AU$177:$BE$185,11,false))+VLOOKUP(AV14,$AU$191:$AY$205,5,false),0) -> 2642
B15: 基本ステータス | AU15: 7 | AV15: 0 | AW15: =Floor( $AW$9+($AW$171-$AW$9) * Pow( (AU15-1) / ($AU$171-1),$AU$189) ,1) -> 1881 | AX15: =Floor( $AX$9+($AX$171-$AX$9) * Pow( (AU15-1) / ($AU$171-1),$AU$189) ,1) -> 2197 | AY15: =VLOOKUP(AV15,$AU$191:$AY$205,4,FALSE)+AW15 -> 1881 | AZ15: =VLOOKUP(AV15,$AU$191:$AY$205,5,FALSE)+AX15 -> 2197 | BA15: =rounddown(($AW15*VLOOKUP($B$13,$AU$177:$AW$185,3,false))+VLOOKUP(AV15,$AU$191:$AY$205,4,false),0) -> 2106 | BB15: =rounddown(($AW15*VLOOKUP($B$13,$AU$177:$AX$185,4,false))+VLOOKUP(AV15,$AU$191:$AY$205,4,false),0) -> 2238 | BC15: =rounddown(($AW15*VLOOKUP($B$13,$AU$177:$AY$185,5,false))+VLOOKUP(AV15,$AU$191:$AY$205,4,false),0) -> 2313 | BD15: =rounddown(($AW15*VLOOKUP($B$13,$AU$177:$AZ$185,6,false))+VLOOKUP(AV15,$AU$191:$AY$205,4,false),0) -> 2351 | BE15: =rounddown(($AW15*VLOOKUP($B$13,$AU$177:$BE$185,7,false))+VLOOKUP(AV15,$AU$191:$AY$205,4,false),0) -> 2351 | BF15: =rounddown(($AW15*VLOOKUP($B$13,$AU$177:$BE$185,8,false))+VLOOKUP(AV15,$AU$191:$AY$205,4,false),0) -> 2351 | BG15: =rounddown(($AW15*VLOOKUP($B$13,$AU$177:$BE$185,9,false))+VLOOKUP(AV15,$AU$191:$AY$205,4,false),0) -> 2351 | BH15: =rounddown(($AW15*VLOOKUP($B$13,$AU$177:$BE$185,10,false))+VLOOKUP(AV15,$AU$191:$AY$205,4,false),0) -> 2351 | BI15: =rounddown(($AW15*VLOOKUP($B$13,$AU$177:$BE$185,11,false))+VLOOKUP(AV15,$AU$191:$AY$205,4,false),0) -> 2351 | BJ15: =rounddown(($AX15*VLOOKUP($B$13,$AU$177:$AW$185,3,false))+VLOOKUP(AV15,$AU$191:$AY$205,5,false),0) -> 2460 | BK15: =rounddown(($AX15*VLOOKUP($B$13,$AU$177:$AX$185,4,false))+VLOOKUP(AV15,$AU$191:$AY$205,5,false),0) -> 2614 | BL15: =rounddown(($AX15*VLOOKUP($B$13,$AU$177:$AY$185,5,false))+VLOOKUP(AV15,$AU$191:$AY$205,5,false),0) -> 2702 | BM15: =rounddown(($AX15*VLOOKUP($B$13,$AU$177:$AZ$185,6,false))+VLOOKUP(AV15,$AU$191:$AY$205,5,false),0) -> 2746 | BN15: =rounddown(($AX15*VLOOKUP($B$13,$AU$177:$BE$185,7,false))+VLOOKUP(AV15,$AU$191:$AY$205,5,false),0) -> 2746 | BO15: =rounddown(($AX15*VLOOKUP($B$13,$AU$177:$BE$185,8,false))+VLOOKUP(AV15,$AU$191:$AY$205,5,false),0) -> 2746 | BP15: =rounddown(($AX15*VLOOKUP($B$13,$AU$177:$BE$185,9,false))+VLOOKUP(AV15,$AU$191:$AY$205,5,false),0) -> 2746 | BQ15: =rounddown(($AX15*VLOOKUP($B$13,$AU$177:$BE$185,10,false))+VLOOKUP(AV15,$AU$191:$AY$205,5,false),0) -> 2746 | BR15: =rounddown(($AX15*VLOOKUP($B$13,$AU$177:$BE$185,11,false))+VLOOKUP(AV15,$AU$191:$AY$205,5,false),0) -> 2746
B16: 召喚コスト | D16: 再召喚時間F | G16: well_distace | J16: 移動速度 | M16: KB回数 | AU16: 8 | AV16: 0 | AW16: =Floor( $AW$9+($AW$171-$AW$9) * Pow( (AU16-1) / ($AU$171-1),$AU$189) ,1) -> 1954 | AX16: =Floor( $AX$9+($AX$171-$AX$9) * Pow( (AU16-1) / ($AU$171-1),$AU$189) ,1) -> 2281 | AY16: =VLOOKUP(AV16,$AU$191:$AY$205,4,FALSE)+AW16 -> 1954 | AZ16: =VLOOKUP(AV16,$AU$191:$AY$205,5,FALSE)+AX16 -> 2281 | BA16: =rounddown(($AW16*VLOOKUP($B$13,$AU$177:$AW$185,3,false))+VLOOKUP(AV16,$AU$191:$AY$205,4,false),0) -> 2188 | BB16: =rounddown(($AW16*VLOOKUP($B$13,$AU$177:$AX$185,4,false))+VLOOKUP(AV16,$AU$191:$AY$205,4,false),0) -> 2325 | BC16: =rounddown(($AW16*VLOOKUP($B$13,$AU$177:$AY$185,5,false))+VLOOKUP(AV16,$AU$191:$AY$205,4,false),0) -> 2403 | BD16: =rounddown(($AW16*VLOOKUP($B$13,$AU$177:$AZ$185,6,false))+VLOOKUP(AV16,$AU$191:$AY$205,4,false),0) -> 2442 | BE16: =rounddown(($AW16*VLOOKUP($B$13,$AU$177:$BE$185,7,false))+VLOOKUP(AV16,$AU$191:$AY$205,4,false),0) -> 2442 | BF16: =rounddown(($AW16*VLOOKUP($B$13,$AU$177:$BE$185,8,false))+VLOOKUP(AV16,$AU$191:$AY$205,4,false),0) -> 2442 | BG16: =rounddown(($AW16*VLOOKUP($B$13,$AU$177:$BE$185,9,false))+VLOOKUP(AV16,$AU$191:$AY$205,4,false),0) -> 2442 | BH16: =rounddown(($AW16*VLOOKUP($B$13,$AU$177:$BE$185,10,false))+VLOOKUP(AV16,$AU$191:$AY$205,4,false),0) -> 2442 | BI16: =rounddown(($AW16*VLOOKUP($B$13,$AU$177:$BE$185,11,false))+VLOOKUP(AV16,$AU$191:$AY$205,4,false),0) -> 2442 | BJ16: =rounddown(($AX16*VLOOKUP($B$13,$AU$177:$AW$185,3,false))+VLOOKUP(AV16,$AU$191:$AY$205,5,false),0) -> 2554 | BK16: =rounddown(($AX16*VLOOKUP($B$13,$AU$177:$AX$185,4,false))+VLOOKUP(AV16,$AU$191:$AY$205,5,false),0) -> 2714 | BL16: =rounddown(($AX16*VLOOKUP($B$13,$AU$177:$AY$185,5,false))+VLOOKUP(AV16,$AU$191:$AY$205,5,false),0) -> 2805 | BM16: =rounddown(($AX16*VLOOKUP($B$13,$AU$177:$AZ$185,6,false))+VLOOKUP(AV16,$AU$191:$AY$205,5,false),0) -> 2851 | BN16: =rounddown(($AX16*VLOOKUP($B$13,$AU$177:$BE$185,7,false))+VLOOKUP(AV16,$AU$191:$AY$205,5,false),0) -> 2851 | BO16: =rounddown(($AX16*VLOOKUP($B$13,$AU$177:$BE$185,8,false))+VLOOKUP(AV16,$AU$191:$AY$205,5,false),0) -> 2851 | BP16: =rounddown(($AX16*VLOOKUP($B$13,$AU$177:$BE$185,9,false))+VLOOKUP(AV16,$AU$191:$AY$205,5,false),0) -> 2851 | BQ16: =rounddown(($AX16*VLOOKUP($B$13,$AU$177:$BE$185,10,false))+VLOOKUP(AV16,$AU$191:$AY$205,5,false),0) -> 2851 | BR16: =rounddown(($AX16*VLOOKUP($B$13,$AU$177:$BE$185,11,false))+VLOOKUP(AV16,$AU$191:$AY$205,5,false),0) -> 2851
B17: =IFERROR(__xludf.DUMMYFUNCTION("IFERROR( INDEX( IMPORTRANGE(""https://docs.google.com/spreadsheets/d/1tAaChe98Zh7vhMfGMK5Y4_ijmNb40fr519GtdZkkDUY/edit?gid=1369914306#gid=1369914306"", ""キャラ基礎数値!M:M""), MATCH(B11, IMPORTRANGE(""https://docs.google.com/spreadsheets/d/1tAaChe98Zh"&"7vhMfGMK5Y4_ijmNb40fr519GtdZkkDUY/edit?gid=1369914306#gid=1369914306"", ""キャラ基礎数値!C:C""), 0) ), ""該当なし"" ) "),620.0) -> 620 | D17: =IFERROR(__xludf.DUMMYFUNCTION("IF( E13 = ""スペシャル"", ""-"", IFERROR( INDEX( IMPORTRANGE(""https://docs.google.com/spreadsheets/d/1tAaChe98Zh7vhMfGMK5Y4_ijmNb40fr519GtdZkkDUY/edit#gid=1369914306"", ""キャラ基礎数値!T:T""), MATCH(B11, IMPORTRANGE(""https://docs.google.com/s"&"preadsheets/d/1tAaChe98Zh7vhMfGMK5Y4_ijmNb40fr519GtdZkkDUY/edit#gid=1369914306"", ""キャラ基礎数値!C:C""), 0) ), ""該当なし"" ) ) "),545.0) -> 545 | G17: =IFERROR(__xludf.DUMMYFUNCTION("IFERROR( INDEX( IMPORTRANGE(""https://docs.google.com/spreadsheets/d/1tAaChe98Zh7vhMfGMK5Y4_ijmNb40fr519GtdZkkDUY/edit#gid=1369914306"", ""キャラ基礎数値!BT:BT""), MATCH(B11, IMPORTRANGE(""https://docs.google.com/spreadsheets/d/1tAaChe98Zh7vhMfGMK5Y4_i"&"jmNb40fr519GtdZkkDUY/edit#gid=1369914306"", ""キャラ基礎数値!C:C""), 0) ), ""該当なし"" ) "),0.29) -> 0.29 | J17: =IFERROR(__xludf.DUMMYFUNCTION("IFERROR( INDEX( IMPORTRANGE(""https://docs.google.com/spreadsheets/d/1tAaChe98Zh7vhMfGMK5Y4_ijmNb40fr519GtdZkkDUY/edit#gid=1369914306"", ""キャラ基礎数値!BS:BS""), MATCH(B11, IMPORTRANGE(""https://docs.google.com/spreadsheets/d/1tAaChe98Zh7vhMfGMK5Y4_i"&"jmNb40fr519GtdZkkDUY/edit#gid=1369914306"", ""キャラ基礎数値!C:C""), 0) ), ""該当なし"" ) "),40.0) -> 40 | M17: =IFERROR(__xludf.DUMMYFUNCTION("IFERROR( INDEX( IMPORTRANGE(""https://docs.google.com/spreadsheets/d/1tAaChe98Zh7vhMfGMK5Y4_ijmNb40fr519GtdZkkDUY/edit#gid=1369914306"", ""キャラ基礎数値!BR:BR""), MATCH(B11, IMPORTRANGE(""https://docs.google.com/spreadsheets/d/1tAaChe98Zh7vhMfGMK5Y4_i"&"jmNb40fr519GtdZkkDUY/edit#gid=1369914306"", ""キャラ基礎数値!C:C""), 0) ), ""該当なし"" ) "),2.0) -> 2 | AU17: 9 | AV17: 0 | AW17: =Floor( $AW$9+($AW$171-$AW$9) * Pow( (AU17-1) / ($AU$171-1),$AU$189) ,1) -> 2027 | AX17: =Floor( $AX$9+($AX$171-$AX$9) * Pow( (AU17-1) / ($AU$171-1),$AU$189) ,1) -> 2367 | AY17: =VLOOKUP(AV17,$AU$191:$AY$205,4,FALSE)+AW17 -> 2027 | AZ17: =VLOOKUP(AV17,$AU$191:$AY$205,5,FALSE)+AX17 -> 2367 | BA17: =rounddown(($AW17*VLOOKUP($B$13,$AU$177:$AW$185,3,false))+VLOOKUP(AV17,$AU$191:$AY$205,4,false),0) -> 2270 | BB17: =rounddown(($AW17*VLOOKUP($B$13,$AU$177:$AX$185,4,false))+VLOOKUP(AV17,$AU$191:$AY$205,4,false),0) -> 2412 | BC17: =rounddown(($AW17*VLOOKUP($B$13,$AU$177:$AY$185,5,false))+VLOOKUP(AV17,$AU$191:$AY$205,4,false),0) -> 2493 | BD17: =rounddown(($AW17*VLOOKUP($B$13,$AU$177:$AZ$185,6,false))+VLOOKUP(AV17,$AU$191:$AY$205,4,false),0) -> 2533 | BE17: =rounddown(($AW17*VLOOKUP($B$13,$AU$177:$BE$185,7,false))+VLOOKUP(AV17,$AU$191:$AY$205,4,false),0) -> 2533 | BF17: =rounddown(($AW17*VLOOKUP($B$13,$AU$177:$BE$185,8,false))+VLOOKUP(AV17,$AU$191:$AY$205,4,false),0) -> 2533 | BG17: =rounddown(($AW17*VLOOKUP($B$13,$AU$177:$BE$185,9,false))+VLOOKUP(AV17,$AU$191:$AY$205,4,false),0) -> 2533 | BH17: =rounddown(($AW17*VLOOKUP($B$13,$AU$177:$BE$185,10,false))+VLOOKUP(AV17,$AU$191:$AY$205,4,false),0) -> 2533 | BI17: =rounddown(($AW17*VLOOKUP($B$13,$AU$177:$BE$185,11,false))+VLOOKUP(AV17,$AU$191:$AY$205,4,false),0) -> 2533 | BJ17: =rounddown(($AX17*VLOOKUP($B$13,$AU$177:$AW$185,3,false))+VLOOKUP(AV17,$AU$191:$AY$205,5,false),0) -> 2651 | BK17: =rounddown(($AX17*VLOOKUP($B$13,$AU$177:$AX$185,4,false))+VLOOKUP(AV17,$AU$191:$AY$205,5,false),0) -> 2816 | BL17: =rounddown(($AX17*VLOOKUP($B$13,$AU$177:$AY$185,5,false))+VLOOKUP(AV17,$AU$191:$AY$205,5,false),0) -> 2911 | BM17: =rounddown(($AX17*VLOOKUP($B$13,$AU$177:$AZ$185,6,false))+VLOOKUP(AV17,$AU$191:$AY$205,5,false),0) -> 2958 | BN17: =rounddown(($AX17*VLOOKUP($B$13,$AU$177:$BE$185,7,false))+VLOOKUP(AV17,$AU$191:$AY$205,5,false),0) -> 2958 | BO17: =rounddown(($AX17*VLOOKUP($B$13,$AU$177:$BE$185,8,false))+VLOOKUP(AV17,$AU$191:$AY$205,5,false),0) -> 2958 | BP17: =rounddown(($AX17*VLOOKUP($B$13,$AU$177:$BE$185,9,false))+VLOOKUP(AV17,$AU$191:$AY$205,5,false),0) -> 2958 | BQ17: =rounddown(($AX17*VLOOKUP($B$13,$AU$177:$BE$185,10,false))+VLOOKUP(AV17,$AU$191:$AY$205,5,false),0) -> 2958 | BR17: =rounddown(($AX17*VLOOKUP($B$13,$AU$177:$BE$185,11,false))+VLOOKUP(AV17,$AU$191:$AY$205,5,false),0) -> 2958
AU18: 10 | AV18: 0 | AW18: =Floor( $AW$9+($AW$171-$AW$9) * Pow( (AU18-1) / ($AU$171-1),$AU$189) ,1) -> 2101 | AX18: =Floor( $AX$9+($AX$171-$AX$9) * Pow( (AU18-1) / ($AU$171-1),$AU$189) ,1) -> 2454 | AY18: =VLOOKUP(AV18,$AU$191:$AY$205,4,FALSE)+AW18 -> 2101 | AZ18: =VLOOKUP(AV18,$AU$191:$AY$205,5,FALSE)+AX18 -> 2454 | BA18: =rounddown(($AW18*VLOOKUP($B$13,$AU$177:$AW$185,3,false))+VLOOKUP(AV18,$AU$191:$AY$205,4,false),0) -> 2353 | BB18: =rounddown(($AW18*VLOOKUP($B$13,$AU$177:$AX$185,4,false))+VLOOKUP(AV18,$AU$191:$AY$205,4,false),0) -> 2500 | BC18: =rounddown(($AW18*VLOOKUP($B$13,$AU$177:$AY$185,5,false))+VLOOKUP(AV18,$AU$191:$AY$205,4,false),0) -> 2584 | BD18: =rounddown(($AW18*VLOOKUP($B$13,$AU$177:$AZ$185,6,false))+VLOOKUP(AV18,$AU$191:$AY$205,4,false),0) -> 2626 | BE18: =rounddown(($AW18*VLOOKUP($B$13,$AU$177:$BE$185,7,false))+VLOOKUP(AV18,$AU$191:$AY$205,4,false),0) -> 2626 | BF18: =rounddown(($AW18*VLOOKUP($B$13,$AU$177:$BE$185,8,false))+VLOOKUP(AV18,$AU$191:$AY$205,4,false),0) -> 2626 | BG18: =rounddown(($AW18*VLOOKUP($B$13,$AU$177:$BE$185,9,false))+VLOOKUP(AV18,$AU$191:$AY$205,4,false),0) -> 2626 | BH18: =rounddown(($AW18*VLOOKUP($B$13,$AU$177:$BE$185,10,false))+VLOOKUP(AV18,$AU$191:$AY$205,4,false),0) -> 2626 | BI18: =rounddown(($AW18*VLOOKUP($B$13,$AU$177:$BE$185,11,false))+VLOOKUP(AV18,$AU$191:$AY$205,4,false),0) -> 2626 | BJ18: =rounddown(($AX18*VLOOKUP($B$13,$AU$177:$AW$185,3,false))+VLOOKUP(AV18,$AU$191:$AY$205,5,false),0) -> 2748 | BK18: =rounddown(($AX18*VLOOKUP($B$13,$AU$177:$AX$185,4,false))+VLOOKUP(AV18,$AU$191:$AY$205,5,false),0) -> 2920 | BL18: =rounddown(($AX18*VLOOKUP($B$13,$AU$177:$AY$185,5,false))+VLOOKUP(AV18,$AU$191:$AY$205,5,false),0) -> 3018 | BM18: =rounddown(($AX18*VLOOKUP($B$13,$AU$177:$AZ$185,6,false))+VLOOKUP(AV18,$AU$191:$AY$205,5,false),0) -> 3067 | BN18: =rounddown(($AX18*VLOOKUP($B$13,$AU$177:$BE$185,7,false))+VLOOKUP(AV18,$AU$191:$AY$205,5,false),0) -> 3067 | BO18: =rounddown(($AX18*VLOOKUP($B$13,$AU$177:$BE$185,8,false))+VLOOKUP(AV18,$AU$191:$AY$205,5,false),0) -> 3067 | BP18: =rounddown(($AX18*VLOOKUP($B$13,$AU$177:$BE$185,9,false))+VLOOKUP(AV18,$AU$191:$AY$205,5,false),0) -> 3067 | BQ18: =rounddown(($AX18*VLOOKUP($B$13,$AU$177:$BE$185,10,false))+VLOOKUP(AV18,$AU$191:$AY$205,5,false),0) -> 3067 | BR18: =rounddown(($AX18*VLOOKUP($B$13,$AU$177:$BE$185,11,false))+VLOOKUP(AV18,$AU$191:$AY$205,5,false),0) -> 3067
B19: Lvステータス | AU19: 10 | AV19: 0 | AW19: =Floor( $AW$9+($AW$171-$AW$9) * Pow( (AU19-1) / ($AU$171-1),$AU$189) ,1) -> 2101 | AX19: =Floor( $AX$9+($AX$171-$AX$9) * Pow( (AU19-1) / ($AU$171-1),$AU$189) ,1) -> 2454 | AY19: =VLOOKUP(AV19,$AU$191:$AY$205,4,FALSE)+AW19 -> 2101 | AZ19: =VLOOKUP(AV19,$AU$191:$AY$205,5,FALSE)+AX19 -> 2454 | BA19: =rounddown(($AW19*VLOOKUP($B$13,$AU$177:$AW$185,3,false))+VLOOKUP(AV19,$AU$191:$AY$205,4,false),0) -> 2353 | BB19: =rounddown(($AW19*VLOOKUP($B$13,$AU$177:$AX$185,4,false))+VLOOKUP(AV19,$AU$191:$AY$205,4,false),0) -> 2500 | BC19: =rounddown(($AW19*VLOOKUP($B$13,$AU$177:$AY$185,5,false))+VLOOKUP(AV19,$AU$191:$AY$205,4,false),0) -> 2584 | BD19: =rounddown(($AW19*VLOOKUP($B$13,$AU$177:$AZ$185,6,false))+VLOOKUP(AV19,$AU$191:$AY$205,4,false),0) -> 2626 | BE19: =rounddown(($AW19*VLOOKUP($B$13,$AU$177:$BE$185,7,false))+VLOOKUP(AV19,$AU$191:$AY$205,4,false),0) -> 2626 | BF19: =rounddown(($AW19*VLOOKUP($B$13,$AU$177:$BE$185,8,false))+VLOOKUP(AV19,$AU$191:$AY$205,4,false),0) -> 2626 | BG19: =rounddown(($AW19*VLOOKUP($B$13,$AU$177:$BE$185,9,false))+VLOOKUP(AV19,$AU$191:$AY$205,4,false),0) -> 2626 | BH19: =rounddown(($AW19*VLOOKUP($B$13,$AU$177:$BE$185,10,false))+VLOOKUP(AV19,$AU$191:$AY$205,4,false),0) -> 2626 | BI19: =rounddown(($AW19*VLOOKUP($B$13,$AU$177:$BE$185,11,false))+VLOOKUP(AV19,$AU$191:$AY$205,4,false),0) -> 2626 | BJ19: =rounddown(($AX19*VLOOKUP($B$13,$AU$177:$AW$185,3,false))+VLOOKUP(AV19,$AU$191:$AY$205,5,false),0) -> 2748 | BK19: =rounddown(($AX19*VLOOKUP($B$13,$AU$177:$AX$185,4,false))+VLOOKUP(AV19,$AU$191:$AY$205,5,false),0) -> 2920 | BL19: =rounddown(($AX19*VLOOKUP($B$13,$AU$177:$AY$185,5,false))+VLOOKUP(AV19,$AU$191:$AY$205,5,false),0) -> 3018 | BM19: =rounddown(($AX19*VLOOKUP($B$13,$AU$177:$AZ$185,6,false))+VLOOKUP(AV19,$AU$191:$AY$205,5,false),0) -> 3067 | BN19: =rounddown(($AX19*VLOOKUP($B$13,$AU$177:$BE$185,7,false))+VLOOKUP(AV19,$AU$191:$AY$205,5,false),0) -> 3067 | BO19: =rounddown(($AX19*VLOOKUP($B$13,$AU$177:$BE$185,8,false))+VLOOKUP(AV19,$AU$191:$AY$205,5,false),0) -> 3067 | BP19: =rounddown(($AX19*VLOOKUP($B$13,$AU$177:$BE$185,9,false))+VLOOKUP(AV19,$AU$191:$AY$205,5,false),0) -> 3067 | BQ19: =rounddown(($AX19*VLOOKUP($B$13,$AU$177:$BE$185,10,false))+VLOOKUP(AV19,$AU$191:$AY$205,5,false),0) -> 3067 | BR19: =rounddown(($AX19*VLOOKUP($B$13,$AU$177:$BE$185,11,false))+VLOOKUP(AV19,$AU$191:$AY$205,5,false),0) -> 3067
B20: 体力Lv1 | E20: 体力Lv150 | H20: 攻撃力Lv1 | K20: 攻撃力Lv150 | AU20: 11 | AV20: 0 | AW20: =Floor( $AW$9+($AW$171-$AW$9) * Pow( (AU20-1) / ($AU$171-1),$AU$189) ,1) -> 2176 | AX20: =Floor( $AX$9+($AX$171-$AX$9) * Pow( (AU20-1) / ($AU$171-1),$AU$189) ,1) -> 2542 | AY20: =VLOOKUP(AV20,$AU$191:$AY$205,4,FALSE)+AW20 -> 2176 | AZ20: =VLOOKUP(AV20,$AU$191:$AY$205,5,FALSE)+AX20 -> 2542 | BA20: =rounddown(($AW20*VLOOKUP($B$13,$AU$177:$AW$185,3,false))+VLOOKUP(AV20,$AU$191:$AY$205,4,false),0) -> 2437 | BB20: =rounddown(($AW20*VLOOKUP($B$13,$AU$177:$AX$185,4,false))+VLOOKUP(AV20,$AU$191:$AY$205,4,false),0) -> 2589 | BC20: =rounddown(($AW20*VLOOKUP($B$13,$AU$177:$AY$185,5,false))+VLOOKUP(AV20,$AU$191:$AY$205,4,false),0) -> 2676 | BD20: =rounddown(($AW20*VLOOKUP($B$13,$AU$177:$AZ$185,6,false))+VLOOKUP(AV20,$AU$191:$AY$205,4,false),0) -> 2720 | BE20: =rounddown(($AW20*VLOOKUP($B$13,$AU$177:$BE$185,7,false))+VLOOKUP(AV20,$AU$191:$AY$205,4,false),0) -> 2720 | BF20: =rounddown(($AW20*VLOOKUP($B$13,$AU$177:$BE$185,8,false))+VLOOKUP(AV20,$AU$191:$AY$205,4,false),0) -> 2720 | BG20: =rounddown(($AW20*VLOOKUP($B$13,$AU$177:$BE$185,9,false))+VLOOKUP(AV20,$AU$191:$AY$205,4,false),0) -> 2720 | BH20: =rounddown(($AW20*VLOOKUP($B$13,$AU$177:$BE$185,10,false))+VLOOKUP(AV20,$AU$191:$AY$205,4,false),0) -> 2720 | BI20: =rounddown(($AW20*VLOOKUP($B$13,$AU$177:$BE$185,11,false))+VLOOKUP(AV20,$AU$191:$AY$205,4,false),0) -> 2720 | BJ20: =rounddown(($AX20*VLOOKUP($B$13,$AU$177:$AW$185,3,false))+VLOOKUP(AV20,$AU$191:$AY$205,5,false),0) -> 2847 | BK20: =rounddown(($AX20*VLOOKUP($B$13,$AU$177:$AX$185,4,false))+VLOOKUP(AV20,$AU$191:$AY$205,5,false),0) -> 3024 | BL20: =rounddown(($AX20*VLOOKUP($B$13,$AU$177:$AY$185,5,false))+VLOOKUP(AV20,$AU$191:$AY$205,5,false),0) -> 3126 | BM20: =rounddown(($AX20*VLOOKUP($B$13,$AU$177:$AZ$185,6,false))+VLOOKUP(AV20,$AU$191:$AY$205,5,false),0) -> 3177 | BN20: =rounddown(($AX20*VLOOKUP($B$13,$AU$177:$BE$185,7,false))+VLOOKUP(AV20,$AU$191:$AY$205,5,false),0) -> 3177 | BO20: =rounddown(($AX20*VLOOKUP($B$13,$AU$177:$BE$185,8,false))+VLOOKUP(AV20,$AU$191:$AY$205,5,false),0) -> 3177 | BP20: =rounddown(($AX20*VLOOKUP($B$13,$AU$177:$BE$185,9,false))+VLOOKUP(AV20,$AU$191:$AY$205,5,false),0) -> 3177 | BQ20: =rounddown(($AX20*VLOOKUP($B$13,$AU$177:$BE$185,10,false))+VLOOKUP(AV20,$AU$191:$AY$205,5,false),0) -> 3177 | BR20: =rounddown(($AX20*VLOOKUP($B$13,$AU$177:$BE$185,11,false))+VLOOKUP(AV20,$AU$191:$AY$205,5,false),0) -> 3177
B21: =IFERROR(__xludf.DUMMYFUNCTION("IF( E13 = ""スペシャル"", ""-"", IFERROR( INDEX( IMPORTRANGE(""https://docs.google.com/spreadsheets/d/1tAaChe98Zh7vhMfGMK5Y4_ijmNb40fr519GtdZkkDUY/edit#gid=1369914306"", ""キャラ基礎数値!AL:AL""), MATCH(B11, IMPORTRANGE(""https://docs.google.com"&"/spreadsheets/d/1tAaChe98Zh7vhMfGMK5Y4_ijmNb40fr519GtdZkkDUY/edit#gid=1369914306"", ""キャラ基礎数値!C:C""), 0) ), ""該当なし"" ) ) "),1490.0) -> 1490 | E21: =IF(E13 = "スペシャル", "-", B21 * 10) -> 14900 | H21: =IFERROR(__xludf.DUMMYFUNCTION("IF( E13 = ""スペシャル"", ""-"", IFERROR( INDEX( IMPORTRANGE(""https://docs.google.com/spreadsheets/d/1tAaChe98Zh7vhMfGMK5Y4_ijmNb40fr519GtdZkkDUY/edit#gid=1369914306"", ""キャラ基礎数値!AX:AX""), MATCH(B11, IMPORTRANGE(""https://docs.google.com"&"/spreadsheets/d/1tAaChe98Zh7vhMfGMK5Y4_ijmNb40fr519GtdZkkDUY/edit#gid=1369914306"", ""キャラ基礎数値!C:C""), 0) ), ""該当なし"" ) ) "),1740.0) -> 1740 | K21: =IF(E13 = "スペシャル", "-", H21 * 10) -> 17400 | AU21: 12 | AV21: 0 | AW21: =Floor( $AW$9+($AW$171-$AW$9) * Pow( (AU21-1) / ($AU$171-1),$AU$189) ,1) -> 2252 | AX21: =Floor( $AX$9+($AX$171-$AX$9) * Pow( (AU21-1) / ($AU$171-1),$AU$189) ,1) -> 2630 | AY21: =VLOOKUP(AV21,$AU$191:$AY$205,4,FALSE)+AW21 -> 2252 | AZ21: =VLOOKUP(AV21,$AU$191:$AY$205,5,FALSE)+AX21 -> 2630 | BA21: =rounddown(($AW21*VLOOKUP($B$13,$AU$177:$AW$185,3,false))+VLOOKUP(AV21,$AU$191:$AY$205,4,false),0) -> 2522 | BB21: =rounddown(($AW21*VLOOKUP($B$13,$AU$177:$AX$185,4,false))+VLOOKUP(AV21,$AU$191:$AY$205,4,false),0) -> 2679 | BC21: =rounddown(($AW21*VLOOKUP($B$13,$AU$177:$AY$185,5,false))+VLOOKUP(AV21,$AU$191:$AY$205,4,false),0) -> 2769 | BD21: =rounddown(($AW21*VLOOKUP($B$13,$AU$177:$AZ$185,6,false))+VLOOKUP(AV21,$AU$191:$AY$205,4,false),0) -> 2815 | BE21: =rounddown(($AW21*VLOOKUP($B$13,$AU$177:$BE$185,7,false))+VLOOKUP(AV21,$AU$191:$AY$205,4,false),0) -> 2815 | BF21: =rounddown(($AW21*VLOOKUP($B$13,$AU$177:$BE$185,8,false))+VLOOKUP(AV21,$AU$191:$AY$205,4,false),0) -> 2815 | BG21: =rounddown(($AW21*VLOOKUP($B$13,$AU$177:$BE$185,9,false))+VLOOKUP(AV21,$AU$191:$AY$205,4,false),0) -> 2815 | BH21: =rounddown(($AW21*VLOOKUP($B$13,$AU$177:$BE$185,10,false))+VLOOKUP(AV21,$AU$191:$AY$205,4,false),0) -> 2815 | BI21: =rounddown(($AW21*VLOOKUP($B$13,$AU$177:$BE$185,11,false))+VLOOKUP(AV21,$AU$191:$AY$205,4,false),0) -> 2815 | BJ21: =rounddown(($AX21*VLOOKUP($B$13,$AU$177:$AW$185,3,false))+VLOOKUP(AV21,$AU$191:$AY$205,5,false),0) -> 2945 | BK21: =rounddown(($AX21*VLOOKUP($B$13,$AU$177:$AX$185,4,false))+VLOOKUP(AV21,$AU$191:$AY$205,5,false),0) -> 3129 | BL21: =rounddown(($AX21*VLOOKUP($B$13,$AU$177:$AY$185,5,false))+VLOOKUP(AV21,$AU$191:$AY$205,5,false),0) -> 3234 | BM21: =rounddown(($AX21*VLOOKUP($B$13,$AU$177:$AZ$185,6,false))+VLOOKUP(AV21,$AU$191:$AY$205,5,false),0) -> 3287 | BN21: =rounddown(($AX21*VLOOKUP($B$13,$AU$177:$BE$185,7,false))+VLOOKUP(AV21,$AU$191:$AY$205,5,false),0) -> 3287 | BO21: =rounddown(($AX21*VLOOKUP($B$13,$AU$177:$BE$185,8,false))+VLOOKUP(AV21,$AU$191:$AY$205,5,false),0) -> 3287 | BP21: =rounddown(($AX21*VLOOKUP($B$13,$AU$177:$BE$185,9,false))+VLOOKUP(AV21,$AU$191:$AY$205,5,false),0) -> 3287 | BQ21: =rounddown(($AX21*VLOOKUP($B$13,$AU$177:$BE$185,10,false))+VLOOKUP(AV21,$AU$191:$AY$205,5,false),0) -> 3287 | BR21: =rounddown(($AX21*VLOOKUP($B$13,$AU$177:$BE$185,11,false))+VLOOKUP(AV21,$AU$191:$AY$205,5,false),0) -> 3287
AU22: 13 | AV22: 0 | AW22: =Floor( $AW$9+($AW$171-$AW$9) * Pow( (AU22-1) / ($AU$171-1),$AU$189) ,1) -> 2329 | AX22: =Floor( $AX$9+($AX$171-$AX$9) * Pow( (AU22-1) / ($AU$171-1),$AU$189) ,1) -> 2720 | AY22: =VLOOKUP(AV22,$AU$191:$AY$205,4,FALSE)+AW22 -> 2329 | AZ22: =VLOOKUP(AV22,$AU$191:$AY$205,5,FALSE)+AX22 -> 2720 | BA22: =rounddown(($AW22*VLOOKUP($B$13,$AU$177:$AW$185,3,false))+VLOOKUP(AV22,$AU$191:$AY$205,4,false),0) -> 2608 | BB22: =rounddown(($AW22*VLOOKUP($B$13,$AU$177:$AX$185,4,false))+VLOOKUP(AV22,$AU$191:$AY$205,4,false),0) -> 2771 | BC22: =rounddown(($AW22*VLOOKUP($B$13,$AU$177:$AY$185,5,false))+VLOOKUP(AV22,$AU$191:$AY$205,4,false),0) -> 2864 | BD22: =rounddown(($AW22*VLOOKUP($B$13,$AU$177:$AZ$185,6,false))+VLOOKUP(AV22,$AU$191:$AY$205,4,false),0) -> 2911 | BE22: =rounddown(($AW22*VLOOKUP($B$13,$AU$177:$BE$185,7,false))+VLOOKUP(AV22,$AU$191:$AY$205,4,false),0) -> 2911 | BF22: =rounddown(($AW22*VLOOKUP($B$13,$AU$177:$BE$185,8,false))+VLOOKUP(AV22,$AU$191:$AY$205,4,false),0) -> 2911 | BG22: =rounddown(($AW22*VLOOKUP($B$13,$AU$177:$BE$185,9,false))+VLOOKUP(AV22,$AU$191:$AY$205,4,false),0) -> 2911 | BH22: =rounddown(($AW22*VLOOKUP($B$13,$AU$177:$BE$185,10,false))+VLOOKUP(AV22,$AU$191:$AY$205,4,false),0) -> 2911 | BI22: =rounddown(($AW22*VLOOKUP($B$13,$AU$177:$BE$185,11,false))+VLOOKUP(AV22,$AU$191:$AY$205,4,false),0) -> 2911 | BJ22: =rounddown(($AX22*VLOOKUP($B$13,$AU$177:$AW$185,3,false))+VLOOKUP(AV22,$AU$191:$AY$205,5,false),0) -> 3046 | BK22: =rounddown(($AX22*VLOOKUP($B$13,$AU$177:$AX$185,4,false))+VLOOKUP(AV22,$AU$191:$AY$205,5,false),0) -> 3236 | BL22: =rounddown(($AX22*VLOOKUP($B$13,$AU$177:$AY$185,5,false))+VLOOKUP(AV22,$AU$191:$AY$205,5,false),0) -> 3345 | BM22: =rounddown(($AX22*VLOOKUP($B$13,$AU$177:$AZ$185,6,false))+VLOOKUP(AV22,$AU$191:$AY$205,5,false),0) -> 3400 | BN22: =rounddown(($AX22*VLOOKUP($B$13,$AU$177:$BE$185,7,false))+VLOOKUP(AV22,$AU$191:$AY$205,5,false),0) -> 3400 | BO22: =rounddown(($AX22*VLOOKUP($B$13,$AU$177:$BE$185,8,false))+VLOOKUP(AV22,$AU$191:$AY$205,5,false),0) -> 3400 | BP22: =rounddown(($AX22*VLOOKUP($B$13,$AU$177:$BE$185,9,false))+VLOOKUP(AV22,$AU$191:$AY$205,5,false),0) -> 3400 | BQ22: =rounddown(($AX22*VLOOKUP($B$13,$AU$177:$BE$185,10,false))+VLOOKUP(AV22,$AU$191:$AY$205,5,false),0) -> 3400 | BR22: =rounddown(($AX22*VLOOKUP($B$13,$AU$177:$BE$185,11,false))+VLOOKUP(AV22,$AU$191:$AY$205,5,false),0) -> 3400
B23: 特性 | I23: 効果値 | K23: 解放ランク | M23: 解放レベル | AU23: 14 | AV23: 0 | AW23: =Floor( $AW$9+($AW$171-$AW$9) * Pow( (AU23-1) / ($AU$171-1),$AU$189) ,1) -> 2406 | AX23: =Floor( $AX$9+($AX$171-$AX$9) * Pow( (AU23-1) / ($AU$171-1),$AU$189) ,1) -> 2810 | AY23: =VLOOKUP(AV23,$AU$191:$AY$205,4,FALSE)+AW23 -> 2406 | AZ23: =VLOOKUP(AV23,$AU$191:$AY$205,5,FALSE)+AX23 -> 2810 | BA23: =rounddown(($AW23*VLOOKUP($B$13,$AU$177:$AW$185,3,false))+VLOOKUP(AV23,$AU$191:$AY$205,4,false),0) -> 2694 | BB23: =rounddown(($AW23*VLOOKUP($B$13,$AU$177:$AX$185,4,false))+VLOOKUP(AV23,$AU$191:$AY$205,4,false),0) -> 2863 | BC23: =rounddown(($AW23*VLOOKUP($B$13,$AU$177:$AY$185,5,false))+VLOOKUP(AV23,$AU$191:$AY$205,4,false),0) -> 2959 | BD23: =rounddown(($AW23*VLOOKUP($B$13,$AU$177:$AZ$185,6,false))+VLOOKUP(AV23,$AU$191:$AY$205,4,false),0) -> 3007 | BE23: =rounddown(($AW23*VLOOKUP($B$13,$AU$177:$BE$185,7,false))+VLOOKUP(AV23,$AU$191:$AY$205,4,false),0) -> 3007 | BF23: =rounddown(($AW23*VLOOKUP($B$13,$AU$177:$BE$185,8,false))+VLOOKUP(AV23,$AU$191:$AY$205,4,false),0) -> 3007 | BG23: =rounddown(($AW23*VLOOKUP($B$13,$AU$177:$BE$185,9,false))+VLOOKUP(AV23,$AU$191:$AY$205,4,false),0) -> 3007 | BH23: =rounddown(($AW23*VLOOKUP($B$13,$AU$177:$BE$185,10,false))+VLOOKUP(AV23,$AU$191:$AY$205,4,false),0) -> 3007 | BI23: =rounddown(($AW23*VLOOKUP($B$13,$AU$177:$BE$185,11,false))+VLOOKUP(AV23,$AU$191:$AY$205,4,false),0) -> 3007 | BJ23: =rounddown(($AX23*VLOOKUP($B$13,$AU$177:$AW$185,3,false))+VLOOKUP(AV23,$AU$191:$AY$205,5,false),0) -> 3147 | BK23: =rounddown(($AX23*VLOOKUP($B$13,$AU$177:$AX$185,4,false))+VLOOKUP(AV23,$AU$191:$AY$205,5,false),0) -> 3343 | BL23: =rounddown(($AX23*VLOOKUP($B$13,$AU$177:$AY$185,5,false))+VLOOKUP(AV23,$AU$191:$AY$205,5,false),0) -> 3456 | BM23: =rounddown(($AX23*VLOOKUP($B$13,$AU$177:$AZ$185,6,false))+VLOOKUP(AV23,$AU$191:$AY$205,5,false),0) -> 3512 | BN23: =rounddown(($AX23*VLOOKUP($B$13,$AU$177:$BE$185,7,false))+VLOOKUP(AV23,$AU$191:$AY$205,5,false),0) -> 3512 | BO23: =rounddown(($AX23*VLOOKUP($B$13,$AU$177:$BE$185,8,false))+VLOOKUP(AV23,$AU$191:$AY$205,5,false),0) -> 3512 | BP23: =rounddown(($AX23*VLOOKUP($B$13,$AU$177:$BE$185,9,false))+VLOOKUP(AV23,$AU$191:$AY$205,5,false),0) -> 3512 | BQ23: =rounddown(($AX23*VLOOKUP($B$13,$AU$177:$BE$185,10,false))+VLOOKUP(AV23,$AU$191:$AY$205,5,false),0) -> 3512 | BR23: =rounddown(($AX23*VLOOKUP($B$13,$AU$177:$BE$185,11,false))+VLOOKUP(AV23,$AU$191:$AY$205,5,false),0) -> 3512
B24: 1 | C24: =IFERROR(__xludf.DUMMYFUNCTION("IFERROR( INDEX( IMPORTRANGE(""https://docs.google.com/spreadsheets/d/1tAaChe98Zh7vhMfGMK5Y4_ijmNb40fr519GtdZkkDUY/edit#gid=1369914306"", ""キャラ基礎数値!BW:BW""), MATCH(B11, IMPORTRANGE(""https://docs.google.com/spreadsheets/d/1tAaChe98Zh7vhMfGMK5Y4_i"&"jmNb40fr519GtdZkkDUY/edit#gid=1369914306"", ""キャラ基礎数値!C:C""), 0) ), ""該当なし"" ) "),"攻撃UPコマ効果UP") -> 攻撃UPコマ効果UP | I24: =IFERROR(__xludf.DUMMYFUNCTION("IFERROR( INDEX( IMPORTRANGE(""https://docs.google.com/spreadsheets/d/1tAaChe98Zh7vhMfGMK5Y4_ijmNb40fr519GtdZkkDUY/edit#gid=1369914306"", ""キャラ基礎数値!BX:BX""), MATCH($B$11, IMPORTRANGE(""https://docs.google.com/spreadsheets/d/1tAaChe98Zh7vhMfGMK5Y4"&"_ijmNb40fr519GtdZkkDUY/edit#gid=1369914306"", ""キャラ基礎数値!C:C""), 0) ), ""該当なし"" ) "),20.0) -> 20 | K24: =IFERROR(__xludf.DUMMYFUNCTION("IFERROR( INDEX( IMPORTRANGE(""https://docs.google.com/spreadsheets/d/1tAaChe98Zh7vhMfGMK5Y4_ijmNb40fr519GtdZkkDUY/edit#gid=1369914306"", ""キャラ基礎数値!BY:BY""), MATCH($B$11, IMPORTRANGE(""https://docs.google.com/spreadsheets/d/1tAaChe98Zh7vhMfGMK5Y4"&"_ijmNb40fr519GtdZkkDUY/edit#gid=1369914306"", ""キャラ基礎数値!C:C""), 0) ), ""該当なし"" ) "),0.0) -> 0 | M24: {=INDEX('参照ランク'!C2:C9,MATCH(K24,'参照ランク'!B2:B9))} -> 0 | AU24: 15 | AV24: 0 | AW24: =Floor( $AW$9+($AW$171-$AW$9) * Pow( (AU24-1) / ($AU$171-1),$AU$189) ,1) -> 2484 | AX24: =Floor( $AX$9+($AX$171-$AX$9) * Pow( (AU24-1) / ($AU$171-1),$AU$189) ,1) -> 2901 | AY24: =VLOOKUP(AV24,$AU$191:$AY$205,4,FALSE)+AW24 -> 2484 | AZ24: =VLOOKUP(AV24,$AU$191:$AY$205,5,FALSE)+AX24 -> 2901 | BA24: =rounddown(($AW24*VLOOKUP($B$13,$AU$177:$AW$185,3,false))+VLOOKUP(AV24,$AU$191:$AY$205,4,false),0) -> 2782 | BB24: =rounddown(($AW24*VLOOKUP($B$13,$AU$177:$AX$185,4,false))+VLOOKUP(AV24,$AU$191:$AY$205,4,false),0) -> 2955 | BC24: =rounddown(($AW24*VLOOKUP($B$13,$AU$177:$AY$185,5,false))+VLOOKUP(AV24,$AU$191:$AY$205,4,false),0) -> 3055 | BD24: =rounddown(($AW24*VLOOKUP($B$13,$AU$177:$AZ$185,6,false))+VLOOKUP(AV24,$AU$191:$AY$205,4,false),0) -> 3105 | BE24: =rounddown(($AW24*VLOOKUP($B$13,$AU$177:$BE$185,7,false))+VLOOKUP(AV24,$AU$191:$AY$205,4,false),0) -> 3105 | BF24: =rounddown(($AW24*VLOOKUP($B$13,$AU$177:$BE$185,8,false))+VLOOKUP(AV24,$AU$191:$AY$205,4,false),0) -> 3105 | BG24: =rounddown(($AW24*VLOOKUP($B$13,$AU$177:$BE$185,9,false))+VLOOKUP(AV24,$AU$191:$AY$205,4,false),0) -> 3105 | BH24: =rounddown(($AW24*VLOOKUP($B$13,$AU$177:$BE$185,10,false))+VLOOKUP(AV24,$AU$191:$AY$205,4,false),0) -> 3105 | BI24: =rounddown(($AW24*VLOOKUP($B$13,$AU$177:$BE$185,11,false))+VLOOKUP(AV24,$AU$191:$AY$205,4,false),0) -> 3105 | BJ24: =rounddown(($AX24*VLOOKUP($B$13,$AU$177:$AW$185,3,false))+VLOOKUP(AV24,$AU$191:$AY$205,5,false),0) -> 3249 | BK24: =rounddown(($AX24*VLOOKUP($B$13,$AU$177:$AX$185,4,false))+VLOOKUP(AV24,$AU$191:$AY$205,5,false),0) -> 3452 | BL24: =rounddown(($AX24*VLOOKUP($B$13,$AU$177:$AY$185,5,false))+VLOOKUP(AV24,$AU$191:$AY$205,5,false),0) -> 3568 | BM24: =rounddown(($AX24*VLOOKUP($B$13,$AU$177:$AZ$185,6,false))+VLOOKUP(AV24,$AU$191:$AY$205,5,false),0) -> 3626 | BN24: =rounddown(($AX24*VLOOKUP($B$13,$AU$177:$BE$185,7,false))+VLOOKUP(AV24,$AU$191:$AY$205,5,false),0) -> 3626 | BO24: =rounddown(($AX24*VLOOKUP($B$13,$AU$177:$BE$185,8,false))+VLOOKUP(AV24,$AU$191:$AY$205,5,false),0) -> 3626 | BP24: =rounddown(($AX24*VLOOKUP($B$13,$AU$177:$BE$185,9,false))+VLOOKUP(AV24,$AU$191:$AY$205,5,false),0) -> 3626 | BQ24: =rounddown(($AX24*VLOOKUP($B$13,$AU$177:$BE$185,10,false))+VLOOKUP(AV24,$AU$191:$AY$205,5,false),0) -> 3626 | BR24: =rounddown(($AX24*VLOOKUP($B$13,$AU$177:$BE$185,11,false))+VLOOKUP(AV24,$AU$191:$AY$205,5,false),0) -> 3626
B25: 2 | C25: =IFERROR(__xludf.DUMMYFUNCTION("IFERROR( INDEX( IMPORTRANGE(""https://docs.google.com/spreadsheets/d/1tAaChe98Zh7vhMfGMK5Y4_ijmNb40fr519GtdZkkDUY/edit#gid=1369914306"", ""キャラ基礎数値!BZ:BZ""), MATCH(B11, IMPORTRANGE(""https://docs.google.com/spreadsheets/d/1tAaChe98Zh7vhMfGMK5Y4_i"&"jmNb40fr519GtdZkkDUY/edit#gid=1369914306"", ""キャラ基礎数値!C:C""), 0) ), ""該当なし"" ) "),"-") -> - | I25: =IFERROR(__xludf.DUMMYFUNCTION("IFERROR( INDEX( IMPORTRANGE(""https://docs.google.com/spreadsheets/d/1tAaChe98Zh7vhMfGMK5Y4_ijmNb40fr519GtdZkkDUY/edit#gid=1369914306"", ""キャラ基礎数値!CA:CA""), MATCH($B$11, IMPORTRANGE(""https://docs.google.com/spreadsheets/d/1tAaChe98Zh7vhMfGMK5Y4"&"_ijmNb40fr519GtdZkkDUY/edit#gid=1369914306"", ""キャラ基礎数値!C:C""), 0) ), ""該当なし"" ) "),"-") -> - | K25: =IFERROR(__xludf.DUMMYFUNCTION("IFERROR( INDEX( IMPORTRANGE(""https://docs.google.com/spreadsheets/d/1tAaChe98Zh7vhMfGMK5Y4_ijmNb40fr519GtdZkkDUY/edit#gid=1369914306"", ""キャラ基礎数値!CB:CB""), MATCH($B$11, IMPORTRANGE(""https://docs.google.com/spreadsheets/d/1tAaChe98Zh7vhMfGMK5Y4"&"_ijmNb40fr519GtdZkkDUY/edit#gid=1369914306"", ""キャラ基礎数値!C:C""), 0) ), ""該当なし"" ) "),"-") -> - | M25: {=INDEX('参照ランク'!C3:C10,MATCH(K25,'参照ランク'!B3:B10))} -> #N/A | AU25: 16 | AV25: 0 | AW25: =Floor( $AW$9+($AW$171-$AW$9) * Pow( (AU25-1) / ($AU$171-1),$AU$189) ,1) -> 2563 | AX25: =Floor( $AX$9+($AX$171-$AX$9) * Pow( (AU25-1) / ($AU$171-1),$AU$189) ,1) -> 2993 | AY25: =VLOOKUP(AV25,$AU$191:$AY$205,4,FALSE)+AW25 -> 2563 | AZ25: =VLOOKUP(AV25,$AU$191:$AY$205,5,FALSE)+AX25 -> 2993 | BA25: =rounddown(($AW25*VLOOKUP($B$13,$AU$177:$AW$185,3,false))+VLOOKUP(AV25,$AU$191:$AY$205,4,false),0) -> 2870 | BB25: =rounddown(($AW25*VLOOKUP($B$13,$AU$177:$AX$185,4,false))+VLOOKUP(AV25,$AU$191:$AY$205,4,false),0) -> 3049 | BC25: =rounddown(($AW25*VLOOKUP($B$13,$AU$177:$AY$185,5,false))+VLOOKUP(AV25,$AU$191:$AY$205,4,false),0) -> 3152 | BD25: =rounddown(($AW25*VLOOKUP($B$13,$AU$177:$AZ$185,6,false))+VLOOKUP(AV25,$AU$191:$AY$205,4,false),0) -> 3203 | BE25: =rounddown(($AW25*VLOOKUP($B$13,$AU$177:$BE$185,7,false))+VLOOKUP(AV25,$AU$191:$AY$205,4,false),0) -> 3203 | BF25: =rounddown(($AW25*VLOOKUP($B$13,$AU$177:$BE$185,8,false))+VLOOKUP(AV25,$AU$191:$AY$205,4,false),0) -> 3203 | BG25: =rounddown(($AW25*VLOOKUP($B$13,$AU$177:$BE$185,9,false))+VLOOKUP(AV25,$AU$191:$AY$205,4,false),0) -> 3203 | BH25: =rounddown(($AW25*VLOOKUP($B$13,$AU$177:$BE$185,10,false))+VLOOKUP(AV25,$AU$191:$AY$205,4,false),0) -> 3203 | BI25: =rounddown(($AW25*VLOOKUP($B$13,$AU$177:$BE$185,11,false))+VLOOKUP(AV25,$AU$191:$AY$205,4,false),0) -> 3203 | BJ25: =rounddown(($AX25*VLOOKUP($B$13,$AU$177:$AW$185,3,false))+VLOOKUP(AV25,$AU$191:$AY$205,5,false),0) -> 3352 | BK25: =rounddown(($AX25*VLOOKUP($B$13,$AU$177:$AX$185,4,false))+VLOOKUP(AV25,$AU$191:$AY$205,5,false),0) -> 3561 | BL25: =rounddown(($AX25*VLOOKUP($B$13,$AU$177:$AY$185,5,false))+VLOOKUP(AV25,$AU$191:$AY$205,5,false),0) -> 3681 | BM25: =rounddown(($AX25*VLOOKUP($B$13,$AU$177:$AZ$185,6,false))+VLOOKUP(AV25,$AU$191:$AY$205,5,false),0) -> 3741 | BN25: =rounddown(($AX25*VLOOKUP($B$13,$AU$177:$BE$185,7,false))+VLOOKUP(AV25,$AU$191:$AY$205,5,false),0) -> 3741 | BO25: =rounddown(($AX25*VLOOKUP($B$13,$AU$177:$BE$185,8,false))+VLOOKUP(AV25,$AU$191:$AY$205,5,false),0) -> 3741 | BP25: =rounddown(($AX25*VLOOKUP($B$13,$AU$177:$BE$185,9,false))+VLOOKUP(AV25,$AU$191:$AY$205,5,false),0) -> 3741 | BQ25: =rounddown(($AX25*VLOOKUP($B$13,$AU$177:$BE$185,10,false))+VLOOKUP(AV25,$AU$191:$AY$205,5,false),0) -> 3741 | BR25: =rounddown(($AX25*VLOOKUP($B$13,$AU$177:$BE$185,11,false))+VLOOKUP(AV25,$AU$191:$AY$205,5,false),0) -> 3741
B26: 3 | C26: - | I26: - | K26: - | M26: {=INDEX('参照ランク'!C4:C11,MATCH(K26,'参照ランク'!B4:B11))} -> #N/A | AU26: 17 | AV26: 0 | AW26: =Floor( $AW$9+($AW$171-$AW$9) * Pow( (AU26-1) / ($AU$171-1),$AU$189) ,1) -> 2642 | AX26: =Floor( $AX$9+($AX$171-$AX$9) * Pow( (AU26-1) / ($AU$171-1),$AU$189) ,1) -> 3085 | AY26: =VLOOKUP(AV26,$AU$191:$AY$205,4,FALSE)+AW26 -> 2642 | AZ26: =VLOOKUP(AV26,$AU$191:$AY$205,5,FALSE)+AX26 -> 3085 | BA26: =rounddown(($AW26*VLOOKUP($B$13,$AU$177:$AW$185,3,false))+VLOOKUP(AV26,$AU$191:$AY$205,4,false),0) -> 2959 | BB26: =rounddown(($AW26*VLOOKUP($B$13,$AU$177:$AX$185,4,false))+VLOOKUP(AV26,$AU$191:$AY$205,4,false),0) -> 3143 | BC26: =rounddown(($AW26*VLOOKUP($B$13,$AU$177:$AY$185,5,false))+VLOOKUP(AV26,$AU$191:$AY$205,4,false),0) -> 3249 | BD26: =rounddown(($AW26*VLOOKUP($B$13,$AU$177:$AZ$185,6,false))+VLOOKUP(AV26,$AU$191:$AY$205,4,false),0) -> 3302 | BE26: =rounddown(($AW26*VLOOKUP($B$13,$AU$177:$BE$185,7,false))+VLOOKUP(AV26,$AU$191:$AY$205,4,false),0) -> 3302 | BF26: =rounddown(($AW26*VLOOKUP($B$13,$AU$177:$BE$185,8,false))+VLOOKUP(AV26,$AU$191:$AY$205,4,false),0) -> 3302 | BG26: =rounddown(($AW26*VLOOKUP($B$13,$AU$177:$BE$185,9,false))+VLOOKUP(AV26,$AU$191:$AY$205,4,false),0) -> 3302 | BH26: =rounddown(($AW26*VLOOKUP($B$13,$AU$177:$BE$185,10,false))+VLOOKUP(AV26,$AU$191:$AY$205,4,false),0) -> 3302 | BI26: =rounddown(($AW26*VLOOKUP($B$13,$AU$177:$BE$185,11,false))+VLOOKUP(AV26,$AU$191:$AY$205,4,false),0) -> 3302 | BJ26: =rounddown(($AX26*VLOOKUP($B$13,$AU$177:$AW$185,3,false))+VLOOKUP(AV26,$AU$191:$AY$205,5,false),0) -> 3455 | BK26: =rounddown(($AX26*VLOOKUP($B$13,$AU$177:$AX$185,4,false))+VLOOKUP(AV26,$AU$191:$AY$205,5,false),0) -> 3671 | BL26: =rounddown(($AX26*VLOOKUP($B$13,$AU$177:$AY$185,5,false))+VLOOKUP(AV26,$AU$191:$AY$205,5,false),0) -> 3794 | BM26: =rounddown(($AX26*VLOOKUP($B$13,$AU$177:$AZ$185,6,false))+VLOOKUP(AV26,$AU$191:$AY$205,5,false),0) -> 3856 | BN26: =rounddown(($AX26*VLOOKUP($B$13,$AU$177:$BE$185,7,false))+VLOOKUP(AV26,$AU$191:$AY$205,5,false),0) -> 3856 | BO26: =rounddown(($AX26*VLOOKUP($B$13,$AU$177:$BE$185,8,false))+VLOOKUP(AV26,$AU$191:$AY$205,5,false),0) -> 3856 | BP26: =rounddown(($AX26*VLOOKUP($B$13,$AU$177:$BE$185,9,false))+VLOOKUP(AV26,$AU$191:$AY$205,5,false),0) -> 3856 | BQ26: =rounddown(($AX26*VLOOKUP($B$13,$AU$177:$BE$185,10,false))+VLOOKUP(AV26,$AU$191:$AY$205,5,false),0) -> 3856 | BR26: =rounddown(($AX26*VLOOKUP($B$13,$AU$177:$BE$185,11,false))+VLOOKUP(AV26,$AU$191:$AY$205,5,false),0) -> 3856
O27: ※解放ランク1=Lv20,ランク2=Lv30。以降同様。 | AU27: 18 | AV27: 0 | AW27: =Floor( $AW$9+($AW$171-$AW$9) * Pow( (AU27-1) / ($AU$171-1),$AU$189) ,1) -> 2721 | AX27: =Floor( $AX$9+($AX$171-$AX$9) * Pow( (AU27-1) / ($AU$171-1),$AU$189) ,1) -> 3178 | AY27: =VLOOKUP(AV27,$AU$191:$AY$205,4,FALSE)+AW27 -> 2721 | AZ27: =VLOOKUP(AV27,$AU$191:$AY$205,5,FALSE)+AX27 -> 3178 | BA27: =rounddown(($AW27*VLOOKUP($B$13,$AU$177:$AW$185,3,false))+VLOOKUP(AV27,$AU$191:$AY$205,4,false),0) -> 3047 | BB27: =rounddown(($AW27*VLOOKUP($B$13,$AU$177:$AX$185,4,false))+VLOOKUP(AV27,$AU$191:$AY$205,4,false),0) -> 3237 | BC27: =rounddown(($AW27*VLOOKUP($B$13,$AU$177:$AY$185,5,false))+VLOOKUP(AV27,$AU$191:$AY$205,4,false),0) -> 3346 | BD27: =rounddown(($AW27*VLOOKUP($B$13,$AU$177:$AZ$185,6,false))+VLOOKUP(AV27,$AU$191:$AY$205,4,false),0) -> 3401 | BE27: =rounddown(($AW27*VLOOKUP($B$13,$AU$177:$BE$185,7,false))+VLOOKUP(AV27,$AU$191:$AY$205,4,false),0) -> 3401 | BF27: =rounddown(($AW27*VLOOKUP($B$13,$AU$177:$BE$185,8,false))+VLOOKUP(AV27,$AU$191:$AY$205,4,false),0) -> 3401 | BG27: =rounddown(($AW27*VLOOKUP($B$13,$AU$177:$BE$185,9,false))+VLOOKUP(AV27,$AU$191:$AY$205,4,false),0) -> 3401 | BH27: =rounddown(($AW27*VLOOKUP($B$13,$AU$177:$BE$185,10,false))+VLOOKUP(AV27,$AU$191:$AY$205,4,false),0) -> 3401 | BI27: =rounddown(($AW27*VLOOKUP($B$13,$AU$177:$BE$185,11,false))+VLOOKUP(AV27,$AU$191:$AY$205,4,false),0) -> 3401 | BJ27: =rounddown(($AX27*VLOOKUP($B$13,$AU$177:$AW$185,3,false))+VLOOKUP(AV27,$AU$191:$AY$205,5,false),0) -> 3559 | BK27: =rounddown(($AX27*VLOOKUP($B$13,$AU$177:$AX$185,4,false))+VLOOKUP(AV27,$AU$191:$AY$205,5,false),0) -> 3781 | BL27: =rounddown(($AX27*VLOOKUP($B$13,$AU$177:$AY$185,5,false))+VLOOKUP(AV27,$AU$191:$AY$205,5,false),0) -> 3908 | BM27: =rounddown(($AX27*VLOOKUP($B$13,$AU$177:$AZ$185,6,false))+VLOOKUP(AV27,$AU$191:$AY$205,5,false),0) -> 3972 | BN27: =rounddown(($AX27*VLOOKUP($B$13,$AU$177:$BE$185,7,false))+VLOOKUP(AV27,$AU$191:$AY$205,5,false),0) -> 3972 | BO27: =rounddown(($AX27*VLOOKUP($B$13,$AU$177:$BE$185,8,false))+VLOOKUP(AV27,$AU$191:$AY$205,5,false),0) -> 3972 | BP27: =rounddown(($AX27*VLOOKUP($B$13,$AU$177:$BE$185,9,false))+VLOOKUP(AV27,$AU$191:$AY$205,5,false),0) -> 3972 | BQ27: =rounddown(($AX27*VLOOKUP($B$13,$AU$177:$BE$185,10,false))+VLOOKUP(AV27,$AU$191:$AY$205,5,false),0) -> 3972 | BR27: =rounddown(($AX27*VLOOKUP($B$13,$AU$177:$BE$185,11,false))+VLOOKUP(AV27,$AU$191:$AY$205,5,false),0) -> 3972
