Workbook

Sheet 01_概要
B1: 01_概要
B4: 地獄楽 いいジャン祭
B6: 地獄楽 いいジャン祭
B8: ◼︎施策名 地獄楽 いいジャン祭
D9: 260116_地獄楽 いいジャン祭 企画書 | E9: 担当：村松
B10: ■内容
B11: 少年ジャンプ+ ジャンブルラッシュ内において、「地獄楽」をピックアップしたイベントとして、 『原作コミック「1巻〜4巻」のストーリー再現』をテーマに据えます！ 「賊王 亜左 弔兵衛」と「山田浅ェ門 桐馬」のエピソードや、画眉丸とメイの出会い、 「民谷 巌鉄斎」の共闘関係にいたるまでのエピソードを中心に展開します。 なお、イベントの実施時期は、2026年1月中旬からを予定しております。
B13: ◼︎開催期間（予定） 01/16（金）15:00〜2/16（月）10:59
B15: ◼︎メイン課金ポイント 地獄楽 いいジャン祭 新キャラ ピックアップガシャ 「賊王 亜左 弔兵衛」（UR）、「山田浅ェ門 桐馬」（SSR）
B17: ◼︎主要コンテンツ ・地獄楽 いいジャン祭 特別ミッションを達成し豪華報酬をGETしよう！ ・地獄楽 いいジャン祭限定のイベントキャラ「メイ」「民谷 巌鉄斎」をそれぞれGETしよう！ ⇨このいいジャン祭を遊び切ると、「メイ」「民谷 巌鉄斎」は最大グレード強化が可能になります！ ・降臨バトルで報酬を獲得しつつランキング上位を目指そう！ ・地獄楽の原作モチーフのエンブレムをGETしよう！
B20: 施策一覧
B22: カテゴリー | E22: 施策名称 | F22: 開始日 | G22: 終了日 | H22: 備考
B23: ='02_施策'!$B5 -> 【デイリー】 | E23: 本能が告げている 危険だと | F23: 46038.625 | G23: 46055.166
B24: ='02_施策'!$B6 -> 【ストーリー】 画眉丸編 | E24: 必ず生きて帰る | F24: 46038.625 | G24: 46069.458
B25: ='02_施策'!$B7 -> 【ストーリー】 共闘関係編 | E25: 朱印の者たち | F25: 46043.625 | G25: 46069.458
B26: ='02_施策'!$B8 -> 【チャレンジ】 | E26: 死罪人と首切り役人 | F26: 46038.625 | G26: 46069.458
B27: ='02_施策'!$B9 -> 【高難易度】 | E27: 手負いの獣は恐ろしいぞ | F27: 46038.625 | G27: 46069.458
B28: ='02_施策'!$B10 -> 【降臨バトル】 | E28: まるで 悪夢を見ているようだ | F28: 46045.625 | G28: 46051.624
B29: ='02_施策'!$B11 -> 【ログインボーナス】 | E29: 地獄楽 いいジャン祭 特別ログインボーナス | F29: 46038.625 | G29: 46055.166
B30: ='02_施策'!$B12 -> 【ミッション】 | E30: 地獄楽 いいジャン祭 特別ミッション | F30: 46038.625 | G30: 46069.458
B31: ='02_施策'!$B13 -> 【コイン獲得クエスト】 | E31: コイン獲得クエスト キャラボーナス | F31: 46038.625 | G31: 46069.458
B35: 新キャラ一覧
B37: キャラID | E37: キャラ名 | G37: 獲得場所 | H37: レアリティ | I37: 獲得属性色 | J37: 備考
B38: chara_jig_00401 | E38: 賊王 亜左 弔兵衛 | G38: ピックアップガシャ | H38: UR | I38: 無
B39: chara_jig_00501 | E39: 山田浅ェ門 桐馬 | G39: ピックアップガシャ | H39: SSR | I39: 緑
B40: chara_jig_00601 | E40: 民谷 巌鉄斎 | G40: イベント報酬 | H40: SR | I40: 青
B41: chara_jig_00701 | E41: メイ | G41: イベント報酬 | H41: SR | I41: 無
B42: enemy_jig_00501 | E42: 山田浅ェ門 源嗣 | J42: 敵専用
B43: enemy_jig_00601 | E43: 朱槿 | J43: 敵専用
B47: 新アイテム一覧
B49: アイテムID | E49: アイテム名 | G49: ID管理シート | H49: 備考 | K49: 記載したい物
B50: piece_jig_00401 | E50: 賊王 亜左 弔兵衛のかけら | G50: GLOW_ID 管理 | K50: キャラのかけら
B51: piece_jig_00501 | E51: 山田浅ェ門 桐馬のかけら | G51: GLOW_ID 管理
B52: piece_jig_00601 | E52: 民谷 巌鉄斎のかけら | G52: GLOW_ID 管理
B53: piece_jig_00701 | E53: メイのかけら | G53: GLOW_ID 管理
B54: memory_chara_jig_00601 | E54: 民谷 巌鉄斎のメモリー | G54: GLOW_ID 管理 | K54: キャラ専用カラーメモリー
B55: memory_chara_jig_00701 | E55: メイのメモリー | G55: GLOW_ID 管理
B56: emblem_event_jig_00001 | E56: 神仙郷 | G56: GLOW_ID 管理 | K56: エンブレム
B57: emblem_adventbattle_jig_season01_00001 | E57: 罪人(1位) | G57: GLOW_ID 管理
B58: emblem_adventbattle_jig_season01_00002 | E58: 罪人(2位) | G58: GLOW_ID 管理
...

Sheet 02_施策
B1: 02_施策
M2: 安藤メモ
B3: ▼全体概要 | K3: 1スタミナ* | M3: 名称 | N3: 登場可否
B4: カテゴリー | C4: 施策名称 | E4: 開始日 | F4: 終了日 | G4: キャンペーンの有無 | H4: キャンペーン期間 | I4: キャンペーン内容 | J4: イベント全般 | K4: ×15コイン | M4: 冷却系の怪異 | N4: ストーリー以外なら可能
B5: 【デイリー】 | C5: ='01_概要'!E23 -> 本能が告げている 危険だと | E5: ='01_概要'!F23 -> 46038.625 | F5: ='01_概要'!G23 -> 46055.166 | G5: - | H5: - | I5: - | M5: つらら | N5: ストーリー以外なら可能
B6: 【ストーリー】 画眉丸編 | C6: ='01_概要'!E24 -> 必ず生きて帰る | E6: ='01_概要'!F24 -> 46038.625 | F6: ='01_概要'!G24 -> 46069.458 | G6: - | H6: - | I6: - | J6: ⇩ストーリークエスト1つで 獲得できるメインの報酬数（初回クリア） | M6: 建造物寄生型の怪異（大） | N6: 可能
B7: 【ストーリー】 共闘関係編 | C7: ='01_概要'!E25 -> 朱印の者たち | E7: ='01_概要'!F25 -> 46043.625 | F7: ='01_概要'!G25 -> 46069.458 | G7: - | H7: - | I7: - | J7: 報酬名 | K7: 報酬数 | M7: 建造物寄生型の怪異（小） | N7: 可能
B8: 【チャレンジ】 | C8: ='01_概要'!E26 -> 死罪人と首切り役人 | E8: ='01_概要'!F26 -> 46038.625 | F8: ='01_概要'!G26 -> 46069.458 | G8: - | H8: - | I8: - | J8: そのキャラのカラーメモリー | K8: 1100 | M8: 工事現場の怪異 | N8: ストーリー２可能
B9: 【高難易度】 | C9: ='01_概要'!E27 -> 手負いの獣は恐ろしいぞ | E9: ='01_概要'!F27 -> 46038.625 | F9: ='01_概要'!G27 -> 46069.458 | G9: - | H9: - | I9: - | J9: メモリーフラグメント・初級 | K9: 15
B10: 【降臨バトル】 | C10: ='01_概要'!E28 -> まるで 悪夢を見ているようだ | E10: ='01_概要'!F28 -> 46045.625 | F10: ='01_概要'!G28 -> 46051.624 | G10: - | H10: - | I10: - | J10: メモリーフラグメント・中級 | K10: 10
B11: 【ログインボーナス】 | C11: ='01_概要'!E29 -> 地獄楽 いいジャン祭 特別ログインボーナス | E11: ='01_概要'!F29 -> 46038.625 | F11: ='01_概要'!G29 -> 46055.166 | J11: メモリーフラグメント・上級 | K11: 1
B12: 【ミッション】 | C12: ='01_概要'!E30 -> 地獄楽 いいジャン祭 特別ミッション | E12: ='01_概要'!F30 -> 46038.625 | F12: ='01_概要'!G30 -> 46069.458 | J12: コイン | K12: 2800
B13: 【コイン獲得クエスト】 | C13: ='01_概要'!E31 -> コイン獲得クエスト キャラボーナス | E13: ='01_概要'!F31 -> 46038.625 | F13: ='01_概要'!G31 -> 46069.458
B15: ◆ログインボーナス
B17: 項目 | C17: 内容
B18: 施策名称 | C18: =C11 -> 地獄楽 いいジャン祭 特別ログインボーナス | F18: ※〇〇[半角スペース]いいジャン祭[半角スペース]特別ログインボーナス 例：怪獣8号 いいジャン祭 特別ログインボーナス
B19: 開催期間 | C19: =E11 -> 46038.625 | D19: 〜 | E19: =F11 -> 46055.166
B21: ログイン日数 （日別） | C21: 日付 | D21: プリズム | E21: コイン | F21: ピックアップガシャチケット | G21: スペシャルガシャチケット | H21: メモリーフラグメント・初級 | I21: メモリーフラグメント・中級 | J21: カラーメモリー・グリーン | K21: カラーメモリー・レッド | L21: 報酬設定の有無
A22: 金 | B22: 1 | C22: 46038.625 | F22: 2 | L22: =SUM(D22:K22) -> 2
A23: 土 | B23: =B22+1 -> 2 | C23: 46039.167 | E23: 5000 | L23: =SUM(D23:K23) -> 5000
A24: 日 | B24: =B23+1 -> 3 | C24: 46040.167 | D24: 40 | L24: =SUM(D24:K24) -> 40
A25: 月 | B25: =B24+1 -> 4 | C25: 46041.167 | H25: 5 | L25: =SUM(D25:K25) -> 5
A26: 火 | B26: =B25+1 -> 5 | C26: 46042.167 | I26: 4 | L26: =SUM(D26:K26) -> 4
A27: 水 | B27: =B26+1 -> 6 | C27: 46043.167 | J27: 300 | L27: =SUM(D27:K27) -> 300
A28: 木 | B28: =B27+1 -> 7 | C28: 46044.167 | G28: 2 | L28: =SUM(D28:K28) -> 2
A29: 金 | B29: =B28+1 -> 8 | C29: 46045.167 | E29: 5000 | L29: =SUM(D29:K29) -> 5000
A30: 土 | B30: =B29+1 -> 9 | C30: 46046.167 | D30: 40 | L30: =SUM(D30:K30) -> 40
A31: 日 | B31: =B30+1 -> 10 | C31: 46047.167 | H31: 10 | L31: =SUM(D31:K31) -> 10
A32: 月 | B32: =B31+1 -> 11 | C32: 46048.167 | K32: 300 | L32: =SUM(D32:K32) -> 300
A33: 火 | B33: =B32+1 -> 12 | C33: 46049.167 | D33: 20 | L33: =SUM(D33:K33) -> 20
A34: 水 | B34: =B33+1 -> 13 | C34: 46050.167 | J34: 300 | L34: =SUM(D34:K34) -> 300
A35: 木 | B35: =B34+1 -> 14 | C35: 46051.167 | E35: 5000 | L35: =SUM(D35:K35) -> 5000
A36: 金 | B36: =B35+1 -> 15 | C36: 46052.167 | K36: 300 | L36: =SUM(D36:K36) -> 300
A37: 土 | B37: =B36+1 -> 16 | C37: 46053.167 | G37: 1 | L37: =SUM(D37:K37) -> 1
A38: 日 | B38: =B37+1 -> 17 | C38: 46054.167 | F38: 1 | L38: =SUM(D38:K38) -> 1
C39: 報酬合計数 | D39: =SUM(D22:D38) -> 100 | E39: =SUM(E22:E38) -> 15000 | F39: =SUM(F22:F38) -> 3 | G39: =SUM(G22:G38) -> 3 | H39: =SUM(H22:H38) -> 15 | I39: =SUM(I22:I38) -> 4 | J39: =SUM(J22:J38) -> 600 | K39: =SUM(K22:K38) -> 600
B42: ◆デイリークエスト
B44: 項目 | C44: 内容
B45: クエスト名 | C45: =C5 -> 本能が告げている 危険だと
B46: 開催期間 | C46: =E5 -> 46038.625 | D46: 〜 | E46: =F5 -> 46055.166
...

Sheet 03_降臨バトル
B1: 03_降臨バトル
B3: 設定担当者
B4: 古澤
B6: 項目 | C6: 内容
B7: 名称 | C7: ='02_施策'!C10 -> まるで 悪夢を見ているようだ
B8: 開催期間 | C8: ='02_施策'!E10 -> 46045.625 | D8: 〜 | E8: ='02_施策'!F10 -> 46051.624
B9: 基礎設計URL | C9: https://docs.google.com/spreadsheets/d/1k60vxX9jRXryJpxS8a_5Ech668eJL0kAe4cwL2TFFmM/edit?gid=0#gid=0
B11: 推奨Lv | C11: 挑戦回数 | D11: 獲得リーダーEXP | E11: 登場キャラ | F11: 登場強敵キャラ | G11: 背景ID | H11: ステージ段数 | I11: ステージ開放条件
B12: 20-30 | C12: 1日最大5回 内2回は広告視聴 | D12: 100 | E12: 全キャラ | F12: 全キャラ | G12: koma_background_jig_00002 | H12: 4 | I12: 1/23 (金)15:00から開放
B15: 設定（その他）
B16: 時間制限 | C16: 90秒 | E16: ボーナス倍率の内訳（%）
B17: クエストTOP画面表示キャラ | C17: 朱槿 | E17: フェス限の新キャラ | G17: 30
B18: クエストTOP画面表示キャラセリフ | C18: なし | E18: ピックアップURなどの新キャラ | G18: 20
E19: 恒常UR(新キャラではない) | G19: 15
E20: ピックアップSSRなどの新キャラ | G20: 10
E21: 恒常SSR(新キャラではない) | G21: 10
E22: イベントSRなどの新キャラ | G22: 10
E23: 恒常SR(新キャラではない) | G23: 5
E24: 恒常R(新キャラではない) | G24: 3
E25: スペシャルキャラは登録不可！ | G25: ー
B26: ボーナス
B27: レアリティ | C27: 対象キャラ | D27: 対象キャラID | E27: ボーナス（%）
B28: UR | C28: 賊王 亜左 弔兵衛 | D28: chara_jig_00401 | E28: 20
B29: UR | C29: がらんの画眉丸 | D29: chara_jig_00001 | E29: 15
B30: SSR | C30: 山田浅ェ門 佐切 | D30: chara_jig_00101 | E30: 10
B31: SSR | C31: 杠 | D31: chara_jig_00201 | E31: 10
B32: SSR | C32: 山田浅ェ門 桐馬 | D32: chara_jig_00501 | E32: 10
B33: SR | C33: 民谷 巌鉄斎 | D33: chara_jig_00601 | E33: 10
B34: SR | C34: 山田浅ェ門 仙汰 | D34: chara_jig_00301 | E34: 5
B38: ▼報酬関連
B39: ◆クリア報酬
B40: ・降臨バトルをプレイし、クリアすることで報酬が獲得できます
B41: ・複数の報酬を設定可能です
B42: クリア報酬 | C42: プリズム | D42: コイン | E42: ピックアップガシャチケット | F42: スペシャルガシャチケット | G42: メモリーフラグメント・初級 | H42: メモリーフラグメント・中級 | I42: メモリーフラグメント・上級 | J42: カラーメモリー・レッド | K42: カラーメモリー・グリーン | L42: カラーメモリー・イエロー | M42: カラーメモリー・ブルー | N42: カラーメモリー・グレー
B43: 報酬数 | C43: 0 | D43: 300 | E43: 0 | F43: 0 | G43: 0 | H43: 0 | I43: 0 | J43: 0 | K43: 0 | L43: 0 | M43: 0 | N43: 0
B45: ランダムクリア報酬 | C45: プリズム | D45: コイン | E45: ピックアップガシャチケット | F45: スペシャルガシャチケット | G45: メモリーフラグメント・初級 | H45: メモリーフラグメント・中級 | I45: メモリーフラグメント・上級 | J45: カラーメモリー・レッド | K45: カラーメモリー・グリーン | L45: カラーメモリー・イエロー | M45: カラーメモリー・ブルー | N45: カラーメモリー・グレー
B46: 報酬数 | C46: 0 | D46: 0 | E46: 0 | F46: 0 | G46: 0 | H46: 0 | I46: 0 | J46: 3 | K46: 3 | L46: 3 | M46: 3 | N46: 3
B47: ドロップ確率 | C47: 0 | D47: 0 | E47: 0 | F47: 0 | G47: 0 | H47: 0 | I47: 0 | J47: 0.2 | K47: 0.2 | L47: 0.2 | M47: 0.2 | N47: 0.2
B49: リーダーEXP | C49: 100
B51: 報酬合計数 | C51: =C43 -> 0 | D51: =D43 -> 300 | E51: =E43 -> 0 | F51: =F43 -> 0 | G51: =G43 -> 0 | H51: =H43 -> 0 | I51: =I43 -> 0 | J51: =J43 -> 0 | ... N51: =N43 -> 0
...

Sheet 04_ミッション
B1: 04_ミッション
B3: ◆いいジャン祭ミッション
B5: 項目 | C5: 内容
B6: 施策名称 | C6: ='01_概要'!E30 -> 地獄楽 いいジャン祭 特別ミッション
B7: 開催期間 | C7: ='01_概要'!F30 -> 46038.625 | D7: 〜 | E7: ='01_概要'!G30 -> 46069.458
B9: ミッション内容 | C9: プリズム | D9: コイン | E9: ピックアップガシャチケット | F9: スペシャルガシャチケット | G9: メモリーフラグメント・初級 | H9: メモリーフラグメント・中級 | I9: メモリーフラグメント・上級 | J9: カラーメモリー・レッド | K9: カラーメモリー・グリーン | L9: カラーメモリー・イエロー | M9: カラーメモリー・ブルー | N9: カラーメモリー・グレー | O9: がらんの画眉丸のかけら | P9: 民谷 巌鉄斎のかけら | Q9: メイのかけら | R9: 民谷 巌鉄斎のカラーメモリー | S9: メイのカラーメモリー
B10: メイ をグレード2まで強化しよう | C10: 0 | D10: 0 | E10: 0 | F10: 0 | G10: 0 | H10: 0 | I10: 0 | J10: 0 | K10: 0 | L10: 0 | M10: 0 | N10: 0 | O10: 0 | P10: 0 | Q10: 0 | R10: 0 | S10: 200
B11: メイ をグレード3まで強化しよう | C11: 0 | D11: 0 | E11: 0 | F11: 0 | G11: 0 | H11: 0 | I11: 0 | J11: 0 | K11: 0 | L11: 0 | M11: 0 | N11: 0 | O11: 0 | P11: 0 | Q11: 0 | R11: 0 | S11: 300
B12: メイ をグレード4まで強化しよう | C12: 0 | D12: 0 | E12: 0 | F12: 0 | G12: 0 | H12: 0 | I12: 0 | J12: 0 | K12: 0 | L12: 0 | M12: 0 | N12: 0 | O12: 0 | P12: 0 | Q12: 0 | R12: 0 | S12: 350
B13: メイ をグレード5まで強化しよう | C13: 0 | D13: 0 | E13: 1 | F13: 0 | G13: 0 | H13: 0 | I13: 0 | J13: 0 | K13: 0 | L13: 0 | M13: 0 | N13: 0 | O13: 0 | P13: 0 | Q13: 0 | R13: 0 | S13: 0
B14: メイ をLv.20まで強化しよう | C14: 0 | D14: 0 | E14: 0 | F14: 0 | G14: 0 | H14: 0 | I14: 0 | J14: 0 | K14: 0 | L14: 0 | M14: 0 | N14: 0 | O14: 0 | P14: 0 | Q14: 10 | R14: 0 | S14: 0
B15: メイ をLv.30まで強化しよう | C15: 0 | D15: 0 | E15: 0 | F15: 0 | G15: 0 | H15: 0 | I15: 0 | J15: 0 | K15: 0 | L15: 0 | M15: 0 | N15: 0 | O15: 0 | P15: 0 | Q15: 20 | R15: 0 | S15: 0
B16: メイ をLv.40まで強化しよう | C16: 0 | D16: 0 | E16: 0 | F16: 0 | G16: 0 | H16: 0 | I16: 0 | J16: 0 | K16: 0 | L16: 0 | M16: 0 | N16: 0 | O16: 0 | P16: 0 | Q16: 20 | R16: 0 | S16: 0
B17: メイ をLv.50まで強化しよう | C17: 0 | D17: 0 | E17: 0 | F17: 0 | G17: 0 | H17: 0 | I17: 0 | J17: 0 | K17: 0 | L17: 0 | M17: 0 | N17: 0 | O17: 0 | P17: 0 | Q17: 20 | R17: 0 | S17: 0
B18: メイ をLv.60まで強化しよう | C18: 0 | D18: 0 | E18: 0 | F18: 0 | G18: 0 | H18: 0 | I18: 0 | J18: 0 | K18: 0 | L18: 0 | M18: 0 | N18: 0 | O18: 0 | P18: 0 | Q18: 30 | R18: 0 | S18: 0
B19: メイ をLv.70まで強化しよう | C19: 0 | D19: 0 | E19: 0 | F19: 0 | G19: 0 | H19: 0 | I19: 1 | J19: 0 | K19: 0 | L19: 0 | M19: 0 | N19: 0 | O19: 0 | P19: 0 | Q19: 0 | R19: 0 | S19: 0
B20: メイ をLv.80まで強化しよう | C20: 50 | D20: 0 | E20: 0 | F20: 0 | G20: 0 | H20: 0 | I20: 0 | J20: 0 | K20: 0 | L20: 0 | M20: 0 | N20: 0 | O20: 0 | P20: 0 | Q20: 0 | R20: 0 | S20: 0
B21: 民谷 巌鉄斎 をグレード2まで強化しよう | C21: 0 | D21: 0 | E21: 0 | F21: 0 | G21: 0 | H21: 0 | I21: 0 | J21: 0 | K21: 0 | L21: 0 | M21: 0 | N21: 0 | O21: 0 | P21: 0 | Q21: 0 | R21: 200 | S21: 0
... B27: 民谷 巌鉄斎 をLv.40まで強化しよう | C27: 0 | D27: 0 | E27: 0 | F27: 0 | G27: 0 | H27: 0 | I27: 0 | J27: 0 | K27: 0 | L27: 0 | M27: 0 | N27: 0 | O27: 0 | P27: 20 | Q27: 0 | R27: 0 | S27: 0
B28: 民谷 巌鉄斎 をLv.50まで強化しよう | C28: 0 | D28: 0 | E28: 0 | F28: 0 | G28: 0 | H28: 0 | I28: 0 | J28: 0 | K28: 0 | L28: 0 | M28: 0 | N28: 0 | O28: 0 | P28: 20 | Q28: 0 | R28: 0
B29: 民谷 巌鉄斎 をLv.60まで強化しよう | C29: 0 | D29: 0 | E29: 0 | F29: 0 | G29: 0 | H29: 0 | I29: 0 | J29: 0 | K29: 0 | L29: 0 | M29: 0 | N29: 0 | O29: 0 | P29: 30 | Q29: 0 | R29: 0
B30: 民谷 巌鉄斎 をLv.70まで強化しよう | C30: 0 | D30: 0 | E30: 0 | F30: 0 | G30: 0 | H30: 0 | I30: 1 | J30: 0 | K30: 0 | L30: 0 | M30: 0 | N30: 0 | O30: 0 | P30: 0 | Q30: 0 | R30: 0
B31: 民谷 巌鉄斎 をLv.80まで強化しよう | C31: 50 | D31: 0 | E31: 0 | F31: 0 | G31: 0 | H31: 0 | I31: 0 | J31: 0 | K31: 0 | L31: 0 | M31: 0 | N31: 0 | O31: 0 | P31: 0 | Q31: 0 | R31: 0
B32: ストーリークエスト「必ず生きて帰る」をクリアしよう | C32: 0 | D32: 12500 | E32: 0 | F32: 0 | G32: 0 | H32: 0 | I32: 0 | J32: 0 | K32: 0 | L32: 0 | M32: 0 | N32: 0 | O32: 0 | P32: 0 | Q32: 0 | R32: 0 | S32: 0
B33: ストーリークエスト「朱印の者たち」をクリアしよう | C33: 0 | D33: 12500 | E33: 0 | F33: 0 | G33: 0 | H33: 0 | I33: 0 | J33: 0 | K33: 0 | L33: 0 | M33: 0 | N33: 0 | O33: 0 | P33: 0 | Q33: 0 | R33: 0 | S33: 0
B34: チャレンジクエスト「死罪人と首切り役人」をクリアしよう | C34: 0 | D34: 0 | E34: 0 | F34: 3 | G34: 0 | H34: 0 | I34: 0 | J34: 0 | K34: 0 | L34: 0 | M34: 0 | N34: 0 | O34: 0 | P34: 0 | Q34: 0 | R34: 0 | S34: 0
B35: 高難易度「手負いの獣は恐ろしいぞ」をクリアしよう | C35: 0 | D35: 0 | E35: 1 | F35: 0 | G35: 0 | H35: 0 | I35: 0 | J35: 0 | K35: 0 | L35: 0 | M35: 0 | N35: 0 | O35: 0 | P35: 0 | Q35: 0 | R35: 0 | S35: 0
B36: 敵を10体撃破しよう | C36: 0 | D36: 0 | E36: 0 | F36: 0 | G36: 5 | H36: 0 | I36: 0 | J36: 0 | K36: 0 | L36: 0 | M36: 0 | N36: 0 | O36: 0 | P36: 0 | Q36: 0 | R36: 0 | S36: 0
B37: 敵を20体撃破しよう | C37: 0 | D37: 0 | E37: 0 | F37: 0 | G37: 5 | H37: 0 | I37: 0 | J37: 0 | K37: 0 | L37: 0 | M37: 0 | N37: 0 | O37: 0 | P37: 0 | Q37: 0 | R37: 0 | S37: 0
B38: 敵を30体撃破しよう | C38: 0 | D38: 0 | E38: 0 | F38: 0 | G38: 5 | H38: 0 | I38: 0 | J38: 0 | K38: 0 | L38: 0 | M38: 0 | N38: 0 | O38: 0 | P38: 0 | Q38: 0 | R38: 0 | S38: 0
B39: 敵を40体撃破しよう | C39: 0 | D39: 0 | E39: 0 | F39: 0 | G39: 5 | H39: 0 | I39: 0 | J39: 0 | K39: 0 | L39: 0 | M39: 0 | N39: 0 | O39: 0 | P39: 0 | Q39: 0 | R39: 0 | S39: 0
B40: 敵を50体撃破しよう | C40: 0 | D40: 0 | E40: 0 | F40: 0 | G40: 10 | H40: 0 | I40: 0 | J40: 0 | K40: 0 | L40: 0 | M40: 0 | N40: 0 | O40: 0 | P40: 0 | Q40: 0 | R40: 0 | S40: 0
B41: 敵を60体撃破しよう | C41: 0 | D41: 0 | E41: 0 | F41: 0 | G41: 0 | H41: 5 | I41: 0 | J41: 0 | K41: 0 | L41: 0 | M41: 0 | N41: 0 | O41: 0 | P41: 0 | Q41: 0 | R41: 0 | S41: 0
B42: 敵を70体撃破しよう | C42: 0 | D42: 0 | E42: 0 | F42: 0 | G42: 0 | H42: 5 | I42: 0 | J42: 0 | K42: 0 | L42: 0 | M42: 0 | N42: 0 | O42: 0 | P42: 0 | Q42: 0 | R42: 0 | S42: 0
B43: 敵を80体撃破しよう | C43: 0 | D43: 0 | E43: 0 | F43: 0 | G43: 0 | H43: 5 | I43: 0 | J43: 0 | K43: 0 | L43: 0 | M43: 0 | N43: 0 | O43: 0 | P43: 0 | Q43: 0 | R43: 0 | S43: 0
... B52: 敵を1000体撃破しよう | C52: 0 | D52: 0 | E52: 0 | F52: 0 | G52: 0 | H52: 0 | I52: 0 | J52: 0 | K52: 0 | L52: 0 | M52: 0 | N52: 0 | O52: 20 | P52: 0 | Q52: 0 | R52: 0 | S52: 0
B54: 報酬合計数 | C54: =SUM(C10:C52) -> 100 | D54: =SUM(D10:D52) -> 25000 | E54: =SUM(E10:E52) -> 5 | F54: =SUM(F10:F52) -> 3 | G54: =SUM(G10:G52) -> 30 | H54: =SUM(H10:H52) -> 20 | I54: =SUM(I10:I52) -> 5 | J54: =SUM(J10:J52) -> 0 | ... S54: =SUM(S10:S52) -> 850

Sheet 01_概要 のテンプレ 
A1: 施策名称
B2: ■施策正式名称 | J2: ■施策通し番号
B5: ■略称 | J5: ※ショットガンに本施策のものを登録する際、各クエスト名前にある通し番号も一緒に記載してください。 ※お知らせの場合は、こちらのアルファベットのみ登録時 に文頭へ置いて下さい。
A11: 施策概要
B13: 思想
B15: ■キャンペーン概要とゲーム外要因
C16: 本企画は、特定IPフィーチャーで開催される一連のイベントをまとめたキャンペーンである。
C17: 特定IPを掘り下げることにより、新規のIPファンを取り込んだり、既存ユーザーにおいてはIPファンのFQを上げ、離れていたIPファンの復帰を目指す。
C18: 特定IPの世界観への没入ができるかどうかが肝となる。
B20: ■施策の目的
C21: ①どんな人に？ | F21: ②どうして欲しいのか？ | I21: ③どんな価値・体験を提供することで？
B27: ■施策全体方向性
C29: objective
D31: KR1:
D32: 例）
D34: KR2:
D35: 例）
D37: KR3:
D38: 例）
B44: 概要
B45: ■日程 | F45: ■：運営、■：マーケ、■：設定期限
E46: マイルストーン | F46: 開始日 | G46: 時間 | H46: 終了日 | I46: 時間 | J46: 期間 | K46: 備考
E47: 監修提出期限日
E48: LINE提出日
E49: データ設定期限日
E50: 単体テスト
E51: 総合テスト
E52: デプロイ日 | G52: 0.41666667
E53: キャンペーン期間 | J53: 12日
E54: 実施開始
B57: ◼︎担当者（チーム）
E58: 作業内容 | F58: 責任者（敬称略） | G58: slackアカウント | I58: 依頼シート
E59: 企画担当 | G59: =VLOOKUP(F59,[1]触らない!$C$3:$D$50,2,FALSE) -> #N/A
E60: キャラデータ作成 | F60: @程塚 | G60: =VLOOKUP(F60,[1]触らない!$C$3:$D$50,2,FALSE) -> #N/A | I60: キャラ一覧
F61: @石橋 | G61: =VLOOKUP(F61,[1]触らない!$C$3:$D$50,2,FALSE) -> #N/A
F62: @今井 | G62: =VLOOKUP(F62,[1]触らない!$C$3:$D$50,2,FALSE) -> #N/A
E63: クエストデータ作成 | F63: @安藤 | G63: =VLOOKUP(F63,[1]触らない!$C$3:$D$50,2,FALSE) -> #N/A | I63: =HYPERLINK("https://docs.google.com/spreadsheets/d/1f45D-eYUxwJb_Qbti6LUcYIBmryrOJScfVyW96Uhw50/edit#gid=913093388","背景一覧") -> 背景一覧 | L63: 仕様書に背景IDと背景名を記載するのはPlan担当者
F64: @小澤 | G64: =VLOOKUP(F64,[1]触らない!$C$3:$D$50,2,FALSE) -> #N/A
F65: @川口 | G65: =VLOOKUP(F65,[1]触らない!$C$3:$D$50,2,FALSE) -> #N/A
E66: クエストスケジュールデータ作成 | F66: @目黒 | G66: =VLOOKUP(F66,[1]触らない!$C$3:$D$50,2,FALSE) -> #N/A
...

Sheet 03_制作＆監修依頼一覧
B1: ・単体テスト開始： ・総合テスト開始： | E1: =SUM(E3:E80) -> 0 | F1: ・文言(タイトル)完了、Click UPタスクいれる完了希望日：X-13営業日前まで ・バナーに必要な内容を仕様書に記載完了希望日：X-5営業日まで ・バナー制作締め切り日：Xまで | H1: ▼いい感じのところに移す | N1: イベント名＆アイテム名＆エンブレム名は16文字(32ﾊﾞｲﾄ)以内 記号(「!」「””」)は半角表記
A2: 施策種別 | B2: 施策名 | C2: 画像サイズ | D2: 画像制作担当 | E2: clickup確認 | F2: バナー内容 | G2: アイテム/エンブレム/スタンプ 参考画像(企画が貼り付ける) | H2: オレンジゾーンでも可 出典元を記載する場所(アイテムとかの参考画像) | I2: フレーバーテキスト 有無 | J2: イラスト版元監修 有無 | K2: フレーバーテキスト | L2: 担当 | M2: 監修/制作物 | N2: 監修/制作文言 | O2: 監修/備考 | P2: 担当 | Q2: 文言制作 ステータス | R2: 監修提出日 | S2: QA(監修返答締め日)
A3: 01_ガチャ
E4: 0
E5: 0
E6: 0
E7: 0 | Q7: 不要
A8: 02_パック
E9: 0
E10: 0
E11: 0 | Q11: 不要
A12: 03_クエスト | B12: ▼引用関数入ってます。
B13: =[2]施策リソース数管理シート!B4 -> #REF! | E13: 0
B14: =[2]施策リソース数管理シート!B5 -> #REF! | E14: 0
B15: =[2]施策リソース数管理シート!B6 -> #REF! | E15: 0
B16: =[2]施策リソース数管理シート!B7 -> #REF! | E16: 0
B17: =[2]施策リソース数管理シート!B8 -> #REF! | E17: 0
B18: =[2]施策リソース数管理シート!B9 -> #REF! | E18: 0
B19: =[2]施策リソース数管理シート!B10 -> #REF! | E19: 0
B20: =[2]施策リソース数管理シート!B11 -> #REF! | E20: 0
B21: =[2]施策リソース数管理シート!B12 -> #REF! | E21: 0
B22: =[2]施策リソース数管理シート!B13 -> #REF! | E22: 0
B23: =[2]施策リソース数管理シート!B14 -> #REF! | E23: 0
B24: =[2]施策リソース数管理シート!B15 -> #REF! | E24: 0
... B26: =[2]施策リソース数管理シート!B17 -> #REF! | E26: 0
A27: 04_団結バトル | B27: ▼引用関数入ってます。
B28: =[2]施策リソース数管理シート!B24 -> #REF! | C28: M/IGN/LINE/T | E28: 0 | Q28: 不要
A29: 06_ミッション | B29: ▼引用関数入ってます。
B30: =[2]施策リソース数管理シート!B27 -> #REF! | C30: M | E30: 0 | F30: 交換所バナー
B31: =[2]施策リソース数管理シート!B28 -> #REF! | E31: 0
B32: =[2]施策リソース数管理シート!B29 -> #REF! | E32: 0
A33: 07_祭施策 | B33: ▼引用関数入ってます。
B34: =[2]施策リソース数管理シート!B30 -> #REF! | E34: 0
B35: =[2]施策リソース数管理シート!B31 -> #REF! | E35: 0
B36: =[2]施策リソース数管理シート!B32 -> #REF! | E36: 0
A37: 11_キャラ | B37: ▼引用関数入ってます。
C38: 不要 | E38: 0 | M38: キャラ名
B39: =[2]施策リソース数管理シート!C5 -> #REF! | C39: 不要 | E39: 0 | M39: キャラ名
B40: =[2]施策リソース数管理シート!C6 -> #REF! | C40: 不要 | E40: 0 | M40: キャラ名
B41: =[2]施策リソース数管理シート!C7 -> #REF! | C41: 不要 | E41: 0 | M41: キャラ名
...

Sheet 02_施策テンプレ のコピー
A3: ルビー | C3: 配布いいジャン祭チケット | E3: 新規イベント本数 | G3: CPで配布キャラ | I3: 10連チケット | J3: ★5確定チケットのかけら | K3: ★4以上確定 | L3: ★3以上確定
A9: 施策詳細
A11: 目次
B13: ログイン動機 | F13: マーケ施策 | H13: 祭り施策
B14: =IFERROR(__xludf.DUMMYFUNCTION("iferror(ArrayFormula(HYPERLINK(""#gid=2015104756&range=""&""C""&match(query('01_概要'!$F$99:$K$160,""select F where I = '""&B13&""'"",false),$C:$C,0),switch(query('01_概要'!$F$99:$K$160,""select F where I = '""&B13&""'""),""FIX"",""【FIX】"","""")&query('01_概要'"&"!$F$99:$K$160,""select F where I = '""&B13&""'"",false))),"""")"),"") | F14: =IFERROR(__xludf.DUMMYFUNCTION("iferror(ArrayFormula(HYPERLINK(""#gid=2015104756&range=""&""C""&match(query('01_概要'!$F$99:$K$160,""select F where I = '""&$F$13&""'"",false),$C:$C,0),switch(query('01_概要'!$F$99:$K$160,""select F where I = '""&$F$13&""'""),""FIX"",""【FIX】"","""")&query('01"&"_概要'!$F$99:$K$160,""select F where I = '""&$F$13&""'"",false))),"""")"),"") | H14: =IFERROR(__xludf.DUMMYFUNCTION("iferror(unique(ArrayFormula(HYPERLINK(""#gid=2015104756&range=""&""C""&match(query('01_概要'!$F$99:$K$160,""select F where I = '""&$H$13&""'"",false),$C:$C,0),switch(query('01_概要'!$F$99:$K$160,""select F where I = '""&$H$13&""'""),""FIX"",""【FIX】"","""")&qu"&"ery('01_概要'!$F$99:$K$160,""select F where I = '""&$H$13&""'"",false)))),"""")"),"")
B37: プレイ動機 | F37: 課金動機 | H37: ホーム設定
B38: =IFERROR(__xludf.DUMMYFUNCTION("iferror(ArrayFormula(HYPERLINK(""#gid=2015104756&range=""&""C""&match(query('01_概要'!$F$99:$K$160,""select F where I = '""&$B$37&""'"",false),$C:$C,0),switch(query('01_概要'!$F$99:$K$160,""select F where I = '""&$B$37&""'""),""FIX"",""【FIX】"","""")&query('01"&"_概要'!$F$99:$K$160,""select F where I = '""&$B$37&""'"",false))),"""")"),"") | F38: =IFERROR(__xludf.DUMMYFUNCTION("iferror(ArrayFormula(HYPERLINK(""#gid=2015104756&range=""&""C""&match(query('01_概要'!$F$99:$K$160,""select F where I = '""&$F$37&""'"",false),$C:$C,0),switch(query('01_概要'!$F$99:$K$160,""select F where I = '""&$F$37&""'""),""FIX"",""【FIX】"","""")&query('01"&"_概要'!$F$99:$K$160,""select F where I = '""&$F$37&""'"",false))),"""")"),"") | H38: =IFERROR(__xludf.DUMMYFUNCTION("iferror(unique(ArrayFormula(HYPERLINK(""#gid=2015104756&range=""&""C""&match(query('01_概要'!$F$99:$K$160,""select F where I = '""&$H$37&""'"",false),$C:$C,0),switch(query('01_概要'!$F$99:$K$160,""select F where I = '""&$H$37&""'""),""FIX"",""【FIX】"","""")&qu"&"ery('01_概要'!$F$99:$K$160,""select F where I = '""&$H$37&""'"",false)))),"""")"),"")
A64: マーケ施策 | I64: 目次へ
A65: 実施するものにチェックを入れてください
C67: 公式ブログ
D68: URL
D69: ミッション名
D70: 報酬
D71: 開催期間
C73: TwitterCP
D75: 内容
D76: 施策名
D77: 報酬
D78: 報酬内容
D80: 開催期間
D81: 配布期間
D82: 内容の備考
D86: 内容
D87: 施策名
D88: 報酬
D89: 報酬内容
D91: 開催期間
... D93: 内容の備考
C98: 原作を読んでみようCP
D100: 内容
D101: 施策名
D102: 報酬
D103: 報酬内容
D105: サイトのURL
D106: 開催期間
D107: 内容の備考
A114: ログイン動機 | I114: 目次へ
B115: ログインボーナス
N116: 目次へ
C117: URL：
...

Sheet 使用しない_制作＆監修依頼一覧
B1: バナー共有日： | C1: 単体テスト開始：
A2: 施策種別 | B2: 施策名 | C2: 内容 | D2: バナー サイズ | E2: 監修/制作物 | F2: 監修/制作文言 | G2: 監修/備考 | H2: 担当 | I2: 文言制作 ステータス | J2: 監修提出日 | K2: QA(監修返答締め日) | L2: タスク テンプレート
A23: ▼ガチャ施策▼ | B23: ▼ガチャ施策▼
A42: スタンプ | B42: ▼使用するキャラ名 | F42: ▼スタンプに使用するセリフを記載する
A50: キャラのかけら | B50: キャラ名称を入れる
D51: アイテム | E51: - | H51: - | I51: 不要
D52: アイテム | E52: - | H52: - | I52: 不要
D53: アイテム | E53: - | H53: - | I53: 不要
D54: アイテム | E54: - | H54: - | I54: 不要
A56: その他画像 | B56: SNS告知に使用するもの（キービジュアル、壁紙配布、アプリアイコン告知、原画）
E58: - | H58: - | I58: 不要
E59: - | H59: - | I59: 不要
E60: - | H60: - | I60: 不要
E61: - | H61: - | I61: 不要
A63: 運営UI | B63: いいジャン祭ページがない時は削除する
B64: タイトル | D64: UI素材 | E64: - | H64: - | I64: 不要
B65: ホーム画面 | D65: UI素材 | E65: - | H65: - | I65: 不要
B66: いいジャン祭ページ | D66: UI素材 | E66: - | H66: - | I66: 不要
B67: ログインボーナス | D67: UI素材 | E67: - | H67: - | I67: 不要
B68: いいジャン祭ページボタンなど | D68: UI素材 | E68: - | H68: - | I68: 不要
A70: アプリアイコン | B70: 候補複数ある場合は全て記載する | C70: ▼キャラの候補を記載する(2案ぐらい)
B71: アプリアイコン | D71: その他 | E71: - | H71: - | I71: 不要

Sheet 背景一覧
A1: =IFERROR(__xludf.DUMMYFUNCTION("ARRAYFORMULA(IMPORTRANGE(""1WqYNNGUNwjHV1WQ6SodbmBmBRHcCBjgnOb9NovikHYY/"",""01_背景一覧!A:G""))"),"#REF!") -> #REF!

Sheet 03_制作依頼一覧
A1: ƒ
B2: ＜目次＞
C3: ◇バナー関連 | D3: ◇UI
C4: ◇アイテム | D4: ◇キャラ・クエスト関連 | F4: これかえる
C5: ◇アプリアイコン
B6: ◇バナー関連
B8: 毎週金曜16:00~16:30「バナーMTG」
B9: ＜参照：告知スケジュール＞
A11: ■施作一覧 | C11: =HYPERLINK("https://docs.google.com/spreadsheets/d/1hp4aNewiB-W636zDiHIIWcZZ2WX1_e8LHGBHVEkv3R8/edit#gid=1550360866","バナーの進捗確認はこちら") -> バナーの進捗確認はこちら | L11: ●LINE | M11: ◯WP
A12: SG | L12: 素材 | P12: 備考
B13: No | C13: 施策 | E13: 概要 | H13: 訴求 | K13: 分類 | L13: バナーL | M13: バナーM | N13: LINE OA | O13: twitter
A14: FALSE | B14: 1
A15: FALSE | B15: 2
A16: FALSE | B16: 3
A17: FALSE | B17: 4
A18: FALSE | B18: 5
A19: FALSE | B19: 6
A20: FALSE | B20: 7
A21: FALSE | B21: 8
A22: FALSE | B22: 9
A23: FALSE | B23: 10
A24: FALSE | B24: 11
A25: FALSE | B25: 12
... A43: FALSE | B43: 30
B48: ■その他告知（キービジュアル、チュートリアル、告知原画、壁紙配布、アプリアイコン配布、上記に記載が無いIGNなど）
A49: SG | L49: 素材 | P49: 備考
B50: No | C50: 施策 | E50: 概要 | H50: 訴求 | K50: 分類 | L50: バナーL | M50: バナーM | N50: LINE OA | O50: twitter
A51: FALSE | B51: 1
A52: FALSE | B52: 2
A53: FALSE | B53: 3
A54: FALSE | B54: 4
A55: FALSE | B55: 5
A56: FALSE | B56: 6
A57: FALSE | B57: 7
A58: FALSE | B58: 8
A59: FALSE | B59: 9
A60: FALSE | B60: 10
A61: FALSE | B61: 11
A62: FALSE | B62: 12
A63: FALSE | B63: 13
...

Sheet 03_制作依頼一覧 のテンプレ
A1: ƒ
B2: ＜目次＞
C3: ◇バナー関連 | D3: ◇UI
C4: ◇アイテム | D4: ◇キャラ・クエスト関連 | F4: これかえる
C5: ◇アプリアイコン
B6: ◇バナー関連
B8: 毎週金曜16:00~16:30「バナーMTG」
B9: ＜参照：告知スケジュール＞
A11: ■施作一覧 | C11: =HYPERLINK("https://docs.google.com/spreadsheets/d/1hp4aNewiB-W636zDiHIIWcZZ2WX1_e8LHGBHVEkv3R8/edit#gid=1550360866","バナーの進捗確認はこちら") -> バナーの進捗確認はこちら | L11: ●LINE | M11: ◯WP
A12: SG | L12: 素材 | P12: 備考
B13: No | C13: 施策 | E13: 概要 | H13: 訴求 | K13: 分類 | L13: バナーL | M13: バナーM | N13: LINE OA | O13: twitter
A14: FALSE | B14: 1
A15: FALSE | B15: 2
A16: FALSE | B16: 3
A17: FALSE | B17: 4
A18: FALSE | B18: 5
A19: FALSE | B19: 6
A20: FALSE | B20: 7
A21: FALSE | B21: 8
A22: FALSE | B22: 9
A23: FALSE | B23: 10
A24: FALSE | B24: 11
A25: FALSE | B25: 12
... A43: FALSE | B43: 30
B48: ■その他告知（キービジュアル、チュートリアル、告知原画、壁紙配布、アプリアイコン配布、上記に記載が無いIGNなど）
A49: SG | L49: 素材 | P49: 備考
B50: No | C50: 施策 | E50: 概要 | H50: 訴求 | K50: 分類 | L50: バナーL | M50: バナーM | N50: LINE OA | O50: twitter
A51: FALSE | B51: 1
A52: FALSE | B52: 2
A53: FALSE | B53: 3
A54: FALSE | B54: 4
A55: FALSE | B55: 5
A56: FALSE | B56: 6
A57: FALSE | B57: 7
A58: FALSE | B58: 8
A59: FALSE | B59: 9
A60: FALSE | B60: 10
A61: FALSE | B61: 11
A62: FALSE | B62: 12
A63: FALSE | B63: 13
...

Sheet 04_監修に依頼したいもの
A1: バナー共有期限 11月17日~20日まで | B1: ※仕様書をご確認頂き、漏れているものがあればご指摘頂けますと幸いです。
A2: 仮名 | B2: 内容 | C2: 制作物 | D2: 担当 | E2: 制作文言 | F2: ステータス | G2: 監修提出日 | H2: QA(監修返答締め日) | I2: 備考

Sheet 04_監修に依頼したいもの テンプレ
A1: バナー共有期限 11月17日~20日まで | B1: ※仕様書をご確認頂き、漏れているものがあればご指摘頂けますと幸いです。
A2: 仮名 | B2: 内容 | C2: 制作物 | D2: 担当 | E2: 制作文言 | F2: ステータス | G2: 監修提出日 | H2: QA(監修返答締め日) | I2: 備考
A12: =#REF! -> #REF!

Sheet 05_報酬一覧
B1: 05_報酬一覧
B3: ◆施策全体の報酬合計数（周回報酬はユーザーの努力報酬、また、ドロップ報酬は確定獲得ではないので、最低限ユーザーに獲得して欲しい報酬数で計算）
B5: カテゴリー/報酬 | C5: プリズム | D5: コイン | E5: ピックアップガシャチケット | F5: スペシャルガシャチケット | G5: メモリーフラグメント・初級 | H5: メモリーフラグメント・中級 | I5: メモリーフラグメント・上級 | J5: カラーメモリー・レッド | K5: カラーメモリー・グリーン | L5: カラーメモリー・イエロー | M5: カラーメモリー・ブルー | N5: カラーメモリー・グレー | O5: メイのかけら | P5: 民谷 巌鉄斎のかけら | Q5: メイのカラーメモリー | R5: 民谷 巌鉄斎のカラーメモリー | S5: メイ | T5: 民谷 巌鉄斎 | U5: 賊王 亜左 弔兵衛のかけら | V5: がらんの画眉丸のかけら | W5: 山田浅ェ門 桐馬のかけら | X5: 神仙郷のエンブレム
B6: ログボ | C6: 100 | D6: 15000 | E6: 3 | F6: 2 | G6: 15 | H6: 4 | I6: 0 | J6: 600 | K6: 600 | L6: 0 | M6: 0 | N6: 0 | O6: 0 | P6: 0 | Q6: 0 | R6: 0 | S6: 0 | T6: 0 | U6: 0 | V6: 0 | W6: 0 | X6: 0
B7: デイリー | C7: 340 | D7: 25500 | E7: 0 | F7: 0 | G7: 0 | H7: 0 | I7: 0 | J7: 0 | K7: 0 | L7: 0 | M7: 0 | N7: 0 | O7: 0 | P7: 0 | Q7: 0 | R7: 0 | S7: 0 | T7: 0 | U7: 0 | V7: 0 | W7: 0 | X7: 0
B8: ストーリー（メイ） | C8: 240 | D8: 3000 | E8: 0 | F8: 0 | G8: 15 | H8: 10 | I8: 1 | J8: 0 | K8: 0 | L8: 0 | M8: 0 | N8: 0 | O8: 0 | P8: 0 | Q8: 1100 | R8: 0 | S8: 1 | T8: 0 | U8: 0 | V8: 0 | W8: 0 | X8: 0
B9: ストーリー（民谷 巌鉄斎） | C9: 240 | D9: 3000 | E9: 0 | F9: 0 | G9: 15 | H9: 10 | I9: 1 | J9: 0 | K9: 0 | L9: 0 | M9: 0 | N9: 0 | O9: 0 | P9: 0 | Q9: 0 | R9: 1100 | S9: 0 | T9: 1 | U9: 0 | V9: 0 | W9: 0 | X9: 0
B10: チャレンジ | C10: 240 | D10: 0 | E10: 4 | F10: 0 | G10: 0 | H10: 0 | I10: 0 | J10: 0 | K10: 0 | L10: 0 | M10: 0 | N10: 0 | O10: 0 | P10: 0 | Q10: 0 | R10: 0 | S10: 0 | T10: 0 | U10: 50 | V10: 10 | W10: 50 | X10: 0
B11: 高難度 | C11: 480 | D11: 5000 | E11: 0 | F11: 3 | G11: 0 | H11: 0 | I11: 0 | J11: 0 | K11: 0 | L11: 0 | M11: 0 | N11: 0 | O11: 0 | P11: 0 | Q11: 0 | R11: 0 | S11: 0 | T11: 0 | U11: 0 | V11: 0 | W11: 0 | X11: 1
B12: ミッション | C12: 100 | D12: 25000 | E12: 5 | F12: 3 | G12: 30 | H12: 20 | I12: 5 | J12: 0 | K12: 0 | L12: 0 | M12: 0 | N12: 0 | O12: 100 | P12: 100 | Q12: 850 | R12: 850 | S12: 0 | T12: 0 | V12: 40
B13: 降臨バトル（期間中最低獲得可能分） | C13: 720 | D13: 72000 | E13: 0 | F13: 0 | G13: 30 | H13: 15 | I13: 1 | J13: 3 | K13: 3 | L13: 3 | M13: 3 | N13: 3 | O13: 0 | P13: 0 | Q13: 0 | R13: 0 | S13: 0 | T13: 0 | U13: 0 | V13: 0 | W13: 0 | X13: 0
L14: 0
B15: 今回のいいジャン祭報酬 | C15: =SUM(C6:C13) -> 2460 | D15: =SUM(D6:D13) -> 148500 | E15: =SUM(E6:E13) -> 12 | F15: =SUM(F6:F13) -> 8 | G15: =SUM(G6:G13) -> 105 | H15: =SUM(H6:H13) -> 59 | I15: =SUM(I6:I13) -> 8 | J15: =SUM(J6:J13) -> 603 | ... X15: =SUM(X6:X13) -> 1
B16: 2.5次元の誘惑 いいジャン祭報酬 | C16: 2130 | D16: 109200 | E16: 9 | F16: 4 | G16: 75 | H16: 42 | I16: 5 | J16: 603 | K16: 3 | L16: 3 | M16: 603 | N16: 3 | O16: 250 | P16: 250 | Q16: 1950 | R16: 1950 | S16: 1 | T16: 1 | U16: 50 | V16: 50 | W16: 50
B17: SPY×FAMILY いいジャン祭報酬合計数 | C17: 2170 | D17: 107800 | E17: 9 | F17: 5 | G17: 70 | H17: 35 | I17: 6 | J17: 203 | K17: 3 | L17: 203 | M17: 603 | N17: 3 | O17: 250 | P17: 250 | Q17: 1950 | R17: 1950 | S17: 1 | T17: 1 | U17: 50 | V17: 50 | W17: 50
B18: 怪獣８号 いいジャン祭報酬合計数 | C18: 2150 | D18: 101450 | E18: 8 | F18: 5 | G18: 70 | H18: 43 | I18: 5 | J18: 3 | K18: 3 | L18: 3 | M18: 903 | N18: 3 | O18: 250 | P18: 250 | Q18: 1950 | R18: 1950 | S18: 1 | T18: 1 | U18: 50 | V18: 50 | W18: 50
D19: ↑周回数に応じて獲得数UPですが1周回を最低期待値（コイン5000枚）を換算します | E19: 1枚多いのはミッションでエンブレムの代わりに配布を行っているからです | J19: ↑カラーメモリーは基本ピックアップガシャの属性に合わせたものが100以上 （Lv.40まで強化できる範囲を上限とし）獲得できるようにします 今回だと青属性なので、カラーメモリー・ブルーが多く獲得できます | O19: ↑周回数によって獲得数UP | P19: ↑周回数によって獲得数UP | S19: ↑周回数によって獲得数UP | T19: ↑周回数によって獲得数UP | U19: ↑ピックアップガシャの新キャラのかけら | W19: ↑ピックアップガシャの新キャラのかけら
J20: 100 | L20: 100 | N20: 100
B21: ▼降臨バトルのランキングやクエストの周回などは最低保証獲得数で計算してます
B22: 報酬関連 | C22: プリズム | D22: コイン | E22: ピックアップガシャチケット | F22: スペシャルガシャチケット | G22: メモリーフラグメント・初級 | H22: メモリーフラグメント・中級 | I22: メモリーフラグメント・上級 | J22: カラーメモリー・レッド | K22: カラーメモリー・グリーン | L22: カラーメモリー・イエロー | M22: カラーメモリー・ブルー | N22: カラーメモリー・グレー
B23: 1ヶ月のいいジャン祭 の報酬数 | C23: =C16*2 -> 4260 | D23: =D16*2 -> 218400 | E23: =E16*2 -> 18 | F23: =F16*2 -> 8 | G23: =G16*2 -> 150 | H23: =H16*2 -> 84 | I23: =I16*2 -> 10 | J23: 100 | K23: 100 | L23: 100 | M23: 100 | N23: 100 | O23: ここで配布数が超える場合は、PDM承認が必要
B24: 1ヶ月の降臨バトル の報酬数 | C24: 770 | D24: 76500 | E24: 0 | F24: 1 | G24: 30 | H24: 15 | I24: 1 | J24: 0 | K24: 0 | L24: 0 | M24: 0 | N24: 0
B25: 連携サイトやマーケで配布可能な量 | C25: 300 | D25: 4500 | E25: 0 | F25: 0 | G25: 0 | H25: 0 | I25: 0 | J25: 50 | K25: 0 | L25: 0 | M25: 0 | N25: 0

Sheet 告知スケジュール のコピー
B1: メモ
A2: 11/12(木)18時 | B2: 藤川さん、佐藤さん
B3: 後藤さん、嘉村さん、小林
B6: OPの1000話記念のマーケ施策（仮）
B7: 1月4日。1000話を迎える記念して、なにかやってもいい許可はもらっている。
B8: ロゴをくれた
B10: 年始のOPは1000万DLで出してはいけない。（）
B11: ユノが売れなくなるから。
B13: 12月29日からOPの情報を出し始める。そこから1000話記念を出したいby後藤
B14: 多分使えるんじゃない…？by藤川さん
B16: バナーに1000話記念をいれたい。
B17: 記念英雄祭ガチャの開催理由に、1000話を使いたい。OPの立て付け自体を1000話にしたい。
B19: データ設定が関わってくれるから、早めに返信が欲しい。by後藤
B20: →バナーにロゴを入れるには。
... B33: ワンピには触れない。
A39: マーケ施策 (LINEさん)
A42: ゲーム内施策
A44: ゲーム内お知らせ
A45: Twitter
A46: LINEOA
A47: プッシュ
A48: IGN（合計3枚）

Sheet 02_施策_REBORN
A1: 前提
B2: ◼︎ルビー金額（鷲見用メモ）
F3: ガチャ1回金額 | G3: 480 | H3: 円
F4: ガチャ1回最安値 | G4: 327 | H4: 円
F5: ルビー1個金額 | G5: =G4/100 -> 3.27 | H5: 円
F6: 1万円分 | G6: =ROUND(10000/G5,0) -> 3058 | H6: 個
C8: ゲーム内報酬レギュレーション
D9: https://docs.google.com/spreadsheets/d/1O9W479tFq6q2bb2JnWhqd-H7Skz4mvsc6oz8opU8L-I/edit#gid=0&range=A1
B11: ■施策について
C12: ・スケジュールは最初に全部出す(ガチャ以外)
C13: ・生放送なし
A17: 施策詳細
B19: 目次
D21: ログイン動機 | H21: マーケ連動施策 | J21: 祭り施策
D22: =IFERROR(__xludf.DUMMYFUNCTION("ArrayFormula(HYPERLINK(""#gid=1943159612&range=""&""C""&match(query('01_概要'!$E$86:$I$111,""select E where I = '""&D21&""'""),$C:$C,0),switch(query('01_概要'!$D$86:$I$111,""select D where I = '""&D21&""'""),""FIX"",""【FIX】"","""")&query('01_概要'!$E$86:$I$111,"&"""select E where I = '""&D21&""'"")))"),"#REF!") -> #REF! | H22: =IFERROR(__xludf.DUMMYFUNCTION("ArrayFormula(HYPERLINK(""#gid=1943159612&range=""&""C""&match(query('01_概要'!$E$86:$I$111,""select E where I = '""&H21&""'""),$C:$C,0),switch(query('01_概要'!$D$86:$I$111,""select D where I = '""&H21&""'""),""FIX"",""【FIX】"","""")&query('01_概要'!$E$86:$I$111,"&"""select E where I = '""&H21&""'"")))"),"#REF!") -> #REF! | J22: =IFERROR(__xludf.DUMMYFUNCTION("ArrayFormula(HYPERLINK(""#gid=1943159612&range=""&""C""&match(query('01_概要'!$E$86:$I$111,""select E where I = '""&J21&""'""),$C:$C,0),switch(query('01_概要'!$D$86:$I$111,""select D where I = '""&J21&""'""),""FIX"",""【FIX】"","""")&query('01_概要'!$E$86:$I$111,"&"""select E where I = '""&J21&""'"")))"),"#REF!") -> #REF!
J23: =IFERROR(__xludf.DUMMYFUNCTION("ArrayFormula(HYPERLINK(""https://docs.google.com/spreadsheets/d/1t052VlLhleL6fIo_2n0r_z7lSC9CnV-6e9ezNXG4QC8/edit#gid=1943159612&range=C165=""&""C""&match(query('01_概要'!$E$86:$I$111,""select E where I = '""&J21&""'""),$C:$C,0),switch(query('01_概要'!$D$86:$"&"I$111,""select D where I = '""&J21&""'""),""FIX"",""【FIX】"","""")&query('01_概要'!$E$86:$I$111,""select E where I = '""&J21&""'"")))"),"#REF!") -> #REF!
D31: プレイ動機 | H31: 課金動機 | J31: ホーム設定
D32: =IFERROR(__xludf.DUMMYFUNCTION("ArrayFormula(HYPERLINK(""#gid=1943159612&range=""&""C""&match(query('01_概要'!$E$86:$I$111,""select E where I = '""&D31&""'""),$C:$C,0),switch(query('01_概要'!$D$86:$I$111,""select D where I = '""&D31&""'""),""FIX"",""【FIX】"","""")&query('01_概要'!$E$86:$I$111,"&"""select E where I = '""&D31&""'"")))"),"#REF!") -> #REF! | H32: =IFERROR(__xludf.DUMMYFUNCTION("ArrayFormula(HYPERLINK(""#gid=1943159612&range=""&""C""&match(query('01_概要'!$E$86:$I$111,""select E where I = '""&H31&""'""),$C:$C,0),switch(query('01_概要'!$D$86:$I$111,""select D where I = '""&H31&""'""),""FIX"",""【FIX】"","""")&query('01_概要'!$E$86:$I$111,"&"""select E where I = '""&H31&""'"")))"),"#REF!") -> #REF! | J32: =IFERROR(__xludf.DUMMYFUNCTION("ArrayFormula(HYPERLINK(""#gid=1943159612&range=""&""C""&match(query('01_概要'!$E$86:$I$111,""select E where I = '""&J31&""'""),$C:$C,0),switch(query('01_概要'!$D$86:$I$111,""select D where I = '""&J31&""'""),""FIX"",""【FIX】"","""")&query('01_概要'!$E$86:$I$111,"&"""select E where I = '""&J31&""'"")))"),"#REF!") -> #REF!
D46: ※セルの色が黄色いところは、まだ内容が確定してないよ！という意味です。
D47: なので確定したらセルの色は消しておいてください。
B49: ログイン動機 | M49: 目次へ
C51: いいジャン祭ログインボーナス | M51: 目次へ
D52: URL：
F53: 項目 | H53: 内容
F54: 責任者 | H54: =VLOOKUP($C51,'01_概要'!$E$86:$K$111,3,FALSE) -> #N/A | I54: =VLOOKUP($C51,'01_概要'!$E$86:$K$111,4,FALSE) -> #N/A
F55: 施策名称 | H55: =C51 -> いいジャン祭ログインボーナス
F56: 分類 | H56: ログインボーナス
F57: 開催期間 | H57: =VLOOKUP(C51,'01_概要'!$E$86:$K$111,6,FALSE) -> #N/A | I57: 〜 | J57: =VLOOKUP(C51,'01_概要'!$E$86:$K$111,7,FALSE) -> #N/A
F58: キャラ・セリフ | H58: リボーン
D60: 目的：
F61: 毎日ログインしたい！と思わせることを目的とする。
D63: 内容：
F64: 日数 | G64: 特典（目玉＝赤文字） | I64: ID | J64: 個数 | K64: 備考 | O64: ルビー配布量 | P64: パール配布量
D65: 43901 | E65: 大 | F65: 1日目 | J65: 1 | Q65: 1
D66: =D65+1 -> 43902 | E66: 大 | F66: 2日目 | J66: 1 | Q66: 1
D67: =D66+1 -> 43903 | F67: 3日目 | J67: 200000 | Q67: 0
D68: =D67+1 -> 43904 | E68: 大 | F68: 4日目 | J68: 100 | Q68: 1
D69: =D68+1 -> 43905 | F69: 5日目 | J69: 1000 | Q69: 0
D70: =D69+1 -> 43906 | E70: 大 | F70: 6日目 | J70: 100 | Q70: 0
D71: =D70+1 -> 43907 | E71: 大 | F71: 7日目 | J71: 1 | Q71: 0
...

Sheet チェック対象管理
A1: チェック | B1: シート名 | C1: マッピング | D1: マスターURL | E1: 最終チェック日時 | F1: 結果
A2: TRUE | B2: ミッション一覧 | C2: マッピング設定_ミッション
A3: TRUE | B3: 依存関係一覧 | C3: マッピング設定_依存関係
A4: TRUE | B4: 報酬一覧 | C4: マッピング設定_報酬

Sheet ミッション一覧
A1: ミッション一覧（MstMissionEvent + MstMissionEventI18n）
A2: ENABLE | B2: id | C2: release_key | D2: mst_event_id | E2: criterion_type | F2: criterion_value | G2: criterion_count | H2: unlock_criterion_type | I2: unlock_criterion_value | J2: unlock_criterion_count | K2: group_key | L2: mst_mission_reward_group_id | M2: sort_order | N2: destination_scene | O2: i18n_id | P2: language | Q2: description
A3: e | B3: event_jig_00001_1 | C3: 202601010 | D3: event_jig_00001 | E3: SpecificUnitGradeUpCount | F3: chara_jig_00701 | G3: 2 | H3: __NULL__ | J3: 0 | L3: jig_00001_event_reward_01 | M3: 1 | N3: UnitList | O3: event_jig_00001_1_ja | P3: ja | Q3: メイ をグレード2まで強化しよう
A4: e | B4: event_jig_00001_2 | C4: 202601010 | D4: event_jig_00001 | E4: SpecificUnitGradeUpCount | F4: chara_jig_00701 | G4: 3 | H4: __NULL__ | J4: 0 | L4: jig_00001_event_reward_02 | M4: 2 | N4: UnitList | O4: event_jig_00001_2_ja | P4: ja | Q4: メイ をグレード3まで強化しよう
A5: e | B5: event_jig_00001_3 | C5: 202601010 | D5: event_jig_00001 | E5: SpecificUnitGradeUpCount | F5: chara_jig_00701 | G5: 4 | H5: __NULL__ | J5: 0 | L5: jig_00001_event_reward_03 | M5: 3 | N5: UnitList | O5: event_jig_00001_3_ja | P5: ja | Q5: メイ をグレード4まで強化しよう
A6: e | B6: event_jig_00001_4 | C6: 202601010 | D6: event_jig_00001 | E6: SpecificUnitGradeUpCount | F6: chara_jig_00701 | G6: 5 | H6: __NULL__ | J6: 0 | L6: jig_00001_event_reward_04 | M6: 4 | N6: UnitList | O6: event_jig_00001_4_ja | P6: ja | Q6: メイ をグレード5まで強化しよう
A7: e | B7: event_jig_00001_5 | C7: 202601010 | D7: event_jig_00001 | E7: SpecificUnitLevel | F7: chara_jig_00701 | G7: 20 | H7: __NULL__ | J7: 0 | L7: jig_00001_event_reward_05 | M7: 5 | N7: UnitList | O7: event_jig_00001_5_ja | P7: ja | Q7: メイ をLv.20まで強化しよう
A8: e | B8: event_jig_00001_6 | C8: 202601010 | D8: event_jig_00001 | E8: SpecificUnitLevel | F8: chara_jig_00701 | G8: 30 | H8: __NULL__ | J8: 0 | L8: jig_00001_event_reward_06 | M8: 6 | N8: UnitList | O8: event_jig_00001_6_ja | P8: ja | Q8: メイ をLv.30まで強化しよう
A9: e | B9: event_jig_00001_7 | C9: 202601010 | D9: event_jig_00001 | E9: SpecificUnitLevel | F9: chara_jig_00701 | G9: 40 | H9: __NULL__ | J9: 0 | L9: jig_00001_event_reward_07 | M9: 7 | N9: UnitList | O9: event_jig_00001_7_ja | P9: ja | Q9: メイ をLv.40まで強化しよう
A10: e | B10: event_jig_00001_8 | C10: 202601010 | D10: event_jig_00001 | E10: SpecificUnitLevel | F10: chara_jig_00701 | G10: 50 | H10: __NULL__ | J10: 0 | L10: jig_00001_event_reward_08 | M10: 8 | N10: UnitList | O10: event_jig_00001_8_ja | P10: ja | Q10: メイ をLv.50まで強化しよう
A11: e | B11: event_jig_00001_9 | C11: 202601010 | D11: event_jig_00001 | E11: SpecificUnitLevel | F11: chara_jig_00701 | G11: 60 | H11: __NULL__ | J11: 0 | L11: jig_00001_event_reward_09 | M11: 9 | N11: UnitList | O11: event_jig_00001_9_ja | P11: ja | Q11: メイ をLv.60まで強化しよう
A12: e | B12: event_jig_00001_10 | C12: 202601010 | D12: event_jig_00001 | E12: SpecificUnitLevel | F12: chara_jig_00701 | G12: 70 | H12: __NULL__ | J12: 0 | L12: jig_00001_event_reward_10 | M12: 10 | N12: UnitList | O12: event_jig_00001_10_ja | P12: ja | Q12: メイ をLv.70まで強化しよう
A13: e | B13: event_jig_00001_11 | C13: 202601010 | D13: event_jig_00001 | E13: SpecificUnitLevel | F13: chara_jig_00701 | G13: 80 | H13: __NULL__ | J13: 0 | L13: jig_00001_event_reward_11 | M13: 11 | N13: UnitList | O13: event_jig_00001_11_ja | P13: ja | Q13: メイ をLv.80まで強化しよう
A14: e | B14: event_jig_00001_12 | C14: 202601010 | D14: event_jig_00001 | E14: SpecificUnitGradeUpCount | F14: chara_jig_00601 | G14: 2 | H14: __NULL__ | J14: 0 | L14: jig_00001_event_reward_12 | M14: 12 | N14: UnitList | O14: event_jig_00001_12_ja | P14: ja | Q14: 民谷 巌鉄斎 をグレード2まで強化しよう
... A28: e | B28: event_jig_00001_26 | C28: 202601010 | D28: event_jig_00001 | E28: SpecificQuestClear | F28: quest_event_jig1_savage | G28: 1 | H28: __NULL__ | J28: 0 | L28: jig_00001_event_reward_26 | M28: 26 | N28: Event | O28: event_jig_00001_26_ja | P28: ja | Q28: 高難易度「手負いの獣は恐ろしいぞ」をクリアしよう
A29: e | B29: event_jig_00001_27 | C29: 202601010 | D29: event_jig_00001 | E29: DefeatEnemyCount | G29: 10 | H29: __NULL__ | J29: 0 | L29: jig_00001_event_reward_27 | M29: 27 | N29: Event | O29: event_jig_00001_27_ja | P29: ja | Q29: 敵を10体撃破しよう
A30: e | B30: event_jig_00001_28 | C30: 202601010 | D30: event_jig_00001 | E30: DefeatEnemyCount | G30: 20 | H30: __NULL__ | J30: 0 | L30: jig_00001_event_reward_28 | M30: 28 | N30: Event | O30: event_jig_00001_28_ja | P30: ja | Q30: 敵を20体撃破しよう
A31: e | B31: event_jig_00001_29 | C31: 202601010 | D31: event_jig_00001 | E31: DefeatEnemyCount | G31: 30 | H31: __NULL__ | J31: 0 | L31: jig_00001_event_reward_29 | M31: 29 | N31: Event | O31: event_jig_00001_29_ja | P31: ja | Q31: 敵を30体撃破しよう
A32: e | B32: event_jig_00001_30 | C32: 202601010 | D32: event_jig_00001 | E32: DefeatEnemyCount | G32: 40 | H32: __NULL__ | J32: 0 | L32: jig_00001_event_reward_30 | M32: 30 | N32: Event | O32: event_jig_00001_30_ja | P32: ja | Q32: 敵を40体撃破しよう
A33: e | B33: event_jig_00001_31 | C33: 202601010 | D33: event_jig_00001 | E33: DefeatEnemyCount | G33: 50 | H33: __NULL__ | J33: 0 | L33: jig_00001_event_reward_31 | M33: 31 | N33: Event | O33: event_jig_00001_31_ja | P33: ja | Q33: 敵を50体撃破しよう
A34: e | B34: event_jig_00001_32 | C34: 202601010 | D34: event_jig_00001 | E34: DefeatEnemyCount | G34: 60 | H34: __NULL__ | J34: 0 | L34: jig_00001_event_reward_32 | M34: 32 | N34: Event | O34: event_jig_00001_32_ja | P34: ja | Q34: 敵を60体撃破しよう
A35: e | B35: event_jig_00001_33 | C35: 202601010 | D35: event_jig_00001 | E35: DefeatEnemyCount | G35: 70 | H35: __NULL__ | J35: 0 | L35: jig_00001_event_reward_33 | M35: 33 | N35: Event | O35: event_jig_00001_33_ja | P35: ja | Q35: 敵を70体撃破しよう
A36: e | B36: event_jig_00001_34 | C36: 202601010 | D36: event_jig_00001 | E36: DefeatEnemyCount | G36: 80 | H36: __NULL__ | J36: 0 | L36: jig_00001_event_reward_34 | M36: 34 | N36: Event | O36: event_jig_00001_34_ja | P36: ja | Q36: 敵を80体撃破しよう
A37: e | B37: event_jig_00001_35 | C37: 202601010 | D37: event_jig_00001 | E37: DefeatEnemyCount | G37: 90 | H37: __NULL__ | J37: 0 | L37: jig_00001_event_reward_35 | M37: 35 | N37: Event | O37: event_jig_00001_35_ja | P37: ja | Q37: 敵を90体撃破しよう
A38: e | B38: event_jig_00001_36 | C38: 202601010 | D38: event_jig_00001 | E38: DefeatEnemyCount | G38: 100 | H38: __NULL__ | J38: 0 | L38: jig_00001_event_reward_36 | M38: 36 | N38: Event | O38: event_jig_00001_36_ja | P38: ja | Q38: 敵を100体撃破しよう
A39: e | B39: event_jig_00001_37 | C39: 202601010 | D39: event_jig_00001 | E39: DefeatEnemyCount | G39: 150 | H39: __NULL__ | J39: 0 | L39: jig_00001_event_reward_37 | M39: 37 | N39: Event | O39: event_jig_00001_37_ja | P39: ja | Q39: 敵を150体撃破しよう
A40: e | B40: event_jig_00001_38 | C40: 202601010 | D40: event_jig_00001 | E40: DefeatEnemyCount | G40: 200 | H40: __NULL__ | J40: 0 | L40: jig_00001_event_reward_38 | M40: 38 | N40: Event | O40: event_jig_00001_38_ja | P40: ja | Q40: 敵を200体撃破しよう
... A45: e | B45: event_jig_00001_43 | C45: 202601010 | D45: event_jig_00001 | E45: DefeatEnemyCount | G45: 1000 | H45: __NULL__ | J45: 0 | L45: jig_00001_event_reward_43 | M45: 43 | N45: Event | O45: event_jig_00001_43_ja | P45: ja | Q45: 敵を1000体撃破しよう

Sheet 依存関係一覧
A1: 依存関係一覧（MstMissionEventDependency）
A2: ENABLE | B2: id | C2: release_key | D2: group_id | E2: mst_mission_event_id | F2: unlock_order | G2: 備考
A3: e | B3: 151 | C3: 202601010 | D3: event_jig_00001_1 | E3: event_jig_00001_1 | F3: 1
A4: e | B4: 152 | C4: 202601010 | D4: event_jig_00001_1 | E4: event_jig_00001_2 | F4: 2
A5: e | B5: 153 | C5: 202601010 | D5: event_jig_00001_1 | E5: event_jig_00001_3 | F5: 3
A6: e | B6: 154 | C6: 202601010 | D6: event_jig_00001_1 | E6: event_jig_00001_4 | F6: 4
A7: e | B7: 155 | C7: 202601010 | D7: event_jig_00001_5 | E7: event_jig_00001_5 | F7: 1
A8: e | B8: 156 | C8: 202601010 | D8: event_jig_00001_5 | E8: event_jig_00001_6 | F8: 2
A9: e | B9: 157 | C9: 202601010 | D9: event_jig_00001_5 | E9: event_jig_00001_7 | F9: 3
A10: e | B10: 158 | C10: 202601010 | D10: event_jig_00001_5 | E10: event_jig_00001_8 | F10: 4
A11: e | B11: 159 | C11: 202601010 | D11: event_jig_00001_5 | E11: event_jig_00001_9 | F11: 5
A12: e | B12: 160 | C12: 202601010 | D12: event_jig_00001_5 | E12: event_jig_00001_10 | F12: 6
A13: e | B13: 161 | C13: 202601010 | D13: event_jig_00001_5 | E13: event_jig_00001_11 | F13: 7
A14: e | B14: 162 | C14: 202601010 | D14: event_jig_00001_12 | E14: event_jig_00001_12 | F14: 1
... A41: e | B41: 189 | C41: 202601010 | D41: event_jig_00001_27 | E41: event_jig_00001_43 | F41: 17

Sheet 報酬一覧
A1: 報酬一覧（MstMissionReward - イベントミッション分）
A2: ENABLE | B2: id | C2: release_key | D2: group_id | E2: resource_type | F2: resource_id | G2: resource_amount | H2: sort_order | I2: 備考
A3: e | B3: mission_reward_480 | C3: 202601010 | D3: jig_00001_event_reward_01 | E3: Item | F3: memory_chara_jig_00701 | G3: 200 | H3: 1 | I3: jigいいジャン祭_ミッション
A4: e | B4: mission_reward_481 | C4: 202601010 | D4: jig_00001_event_reward_02 | E4: Item | F4: memory_chara_jig_00701 | G4: 300 | H4: 1 | I4: jigいいジャン祭_ミッション
A5: e | B5: mission_reward_482 | C5: 202601010 | D5: jig_00001_event_reward_03 | E5: Item | F5: memory_chara_jig_00701 | G5: 350 | H5: 1 | I5: jigいいジャン祭_ミッション
A6: e | B6: mission_reward_483 | C6: 202601010 | D6: jig_00001_event_reward_04 | E6: Item | F6: ticket_glo_00003 | G6: 1 | H6: 1 | I6: jigいいジャン祭_ミッション
A7: e | B7: mission_reward_484 | C7: 202601010 | D7: jig_00001_event_reward_05 | E7: Item | F7: piece_jig_00701 | G7: 10 | H7: 1 | I7: jigいいジャン祭_ミッション
A8: e | B8: mission_reward_485 | C8: 202601010 | D8: jig_00001_event_reward_06 | E8: Item | F8: piece_jig_00701 | G8: 20 | H8: 1 | I8: jigいいジャン祭_ミッション
A9: e | B9: mission_reward_486 | C9: 202601010 | D9: jig_00001_event_reward_07 | E9: Item | F9: piece_jig_00701 | G9: 20 | H9: 1 | I9: jigいいジャン祭_ミッション
A10: e | B10: mission_reward_487 | C10: 202601010 | D10: jig_00001_event_reward_08 | E10: Item | F10: piece_jig_00701 | G10: 20 | H10: 1 | I10: jigいいジャン祭_ミッション
A11: e | B11: mission_reward_488 | C11: 202601010 | D11: jig_00001_event_reward_09 | E11: Item | F11: piece_jig_00701 | G11: 30 | H11: 1 | I11: jigいいジャン祭_ミッション
A12: e | B12: mission_reward_489 | C12: 202601010 | D12: jig_00001_event_reward_10 | E12: Item | F12: memoryfragment_glo_00003 | G12: 1 | H12: 1 | I12: jigいいジャン祭_ミッション
A13: e | B13: mission_reward_490 | C13: 202601010 | D13: jig_00001_event_reward_11 | E13: FreeDiamond | G13: 50 | H13: 1 | I13: jigいいジャン祭_ミッション
A14: e | B14: mission_reward_491 | C14: 202601010 | D14: jig_00001_event_reward_12 | E14: Item | F14: memory_chara_jig_00601 | G14: 200 | H14: 1 | I14: jigいいジャン祭_ミッション
A15: e | B15: mission_reward_492 | C15: 202601010 | D15: jig_00001_event_reward_13 | E15: Item | F15: memory_chara_jig_00601 | G15: 300 | H15: 1 | I15: jigいいジャン祭_ミッション
A16: e | B16: mission_reward_493 | C16: 202601010 | D16: jig_00001_event_reward_14 | E16: Item | F16: memory_chara_jig_00601 | G16: 350 | H16: 1 | I16: jigいいジャン祭_ミッション
A17: e | B17: mission_reward_494 | C17: 202601010 | D17: jig_00001_event_reward_15 | E17: Item | F17: ticket_glo_00003 | G17: 1 | H17: 1 | I17: jigいいジャン祭_ミッション
A18: e | B18: mission_reward_495 | C18: 202601010 | D18: jig_00001_event_reward_16 | E18: Item | F18: piece_jig_00601 | G18: 10 | H18: 1 | I18: jigいいジャン祭_ミッション
A19: e | B19: mission_reward_496 | C19: 202601010 | D19: jig_00001_event_reward_17 | E19: Item | F19: piece_jig_00601 | G19: 20 | H19: 1 | I19: jigいいジャン祭_ミッション
A20: e | B20: mission_reward_497 | C20: 202601010 | D20: jig_00001_event_reward_18 | E20: Item | F20: piece_jig_00601 | G20: 20 | H20: 1 | I20: jigいいジャン祭_ミッション
A21: e | B21: mission_reward_498 | C21: 202601010 | D21: jig_00001_event_reward_19 | E21: Item | F21: piece_jig_00601 | G21: 20 | H21: 1 | I21: jigいいジャン祭_ミッション
A22: e | B22: mission_reward_499 | C22: 202601010 | D22: jig_00001_event_reward_20 | E22: Item | F22: piece_jig_00601 | G22: 30 | H22: 1 | I22: jigいいジャン祭_ミッション
A23: e | B23: mission_reward_500 | C23: 202601010 | D23: jig_00001_event_reward_21 | E23: Item | F23: memoryfragment_glo_00003 | G23: 1 | H23: 1 | I23: jigいいジャン祭_ミッション
A24: e | B24: mission_reward_501 | C24: 202601010 | D24: jig_00001_event_reward_22 | E24: FreeDiamond | G24: 50 | H24: 1 | I24: jigいいジャン祭_ミッション
A25: e | B25: mission_reward_502 | C25: 202601010 | D25: jig_00001_event_reward_23 | E25: Coin | G25: 12500 | H25: 1 | I25: jigいいジャン祭_ミッション
A26: e | B26: mission_reward_503 | C26: 202601010 | D26: jig_00001_event_reward_24 | E26: Coin | G26: 12500 | H26: 1 | I26: jigいいジャン祭_ミッション
A27: e | B27: mission_reward_504 | C27: 202601010 | D27: jig_00001_event_reward_25 | E27: Item | F27: ticket_glo_00002 | G27: 3 | H27: 1 | I27: jigいいジャン祭_ミッション
A28: e | B28: mission_reward_505 | C28: 202601010 | D28: jig_00001_event_reward_26 | E28: Item | F28: ticket_glo_00003 | G28: 1 | H28: 1 | I28: jigいいジャン祭_ミッション
A29: e | B29: mission_reward_506 | C29: 202601010 | D29: jig_00001_event_reward_27 | E29: Item | F29: memoryfragment_glo_00001 | G29: 5 | H29: 1 | I29: jigいいジャン祭_ミッション
A30: e | B30: mission_reward_507 | C30: 202601010 | D30: jig_00001_event_reward_28 | E30: Item | F30: memoryfragment_glo_00001 | G30: 5 | H30: 1 | I30: jigいいジャン祭_ミッション
A31: e | B31: mission_reward_508 | C31: 202601010 | D31: jig_00001_event_reward_29 | E31: Item | F31: memoryfragment_glo_00001 | G31: 5 | H31: 1 | I31: jigいいジャン祭_ミッション
A32: e | B32: mission_reward_509 | C32: 202601010 | D32: jig_00001_event_reward_30 | E32: Item | F32: memoryfragment_glo_00001 | G32: 5 | H32: 1 | I32: jigいいジャン祭_ミッション
A33: e | B33: mission_reward_510 | C33: 202601010 | D33: jig_00001_event_reward_31 | E33: Item | F33: memoryfragment_glo_00001 | G33: 10 | H33: 1 | I33: jigいいジャン祭_ミッション
A34: e | B34: mission_reward_511 | C34: 202601010 | D34: jig_00001_event_reward_32 | E34: Item | F34: memoryfragment_glo_00002 | G34: 5 | H34: 1 | I34: jigいいジャン祭_ミッション
A35: e | B35: mission_reward_512 | C35: 202601010 | D35: jig_00001_event_reward_33 | E35: Item | F35: memoryfragment_glo_00002 | G35: 5 | H35: 1 | I35: jigいいジャン祭_ミッション
A36: e | B36: mission_reward_513 | C36: 202601010 | D36: jig_00001_event_reward_34 | E36: Item | F36: memoryfragment_glo_00002 | G36: 5 | H36: 1 | I36: jigいいジャン祭_ミッション
A37: e | B37: mission_reward_514 | C37: 202601010 | D37: jig_00001_event_reward_35 | E37: Item | F37: memoryfragment_glo_00002 | G37: 5 | H37: 1 | I37: jigいいジャン祭_ミッション
A38: e | B38: mission_reward_515 | C38: 202601010 | D38: jig_00001_event_reward_36 | E38: Item | F38: memoryfragment_glo_00003 | G38: 1 | H38: 1 | I38: jigいいジャン祭_ミッション
... A45: e | B45: mission_reward_522 | C45: 202601010 | D45: jig_00001_event_reward_43 | E45: Item | F45: piece_jig_00001 | G45: 20 | H45: 1 | I45: jigいいジャン祭_ミッション

Sheet マッピング設定_ミッション
A1: 項目名 | B1: 方向 | C1: 設計書範囲 | D1: マスター名 | E1: マスター列名 | F1: チェック無視 | G1: ユニークキー | H1: 展開タイプ | I1: 空白無視
C2: A3:A100 | D2: MstMissionEvent | E2: ENABLE | F2: FALSE | G2: FALSE | H2: 通常 | I2: FALSE
C3: B3:B100 | D3: MstMissionEvent | E3: id | F3: FALSE | G3: TRUE | H3: 通常 | I3: FALSE
C4: C3:C100 | D4: MstMissionEvent | E4: release_key | F4: FALSE | G4: FALSE | H4: 通常 | I4: FALSE
C5: D3:D100 | D5: MstMissionEvent | E5: mst_event_id | F5: FALSE | G5: FALSE | H5: 通常 | I5: FALSE
C6: E3:E100 | D6: MstMissionEvent | E6: criterion_type | F6: FALSE | G6: FALSE | H6: 通常 | I6: FALSE
C7: F3:F100 | D7: MstMissionEvent | E7: criterion_value | F7: FALSE | G7: FALSE | H7: 通常 | I7: FALSE
C8: G3:G100 | D8: MstMissionEvent | E8: criterion_count | F8: FALSE | G8: FALSE | H8: 通常 | I8: FALSE
C9: H3:H100 | D9: MstMissionEvent | E9: unlock_criterion_type | F9: FALSE | G9: FALSE | H9: 通常 | I9: FALSE
C10: I3:I100 | D10: MstMissionEvent | E10: unlock_criterion_value | F10: FALSE | G10: FALSE | H10: 通常 | I10: FALSE
C11: J3:J100 | D11: MstMissionEvent | E11: unlock_criterion_count | F11: FALSE | G11: FALSE | H11: 通常 | I11: FALSE
C12: K3:K100 | D12: MstMissionEvent | E12: group_key | F12: FALSE | G12: FALSE | H12: 通常 | I12: FALSE
C13: L3:L100 | D13: MstMissionEvent | E13: mst_mission_reward_group_id | F13: FALSE | G13: FALSE | H13: 通常 | I13: FALSE
... C21: Q3:Q100 | D21: MstMissionEventI18n | E21: description | F21: FALSE | G21: FALSE | H21: 通常 | I21: FALSE

Sheet マッピング設定_依存関係
A1: 項目名 | B1: 方向 | C1: 設計書範囲 | D1: マスター名 | E1: マスター列名 | F1: チェック無視 | G1: ユニークキー | H1: 展開タイプ | I1: 空白無視
C2: A3:A100 | D2: MstMissionEventDependency | E2: ENABLE | F2: FALSE | G2: FALSE | H2: 通常 | I2: FALSE
C3: B3:B100 | D3: MstMissionEventDependency | E3: id | F3: FALSE | G3: TRUE | H3: 通常 | I3: FALSE
C4: C3:C100 | D4: MstMissionEventDependency | E4: release_key | F4: FALSE | G4: FALSE | H4: 通常 | I4: FALSE
C5: D3:D100 | D5: MstMissionEventDependency | E5: group_id | F5: FALSE | G5: FALSE | H5: 通常 | I5: FALSE
C6: E3:E100 | D6: MstMissionEventDependency | E6: mst_mission_event_id | F6: FALSE | G6: FALSE | H6: 通常 | I6: FALSE
C7: F3:F100 | D7: MstMissionEventDependency | E7: unlock_order | F7: FALSE | G7: FALSE | H7: 通常 | I7: FALSE
C8: G3:G100 | D8: MstMissionEventDependency | E8: 備考 | F8: FALSE | G8: FALSE | H8: 通常 | I8: FALSE

Sheet マッピング設定_報酬
A1: 項目名 | B1: 方向 | C1: 設計書範囲 | D1: マスター名 | E1: マスター列名 | F1: チェック無視 | G1: ユニークキー | H1: 展開タイプ | I1: 空白無視
C2: A3:A100 | D2: MstMissionReward | E2: ENABLE | F2: FALSE | G2: FALSE | H2: 通常 | I2: FALSE
C3: B3:B100 | D3: MstMissionReward | E3: id | F3: FALSE | G3: TRUE | H3: 通常 | I3: FALSE
C4: C3:C100 | D4: MstMissionReward | E4: release_key | F4: FALSE | G4: FALSE | H4: 通常 | I4: FALSE
C5: D3:D100 | D5: MstMissionReward | E5: group_id | F5: FALSE | G5: FALSE | H5: 通常 | I5: FALSE
C6: E3:E100 | D6: MstMissionReward | E6: resource_type | F6: FALSE | G6: FALSE | H6: 通常 | I6: FALSE
C7: F3:F100 | D7: MstMissionReward | E7: resource_id | F7: FALSE | G7: FALSE | H7: 通常 | I7: FALSE
C8: G3:G100 | D8: MstMissionReward | E8: resource_amount | F8: FALSE | G8: FALSE | H8: 通常 | I8: FALSE
C9: H3:H100 | D9: MstMissionReward | E9: sort_order | F9: FALSE | G9: FALSE | H9: 通常 | I9: FALSE
C10: I3:I100 | D10: MstMissionReward | E10: 備考 | F10: FALSE | G10: FALSE | H10: 通常 | I10: FALSE
