Workbook

Sheet チェック対象管理
A1: チェック | B1: シート名 | C1: マッピング | D1: マスターURL | E1: 最終チェック日時 | F1: 結果
A2: FALSE | B2: 1話 | C2: マッピング設定シート_new | D2: https://docs.google.com/spreadsheets/d/1TS8YjnOCA1QWgrPJa5HzzKVS7WefPnRxDbr5XFhNQ5o/edit?gid=1350936069#gid=1350936069 | E2: 46027.68 | F2: ✅ OK
A3: FALSE | B3: 2話 | C3: マッピング設定シート_new | D3: https://docs.google.com/spreadsheets/d/1TS8YjnOCA1QWgrPJa5HzzKVS7WefPnRxDbr5XFhNQ5o/edit?gid=1350936069#gid=1350936069 | E3: 46027.68 | F3: ✅ OK
A4: FALSE | B4: 3話 | C4: マッピング設定シート_new | D4: https://docs.google.com/spreadsheets/d/1TS8YjnOCA1QWgrPJa5HzzKVS7WefPnRxDbr5XFhNQ5o/edit?gid=1350936069#gid=1350936069 | E4: 46027.68 | F4: ✅ OK
A5: FALSE | B5: 4話 | C5: マッピング設定シート_new | D5: https://docs.google.com/spreadsheets/d/1TS8YjnOCA1QWgrPJa5HzzKVS7WefPnRxDbr5XFhNQ5o/edit?gid=1350936069#gid=1350936069 | E5: 46027.68 | F5: ✅ OK
A6: FALSE | B6: 5話 | C6: マッピング設定シート_new | D6: https://docs.google.com/spreadsheets/d/1TS8YjnOCA1QWgrPJa5HzzKVS7WefPnRxDbr5XFhNQ5o/edit?gid=1350936069#gid=1350936069 | E6: 46027.68 | F6: ✅ OK
A7: TRUE | B7: 6話 | C7: マッピング設定シート_new | D7: https://docs.google.com/spreadsheets/d/1TS8YjnOCA1QWgrPJa5HzzKVS7WefPnRxDbr5XFhNQ5o/edit?gid=1350936069#gid=1350936069 | E7: 46027.68 | F7: ✅ OK
A8: FALSE
A9: FALSE
A10: FALSE
A11: FALSE
A12: FALSE
A13: FALSE
A14: FALSE
A15: FALSE
A16: FALSE
A17: FALSE
A18: FALSE
A19: FALSE

Sheet MstAutoPlayerSequence
A1: シート名 | B1: id | C1: sequence_set_id | D1: sequence_group_id | E1: sequence_element_id | F1: priority_sequence_element_id | G1: condition_type | H1: condition_value | I1: action_type | J1: action_value | K1: action_value2 | L1: summon_count | M1: summon_interval | N1: summon_animation_type | O1: summon_position | P1: move_start_condition_type | Q1: move_start_condition_value | R1: move_stop_condition_type | S1: move_stop_condition_value | T1: move_restart_condition_type | U1: move_restart_condition_value | V1: move_loop_count | W1: is_summon_unit_outpost_damage_invalidation | X1: last_boss_trigger | Y1: aura_type | Z1: death_type | AA1: enemy_hp_coef | AB1: enemy_attack_coef | AC1: enemy_speed_coef | AD1: override_drop_battle_point | AE1: defeated_score | AF1: action_delay | AG1: deactivation_condition_type | AH1: deactivation_condition_value | AI1: release_key
A2: 6話 | C2: event_jig1_charaget01_00006 | E2: 1 | G2: ElapsedTime | H2: 500 | I2: SummonEnemy | J2: e_jig_00601_jig1_charaget01_Boss_Colorless | L2: 1 | M2: 0 | N2: None | P2: None | R2: None | T2: None | W2: TRUE | Y2: Default | Z2: Normal | AA2: 15 | AB2: 4.5 | AC2: 1 | AD2: 200 | AE2: 0 | AG2: None | AI2: 202601010
A3: 6話 | C3: event_jig1_charaget01_00006 | E3: 2 | G3: ElapsedTime | H3: 3500 | I3: SummonEnemy | J3: e_jig_00301_jig1_charaget01_Normal_Green | L3: 2 | M3: 2000 | N3: None | P3: None | R3: None | T3: None | W3: FALSE | Y3: Default | Z3: Normal | AA3: 30 | AB3: 3 | AC3: 1 | AD3: 100 | AE3: 0 | AG3: None | AI3: 202601010
A4: 6話 | C4: event_jig1_charaget01_00006 | E4: 3 | G4: ElapsedTime | H4: 2000 | I4: SummonEnemy | J4: e_jig_00001_jig1_charaget01_Normal_Colorless | L4: 2 | M4: 2000 | N4: None | P4: None | R4: None | T4: None | W4: FALSE | Y4: Default | Z4: Normal | AA4: 80 | AB4: 1.5 | AC4: 1 | AD4: 50 | AE4: 0 | AG4: None | AI4: 202601010
A5: 6話 | C5: event_jig1_charaget01_00006 | E5: 4 | G5: ElapsedTime | H5: 800 | I5: SummonEnemy | J5: e_jig_00401_jig1_charaget01_Normal_Green | L5: 2 | M5: 50 | N5: None | P5: None | R5: None | T5: None | W5: FALSE | Y5: Default | Z5: Normal | AA5: 10 | AB5: 2 | AC5: 1 | AD5: 100 | AE5: 0 | AG5: None | AI5: 202601010
A6: 6話 | C6: event_jig1_charaget01_00006 | E6: 5 | G6: ElapsedTime | H6: 200 | I6: SummonEnemy | J6: e_jig_00402_jig1_charaget01_Normal_Colorless | L6: 1 | M6: 50 | N6: None | P6: None | R6: None | T6: None | W6: FALSE | Y6: Default | Z6: Normal | AA6: 40 | AB6: 1 | AC6: 1 | AD6: 100 | AE6: 0 | AG6: None | AI6: 202601010
A7: 6話 | C7: event_jig1_charaget01_00006 | E7: 6 | G7: ElapsedTime | H7: 2700 | I7: SummonEnemy | J7: e_jig_00401_jig1_charaget01_Normal_Green | L7: 3 | M7: 50 | N7: None | P7: None | R7: None | T7: None | W7: FALSE | Y7: Default | Z7: Normal | AA7: 10 | AB7: 2 | AC7: 1 | AD7: 50 | AE7: 0 | AG7: None | AI7: 202601010
A8: 6話 | C8: event_jig1_charaget01_00006 | E8: 7 | G8: ElapsedTime | H8: 3500 | I8: SummonEnemy | J8: e_jig_00402_jig1_charaget01_Normal_Colorless | L8: 3 | M8: 50 | N8: None | P8: None | R8: None | T8: None | W8: FALSE | Y8: Default | Z8: Normal | AA8: 40 | AB8: 1 | AC8: 1 | AD8: 50 | AE8: 0 | AG8: None | AI8: 202601010
A9: 6話 | C9: event_jig1_charaget01_00006 | E9: 8 | G9: ElapsedTime | H9: 4500 | I9: SummonEnemy | J9: e_jig_00401_jig1_charaget01_Normal_Green | L9: 10 | M9: 500 | N9: None | P9: None | R9: None | T9: None | W9: FALSE | Y9: Default | Z9: Normal | AA9: 10 | AB9: 2 | AC9: 1 | AD9: 50 | AE9: 0 | AG9: None | AI9: 202601010
A10: 5話 | C10: event_jig1_charaget01_00005 | E10: 1 | G10: InitialSummon | H10: 0 | I10: SummonEnemy | J10: e_jig_00601_jig1_charaget01_Boss_Colorless | L10: 1 | M10: 0 | N10: None | O10: 0.7 | P10: Damage | Q10: 1 | R10: None | T10: None | W10: TRUE | Y10: Default | Z10: Normal | AA10: 12 | AB10: 4.5 | AC10: 1 | AD10: 200 | AE10: 0 | AG10: None | AI10: 202601010
A11: 5話 | C11: event_jig1_charaget01_00005 | E11: 2 | G11: ElapsedTime | H11: 2500 | I11: SummonEnemy | J11: e_jig_00301_jig1_charaget01_Normal_Green | L11: 2 | M11: 2000 | N11: None | P11: None | R11: None | T11: None | W11: FALSE | Y11: Default | Z11: Normal | AA11: 23 | AB11: 3 | AC11: 1 | AD11: 100 | AE11: 0 | AG11: None | AI11: 202601010
A12: 5話 | C12: event_jig1_charaget01_00005 | E12: 3 | G12: FriendUnitDead | H12: 2 | I12: SummonEnemy | J12: e_jig_00301_jig1_charaget01_Normal_Green | L12: 1 | M12: 0 | N12: None | P12: None | R12: None | T12: None | W12: FALSE | Y12: Default | Z12: Normal | AA12: 23 | AB12: 3 | AC12: 1 | AD12: 100 | AE12: 0 | AF12: 1750 | AG12: None | AI12: 202601010
A13: 5話 | C13: event_jig1_charaget01_00005 | E13: 4 | G13: ElapsedTime | H13: 1200 | I13: SummonEnemy | J13: e_jig_00401_jig1_charaget01_Normal_Green | L13: 5 | M13: 1500 | N13: None | P13: None | R13: None | T13: None | W13: FALSE | Y13: Default | Z13: Normal | AA13: 10 | AB13: 2.5 | AC13: 1 | AD13: 100 | AE13: 0 | AG13: None | AI13: 202601010
A14: 5話 | C14: event_jig1_charaget01_00005 | E14: 5 | G14: ElapsedTime | H14: 800 | I14: SummonEnemy | J14: e_jig_00402_jig1_charaget01_Normal_Colorless | L14: 5 | M14: 800 | N14: None | P14: None | R14: None | T14: None | W14: FALSE | Y14: Default | Z14: Normal | AA14: 32 | AB14: 1.5 | AC14: 1 | AD14: 100 | AE14: 0 | AG14: None | AI14: 202601010
A15: 5話 | C15: event_jig1_charaget01_00005 | E15: 6 | G15: OutpostHpPercentage | H15: 99 | I15: SummonEnemy | J15: e_jig_00301_jig1_charaget01_Normal_Green | L15: 1 | M15: 0 | N15: None | P15: None | R15: None | T15: None | W15: FALSE | Y15: Default | Z15: Normal | AA15: 23 | AB15: 3 | AC15: 1 | AD15: 50 | AE15: 0 | AF15: 300 | AG15: None | AI15: 202601010
A16: 5話 | C16: event_jig1_charaget01_00005 | E16: 7 | G16: OutpostHpPercentage | H16: 99 | I16: SummonEnemy | J16: e_jig_00402_jig1_charaget01_Normal_Colorless | L16: 1 | M16: 0 | N16: None | P16: None | R16: None | T16: None | W16: FALSE | Y16: Default | Z16: Normal | AA16: 32 | AB16: 1.5 | AC16: 1 | AD16: 50 | AE16: 0 | AF16: 50 | AG16: None | AI16: 202601010
A17: 4話 | C17: event_jig1_charaget01_00004 | E17: 1 | G17: ElapsedTime | H17: 550 | I17: SummonEnemy | J17: c_jig_00201_jig1_charaget01_Boss_Green | L17: 1 | M17: 0 | N17: None | P17: None | R17: None | T17: None | W17: FALSE | Y17: Default | Z17: Normal | AA17: 6 | AB17: 4 | AC17: 1 | AD17: 200 | AE17: 0 | AG17: None | AI17: 202601010
A18: 4話 | C18: event_jig1_charaget01_00004 | E18: 2 | G18: ElapsedTime | H18: 200 | I18: SummonEnemy | J18: c_jig_00301_jig1_charaget01_Boss_Colorless | L18: 1 | M18: 0 | N18: None | P18: None | R18: None | T18: None | W18: FALSE | Y18: Default | Z18: Normal | AA18: 12 | AB18: 3 | AC18: 1 | AD18: 200 | AE18: 0 | AG18: None | AI18: 202601010
A19: 4話 | C19: event_jig1_charaget01_00004 | E19: 3 | G19: FriendUnitDead | H19: 1 | I19: SummonEnemy | J19: e_jig_00301_jig1_charaget01_Normal_Green | L19: 1 | M19: 0 | N19: None | P19: None | R19: None | T19: None | W19: FALSE | Y19: Default | Z19: Normal | AA19: 15 | AB19: 4 | AC19: 1 | AD19: 100 | AE19: 0 | AF19: 50 | AG19: None | AI19: 202601010
A20: 4話 | C20: event_jig1_charaget01_00004 | E20: 4 | G20: ElapsedTime | H20: 800 | I20: SummonEnemy | J20: e_jig_00401_jig1_charaget01_Normal_Green | L20: 4 | M20: 250 | N20: None | P20: None | R20: None | T20: None | W20: FALSE | Y20: Default | Z20: Normal | AA20: 1 | AB20: 2.5 | AC20: 1 | AD20: 50 | AE20: 0 | AG20: None | AI20: 202601010
A21: 4話 | C21: event_jig1_charaget01_00004 | E21: 5 | G21: FriendUnitDead | H21: 2 | I21: SummonEnemy | J21: e_jig_00402_jig1_charaget01_Normal_Colorless | L21: 2 | M21: 50 | N21: None | P21: None | R21: None | T21: None | W21: FALSE | Y21: Default | Z21: Normal | AA21: 30 | AB21: 1.5 | AC21: 1 | AD21: 50 | AE21: 0 | AF21: 50 | AG21: None | AI21: 202601010
A22: 3話 | C22: event_jig1_charaget01_00003 | E22: 1 | G22: EnterTargetKomaIndex | H22: 1 | I22: SummonEnemy | J22: c_jig_00001_jig1_charaget01_Boss_Yellow | L22: 1 | M22: 0 | N22: None | P22: None | R22: None | T22: None | W22: FALSE | Y22: Default | Z22: Normal | AA22: 4 | AB22: 2 | AC22: 1 | AD22: 200 | AE22: 0 | AF22: 50 | AG22: None | AI22: 202601010
A23: 3話 | C23: event_jig1_charaget01_00003 | E23: 2 | G23: EnterTargetKomaIndex | H23: 1 | I23: SummonEnemy | J23: c_jig_00101_jig1_charaget01_Boss_Yellow | L23: 1 | M23: 0 | N23: None | P23: None | R23: None | T23: None | W23: FALSE | Y23: Default | Z23: Normal | AA23: 3 | AB23: 3 | AC23: 1 | AD23: 200 | AE23: 0 | AF23: 300 | AG23: None | AI23: 202601010
A24: 3話 | C24: event_jig1_charaget01_00003 | E24: 3 | G24: InitialSummon | H24: 1 | I24: SummonEnemy | J24: e_jig_00402_jig1_charaget01_Normal_Colorless | L24: 1 | M24: 0 | N24: None | O24: 1.7 | P24: EnterTargetKoma | Q24: 1 | R24: None | T24: None | W24: FALSE | Y24: Default | Z24: Normal | AA24: 20 | AB24: 0.8 | AC24: 1 | AD24: 50 | AE24: 0 | AG24: None | AI24: 202601010
A25: 3話 | C25: event_jig1_charaget01_00003 | E25: 4 | G25: FriendUnitDead | H25: 3 | I25: SummonEnemy | J25: e_jig_00402_jig1_charaget01_Normal_Colorless | L25: 2 | M25: 50 | N25: None | P25: None | R25: None | T25: None | W25: FALSE | Y25: Default | Z25: Normal | AA25: 20 | AB25: 0.8 | AC25: 1 | AD25: 50 | AE25: 0 | AG25: None | AI25: 202601010
A26: 3話 | C26: event_jig1_charaget01_00003 | E26: 5 | G26: ElapsedTime | H26: 1500 | I26: SummonEnemy | J26: e_jig_00402_jig1_charaget01_Normal_Colorless | L26: 1 | M26: 0 | N26: None | P26: None | R26: None | T26: None | W26: FALSE | Y26: Default | Z26: Normal | AA26: 20 | AB26: 0.8 | AC26: 1 | AD26: 50 | AE26: 0 | AG26: None | AI26: 202601010
A27: 3話 | C27: event_jig1_charaget01_00003 | E27: 6 | G27: FriendUnitDead | H27: 2 | I27: SummonEnemy | J27: e_jig_00402_jig1_charaget01_Normal_Colorless | L27: 3 | M27: 1000 | N27: None | P27: None | R27: None | T27: None | W27: FALSE | Y27: Default | Z27: Normal | AA27: 20 | AB27: 0.8 | AC27: 1 | AD27: 50 | AE27: 0 | AF27: 50 | AG27: None | AI27: 202601010
A28: 2話 | C28: event_jig1_charaget01_00002 | E28: 1 | G28: FriendUnitDead | H28: 3 | I28: SummonEnemy | J28: c_jig_00101_jig1_charaget01_Boss_Yellow | L28: 1 | M28: 0 | N28: None | P28: None | R28: None | T28: None | W28: FALSE | Y28: Default | Z28: Normal | AA28: 2.5 | AB28: 3 | AC28: 1 | AD28: 200 | AE28: 0 | AF28: 50 | AG28: None | AI28: 202601010
A29: 2話 | C29: event_jig1_charaget01_00002 | E29: 2 | G29: InitialSummon | H29: 0 | I29: SummonEnemy | J29: e_jig_00501_jig1_charaget01_Boss_Colorless | L29: 1 | M29: 0 | N29: None | O29: 1.4 | P29: EnterTargetKoma | Q29: 1 | R29: None | T29: None | W29: FALSE | Y29: Default | Z29: Normal | AA29: 9 | AB29: 0.8 | AC29: 1 | AD29: 200 | AE29: 0 | AG29: None | AI29: 202601010
A30: 2話 | C30: event_jig1_charaget01_00002 | E30: 3 | G30: ElapsedTime | H30: 250 | I30: SummonEnemy | J30: e_jig_00401_jig1_charaget01_Normal_Green | L30: 2 | M30: 50 | N30: None | P30: None | R30: None | T30: None | W30: FALSE | Y30: Default | Z30: Normal | AA30: 5 | AB30: 0.5 | AC30: 1 | AD30: 75 | AE30: 0 | AG30: None | AI30: 202601010
A31: 2話 | C31: event_jig1_charaget01_00002 | E31: 4 | G31: ElapsedTime | H31: 1700 | I31: SummonEnemy | J31: e_jig_00401_jig1_charaget01_Normal_Green | L31: 2 | M31: 50 | N31: None | P31: None | R31: None | T31: None | W31: FALSE | Y31: Default | Z31: Normal | AA31: 5 | AB31: 0.5 | AC31: 1 | AD31: 75 | AE31: 0 | AG31: None | AI31: 202601010
A32: 2話 | C32: event_jig1_charaget01_00002 | E32: 5 | G32: ElapsedTime | H32: 2200 | I32: SummonEnemy | J32: e_jig_00301_jig1_charaget01_Normal_Green | L32: 1 | M32: 0 | N32: None | P32: None | R32: None | T32: None | W32: FALSE | Y32: Default | Z32: Normal | AA32: 8 | AB32: 1 | AC32: 1 | AD32: 75 | AE32: 0 | AG32: None | AI32: 202601010
A33: 1話 | C33: event_jig1_charaget01_00001 | E33: 1 | G33: ElapsedTime | H33: 300 | I33: SummonEnemy | J33: e_jig_00402_jig1_charaget01_Normal_Colorless | L33: 3 | M33: 200 | N33: None | P33: None | R33: None | T33: None | W33: FALSE | Y33: Default | Z33: Normal | AA33: 1 | AB33: 0.5 | AC33: 1 | AD33: 75 | AE33: 0 | AG33: None | AI33: 202601010
A34: 1話 | C34: event_jig1_charaget01_00001 | E34: 2 | G34: FriendUnitDead | H34: 1 | I34: SummonEnemy | J34: e_jig_00402_jig1_charaget01_Normal_Colorless | L34: 2 | M34: 50 | N34: None | P34: None | R34: None | T34: None | W34: FALSE | Y34: Default | Z34: Normal | AA34: 1 | AB34: 0.5 | AC34: 1 | AD34: 75 | AE34: 0 | AF34: 250 | AG34: None | AI34: 202601010
A35: 1話 | C35: event_jig1_charaget01_00001 | E35: 3 | G35: OutpostHpPercentage | H35: 99 | I35: SummonEnemy | J35: e_jig_00402_jig1_charaget01_Normal_Colorless | L35: 2 | M35: 50 | N35: None | P35: None | R35: None | T35: None | W35: FALSE | Y35: Default | Z35: Normal | AA35: 1 | AB35: 0.5 | AC35: 1 | AD35: 75 | AE35: 0 | AG35: None | AI35: 202601010
A36: 1話 | C36: event_jig1_charaget01_00001 | E36: 4 | G36: ElapsedTime | H36: 350 | I36: SummonEnemy | J36: e_jig_00401_jig1_charaget01_Normal_Green | L36: 2 | M36: 50 | N36: None | P36: None | R36: None | T36: None | W36: FALSE | Y36: Default | Z36: Normal | AA36: 6 | AB36: 2 | AC36: 1 | AD36: 100 | AE36: 0 | AG36: None | AI36: 202601010
A37: 1話 | C37: event_jig1_charaget01_00001 | E37: 5 | G37: ElapsedTime | H37: 99 | I37: SummonEnemy | J37: e_jig_00401_jig1_charaget01_Normal_Green | L37: 1 | M37: 50 | N37: None | P37: None | R37: None | T37: None | W37: FALSE | Y37: Default | Z37: Normal | AA37: 6 | AB37: 2 | AC37: 1 | AD37: 100 | AE37: 0 | AG37: None | AI37: 202601010

Sheet master_config
A1: master名 | B1: startRow | C1: startCol
A2: MstAutoPlayerSequence | B2: 3 | C2: 2

Sheet マッピング設定シート_new
A1: 項目名 | B1: 方向 | C1: マスター名 | D1: チェック無視 | E1: マスター列名 | F1: ユニークキー | G1: 展開タイプ | H1: 空白無視
B2: ▼ | C2: MstAutoPlayerSequence | D2: TRUE | E2: id | F2: TRUE | G2: 通常 | H2: TRUE
A3: 敵ゲートID | B3: ▼ | C3: MstAutoPlayerSequence | D3: FALSE | E3: sequence_set_id | G3: 下方継承 | H3: FALSE
A4: sequence_group_id | B4: ▼ | C4: MstAutoPlayerSequence | D4: FALSE | E4: sequence_group_id | G4: 通常 | H4: FALSE
A5: sequence_element_id | B5: ▼ | C5: MstAutoPlayerSequence | D5: FALSE | E5: sequence_element_id | F5: TRUE | G5: 通常 | H5: TRUE
A6: priority_sequence_element_id | B6: ▼ | C6: MstAutoPlayerSequence | D6: FALSE | E6: priority_sequence_element_id | G6: 通常 | H6: FALSE
A7: condition_type | B7: ▼ | C7: MstAutoPlayerSequence | D7: FALSE | E7: condition_type | G7: 通常 | H7: FALSE
A8: condition_value | B8: ▼ | C8: MstAutoPlayerSequence | D8: FALSE | E8: condition_value | G8: 通常 | H8: FALSE
A9: action_type | B9: ▼ | C9: MstAutoPlayerSequence | D9: FALSE | E9: action_type | G9: 通常 | H9: FALSE
A10: action_value | B10: ▼ | C10: MstAutoPlayerSequence | D10: FALSE | E10: action_value | G10: 通常 | H10: FALSE
A11: action_value2 | B11: ▼ | C11: MstAutoPlayerSequence | D11: FALSE | E11: action_value2 | G11: 通常 | H11: FALSE
A12: summon_count | B12: ▼ | C12: MstAutoPlayerSequence | D12: FALSE | E12: summon_count | G12: 通常 | H12: FALSE
A13: summon_interval | B13: ▼ | C13: MstAutoPlayerSequence | D13: FALSE | E13: summon_interval | G13: 通常 | H13: FALSE
A14: summon_animation_type | B14: ▼ | C14: MstAutoPlayerSequence | D14: FALSE | E14: summon_animation_type | G14: 通常 | H14: FALSE
A15: summon_position | B15: ▼ | C15: MstAutoPlayerSequence | D15: FALSE | E15: summon_position | G15: 通常 | H15: FALSE
A16: move_start_condition_type | B16: ▼ | C16: MstAutoPlayerSequence | D16: FALSE | E16: move_start_condition_type | G16: 通常 | H16: FALSE
A17: move_start_condition_value | B17: ▼ | C17: MstAutoPlayerSequence | D17: FALSE | E17: move_start_condition_value | G17: 通常 | H17: FALSE
... A35: リリースキー | B35: ▼ | C35: MstAutoPlayerSequence | D35: FALSE | E35: release_key | G35: 下方継承 | H35: FALSE

Sheet ステージ概要
B2: 作成開始日 | E2: 担当者 | P2: クエストフレーバーテキスト（最大18文字×8行） | AA2: 文字数
B3: 46000 | E3: 前田 | AA3: =len(P3)
AA4: =len(P4)
AA5: =len(P5)
B6: クエスト名 | E6: =iferror(VLOOKUP(E7,'クエストID_管理'!F:G,2,false),"クエストIDを入力してください,又はクエストID_管理シートの関数を有効化してください") | AA6: =len(P6)
B7: クエストID | E7: quest_event_jig1_charaget01 | AA7: =len(P7)
B8: クエスト種類 | E8: イベントクエスト | AA8: =len(P8)
B9: リリースキー | E9: 202601010 | AA9: =len(P9)
AA10: =len(P10)
P11: ※!（エクスクラメーションマーク）は半角で
B12: 開催期間
B13: 開始日時 | D13: 46038 | G13: 15:00:00 | J13: から
B14: 終了日時 | D14: 46069 | G14: 10:59:59 | J14: 終了
B16: クエストトップ表示キャラID | E16: キャラ名 | H16: セリフ1 | K16: セリフ2 | N16: セリフ3
B17: chara_jig_00701 | E17: メイ | H17: モウ一度ダケ… 会イタイ | K17: 手打ち | N17: 手打ち
E18: error | H18: 手打ち | K18: 手打ち | N18: 手打ち
E19: error | H19: 手打ち | K19: 手打ち | N19: 手打ち

Sheet 早見表
B1: 元シート | C1: GLOW_クエストレギュレーション
B2: 推奨PTLv | C2: 難易度 | D2: 雑魚HP RPG系 | G2: 雑魚ATK※バフ考慮外 | J2: ボスHP | M2: ボスATK※バフ考慮外 | P2: ゲートHP | Q2: 備考
D3: ディフェンス | E3: アタック / テクニカル | F3: サポート | G3: ディフェンス | H3: アタック / テクニカル | I3: サポート | J3: ディフェンス | K3: アタック / テクニカル | L3: サポート | M3: ディフェンス | N3: アタック / テクニカル | O3: サポート | P3: 各ステージ毎に調整
B4: Lv1~/星1 | C4: Normal 1 | D4: 5600 | E4: 1050 | F4: 2450 | G4: 21 | H4: 70 | I4: 35 | J4: 56000 | K4: 10500 | L4: 24500 | M4: 56 | N4: 140 | O4: 84 | P4: 5000
B5: Lv2~/星1 | C5: Normal 2 | D5: 6300 | E5: 1400 | F5: 2800 | G5: 28 | H5: 84 | I5: 49 | J5: 63000 | K5: 14000 | L5: 28000 | M5: 56 | N5: 140 | O5: 84 | P5: 5000
B6: Lv3~/星1 | C6: Normal 3 | D6: 7000 | E6: 2450 | F6: 3150 | G6: 49 | H6: 119 | I6: 70 | J6: 70000 | K6: 24500 | L6: 31500 | M6: 84 | N6: 175 | O6: 105 | P6: 5000
B7: Lv5~/星1 | C7: Normal 4 | D7: 8400 | E7: 3150 | F7: 3500 | G7: 70 | H7: 140 | I7: 91 | J7: 84000 | K7: 31500 | L7: 35000 | M7: 84 | N7: 175 | O7: 105 | P7: 15000
B8: Lv7~/星1 | C8: Normal 5 | D8: 9800 | E8: 3850 | F8: 3850 | G8: 84 | H8: 175 | I8: 105 | J8: 98000 | K8: 38500 | L8: 38500 | M8: 98 | N8: 210 | O8: 126 | P8: 15000
B9: Lv10~/星1 | C9: Normal 6 | D9: 11900 | E9: 4900 | F9: 5600 | G9: 105 | H9: 210 | I9: 140 | J9: 119000 | K9: 49000 | L9: 56000 | M9: 119 | N9: 350 | O9: 210 | P9: 25000
B10: Lv15~/星1 | C10: Normal 7 | D10: 15400 | E10: 6650 | F10: 7000 | G10: 140 | H10: 280 | I10: 210 | J10: 154000 | K10: 66500 | L10: 70000 | M10: 140 | N10: 420 | O10: 280 | P10: 25000
B11: Lv20~/星1 | C11: Normal 8 | D11: 18900 | E11: 8400 | F11: 9100 | G11: 210 | H11: 350 | I11: 245 | J11: 189000 | K11: 84000 | L11: 91000 | M11: 210 | N11: 490 | O11: 350 | P11: 25000
B12: Lv25~/星1 | C12: Normal 9 | D12: 22400 | E12: 10150 | F12: 11900 | G12: 280 | H12: 420 | I12: 245 | J12: 224000 | K12: 101500 | L12: 119000 | M12: 280 | N12: 560 | O12: 420 | P12: 30000
B13: Lv30~/星1 | C13: Normal 10 | D13: 26600 | E13: 11900 | F13: 14700 | G13: 350 | H13: 560 | I13: 350 | J13: 266000 | K13: 119000 | L13: 147000 | M13: 350 | N13: 770 | O13: 490 | P13: 30000
B14: Lv35~/星1 | C14: Normal 11 | D14: 31500 | E14: 14000 | F14: 17500 | G14: 350 | H14: 700 | I14: 420 | J14: 315000 | K14: 140000 | L14: 175000 | M14: 420 | N14: 840 | O14: 560 | P14: 30000
B15: Lv40~/星1 | C15: Normal 12,13 Hard ~3 | D15: 38500 | E15: 16800 | F15: 20300 | G15: 420 | H15: 840 | I15: 490 | J15: 350000 | K15: 175000 | L15: 231000 | M15: 490 | N15: 980 | O15: 700 | P15: 50000
... B17: Lv50~/星1 | C17: Normal 16 Hard ~6 | D17: 49000 | E17: 21000 | F17: 26600 | G17: 490 | H17: 1120 | I17: 630 | J17: 490000 | K17: 245000 | L17: 315000 | M17: 630 | N17: 1260 | O17: 910 | P17: 50000
B18: Lv55~/星1 | D18: 56000 | E18: 24500 | F18: 30100 | G18: 490 | H18: 1260 | I18: 700 | J18: 560000 | K18: 280000 | L18: 350000 | M18: 700 | N18: 1400 | O18: 910 | P18: 50000
B19: Lv60~/星1 | C19: Hard ~9 | D19: 63000 | E19: 28000 | F19: 33600 | G19: 560 | H19: 1400 | I19: 770 | J19: 630000 | K19: 350000 | L19: 420000 | M19: 770 | N19: 1540 | O19: 1050 | P19: 75000
B20: Lv65~/星1 | D20: 70000 | E20: 31500 | F20: 37100 | G20: 560 | H20: 1540 | I20: 840 | J20: 770000 | K20: 420000 | L20: 560000 | M20: 840 | N20: 1750 | O20: 1120 | P20: 75000
B21: Lv70~/星1 | C21: Hard ~13 | D21: 77000 | E21: 35000 | F21: 43400 | G21: 630 | H21: 1680 | I21: 910 | J21: 980000 | K21: 560000 | L21: 700000 | M21: 910 | N21: 1960 | O21: 1260 | P21: 75000
B22: Lv75~/星1 | D22: 84000 | E22: 38500 | F22: 49700 | G22: 630 | H22: 1820 | I22: 980 | J22: 1190000 | K22: 700000 | L22: 910000 | M22: 980 | N22: 2170 | O22: 1260 | P22: 100000
B23: Lv80~/星1 | C23: Hard ~16 | D23: 91000 | E23: 42000 | F23: 56000 | G23: 700 | H23: 1960 | I23: 1050 | J23: 1400000 | K23: 840000 | L23: 1050000 | M23: 1120 | N23: 2380 | O23: 1400 | P23: 100000
B24: Lv60~/星3 | C24: Ex main ~5 | D24: 75600 | E24: 33600 | F24: 40320 | G24: 672 | H24: 1680 | I24: 924 | J24: 756000 | K24: 420000 | L24: 504000 | M24: 924 | N24: 1848 | O24: 1260 | P24: 150000
B25: Lv60~/星5 | C25: Ex | D25: 88200 | E25: 39200 | F25: 47040 | G25: 784 | H25: 1960 | I25: 1078 | J25: 882000 | K25: 490000 | L25: 588000 | M25: 1078 | N25: 2156 | O25: 1470 | P25: 150000
B26: Lv70~/星3 | C26: Ex main ~10 | D26: 100100 | E26: 45500 | F26: 56420 | G26: 819 | H26: 2184 | I26: 1183 | J26: 1274000 | K26: 728000 | L26: 910000 | M26: 1183 | N26: 2548 | O26: 1638 | P26: 150000
B27: Lv70~/星5 | C27: Ex | D27: 115500 | E27: 52500 | F27: 65100 | G27: 945 | H27: 2520 | I27: 1365 | J27: 1470000 | K27: 840000 | L27: 1050000 | M27: 1365 | N27: 2940 | O27: 1890 | P27: 200000
B28: Lv80~/星3 | C28: Ex main ~16 | D28: 118300 | E28: 54600 | F28: 72800 | G28: 910 | H28: 2548 | I28: 1365 | J28: 1820000 | K28: 1092000 | L28: 1365000 | M28: 1456 | N28: 3094 | O28: 1820 | P28: 200000
B29: Lv80~/星5 | C29: Ex | D29: 136500 | E29: 63000 | F29: 84000 | G29: 1050 | H29: 2940 | I29: 1575 | J29: 2100000 | K29: 1260000 | L29: 1575000 | M29: 1680 | N29: 3570 | O29: 2100 | P29: 300000
B30: any | C30: 1日1回 | J30: 210000 | M30: 21 | N30: 70 | O30: 35 | P30: 1000
B31: Lv1~/星1 | C31: ストーリー1話 | D31: 5600 | E31: 1050 | F31: 2450 | G31: 21 | H31: 70 | I31: 35 | J31: 56000 | K31: 10500 | L31: 24500 | M31: 56 | N31: 140 | O31: 84 | P31: 5000
B32: Lv3~/星1 | C32: ストーリー2話 | D32: 7000 | E32: 2450 | F32: 3150 | G32: 49 | H32: 119 | I32: 70 | J32: 70000 | K32: 24500 | L32: 31500 | M32: 84 | N32: 175 | O32: 105 | P32: 5000
B33: Lv5~/星1 | C33: ストーリー3話,4話 | D33: 8400 | E33: 3150 | F33: 3500 | G33: 70 | H33: 140 | I33: 91 | J33: 84000 | K33: 31500 | L33: 35000 | M33: 84 | N33: 175 | O33: 105 | P33: 15000
B34: Lv10~/星1 | C34: ストーリー5話,6話 | D34: 11900 | E34: 4900 | F34: 5600 | G34: 105 | H34: 210 | I34: 140 | J34: 119000 | K34: 49000 | L34: 56000 | M34: 119 | N34: 350 | O34: 210 | P34: 25000
B35: Lv15~/星1 | C35: ストーリー7話 | D35: 15400 | E35: 6650 | F35: 7000 | G35: 140 | H35: 280 | I35: 210 | J35: 154000 | K35: 6650 | L35: 70000 | M35: 140 | N35: 420 | O35: 280 | P35: 25000
B36: Lv20~/星1 | C36: ストーリー8話 | D36: 18900 | E36: 8400 | F36: 9100 | G36: 210 | H36: 350 | I36: 245 | J36: 189000 | K36: 84000 | L36: 91000 | M36: 210 | N36: 490 | O36: 350 | P36: 25000
B37: Lv30~/星1 | C37: チャレンジ1話 | D37: 26600 | E37: 11900 | F37: 14700 | G37: 350 | H37: 560 | I37: 350 | J37: 266000 | K37: 119000 | L37: 147000 | M37: 350 | N37: 770 | O37: 490 | P37: 30000
B38: Lv30~/星1 | C38: チャレンジ2話 | D38: 26600 | E38: 11900 | F38: 14700 | G38: 350 | H38: 560 | I38: 350 | J38: 266000 | K38: 119000 | L38: 147000 | M38: 350 | N38: 770 | O38: 490 | P38: 30000
B39: Lv40~/星1 | C39: チャレンジ3話 | D39: 38500 | E39: 16800 | F39: 20300 | G39: 420 | H39: 840 | I39: 490 | J39: 350000 | K39: 175000 | L39: 231000 | M39: 490 | N39: 980 | O39: 700 | P39: 50000
B40: Lv50~/星1 | C40: チャレンジ4話 | D40: 49000 | E40: 21000 | F40: 26600 | G40: 490 | H40: 1120 | I40: 630 | J40: 490000 | K40: 245000 | L40: 315000 | M40: 630 | N40: 1260 | O40: 910 | P40: 50000
B41: Lv70~/星1 | C41: 高難度ver1 1話 | D41: 77000 | E41: 35000 | F41: 43400 | G41: 630 | H41: 1680 | I41: 910 | J41: 980000 | K41: 560000 | L41: 700000 | M41: 910 | N41: 1960 | O41: 1260 | P41: 150000
...

Sheet ステージ設計▶︎

Sheet 1話
B2: ■基礎情報
B4: ステージコンセプト | S4: ステージ情報詳細
B5: 強敵楪+極楽蝶のステージ | S5: 【属性情報】 緑属性の敵が登場するので赤属性のキャラは有利に戦うこともできるぞ! さらに、無属性の敵も登場するぞ! 【ギミック情報】 毒攻撃をしてくる敵が登場するぞ! 特性で毒ダメージ軽減を持っているキャラを編成しよう! ファントムゲートにダメージを与えると出現する敵もいるぞ!
B9: ステージ名（最大20文字） | G9: 文字数 | I9: スタミナ | K9: 難易度 | N9: 推奨PTLv | Q9: 通常BGM | V9: ボスBGM
B10: 1話 | G10: =len(B10) | I10: 5 | K10: イベント全般 | N10: 10 | Q10: SSE_SBG_003_003 | V10: SSE_SBG_003_004
B12: 味方ゲートID | E12: 敵ゲートID | H12: 敵ゲートasset | K12: 敵ゲートHP | N12: リリースキー
B13: default | E13: event_jig1_charaget01_00001 | H13: event_jig_0001 | K13: 30000 | N13: 202601010
B15: ■報酬設計
B17: クリアコイン | E17: リーダーEXP | H17: 原画のかけら確率 | K17: 原画のかけら種
B18: 100 | E18: =I10*10 | H18: 1 | K18: 5,7
B20: ドロップ区分 | E20: リソースtype | G20: アイテムID | J20: アイテム名 | R20: ドロップ数 | T20: ドロップ率
B21: FirstClear | E21: Unit | G21: chara_jig_00701 | J21: メイ | R21: 1 | T21: 100
B22: FirstClear | E22: =if(J22="プリズム","FreeDiamond","Item") | G22: prism_glo_00001 | J22: プリズム | R22: 40 | T22: 100
B23: FirstClear | E23: =if(J23="プリズム","FreeDiamond","Item") | G23: Coin | J23: コイン | R23: 500 | T23: 100
B24: Random | E24: =if(J24="プリズム","FreeDiamond","Item") | G24: piece_jig_00701 | J24: メイのかけら | R24: 1 | T24: 10
E25: =if(J25="プリズム","FreeDiamond","Item") | G25: none
E26: =if(J26="プリズム","FreeDiamond","Item") | G26: none
B28: ■コマ設計
B30: 行数 | D30: 行パターンID | F30: コマ数 | H30: コマ高さ | J30: コマ幅1 | L30: コマ幅2 | N30: コマ幅3 | P30: コマ幅4 | R30: コマ背景 | U30: コマ効果1 | Z30: 効果時間 | AB30: 効果数値 | AD30: コマ効果2 | AI30: 効果時間 | AK30: 効果数値 | AM30: コマ効果3 | AR30: 効果時間 | AT30: 効果数値 | AV30: コマ効果4 | BA30: 効果時間 | BC30: 効果数値
B31: 1行目 | D31: 6 | F31: =iferror(vlookup(D31,'行パターン'!$A$2:$C61,2,false),"error") | H31: 0.55 | J31: 0.5 | L31: 0.5 | N31: none | P31: none | R31: jig_00001
B32: 2行目 | D32: 1 | F32: =iferror(vlookup(D32,'行パターン'!$A$2:$C61,2,false),"error") | H32: 0.55 | J32: 1 | L32: none | N32: none | P32: none | R32: jig_00001
B33: 3行目 | F33: =iferror(vlookup(D33,'行パターン'!$A$2:$C61,2,false)," ")
B34: 4行目 | F34: =iferror(vlookup(D34,'行パターン'!$A$2:$C61,2,false)," ")
B35: 5行目 | F35: =iferror(vlookup(D35,'行パターン'!$A$2:$C61,2,false)," ")
B37: ■Enemyシーケンス | F37: ※コピペして使用
B39: sequence _group_id | D39: sequence_ element_id | F39: priority_sequence_element_id | H39: Enemy_ID | L39: ファントム名 | P39: unit_kind | R39: 属性 | T39: ロール | V39: オーラタイプ | X39: 死亡タイプ | Z39: 必殺ワザ有無 | AB39: 体力 | AD39: 体力係数 | AF39: 攻撃力 | AH39: 攻撃係数 | AJ39: 通常攻撃F | AL39: 通常攻撃CDF | AN39: 通常攻撃DPS | AP39: 通常攻撃備考 | AT39: 必殺技内容 | AY39: 必殺発動回数 | BA39: 必殺技F(秒) | BC39: 特性 | BE39: 移動速度 | BG39: well_distance | BI39: start_range | BK39: end_range | BM39: 攻撃範囲 | BO39: KB回数 | BQ39: 撃破p | BS39: 上書き撃破p | BU39: 変身先ID | BW39: 変身条件1 | BY39: 変身条件2 | CA39: 出撃条件 condition_type | CE39: 出撃開始値 condition_value | CG39: 出撃感覚値 summon_interval | CI39: 召喚回数 summon_count | CK39: アクション遅延 action_delay | CM39: 出撃 アニメーション | CO39: 召喚pos summon_position | CQ39: 移動開始条件 move_start_condition_type | CU39: 移動開始値 condition_value | CW39: 移動停止条件 move_stop_condition_type | DA39: 移動停止値 | DC39: 移動再スタート条件 move_restart_condition_type | DG39: 移動再スタート値 | DI39: 再スタート回数 move_loop_count | DK39: ゲート無敵化 | DM39: 出現停止条件 | DQ39: 停止条件値 | DS39: 備考 | EA39: sequence_group_id | EB39: sequence_element_id | EC39: priority_sequence_element_id | ED39: condition_type | EE39: condition_value | EF39: action_type | EG39: action_value | EH39: action_value2 | EI39: summon_count | EJ39: summon_interval | EK39: summon_animation_type | EL39: summon_position | EM39: move_start_condition_type | EN39: move_start_condition_value | EO39: move_stop_condition_type | EP39: move_stop_condition_value | EQ39: move_restart_condition_type | ER39: move_restart_condition_value | ES39: move_loop_count | ET39: is_summon_unit_outpost_damage_invalidation | EV39: aura_type | EW39: death_type | EX39: enemy_hp_coef | EY39: enemy_attack_coef | EZ39: enemy_speed_coef | FA39: override_drop_battle_point | FB39: defeated_score | FC39: action_delay | FD39: deactivation_condition_type | FE39: deactivation_condition_value
D40: 1 | H40: e_jig_00402_jig1_charaget01_Normal_Colorless | L40: 極楽蝶 | P40: Normal | R40: Colorless | T40: Defense | V40: Default | X40: Normal | AB40: 1000 | AD40: 1 | AF40: 50 | AH40: 0.5 | AJ40: 105 | AL40: 200 | AN40: =iferror(AF40*(50/(AJ40+AL40)),"攻撃力に数値を入力") | AY40: - | BA40: none | BE40: 25 | BG40: 0.22 | BI40: 0 | BK40: 0.23 | BM40: 100 | BO40: 2 | BQ40: 50 | BS40: 75 | CA40: ElapsedTime | CE40: 300 | CG40: 200 | CI40: 3 | CM40: None | CQ40: None | CW40: None | DC40: None | DK40: FALSE | DM40: None | EA40: =B40 | EB40: =D40 | EC40: =F40 | ED40: =CA40 | EE40: =CE40 | EF40: ="SummonEnemy" | EG40: =H40 | EI40: =CI40 | EJ40: =CG40 | EK40: =CM40 | EL40: =CO40 | EM40: =CQ40 | EN40: =CU40 | EO40: =CW40 | EP40: =DA40 | EQ40: =DC40 | ER40: =DG40 | ES40: =DI40 | ET40: =DK40 | EV40: =V40 | EW40: =X40 | EX40: =AD40 | EY40: =AH40 | EZ40: ="1" | FA40: =BS40 | FB40: 0 | FC40: =CK40 | FD40: =DM40
D41: 2 | H41: e_jig_00402_jig1_charaget01_Normal_Colorless | L41: 極楽蝶 | P41: Normal | R41: Colorless | T41: Defense | V41: Default | X41: Normal | AB41: 1000 | AD41: 1 | AF41: 50 | AH41: 0.5 | AJ41: 105 | AL41: 200 | AN41: =iferror(AF41*(50/(AJ41+AL41)),"攻撃力に数値を入力") | AY41: - | BA41: none | BE41: 25 | BG41: 0.22 | BI41: 0 | BK41: 0.23 | BM41: 100 | BO41: 2 | BQ41: 50 | BS41: 75 | CA41: FriendUnitDead | CE41: 1 | CG41: 50 | CI41: 2 | CK41: 250 | CM41: None | CQ41: None | CW41: None | DC41: None | DK41: FALSE | DM41: None | EA41: =B41 | EB41: =D41 | EC41: =F41 | ED41: =CA41 | EE41: =CE41 | EF41: ="SummonEnemy" | EG41: =H41 | EI41: =CI41 | EJ41: =CG41 | EK41: =CM41 | EL41: =CO41 | EM41: =CQ41 | EN41: =CU41 | EO41: =CW41 | EP41: =DA41 | EQ41: =DC41 | ER41: =DG41 | ES41: =DI41 | ET41: =DK41 | EV41: =V41 | EW41: =X41 | EX41: =AD41 | EY41: =AH41 | EZ41: ="1" | FA41: =BS41 | FB41: 0 | FC41: =CK41 | FD41: =DM41
D42: 3 | H42: e_jig_00402_jig1_charaget01_Normal_Colorless | L42: 極楽蝶 | P42: Normal | R42: Colorless | T42: Defense | V42: Default | X42: Normal | AB42: 1000 | AD42: 1 | AF42: 50 | AH42: 0.5 | AJ42: 105 | AL42: 200 | AN42: =iferror(AF42*(50/(AJ42+AL42)),"攻撃力に数値を入力") | AY42: - | BA42: none | BE42: 25 | BG42: 0.22 | BI42: 0 | BK42: 0.23 | BM42: 100 | BO42: 2 | BQ42: 50 | BS42: 75 | CA42: OutpostHpPercentage | CE42: 99 | CG42: 50 | CI42: 2 | CM42: None | CQ42: None | CW42: None | DC42: None | DK42: FALSE | DM42: None | EA42: =B42 | EB42: =D42 | EC42: =F42 | ED42: =CA42 | EE42: =CE42 | EF42: ="SummonEnemy" | EG42: =H42 | EI42: =CI42 | EJ42: =CG42 | EK42: =CM42 | EL42: =CO42 | EM42: =CQ42 | EN42: =CU42 | EO42: =CW42 | EP42: =DA42 | EQ42: =DC42 | ER42: =DG42 | ES42: =DI42 | ET42: =DK42 | EV42: =V42 | EW42: =X42 | EX42: =AD42 | EY42: =AH42 | EZ42: ="1" | FA42: =BS42 | FB42: 0 | FC42: =CK42 | FD42: =DM42
D43: 4 | H43: e_jig_00401_jig1_charaget01_Normal_Green | L43: 極楽蝶 | P43: Normal | R43: Green | T43: Technical | V43: Default | X43: Normal | AB43: 6000 | AD43: 6 | AF43: 200 | AH43: 2 | AJ43: 65 | AL43: 125 | AN43: =iferror(AF43*(50/(AJ43+AL43)),"攻撃力に数値を入力") | AP43: 100%の確率で6秒間1%の毒にする | AY43: - | BA43: none | BE43: 33 | BG43: 0.24 | BI43: 0 | BK43: 0.25 | BM43: 1 | BO43: 2 | BQ43: 50 | BS43: 100 | CA43: ElapsedTime | CE43: 350 | CG43: 50 | CI43: 2 | CM43: None | CQ43: None | CW43: None | DC43: None | DK43: FALSE | DM43: None | EA43: =B43 | EB43: =D43 | EC43: =F43 | ED43: =CA43 | EE43: =CE43 | EF43: ="SummonEnemy" | EG43: =H43 | EI43: =CI43 | EJ43: =CG43 | EK43: =CM43 | EL43: =CO43 | EM43: =CQ43 | EN43: =CU43 | EO43: =CW43 | EP43: =DA43 | EQ43: =DC43 | ER43: =DG43 | ES43: =DI43 | ET43: =DK43 | EV43: =V43 | EW43: =X43 | EX43: =AD43 | EY43: =AH43 | EZ43: ="1" | FA43: =BS43 | FB43: 0 | FC43: =CK43 | FD43: =DM43
D44: 5 | H44: e_jig_00401_jig1_charaget01_Normal_Green | L44: 極楽蝶 | P44: Normal | R44: Green | T44: Technical | V44: Default | X44: Normal | AB44: 6000 | AD44: 6 | AF44: 200 | AH44: 2 | AJ44: 65 | AL44: 125 | AN44: =iferror(AF44*(50/(AJ44+AL44)),"攻撃力に数値を入力") | AP44: 100%の確率で6秒間1%の毒にする | AY44: - | BA44: none | BE44: 33 | BG44: 0.24 | BI44: 0 | BK44: 0.25 | BM44: 1 | BO44: 2 | BQ44: 50 | BS44: 100 | CA44: ElapsedTime | CE44: 99 | CG44: 50 | CI44: 1 | CM44: None | CQ44: None | CW44: None | DC44: None | DK44: FALSE | DM44: None | EA44: =B44 | EB44: =D44 | EC44: =F44 | ED44: =CA44 | EE44: =CE44 | EF44: ="SummonEnemy" | EG44: =H44 | EI44: =CI44 | EJ44: =CG44 | EK44: =CM44 | EL44: =CO44 | EM44: =CQ44 | EN44: =CU44 | EO44: =CW44 | EP44: =DA44 | EQ44: =DC44 | ER44: =DG44 | ES44: =DI44 | ET44: =DK44 | EV44: =V44 | EW44: =X44 | EX44: =AD44 | EY44: =AH44 | EZ44: ="1" | FA44: =BS44 | FB44: 0 | FC44: =CK44 | FD44: =DM44
L45: none | P45: none | R45: none | T45: none | V45: Default | X45: Normal | AB45: none | AD45: 1 | AF45: none | AH45: 1 | AJ45: none | AL45: none | AN45: =iferror(AF45*(50/(AJ45+AL45)),"攻撃力に数値を入力") | AP45: none | AT45: none | AY45: none | BA45: none | BC45: none | BE45: none | BG45: none | BI45: none | BK45: none | BM45: none | BO45: none | BQ45: none | CA45: 未入力 | CM45: None | CQ45: None | CW45: None | DC45: None | DK45: FALSE | DM45: None | EA45: =B45 | EB45: =D45 | EC45: =F45 | ED45: =CA45 | EE45: =CE45 | EF45: ="SummonEnemy" | EG45: =H45 | EI45: =CI45 | EJ45: =CG45 | EK45: =CM45 | EL45: =CO45 | EM45: =CQ45 | EN45: =CU45 | EO45: =CW45 | EP45: =DA45 | EQ45: =DC45 | ER45: =DG45 | ES45: =DI45 | ET45: =DK45 | EV45: =V45 | EW45: =X45 | EX45: =AD45 | EY45: =AH45 | EZ45: ="1" | FA45: =BS45 | FB45: 0 | FC45: =CK45 | FD45: =DM45
L46: none | P46: none | R46: none | T46: none | V46: Default | X46: Normal | AB46: none | AD46: 1 | AF46: none | AH46: 1 | AJ46: none | AL46: none | AN46: =iferror(AF46*(50/(AJ46+AL46)),"攻撃力に数値を入力") | AP46: none | AT46: none | AY46: none | BA46: none | BC46: none | BE46: none | BG46: none | BI46: none | BK46: none | BM46: none | BO46: none | BQ46: none | CA46: 未入力 | CM46: None | CQ46: None | CW46: None | DC46: None | DK46: FALSE | DM46: None | EA46: =B46 | EB46: =D46 | EC46: =F46 | ED46: =CA46 | EE46: =CE46 | EF46: ="SummonEnemy" | EG46: =H46 | EI46: =CI46 | EJ46: =CG46 | EK46: =CM46 | EL46: =CO46 | EM46: =CQ46 | EN46: =CU46 | EO46: =CW46 | EP46: =DA46 | EQ46: =DC46 | ER46: =DG46 | ES46: =DI46 | ET46: =DK46 | EV46: =V46 | EW46: =X46 | EX46: =AD46 | EY46: =AH46 | EZ46: ="1" | FA46: =BS46 | FB46: 0 | FC46: =CK46 | FD46: =DM46
L47: none | P47: none | R47: none | T47: none | V47: Default | X47: Normal | AB47: none | AD47: 1 | AF47: none | AH47: 1 | AJ47: none | AL47: none | AN47: =iferror(AF47*(50/(AJ47+AL47)),"攻撃力に数値を入力") | AP47: none | AT47: none | AY47: none | BA47: none | BC47: none | BE47: none | BG47: none | BI47: none | BK47: none | BM47: none | BO47: none | BQ47: none | CA47: 未入力 | CM47: None | CQ47: None | CW47: None | DC47: None | DK47: FALSE | DM47: None | EA47: =B47 | EB47: =D47 | EC47: =F47 | ED47: =CA47 | EE47: =CE47 | EF47: ="SummonEnemy" | EG47: =H47 | EI47: =CI47 | EJ47: =CG47 | EK47: =CM47 | EL47: =CO47 | EM47: =CQ47 | EN47: =CU47 | EO47: =CW47 | EP47: =DA47 | EQ47: =DC47 | ER47: =DG47 | ES47: =DI47 | ET47: =DK47 | EV47: =V47 | EW47: =X47 | EX47: =AD47 | EY47: =AH47 | EZ47: ="1" | FA47: =BS47 | FB47: 0 | FC47: =CK47 | FD47: =DM47
L48: none | P48: none | R48: none | T48: none | V48: Default | X48: Normal | AB48: none | AD48: 1 | AF48: none | AH48: 1 | AJ48: none | AL48: none | AN48: =iferror(AF48*(50/(AJ48+AL48)),"攻撃力に数値を入力") | AP48: none | AT48: none | AY48: none | BA48: none | BC48: none | BE48: none | BG48: none | BI48: none | BK48: none | BM48: none | BO48: none | BQ48: none | CA48: 未入力 | CM48: None | CQ48: None | CW48: None | DC48: None | DK48: FALSE | DM48: None | EA48: =B48 | EB48: =D48 | EC48: =F48 | ED48: =CA48 | EE48: =CE48 | EF48: ="SummonEnemy" | EG48: =H48 | EI48: =CI48 | EJ48: =CG48 | EK48: =CM48 | EL48: =CO48 | EM48: =CQ48 | EN48: =CU48 | EO48: =CW48 | EP48: =DA48 | EQ48: =DC48 | ER48: =DG48 | ES48: =DI48 | ET48: =DK48 | EV48: =V48 | EW48: =X48 | EX48: =AD48 | EY48: =AH48 | EZ48: ="1" | FA48: =BS48 | FB48: 0 | FC48: =CK48 | FD48: =DM48
L49: none | P49: none | R49: none | T49: none | V49: Default | X49: Normal | AB49: none | AD49: 1 | AF49: none | AH49: 1 | AJ49: none | AL49: none | AN49: =iferror(AF49*(50/(AJ49+AL49)),"攻撃力に数値を入力") | AP49: none | AT49: none | AY49: none | BA49: none | BC49: none | BE49: none | BG49: none | BI49: none | BK49: none | BM49: none | BO49: none | BQ49: none | CA49: 未入力 | CM49: None | CQ49: None | CW49: None | DC49: None | DK49: FALSE | DM49: None | EA49: =B49 | EB49: =D49 | EC49: =F49 | ED49: =CA49 | EE49: =CE49 | EF49: ="SummonEnemy" | EG49: =H49 | EI49: =CI49 | EJ49: =CG49 | EK49: =CM49 | EL49: =CO49 | EM49: =CQ49 | EN49: =CU49 | EO49: =CW49 | EP49: =DA49 | EQ49: =DC49 | ER49: =DG49 | ES49: =DI49 | ET49: =DK49 | EV49: =V49 | EW49: =X49 | EX49: =AD49 | EY49: =AH49 | EZ49: ="1" | FA49: =BS49 | FB49: 0 | FC49: =CK49 | FD49: =DM49
L50: none | P50: none | R50: none | T50: none | V50: Default | X50: Normal | AB50: none | AD50: 1 | AF50: none | AH50: 1 | AJ50: none | AL50: none | AN50: =iferror(AF50*(50/(AJ50+AL50)),"攻撃力に数値を入力") | AP50: none | AT50: none | AY50: none | BA50: none | BC50: none | BE50: none | BG50: none | BI50: none | BK50: none | BM50: none | BO50: none | BQ50: none | CA50: 未入力 | CM50: None | CQ50: None | CW50: None | DC50: None | DK50: FALSE | DM50: None | EA50: =B50 | EB50: =D50 | EC50: =F50 | ED50: =CA50 | EE50: =CE50 | EF50: ="SummonEnemy" | EG50: =H50 | EI50: =CI50 | EJ50: =CG50 | EK50: =CM50 | EL50: =CO50 | EM50: =CQ50 | EN50: =CU50 | EO50: =CW50 | EP50: =DA50 | EQ50: =DC50 | ER50: =DG50 | ES50: =DI50 | ET50: =DK50 | EV50: =V50 | EW50: =X50 | EX50: =AD50 | EY50: =AH50 | EZ50: ="1" | FA50: =BS50 | FB50: 0 | FC50: =CK50 | FD50: =DM50
L51: none | P51: none | R51: none | T51: none | V51: Default | X51: Normal | AB51: none | AD51: 1 | AF51: none | AH51: 1 | AJ51: none | AL51: none | AN51: =iferror(AF51*(50/(AJ51+AL51)),"攻撃力に数値を入力") | AP51: none | AT51: none | AY51: none | BA51: none | BC51: none | BE51: none | BG51: none | BI51: none | BK51: none | BM51: none | BO51: none | BQ51: none | CA51: 未入力 | CM51: None | CQ51: None | CW51: None | DC51: None | DK51: FALSE | DM51: None | EA51: =B51 | EB51: =D51 | EC51: =F51 | ED51: =CA51 | EE51: =CE51 | EF51: ="SummonEnemy" | EG51: =H51 | EI51: =CI51 | EJ51: =CG51 | EK51: =CM51 | EL51: =CO51 | EM51: =CQ51 | EN51: =CU51 | EO51: =CW51 | EP51: =DA51 | EQ51: =DC51 | ER51: =DG51 | ES51: =DI51 | ET51: =DK51 | EV51: =V51 | EW51: =X51 | EX51: =AD51 | EY51: =AH51 | EZ51: ="1" | FA51: =BS51 | FB51: 0 | FC51: =CK51 | FD51: =DM51
L52: none | P52: none | R52: none | T52: none | V52: Default | X52: Normal | AB52: none | AD52: 1 | AF52: none | AH52: 1 | AJ52: none | AL52: none | AN52: =iferror(AF52*(50/(AJ52+AL52)),"攻撃力に数値を入力") | AP52: none | AT52: none | AY52: none | BA52: none | BC52: none | BE52: none | BG52: none | BI52: none | BK52: none | BM52: none | BO52: none | BQ52: none | CA52: 未入力 | CM52: None | CQ52: None | CW52: None | DC52: None | DK52: FALSE | DM52: None | EA52: =B52 | EB52: =D52 | EC52: =F52 | ED52: =CA52 | EE52: =CE52 | EF52: ="SummonEnemy" | EG52: =H52 | EI52: =CI52 | EJ52: =CG52 | EK52: =CM52 | EL52: =CO52 | EM52: =CQ52 | EN52: =CU52 | EO52: =CW52 | EP52: =DA52 | EQ52: =DC52 | ER52: =DG52 | ES52: =DI52 | ET52: =DK52 | EV52: =V52 | EW52: =X52 | EX52: =AD52 | EY52: =AH52 | EZ52: ="1" | FA52: =BS52 | FB52: 0 | FC52: =CK52 | FD52: =DM52
L53: none | P53: none | R53: none | T53: none | V53: Default | X53: Normal | AB53: none | AD53: 1 | AF53: none | AH53: 1 | AJ53: none | AL53: none | AN53: =iferror(AF53*(50/(AJ53+AL53)),"攻撃力に数値を入力") | AP53: none | AT53: none | AY53: none | BA53: none | BC53: none | BE53: none | BG53: none | BI53: none | BK53: none | BM53: none | BO53: none | BQ53: none | CA53: 未入力 | CM53: None | CQ53: None | CW53: None | DC53: None | DK53: FALSE | DM53: None | EA53: =B53 | EB53: =D53 | EC53: =F53 | ED53: =CA53 | EE53: =CE53 | EF53: ="SummonEnemy" | EG53: =H53 | EI53: =CI53 | EJ53: =CG53 | EK53: =CM53 | EL53: =CO53 | EM53: =CQ53 | EN53: =CU53 | EO53: =CW53 | EP53: =DA53 | EQ53: =DC53 | ER53: =DG53 | ES53: =DI53 | ET53: =DK53 | EV53: =V53 | EW53: =X53 | EX53: =AD53 | EY53: =AH53 | EZ53: ="1" | FA53: =BS53 | FB53: 0 | FC53: =CK53 | FD53: =DM53
...

Sheet 2話
B2: ■基礎情報
B4: ステージコンセプト | S4: ステージ情報詳細
B5: 強敵 山田浅ェ門 佐切 山田浅ェ門 源嗣 雑魚 そう神がDPS出してくる極楽蝶 | S5: 【属性情報】 黄属性の敵が登場するので緑属性のキャラは有利に戦うこともできるぞ! 緑属性の敵が登場するので赤属性のキャラは有利に戦うこともできるぞ! さらに、無属性の敵も登場するぞ! 【コマ効果情報】 突風コマが登場するぞ! 特性で突風コマ無効化を持っているキャラを編成しよう! 【ギミック情報】 毒攻撃をしてくる敵が登場するぞ! 特性で毒ダメージ軽減を持っているキャラを編成しよう!
B9: ステージ名（最大20文字） | G9: 文字数 | I9: スタミナ | K9: 難易度 | N9: 推奨PTLv | Q9: 通常BGM | V9: ボスBGM
B10: 2話 | G10: =len(B10) | I10: 5 | K10: イベント全般 | N10: 15 | Q10: SSE_SBG_003_003 | V10: SSE_SBG_003_004
B12: 味方ゲートID | E12: 敵ゲートID | H12: 敵ゲートasset | K12: 敵ゲートHP | N12: リリースキー
B13: default | E13: event_jig1_charaget01_00002 | H13: event_jig_0001 | K13: 35000 | N13: 202601010
B15: ■報酬設計
B17: クリアコイン | E17: リーダーEXP | H17: 原画のかけら確率 | K17: 原画のかけら種
B18: 100 | E18: =I10*10 | H18: 1 | K18: 11,16
B20: ドロップ区分 | E20: リソースtype | G20: アイテムID | J20: アイテム名 | R20: ドロップ数 | T20: ドロップ率
B21: FirstClear | E21: =if(J21="プリズム","FreeDiamond","item") | G21: prism_glo_00001 | J21: プリズム | R21: 40 | T21: 100
B22: FirstClear | E22: =if(J22="プリズム","FreeDiamond","Item") | G22: Coin | J22: コイン | R22: 500 | T22: 100
B23: FirstClear | E23: =if(J23="プリズム","FreeDiamond","Item") | G23: memory_chara_jig_00701 | J23: メイのメモリー | R23: 200 | T23: 100
B24: Random | E24: =if(J24="プリズム","FreeDiamond","Item") | G24: piece_jig_00701 | J24: メイのかけら | R24: 1 | T24: 20
E25: =if(J25="プリズム","FreeDiamond","Item") | G25: none
E26: =if(J26="プリズム","FreeDiamond","Item") | G26: none
B28: ■コマ設計
B30: 行数 | D30: 行パターンID | F30: コマ数 | H30: コマ高さ | J30: コマ幅1 | L30: コマ幅2 | N30: コマ幅3 | P30: コマ幅4 | R30: コマ背景 | U30: コマ効果1 | Z30: 効果時間 | AB30: 効果数値 | AD30: コマ効果2 | AI30: 効果時間 | AK30: 効果数値 | AM30: コマ効果3 | AR30: 効果時間 | AT30: 効果数値 | AV30: コマ効果4 | BA30: 効果時間 | BC30: 効果数値
B31: 1行目 | D31: 5 | F31: =iferror(vlookup(D31,'行パターン'!$A$2:$C61,2,false),"error") | H31: 0.55 | J31: 0.25 | L31: 0.75 | N31: none | P31: none | R31: jig_00002
B32: 2行目 | D32: 4 | F32: =iferror(vlookup(D32,'行パターン'!$A$2:$C61,2,false),"error") | H32: 0.55 | J32: 0.75 | L32: 0.25 | N32: none | P32: none | R32: jig_00002 | U32: Gust | Z32: 1500 | AB32: 0.5
B33: 3行目 | F33: =iferror(vlookup(D33,'行パターン'!$A$2:$C61,2,false)," ")
B34: 4行目 | F34: =iferror(vlookup(D34,'行パターン'!$A$2:$C61,2,false)," ")
B35: 5行目 | F35: =iferror(vlookup(D35,'行パターン'!$A$2:$C61,2,false)," ")
B37: ■Enemyシーケンス | F37: ※コピペして使用
B39: sequence _group_id | D39: sequence_ element_id | F39: priority_sequence_element_id | H39: Enemy_ID | L39: ファントム名 | P39: unit_kind | R39: 属性 | T39: ロール | V39: オーラタイプ | X39: 死亡タイプ | Z39: 必殺ワザ有無 | AB39: 体力 | AD39: 体力係数 | AF39: 攻撃力 | AH39: 攻撃係数 | AJ39: 通常攻撃F | AL39: 通常攻撃CDF | AN39: 通常攻撃DPS | AP39: 通常攻撃備考 | AT39: 必殺技内容 | AY39: 必殺発動回数 | BA39: 必殺技F(秒) | BC39: 特性 | BE39: 移動速度 | BG39: well_distance | BI39: start_range | BK39: end_range | BM39: 攻撃範囲 | BO39: KB回数 | BQ39: 撃破p | BS39: 上書き撃破p | BU39: 変身先ID | BW39: 変身条件1 | BY39: 変身条件2 | CA39: 出撃条件 condition_type | CE39: 出撃開始値 condition_value | CG39: 出撃感覚値 summon_interval | CI39: 召喚回数 summon_count | CK39: アクション遅延 action_delay | CM39: 出撃 アニメーション | CO39: 召喚pos summon_position | CQ39: 移動開始条件 move_start_condition_type | CU39: 移動開始値 condition_value | CW39: 移動停止条件 move_stop_condition_type | DA39: 移動停止値 | DC39: 移動再スタート条件 move_restart_condition_type | DG39: 移動再スタート値 | DI39: 再スタート回数 move_loop_count | DK39: ゲート無敵化 | DM39: 出現停止条件 | DQ39: 停止条件値 | DS39: 備考 | EA39: sequence_group_id | EB39: sequence_element_id | EC39: priority_sequence_element_id | ED39: condition_type | EE39: condition_value | EF39: action_type | EG39: action_value | EH39: action_value2 | EI39: summon_count | EJ39: summon_interval | EK39: summon_animation_type | EL39: summon_position | EM39: move_start_condition_type | EN39: move_start_condition_value | EO39: move_stop_condition_type | EP39: move_stop_condition_value | EQ39: move_restart_condition_type | ER39: move_restart_condition_value | ES39: move_loop_count | ET39: is_summon_unit_outpost_damage_invalidation | EV39: aura_type | EW39: death_type | EX39: enemy_hp_coef | EY39: enemy_attack_coef | EZ39: enemy_speed_coef | FA39: override_drop_battle_point | FB39: defeated_score | FC39: action_delay | FD39: deactivation_condition_type | FE39: deactivation_condition_value
D40: 1 | H40: c_jig_00101_jig1_charaget01_Boss_Yellow | L40: 山田浅ェ門 佐切 | P40: Boss | R40: Yellow | T40: Attack | V40: Default | X40: Normal | AB40: 25000 | AD40: 2.5 | AF40: 300 | AH40: 3 | AJ40: 75 | AL40: 75 | AN40: =iferror(AF40*(50/(AJ40+AL40)),"攻撃力に数値を入力") | AT40: 中範囲攻撃 | AY40: 6 | BA40: 125 | BE40: 34 | BG40: 0.22 | BI40: 0 | BK40: 0.23 | BM40: 1 | BO40: 2 | BQ40: 100 | BS40: 200 | CA40: FriendUnitDead | CE40: 3 | CG40: 0 | CI40: 1 | CK40: 50 | CM40: None | CQ40: None | CW40: None | DC40: None | DK40: FALSE | DM40: None | EA40: =B40 | EB40: =D40 | EC40: =F40 | ED40: =CA40 | EE40: =CE40 | EF40: ="SummonEnemy" | EG40: =H40 | EI40: =CI40 | EJ40: =CG40 | EK40: =CM40 | EL40: =CO40 | EM40: =CQ40 | EN40: =CU40 | EO40: =CW40 | EP40: =DA40 | EQ40: =DC40 | ER40: =DG40 | ES40: =DI40 | ET40: =DK40 | EV40: =V40 | EW40: =X40 | EX40: =AD40 | EY40: =AH40 | EZ40: ="1" | FA40: =BS40 | FB40: 0 | FC40: =CK40 | FD40: =DM40
D41: 2 | H41: e_jig_00501_jig1_charaget01_Boss_Colorless | L41: 山田浅ェ門 源嗣 | P41: Boss | R41: Colorless | T41: Defense | V41: Default | X41: Normal | AB41: 90000 | AD41: 9 | AF41: 80 | AH41: 0.8 | AJ41: 71.5 | AN41: =iferror(AF41*(50/(AJ41+AL41)),"攻撃力に数値を入力") | AY41: - | BA41: none | BE41: 34 | BO41: 1 | BQ41: 100 | BS41: 200 | CA41: InitialSummon | CE41: 0 | CG41: 0 | CI41: 1 | CM41: None | CO41: 1.4 | CQ41: EnterTargetKoma | CU41: 1 | CW41: None | DC41: None | DK41: FALSE | DM41: None | EA41: =B41 | EB41: =D41 | EC41: =F41 | ED41: =CA41 | EE41: =CE41 | EF41: ="SummonEnemy" | EG41: =H41 | EI41: =CI41 | EJ41: =CG41 | EK41: =CM41 | EL41: =CO41 | EM41: =CQ41 | EN41: =CU41 | EO41: =CW41 | EP41: =DA41 | EQ41: =DC41 | ER41: =DG41 | ES41: =DI41 | ET41: =DK41 | EV41: =V41 | EW41: =X41 | EX41: =AD41 | EY41: =AH41 | EZ41: ="1" | FA41: =BS41 | FB41: 0 | FC41: =CK41 | FD41: =DM41
D42: 3 | H42: e_jig_00401_jig1_charaget01_Normal_Green | L42: 極楽蝶 | P42: Normal | R42: Green | T42: Technical | V42: Default | X42: Normal | AB42: 5000 | AD42: 5 | AF42: 50 | AH42: 0.5 | AJ42: 65 | AL42: 125 | AN42: =iferror(AF42*(50/(AJ42+AL42)),"攻撃力に数値を入力") | AP42: 100%の確率で6秒間1%の毒にする | AY42: - | BA42: none | BE42: 33 | BG42: 0.24 | BI42: 0 | BK42: 0.25 | BM42: 1 | BO42: 2 | BQ42: 50 | BS42: 75 | CA42: ElapsedTime | CE42: 250 | CG42: 50 | CI42: 2 | CM42: None | CQ42: None | CW42: None | DC42: None | DK42: FALSE | DM42: None | EA42: =B42 | EB42: =D42 | EC42: =F42 | ED42: =CA42 | EE42: =CE42 | EF42: ="SummonEnemy" | EG42: =H42 | EI42: =CI42 | EJ42: =CG42 | EK42: =CM42 | EL42: =CO42 | EM42: =CQ42 | EN42: =CU42 | EO42: =CW42 | EP42: =DA42 | EQ42: =DC42 | ER42: =DG42 | ES42: =DI42 | ET42: =DK42 | EV42: =V42 | EW42: =X42 | EX42: =AD42 | EY42: =AH42 | EZ42: ="1" | FA42: =BS42 | FB42: 0 | FC42: =CK42 | FD42: =DM42
D43: 4 | H43: e_jig_00401_jig1_charaget01_Normal_Green | L43: 極楽蝶 | P43: Normal | R43: Green | T43: Technical | V43: Default | X43: Normal | AB43: 5000 | AD43: 5 | AF43: 50 | AH43: 0.5 | AJ43: 65 | AL43: 125 | AN43: =iferror(AF43*(50/(AJ43+AL43)),"攻撃力に数値を入力") | AP43: 100%の確率で6秒間1%の毒にする | AY43: - | BA43: none | BE43: 33 | BG43: 0.24 | BI43: 0 | BK43: 0.25 | BM43: 1 | BO43: 2 | BQ43: 50 | BS43: 75 | CA43: ElapsedTime | CE43: 1700 | CG43: 50 | CI43: 2 | CM43: None | CQ43: None | CW43: None | DC43: None | DK43: FALSE | DM43: None | EA43: =B43 | EB43: =D43 | EC43: =F43 | ED43: =CA43 | EE43: =CE43 | EF43: ="SummonEnemy" | EG43: =H43 | EI43: =CI43 | EJ43: =CG43 | EK43: =CM43 | EL43: =CO43 | EM43: =CQ43 | EN43: =CU43 | EO43: =CW43 | EP43: =DA43 | EQ43: =DC43 | ER43: =DG43 | ES43: =DI43 | ET43: =DK43 | EV43: =V43 | EW43: =X43 | EX43: =AD43 | EY43: =AH43 | EZ43: ="1" | FA43: =BS43 | FB43: 0 | FC43: =CK43 | FD43: =DM43
D44: 5 | H44: e_jig_00301_jig1_charaget01_Normal_Green | L44: 竈神 魚 | P44: Normal | R44: Green | T44: Attack | V44: Default | X44: Normal | AB44: 8000 | AD44: 8 | AF44: 100 | AH44: 1 | AJ44: 75 | AL44: 10 | AN44: =iferror(AF44*(50/(AJ44+AL44)),"攻撃力に数値を入力") | AY44: - | BA44: none | BE44: 37 | BG44: 0.22 | BI44: 0 | BK44: 0.23 | BM44: 1 | BO44: 4 | BQ44: 50 | BS44: 75 | CA44: ElapsedTime | CE44: 2200 | CG44: 0 | CI44: 1 | CM44: None | CQ44: None | CW44: None | DC44: None | DK44: FALSE | DM44: None | EA44: =B44 | EB44: =D44 | EC44: =F44 | ED44: =CA44 | EE44: =CE44 | EF44: ="SummonEnemy" | EG44: =H44 | EI44: =CI44 | EJ44: =CG44 | EK44: =CM44 | EL44: =CO44 | EM44: =CQ44 | EN44: =CU44 | EO44: =CW44 | EP44: =DA44 | EQ44: =DC44 | ER44: =DG44 | ES44: =DI44 | ET44: =DK44 | EV44: =V44 | EW44: =X44 | EX44: =AD44 | EY44: =AH44 | EZ44: ="1" | FA44: =BS44 | FB44: 0 | FC44: =CK44 | FD44: =DM44
L45: none | P45: none | R45: none | T45: none | V45: Default | X45: Normal | AB45: none | AD45: 1 | AF45: none | AH45: 1 | AJ45: none | AL45: none | AN45: =iferror(AF45*(50/(AJ45+AL45)),"攻撃力に数値を入力") | AP45: none | AT45: none | AY45: none | BA45: none | BC45: none | BE45: none | BG45: none | BI45: none | BK45: none | BM45: none | BO45: none | BQ45: none | CA45: 未入力 | CM45: None | CQ45: None | CW45: None | DC45: None | DK45: FALSE | DM45: None | EA45: =B45 | EB45: =D45 | EC45: =F45 | ED45: =CA45 | EE45: =CE45 | EF45: ="SummonEnemy" | EG45: =H45 | EI45: =CI45 | EJ45: =CG45 | EK45: =CM45 | EL45: =CO45 | EM45: =CQ45 | EN45: =CU45 | EO45: =CW45 | EP45: =DA45 | EQ45: =DC45 | ER45: =DG45 | ES45: =DI45 | ET45: =DK45 | EV45: =V45 | EW45: =X45 | EX45: =AD45 | EY45: =AH45 | EZ45: ="1" | FA45: =BS45 | FB45: 0 | FC45: =CK45 | FD45: =DM45
L46: none | P46: none | R46: none | T46: none | V46: Default | X46: Normal | AB46: none | AD46: 1 | AF46: none | AH46: 1 | AJ46: none | AL46: none | AN46: =iferror(AF46*(50/(AJ46+AL46)),"攻撃力に数値を入力") | AP46: none | AT46: none | AY46: none | BA46: none | BC46: none | BE46: none | BG46: none | BI46: none | BK46: none | BM46: none | BO46: none | BQ46: none | CA46: 未入力 | CM46: None | CQ46: None | CW46: None | DC46: None | DK46: FALSE | DM46: None | EA46: =B46 | EB46: =D46 | EC46: =F46 | ED46: =CA46 | EE46: =CE46 | EF46: ="SummonEnemy" | EG46: =H46 | EI46: =CI46 | EJ46: =CG46 | EK46: =CM46 | EL46: =CO46 | EM46: =CQ46 | EN46: =CU46 | EO46: =CW46 | EP46: =DA46 | EQ46: =DC46 | ER46: =DG46 | ES46: =DI46 | ET46: =DK46 | EV46: =V46 | EW46: =X46 | EX46: =AD46 | EY46: =AH46 | EZ46: ="1" | FA46: =BS46 | FB46: 0 | FC46: =CK46 | FD46: =DM46
L47: none | P47: none | R47: none | T47: none | V47: Default | X47: Normal | AB47: none | AD47: 1 | AF47: none | AH47: 1 | AJ47: none | AL47: none | AN47: =iferror(AF47*(50/(AJ47+AL47)),"攻撃力に数値を入力") | AP47: none | AT47: none | AY47: none | BA47: none | BC47: none | BE47: none | BG47: none | BI47: none | BK47: none | BM47: none | BO47: none | BQ47: none | CA47: 未入力 | CM47: None | CQ47: None | CW47: None | DC47: None | DK47: FALSE | DM47: None | EA47: =B47 | EB47: =D47 | EC47: =F47 | ED47: =CA47 | EE47: =CE47 | EF47: ="SummonEnemy" | EG47: =H47 | EI47: =CI47 | EJ47: =CG47 | EK47: =CM47 | EL47: =CO47 | EM47: =CQ47 | EN47: =CU47 | EO47: =CW47 | EP47: =DA47 | EQ47: =DC47 | ER47: =DG47 | ES47: =DI47 | ET47: =DK47 | EV47: =V47 | EW47: =X47 | EX47: =AD47 | EY47: =AH47 | EZ47: ="1" | FA47: =BS47 | FB47: 0 | FC47: =CK47 | FD47: =DM47
L48: none | P48: none | R48: none | T48: none | V48: Default | X48: Normal | AB48: none | AD48: 1 | AF48: none | AH48: 1 | AJ48: none | AL48: none | AN48: =iferror(AF48*(50/(AJ48+AL48)),"攻撃力に数値を入力") | AP48: none | AT48: none | AY48: none | BA48: none | BC48: none | BE48: none | BG48: none | BI48: none | BK48: none | BM48: none | BO48: none | BQ48: none | CA48: 未入力 | CM48: None | CQ48: None | CW48: None | DC48: None | DK48: FALSE | DM48: None | EA48: =B48 | EB48: =D48 | EC48: =F48 | ED48: =CA48 | EE48: =CE48 | EF48: ="SummonEnemy" | EG48: =H48 | EI48: =CI48 | EJ48: =CG48 | EK48: =CM48 | EL48: =CO48 | EM48: =CQ48 | EN48: =CU48 | EO48: =CW48 | EP48: =DA48 | EQ48: =DC48 | ER48: =DG48 | ES48: =DI48 | ET48: =DK48 | EV48: =V48 | EW48: =X48 | EX48: =AD48 | EY48: =AH48 | EZ48: ="1" | FA48: =BS48 | FB48: 0 | FC48: =CK48 | FD48: =DM48
L49: none | P49: none | R49: none | T49: none | V49: Default | X49: Normal | AB49: none | AD49: 1 | AF49: none | AH49: 1 | AJ49: none | AL49: none | AN49: =iferror(AF49*(50/(AJ49+AL49)),"攻撃力に数値を入力") | AP49: none | AT49: none | AY49: none | BA49: none | BC49: none | BE49: none | BG49: none | BI49: none | BK49: none | BM49: none | BO49: none | BQ49: none | CA49: 未入力 | CM49: None | CQ49: None | CW49: None | DC49: None | DK49: FALSE | DM49: None | EA49: =B49 | EB49: =D49 | EC49: =F49 | ED49: =CA49 | EE49: =CE49 | EF49: ="SummonEnemy" | EG49: =H49 | EI49: =CI49 | EJ49: =CG49 | EK49: =CM49 | EL49: =CO49 | EM49: =CQ49 | EN49: =CU49 | EO49: =CW49 | EP49: =DA49 | EQ49: =DC49 | ER49: =DG49 | ES49: =DI49 | ET49: =DK49 | EV49: =V49 | EW49: =X49 | EX49: =AD49 | EY49: =AH49 | EZ49: ="1" | FA49: =BS49 | FB49: 0 | FC49: =CK49 | FD49: =DM49
L50: none | P50: none | R50: none | T50: none | V50: Default | X50: Normal | AB50: none | AD50: 1 | AF50: none | AH50: 1 | AJ50: none | AL50: none | AN50: =iferror(AF50*(50/(AJ50+AL50)),"攻撃力に数値を入力") | AP50: none | AT50: none | AY50: none | BA50: none | BC50: none | BE50: none | BG50: none | BI50: none | BK50: none | BM50: none | BO50: none | BQ50: none | CA50: 未入力 | CM50: None | CQ50: None | CW50: None | DC50: None | DK50: FALSE | DM50: None | EA50: =B50 | EB50: =D50 | EC50: =F50 | ED50: =CA50 | EE50: =CE50 | EF50: ="SummonEnemy" | EG50: =H50 | EI50: =CI50 | EJ50: =CG50 | EK50: =CM50 | EL50: =CO50 | EM50: =CQ50 | EN50: =CU50 | EO50: =CW50 | EP50: =DA50 | EQ50: =DC50 | ER50: =DG50 | ES50: =DI50 | ET50: =DK50 | EV50: =V50 | EW50: =X50 | EX50: =AD50 | EY50: =AH50 | EZ50: ="1" | FA50: =BS50 | FB50: 0 | FC50: =CK50 | FD50: =DM50
L51: none | P51: none | R51: none | T51: none | V51: Default | X51: Normal | AB51: none | AD51: 1 | AF51: none | AH51: 1 | AJ51: none | AL51: none | AN51: =iferror(AF51*(50/(AJ51+AL51)),"攻撃力に数値を入力") | AP51: none | AT51: none | AY51: none | BA51: none | BC51: none | BE51: none | BG51: none | BI51: none | BK51: none | BM51: none | BO51: none | BQ51: none | CA51: 未入力 | CM51: None | CQ51: None | CW51: None | DC51: None | DK51: FALSE | DM51: None | EA51: =B51 | EB51: =D51 | EC51: =F51 | ED51: =CA51 | EE51: =CE51 | EF51: ="SummonEnemy" | EG51: =H51 | EI51: =CI51 | EJ51: =CG51 | EK51: =CM51 | EL51: =CO51 | EM51: =CQ51 | EN51: =CU51 | EO51: =CW51 | EP51: =DA51 | EQ51: =DC51 | ER51: =DG51 | ES51: =DI51 | ET51: =DK51 | EV51: =V51 | EW51: =X51 | EX51: =AD51 | EY51: =AH51 | EZ51: ="1" | FA51: =BS51 | FB51: 0 | FC51: =CK51 | FD51: =DM51
L52: none | P52: none | R52: none | T52: none | V52: Default | X52: Normal | AB52: none | AD52: 1 | AF52: none | AH52: 1 | AJ52: none | AL52: none | AN52: =iferror(AF52*(50/(AJ52+AL52)),"攻撃力に数値を入力") | AP52: none | AT52: none | AY52: none | BA52: none | BC52: none | BE52: none | BG52: none | BI52: none | BK52: none | BM52: none | BO52: none | BQ52: none | CA52: 未入力 | CM52: None | CQ52: None | CW52: None | DC52: None | DK52: FALSE | DM52: None | EA52: =B52 | EB52: =D52 | EC52: =F52 | ED52: =CA52 | EE52: =CE52 | EF52: ="SummonEnemy" | EG52: =H52 | EI52: =CI52 | EJ52: =CG52 | EK52: =CM52 | EL52: =CO52 | EM52: =CQ52 | EN52: =CU52 | EO52: =CW52 | EP52: =DA52 | EQ52: =DC52 | ER52: =DG52 | ES52: =DI52 | ET52: =DK52 | EV52: =V52 | EW52: =X52 | EX52: =AD52 | EY52: =AH52 | EZ52: ="1" | FA52: =BS52 | FB52: 0 | FC52: =CK52 | FD52: =DM52
L53: none | P53: none | R53: none | T53: none | V53: Default | X53: Normal | AB53: none | AD53: 1 | AF53: none | AH53: 1 | AJ53: none | AL53: none | AN53: =iferror(AF53*(50/(AJ53+AL53)),"攻撃力に数値を入力") | AP53: none | AT53: none | AY53: none | BA53: none | BC53: none | BE53: none | BG53: none | BI53: none | BK53: none | BM53: none | BO53: none | BQ53: none | CA53: 未入力 | CM53: None | CQ53: None | CW53: None | DC53: None | DK53: FALSE | DM53: None | EA53: =B53 | EB53: =D53 | EC53: =F53 | ED53: =CA53 | EE53: =CE53 | EF53: ="SummonEnemy" | EG53: =H53 | EI53: =CI53 | EJ53: =CG53 | EK53: =CM53 | EL53: =CO53 | EM53: =CQ53 | EN53: =CU53 | EO53: =CW53 | EP53: =DA53 | EQ53: =DC53 | ER53: =DG53 | ES53: =DI53 | ET53: =DK53 | EV53: =V53 | EW53: =X53 | EX53: =AD53 | EY53: =AH53 | EZ53: ="1" | FA53: =BS53 | FB53: 0 | FC53: =CK53 | FD53: =DM53
...

Sheet 3話
B2: ■基礎情報
B4: ステージコンセプト | S4: ステージ情報詳細
B5: 強敵 がらんの画眉丸 山田浅ェ門 佐切 雑魚 蝶 | S5: 【属性情報】 黄属性の敵が登場するので緑属性のキャラは有利に戦うこともできるぞ! さらに、無属性の敵も登場するぞ! 【ギミック情報】 火傷攻撃をしてくる敵が登場するぞ! 特性で火傷ダメージ軽減を持っているキャラを編成しよう! 味方がコマに侵入すると、出現する敵もいるぞ!
B9: ステージ名（最大20文字） | G9: 文字数 | I9: スタミナ | K9: 難易度 | N9: 推奨PTLv | Q9: 通常BGM | V9: ボスBGM
B10: 3話 | G10: =len(B10) | I10: 7 | K10: イベント全般 | N10: 20 | Q10: SSE_SBG_003_003 | V10: SSE_SBG_003_004
B12: 味方ゲートID | E12: 敵ゲートID | H12: 敵ゲートasset | K12: 敵ゲートHP | N12: リリースキー
B13: default | E13: event_jig1_charaget01_00003 | H13: event_jig_0001 | K13: 40000 | N13: 202601010
B15: ■報酬設計
B17: クリアコイン | E17: リーダーEXP | H17: 原画のかけら確率 | K17: 原画のかけら種
B18: 150 | E18: =I10*10 | H18: 1 | K18: 2,9,13
B20: ドロップ区分 | E20: リソースtype | G20: アイテムID | J20: アイテム名 | R20: ドロップ数 | T20: ドロップ率
B21: FirstClear | E21: =if(J21="プリズム","FreeDiamond","item") | G21: prism_glo_00001 | J21: プリズム | R21: 40 | T21: 100
B22: FirstClear | E22: =if(J22="プリズム","FreeDiamond","Item") | G22: Coin | J22: コイン | R22: 500 | T22: 100
B23: FirstClear | E23: =if(J23="プリズム","FreeDiamond","Item") | G23: memory_chara_jig_00701 | J23: メイのメモリー | R23: 300 | T23: 100
B24: Random | E24: =if(J24="プリズム","FreeDiamond","Item") | G24: piece_jig_00701 | J24: メイのかけら | R24: 2 | T24: 30
E25: =if(J25="プリズム","FreeDiamond","Item") | G25: none
E26: =if(J26="プリズム","FreeDiamond","Item") | G26: none
B28: ■コマ設計
B30: 行数 | D30: 行パターンID | F30: コマ数 | H30: コマ高さ | J30: コマ幅1 | L30: コマ幅2 | N30: コマ幅3 | P30: コマ幅4 | R30: コマ背景 | U30: コマ効果1 | Z30: 効果時間 | AB30: 効果数値 | AD30: コマ効果2 | AI30: 効果時間 | AK30: 効果数値 | AM30: コマ効果3 | AR30: 効果時間 | AT30: 効果数値 | AV30: コマ効果4 | BA30: 効果時間 | BC30: 効果数値
B31: 1行目 | D31: 1 | F31: =iferror(vlookup(D31,'行パターン'!$A$2:$C61,2,false),"error") | H31: 0.55 | J31: 1 | L31: none | N31: none | P31: none | R31: jig_00002
B32: 2行目 | D32: 6 | F32: =iferror(vlookup(D32,'行パターン'!$A$2:$C61,2,false),"error") | H32: 0.55 | J32: 0.5 | L32: 0.5 | N32: none | P32: none | R32: jig_00002
B33: 3行目 | F33: =iferror(vlookup(D33,'行パターン'!$A$2:$C61,2,false)," ")
B34: 4行目 | F34: =iferror(vlookup(D34,'行パターン'!$A$2:$C61,2,false)," ")
B35: 5行目 | F35: =iferror(vlookup(D35,'行パターン'!$A$2:$C61,2,false)," ")
B37: ■Enemyシーケンス | F37: ※コピペして使用
