Workbook

Sheet 報酬
B1: 限界チャレンジ_報酬
B3: ▼基本情報 | F3: MstAutoPlayerSequenceがやばいのでvdのmasterdataに固有で同じのを設定できるようにしたい
B4: 開始日 | C4: 46125.625 | F4: カード効果は以下を参照する
B5: 終了日 | C5: 無期限 | F5: https://docs.google.com/spreadsheets/d/1D5JYX9W2KpGQQrejkP6grv6Qds1GhjyAd6eNjJVa6eM/edit?gid=1084645352#gid=1084645352
B6: 備考 | C6: 毎月04:00にフロア到達報酬はリセット | F6: https://docs.google.com/spreadsheets/d/1D5JYX9W2KpGQQrejkP6grv6Qds1GhjyAd6eNjJVa6eM/edit?gid=1301003540#gid=1301003540
B8: ◆クリア報酬
B9: ・限界チャレンジを1回プレイし、ボスフロアがクリア扱いになる毎に報酬獲得された状態になり、リザルト画面でまとめて報酬獲得できます
B10: ▼ノーマルブロック報酬（全作品共通）
B11: クリア報酬
B12: 報酬内容 | C12: プリズム | D12: コイン
B13: 報酬数 | C13: 0 | D13: 100
B15: ランダムクリア報酬
B16: 報酬内容 | C16: プリズム | D16: コイン | E16: コイン | F16: コイン
B17: 報酬数 | C17: 0 | D17: 100 | E17: 300 | F17: 500
B18: ドロップ確率 | C18: 0 | D18: 0.6 | E18: 0.3 | F18: 0.1
B21: ▼ボスブロック報酬（全作品共通）
B22: クリア報酬
B23: 報酬内容 | C23: プリズム | D23: コイン
B24: 報酬数 | C24: 0 | D24: 500
B26: ランダムクリア報酬
B27: 報酬内容 | C27: プリズム | D27: コイン | E27: コイン | F27: コイン
B28: 報酬数 | C28: 0 | D28: 500 | E28: 750 | F28: 1000
B29: ドロップ確率 | C29: 0 | D29: 0.6 | E29: 0.3 | F29: 0.1
B32: ▼到達フロア報酬係数（作品ポイントにもクリア報酬にもかかる）
B33: 到達フロア数 | C33: 到達フロア報酬係数
B34: 1以上 | C34: 1 | D34: =1500*C34 -> 1500 | E34: =70*C34 -> 70
B35: 10以上 | C35: 1.2 | D35: =1500*C35 -> 1800 | E35: =70*C35 -> 84
B36: 20以上 | C36: 1.3 | D36: =1500*C36 -> 1950 | E36: =70*C36 -> 91
B37: 30以上 | C37: 1.5 | D37: =1500*C37 -> 2250 | E37: =70*C37 -> 105
B38: 40以上 | C38: 1.7 | D38: =1500*C38 -> 2550 | E38: =70*C38 -> 119
B39: 50以上 | C39: 2 | D39: =1500*C39 -> 3000 | E39: =70*C39 -> 140
B42: ◆到達フロア数報酬
B43: ・限界チャレンジは毎月初め04:00に実績がリセットされます。それまでの間の1ヶ月間で、あらかじめ設定されたフロア目標に到達することで報酬を獲得することができます。
B45: 到達フロア数 | C45: プリズム | D45: コイン | E45: ピックアップガシャチケット | F45: スペシャルガシャチケット | G45: メモリーフラグメント・初級 | H45: メモリーフラグメント・中級 | I45: メモリーフラグメント・上級
B46: 1 | C46: 0 | D46: 5000 | E46: 0 | F46: 0 | G46: 0 | H46: 0 | I46: 0
B47: 5 | C47: 0 | D47: 0 | E47: 0 | F47: 1 | G47: 0 | H47: 0 | I47: 0
B48: 10 | C48: 0 | D48: 10000 | E48: 0 | F48: 0 | G48: 0 | H48: 0 | I48: 0
B49: 15 | C49: 50 | D49: 0 | E49: 0 | F49: 0 | G49: 0 | H49: 0 | I49: 0
B50: 20 | C50: 0 | D50: 35000 | E50: 0 | F50: 0 | G50: 0 | H50: 0 | I50: 0
B51: 30 | C51: 100 | D51: 0 | E51: 0 | G51: 0 | H51: 0 | I51: 0
...

Sheet 交換所
B1: 限界チャレンジ_交換所
B3: ▼基本情報 | G3: ユーザーレベル | H3: 最大スタミナ
B4: 交換所名称 | C4: 限界チャレンジ交換所 | G4: 10 | H4: 63
B5: 開始日 | C5: 46125.625 | G5: 30 | H5: 94
B6: 終了日 | C6: 無期限 | G6: 50 | H6: 127
B7: 備考 | C7: 毎月04:00に交換ラインナップ上限数リセット | G7: 90 | H7: 195
G8: 100 | H8: 212
B9: ▼収集アイテム | G9: 130 | H9: 264
B10: アイテム名 | C10: 単価
B11: 「作品名」ポイント | C11: =50*7.56 -> 378 | D11: ⇦50スタミナで1ブロックでもクリアすれば、10ポイント獲得できる
B14: ▼意図・調整方針
B15: 「作品名」ポイントは、作品ブロック単位毎でその作品のポイントが獲得できる。 そのため、各作品毎の交換所も交換ラインアップは共通かつ交換レートも共通の値を使用する。 唯一違うのは、作品交換所毎で合わせて『「作品名」の表紙』がラインナップにあるので、そこだけ違う。
I16: ⇩工数でv.1.6.0間に合わないかも
B17: 獲得先 | C17: 獲得ポイント種別 | D17: 基礎ポイント数 | E17: 1回挑戦でかかる平均フロア到達数からのフロア係数の値 | F17: 1回の挑戦で到達できる平均フロア数 | G17: 1日の最大挑戦回数平均 （200スタミナを上限基準） | H17: 総獲得ポイント数 | I17: 広告視聴の報酬量2倍ボーナスを適用時
B18: その作品の通常ブロック | C18: 「作品名」ポイント | D18: 20 | E18: 1.2 | F18: 10 | G18: =200/30 -> 6.6666667 | H18: =D18*E18*F18*G18 -> 1600 | I18: =H18*2 -> 3200
B19: その作品のボスブロック | C19: 「作品名」ポイント | D19: 40 | E19: 1.2 | F19: 5 | G19: =200/30 -> 6.6666667 | H19: =D19*E19*F19*G19 -> 1600 | I19: =H19*2 -> 3200
B20: ⬆︎このコンテンツに1回挑戦するのに必要なスタミナ量が30で、時間制限は300秒
B23: ▼交換所ラインナップ（「作品の表紙」以外は全ての交換所でラインナップは共通とする）
B24: アイテム区分 | C24: アイテム名称 | D24: 1回交換につき獲得できる数 | E24: 交換上限 | F24: 1回の交換に必要なpt数 | G24: 交換所リセット期間までの1ヶ月間の最大獲得数 | H24: 交換所リセット期間までの1ヶ月間の最大獲得数を交換するのに必要なポイント数 | I24: 単価
B25: 恒常 | C25: プリズム | D25: 50 | E25: 1 | F25: 5000 | G25: =D25*E25 -> 50 | H25: =E25*F25 -> 5000 | I25: 2
B26: 恒常 | C26: 「〇〇作品名」の表紙 | D26: 1 | E26: 40 | F26: 1000 | G26: =D26*E26 -> 40 | H26: =E26*F26 -> 40000 | I26: 378
B27: 恒常 | C27: 伝説のペン | D27: 1 | E27: 10 | F27: 500 | G27: =D27*E27 -> 10 | H27: =E27*F27 -> 5000 | I27: 226.8
B28: 恒常 | C28: 魂のインク | D28: 1 | E28: 30 | F28: 300 | G28: =D28*E28 -> 30 | H28: =E28*F28 -> 9000 | I28: 151.2
B29: 恒常 | C29: 普通の原稿用紙 | D29: 1 | E29: 50 | F29: 100 | G29: =D29*E29 -> 50 | H29: =E29*F29 -> 5000 | I29: 75.6
B30: 恒常 | C30: ピックアップガシャチケット | D30: 1 | E30: 1 | F30: 10000 | G30: =D30*E30 -> 1 | H30: =E30*F30 -> 10000 | I30: 300
B31: 恒常 | C31: メモリーフラグメント・上級 | D31: 1 | E31: 1 | F31: 500 | G31: =D31*E31 -> 1 | H31: =E31*F31 -> 500 | I31: 30
B32: 恒常 | C32: メモリーフラグメント・中級 | D32: 1 | E32: 15 | F32: 300 | G32: =D32*E32 -> 15 | H32: =E32*F32 -> 4500 | I32: 15
B33: 恒常 | C33: メモリーフラグメント・初級 | D33: 1 | E33: 30 | F33: 100 | G33: =D33*E33 -> 30 | H33: =E33*F33 -> 3000 | I33: 10
B34: 恒常 | C34: カラーメモリー・グレー | D34: 5 | E34: 10 | F34: 50 | G34: =D34*E34 -> 50 | H34: =E34*F34 -> 500 | I34: 0.27
B35: 恒常 | C35: カラーメモリー・レッド | D35: 5 | E35: 10 | F35: 50 | G35: =D35*E35 -> 50 | H35: =E35*F35 -> 500 | I35: 0.27
B36: 恒常 | C36: カラーメモリー・ブルー | D36: 5 | E36: 10 | F36: 50 | G36: =D36*E36 -> 50 | H36: =E36*F36 -> 500 | I36: 0.27
... B40: 恒常 | C40: コイン | D40: 100 | E40: 150 | F40: 10 | G40: =D40*E40 -> 15000 | H40: =E40*F40 -> 1500 | I40: 0.01
H42: =SUM(H25:H40)/sum(H18:H19) -> 27.1875 | I42: =H42*16 -> 435
B43: ▼v.1.6.1リリース時に設定される交換所と作品ポイント | H43: =H42*30 -> 815.625 | I43: =H43*16 -> 13050
B44: その作品のURの原画が追加されるタイミングに合わせて交換所と作品ポイントも追加する
B45: 交換所 | C45: 作品ポイント
B46: 『SPY×FAMILY』 の作品ポイント交換所 | C46: 『SPY×FAMILY』 の作品ポイント
B47: 『ダンダダン』 の作品ポイント交換所 | C47: 『ダンダダン』 の作品ポイント
B48: 『姫様“拷問”の時間です』 の作品ポイント交換所 | C48: 『姫様“拷問”の時間です』 の作品ポイント
B49: 『チェンソーマン』 の作品ポイント交換所 | C49: 『チェンソーマン』 の作品ポイント
...

Sheet ミッション
B1: 限界チャレンジ_ミッション
B3: 項目 | C3: 内容
B4: 施策名称 | C4: 限界チャレンジ ミッション
B5: 開催期間 | C5: 46125.625 | D5: 〜 | E5: 無期限
B6: 備考 | C6: 毎月04:00に実績リセット
B8: ミッション内容/報酬カテゴリー | C8: プリズム | D8: コイン | E8: ピックアップガシャチケット | F8: スペシャルガシャチケット | G8: メモリーフラグメント・初級 | H8: メモリーフラグメント・中級 | I8: メモリーフラグメント・上級
B9: 限界チャレンジで強敵を累計1体撃破しよう | G9: 10
B10: 限界チャレンジで強敵を累計3体撃破しよう | H10: 5
B11: 限界チャレンジで強敵を累計5体撃破しよう | I11: 1
B12: 限界チャレンジで強敵を累計10体撃破しよう | E12: 1
B13: 限界チャレンジで累計10フロア到達しよう | D13: 5000
B14: 限界チャレンジで累計20フロア到達しよう | D14: 10000
B15: 限界チャレンジで累計30フロア到達しよう | D15: 15000
B16: 限界チャレンジで累計40フロア到達しよう | D16: 20000
B17: 限界チャレンジで累計50フロア到達しよう | D17: 25000
B18: 限界チャレンジで『SPY×FAMILY』作品の強敵を1体撃破しよう | C18: 20
B19: 限界チャレンジで『ダンダダン』作品の強敵を1体撃破しよう | C19: 20
B20: 限界チャレンジで『姫様“拷問”の時間です』作品の強敵を1体撃破しよう | C20: 20
B21: 限界チャレンジで『チェンソーマン』作品の強敵を1体撃破しよう | C21: 20
B22: 限界チャレンジで『株式会社マジルミエ』作品の強敵を1体撃破しよう | C22: 20
B23: 限界チャレンジで『怪獣８号』作品の強敵を1体撃破しよう | C23: 20
B24: 限界チャレンジで『2.5次元の誘惑』作品の強敵を1体撃破しよう | C24: 20
B25: 限界チャレンジで『魔都精兵のスレイブ』作品の強敵を1体撃破しよう | C25: 20
B26: 限界チャレンジで『サマータイムレンダ』作品の強敵を1体撃破しよう | C26: 20
B27: 限界チャレンジで『地獄楽』作品の強敵を1体撃破しよう | C27: 20
B28: 限界チャレンジで『タコピーの原罪』作品の強敵を1体撃破しよう | C28: 20
B29: 限界チャレンジで『【推しの子】』作品の強敵を1体撃破しよう | C29: 20
... B32: 限界チャレンジで『ふつうの軽音部』作品の強敵を1体撃破しよう | C32: 20
B34: 報酬合計数 | C34: =sum(C9:C32) -> 300 | D34: =sum(D9:D32) -> 75000 | E34: =sum(E9:E32) -> 1 | F34: =sum(F9:F32) -> 0 | G34: =sum(G9:G32) -> 10 | H34: =sum(H9:H32) -> 5 | I34: =sum(I9:I32) -> 1

Sheet インゲームその他設定
B1: 限界チャレンジ_報酬
B3: ▼基本情報 | F3: MstAutoPlayerSequenceがやばいのでvdのmasterdataに固有で同じのを設定できるようにしたい
B4: 開始日 | C4: 46125.625 | F4: カード効果は以下を参照する
B5: 終了日 | C5: 無期限 | F5: https://docs.google.com/spreadsheets/d/1D5JYX9W2KpGQQrejkP6grv6Qds1GhjyAd6eNjJVa6eM/edit?gid=1084645352#gid=1084645352
F6: https://docs.google.com/spreadsheets/d/1D5JYX9W2KpGQQrejkP6grv6Qds1GhjyAd6eNjJVa6eM/edit?gid=1301003540#gid=1301003540
B8: ◆カード効果
B9: ・限界チャレンジを1回プレイし、ボスフロアがクリア扱いになる毎に報酬獲得された状態になり、リザルト画面でまとめて報酬獲得できます
B10: ▼ノーマルブロック ・ルーレットゲージが溜まった時にルーレットを回し、カード効果をランダムに1枚獲得できる。 ・バトル中に一定確率で登場するレアファントムを撃破することで、ルーレットゲージのルーレットを回し、カード効果をランダムに1枚獲得できる。 ・カード効果は到達フロアの進捗数に応じて効果内容が強くなる（5フロア目で獲得できるカード効果は攻撃10%UPぐらいだが10フロア目だと20%の効果を得られるなど）。
B12: ▼到達フロア報酬係数
B13: 到達フロア数 | C13: 効果内容
B14: 1以上
B20: 10以上
B21: 20以上
B22: 30以上
B23: 40以上
B24: 50以上
B27: ◆敵ステータス変更フロア係数
B28: ・限界チャレンジは一定数のフロアに到達すると敵のステータス（攻撃と体力）に係数がかかり、登場する敵が強くなります。
B29: ▼フロアステータス係数 | E29: ▼基本ステータス数値
B30: 到達フロア数 | C30: 到達フロア報酬係数 | E30: キャラ種別/ステータス | F30: 攻撃 | G30: 体力
B31: 1以上 | C31: 1 | E31: 雑魚1体 | F31: 5000 | G31: 1000
B32: 5以上 | C32: 1.2 | E32: ボス1体 | F32: 20000 | G32: 10000
B33: 10以上 | C33: 1.4
B34: 20以上 | C34: 1.6
B35: 30以上 | C35: 1.8
B36: 40以上 | C36: 2
B37: 50以上 | C37: 2.5

Sheet 通常ブロック
B1: 通常ブロック_SPY×FAMILY
B3: ■基礎情報
B5: ステージコンセプト
B6: 雑魚敵はSPY×FAMILYの敵を使用する。 雑魚は体力は1000ほど、攻撃は5000、移動速度は、少し速い、必殺ワザの使用はなし。 ゴールドファントムの登場確率は1体のみ出現し、一律10%の確率で登場する。
B10: BGM
B11: ファイル名
E12: ⇩チュートリアルの敵原画固定 | K12: ⇩100固定
B13: 味方ゲートID | E13: 敵ゲートID | H13: 敵ゲートasset | K13: 敵ゲートHP | N13: リリースキー
B14: default | E14: 入力してね | H14: 入力してね | K14: 100 | N14: 入力してね
B16: ■コマ設計
B18: 行数 | D18: 行パターンID | F18: コマ数 | H18: コマ高さ | J18: コマ幅1 | L18: コマ幅2 | N18: コマ幅3 | P18: コマ幅4 | U18: コマ効果1 | Z18: 効果時間 | AB18: 効果数値 | AD18: コマ効果2 | AI18: 効果時間 | AK18: 効果数値 | AM18: コマ効果3 | AR18: 効果時間 | AT18: 効果数値 | AV18: コマ効果4 | BA18: 効果時間 | BC18: 効果数値
B19: 1行目 | D19: 1 | F19: =iferror(vlookup(D19,'行パターン'!$A$2:$C48,2,false),"error") -> error | H19: 0.55 | J19: =iferror(INDEX('行パターン'!D:D,MATCH(D19,'行パターン'!A:A,0),0),"error") -> error | L19: =iferror(if(sum(J19)=1,"none",INDEX('行パターン'!E:E,MATCH($D19,'行パターン'!$A:$A,0),0)),"") | N19: =iferror(if(sum(J19:M19)=1,"none",INDEX('行パターン'!F:F,MATCH($D19,'行パターン'!$A:$A,0),0)),"") | P19: =iferror(if(sum(J19:O19)=1,"none",INDEX('行パターン'!G:G,MATCH($D19,'行パターン'!$A:$A,0),0)),"")
B20: 2行目 | D20: 10 | F20: =iferror(vlookup(D20,'行パターン'!$A$2:$C49,2,false),"error") -> error | H20: 0.55 | J20: =iferror(INDEX('行パターン'!D:D,MATCH(D20,'行パターン'!A:A,0),0),"error") -> error | L20: =iferror(if(sum(J20)=1,"none",INDEX('行パターン'!E:E,MATCH($D20,'行パターン'!$A:$A,0),0)),"") | N20: =iferror(if(sum(J20:M20)=1,"none",INDEX('行パターン'!F:F,MATCH($D20,'行パターン'!$A:$A,0),0)),"") | P20: =iferror(if(sum(J20:O20)=1,"none",INDEX('行パターン'!G:G,MATCH($D20,'行パターン'!$A:$A,0),0)),"")
B21: 3行目 | F21: =iferror(vlookup(D21,'行パターン'!$A$2:$C48,2,false)," ") | J21: {=iferror(INDEX('行パターン'!D:D,MATCH(D21,'行パターン'!A:A,0),0)," ")} | L21: =iferror(if(sum(J21)=1,"none",INDEX('行パターン'!E:E,MATCH($D21,'行パターン'!$A:$A,0),0)),"") | N21: =iferror(if(sum(J21:M21)=1,"none",INDEX('行パターン'!F:F,MATCH($D21,'行パターン'!$A:$A,0),0)),"") | P21: {=iferror(if(sum(J21:O21)=1,"none",INDEX('行パターン'!H:H,MATCH($D21,'行パターン'!$A:$A,0),0)),"")}
B22: ※通常ブロックは3行(フロア)固定
B24: ■Enemyシーケンス | F24: ※コピペして使用
B26: sequence _group_id | D26: sequence_ element_id | F26: priority_sequence_element_id | H26: Enemy_ID | L26: ファントム名 | P26: unit_kind | R26: 属性 | T26: ロール | V26: オーラタイプ | X26: 死亡タイプ | Z26: 必殺ワザ有無 | AB26: 体力 | AD26: 体力係数 | AF26: 攻撃力 | AH26: 攻撃係数 | AJ26: 通常攻撃F | AL26: 通常攻撃CDF | AN26: 通常攻撃DPS | AP26: 通常攻撃備考 | AT26: 必殺技内容 | AY26: 必殺発動回数 | BA26: 必殺技F(秒) | BC26: 特性 | BE26: 移動速度 | BG26: well_distance | BI26: start_range | BK26: end_range | BM26: 攻撃範囲 | BO26: KB回数 | BQ26: 撃破p | BS26: 上書き撃破p | BU26: 変身先ID | BW26: 変身条件1 | BY26: 変身条件2 | CA26: 出撃条件 condition_type | CE26: 出撃開始値 condition_value | CG26: 出撃間隔値 summon_interval | CI26: 召喚回数 summon_count | CK26: アクション遅延 action_delay | CM26: 出撃 アニメーション | CO26: 召喚pos summon_position | CQ26: 移動開始条件 move_start_condition_type | CU26: 移動開始値 condition_value | CW26: 移動停止条件 move_stop_condition_type | DA26: 移動停止値 | DC26: 移動再スタート条件 move_restart_condition_type | DG26: 移動再スタート値 | DI26: 再スタート回数 move_loop_count | DK26: ゲート無敵化 | DM26: 出現停止条件 | DQ26: 停止条件値 | DS26: 備考 | EA26: sequence_group_id | EB26: sequence_element_id | EC26: priority_sequence_element_id | ED26: condition_type | EE26: condition_value | EF26: action_type | EG26: action_value | EH26: action_value2 | EI26: summon_count | EJ26: summon_interval | EK26: summon_animation_type | EL26: summon_position | EM26: move_start_condition_type | EN26: move_start_condition_value | EO26: move_stop_condition_type | EP26: move_stop_condition_value | EQ26: move_restart_condition_type | ER26: move_restart_condition_value | ES26: move_loop_count | ET26: is_summon_unit_outpost_damage_invalidation | EU26: last_boss_trigger | EV26: aura_type | EW26: death_type | EX26: enemy_hp_coef | EY26: enemy_attack_coef | EZ26: enemy_speed_coef | FA26: override_drop_battle_point | FB26: defeated_score | FC26: action_delay | FD26: deactivation_condition_type | FE26: deactivation_condition_value
D27: 1 | H27: c_spy_00101_general_n_Boss_Blue | L27: {=iferror(INDEX('ファントムマスター'!F:F,MATCH(H27,'ファントムマスター'!D:D,0),0),"error")} -> <黄昏> ロイド | P27: =iferror(INDEX('ファントムマスター'!H:H,MATCH(H27,'ファントムマスター'!D:D,0),0),"none") -> none | R27: =iferror(INDEX('ファントムマスター'!J:J,MATCH(H27,'ファントムマスター'!D:D,0),0),"none") -> none | T27: =iferror(INDEX('ファントムマスター'!I:I,MATCH(H27,'ファントムマスター'!D:D,0),0),"none") -> none | V27: Default | X27: Normal | AB27: =iferror(INDEX('ファントムマスター'!K:K,MATCH(H27,'ファントムマスター'!D:D,0),0)*AD27,"none") -> none | AD27: 1 | AF27: =iferror(INDEX('ファントムマスター'!O:O,MATCH(H27,'ファントムマスター'!D:D,0),0)*AH27,"none") -> none | AH27: 1 | AJ27: =iferror(right(INDEX('ファントムマスター'!T:T,MATCH(H27,'ファントムマスター'!D:D,0),0),4)*50,"none") -> none | AL27: =iferror(right(INDEX('ファントムマスター'!V:V,MATCH(H27,'ファントムマスター'!D:D,0),0),4),"none") -> none | AN27: =iferror(AF27*(50/(AJ27+AL27)),"攻撃力に数値を入力") -> 攻撃力に数値を入力 | AT27: =iferror(INDEX('ファントムマスター'!Y:Y,MATCH(H27,'ファントムマスター'!D:D,0),0),"none") -> none | AY27: =iferror(INDEX('ファントムマスター'!Z:Z,MATCH(H27,'ファントムマスター'!D:D,0),0),"none") -> none | BA27: =iferror(INDEX('ファントムマスター'!W:W,MATCH(H27,'ファントムマスター'!D:D,0),0)*50,"none") -> none | BC27: =iferror(INDEX('ファントムマスター'!AA:AA,MATCH(H27,'ファントムマスター'!D:D,0),0),"none") -> none | BE27: =iferror(INDEX('ファントムマスター'!M:M,MATCH(H27,'ファントムマスター'!D:D,0),0),"none") -> none | BG27: =iferror(INDEX('ファントムマスター'!N:N,MATCH(H27,'ファントムマスター'!D:D,0),0),"none") -> none | BI27: =iferror(INDEX('ファントムマスター'!P:P,MATCH(H27,'ファントムマスター'!D:D,0),0),"none") -> none | BK27: =iferror(INDEX('ファントムマスター'!Q:Q,MATCH(H27,'ファントムマスター'!D:D,0),0),"none") -> none | BM27: =iferror(INDEX('ファントムマスター'!R:R,MATCH(H27,'ファントムマスター'!D:D,0),0),"none") -> none | BO27: =iferror(INDEX('ファントムマスター'!L:L,MATCH(H27,'ファントムマスター'!D:D,0),0),"none") -> none | BQ27: =iferror(INDEX('ファントムマスター'!S:S,MATCH(H27,'ファントムマスター'!D:D,0),0),"none") -> none | CA27: 未入力 | CE27: 1 | CG27: 10 | CI27: 99 | CM27: None | CQ27: None | CW27: None | DC27: None | DK27: FALSE | DM27: None | EA27: =B27 | EB27: =D27 -> 1 | EC27: =F27 | ED27: =CA27 -> 未入力 | EE27: =CE27 -> 1 | EF27: ="SummonEnemy" -> SummonEnemy | EG27: =H27 -> c_spy_00101_general_n_Boss_Blue | EI27: =CI27 -> 99 | EJ27: =CG27 -> 10 | EK27: =CM27 -> None | EL27: =CO27 | EM27: =CQ27 -> None | EN27: =CU27 | EO27: =CW27 -> None | EP27: =DA27 | EQ27: =DC27 -> None | ER27: =DG27 | ES27: =DI27 | ET27: =DK27 -> FALSE | EV27: =V27 -> Default | EW27: =X27 -> Normal | EX27: =AD27 -> 1 | EY27: =AH27 -> 1 | EZ27: ="1" -> 1 | FA27: =BS27 | FB27: 0 | FC27: =CK27 | FD27: =DM27 -> None | FE27: =DQ27
L28: =iferror(INDEX('ファントムマスター'!F:F,MATCH(H28,'ファントムマスター'!D:D,0),0),"none") -> none | P28: =iferror(INDEX('ファントムマスター'!H:H,MATCH(H28,'ファントムマスター'!D:D,0),0),"none") -> none | R28: =iferror(INDEX('ファントムマスター'!J:J,MATCH(H28,'ファントムマスター'!D:D,0),0),"none") -> none | T28: =iferror(INDEX('ファントムマスター'!I:I,MATCH(H28,'ファントムマスター'!D:D,0),0),"none") -> none | V28: Default | X28: Normal | AB28: =iferror(INDEX('ファントムマスター'!K:K,MATCH(H28,'ファントムマスター'!D:D,0),0)*AD28,"none") -> none | AD28: 1 | AF28: =iferror(INDEX('ファントムマスター'!O:O,MATCH(H28,'ファントムマスター'!D:D,0),0)*AH28,"none") -> none | AH28: 1 | AJ28: =iferror(right(INDEX('ファントムマスター'!T:T,MATCH(H28,'ファントムマスター'!D:D,0),0),4)*50,"none") -> none | AL28: =iferror(right(INDEX('ファントムマスター'!V:V,MATCH(H28,'ファントムマスター'!D:D,0),0),4),"none") -> none | AN28: =iferror(AF28*(50/(AJ28+AL28)),"攻撃力に数値を入力") -> 攻撃力に数値を入力 | AT28: =iferror(INDEX('ファントムマスター'!Y:Y,MATCH(H28,'ファントムマスター'!D:D,0),0),"none") -> none | AY28: =iferror(INDEX('ファントムマスター'!Z:Z,MATCH(H28,'ファントムマスター'!D:D,0),0),"none") -> none | BA28: =iferror(INDEX('ファントムマスター'!W:W,MATCH(H28,'ファントムマスター'!D:D,0),0)*50,"none") -> none | BC28: =iferror(INDEX('ファントムマスター'!AA:AA,MATCH(H28,'ファントムマスター'!D:D,0),0),"none") -> none | BE28: =iferror(INDEX('ファントムマスター'!M:M,MATCH(H28,'ファントムマスター'!D:D,0),0),"none") -> none | BG28: =iferror(INDEX('ファントムマスター'!N:N,MATCH(H28,'ファントムマスター'!D:D,0),0),"none") -> none | BI28: =iferror(INDEX('ファントムマスター'!P:P,MATCH(H28,'ファントムマスター'!D:D,0),0),"none") -> none | BK28: =iferror(INDEX('ファントムマスター'!Q:Q,MATCH(H28,'ファントムマスター'!D:D,0),0),"none") -> none | BM28: =iferror(INDEX('ファントムマスター'!R:R,MATCH(H28,'ファントムマスター'!D:D,0),0),"none") -> none | BO28: =iferror(INDEX('ファントムマスター'!L:L,MATCH(H28,'ファントムマスター'!D:D,0),0),"none") -> none | BQ28: =iferror(INDEX('ファントムマスター'!S:S,MATCH(H28,'ファントムマスター'!D:D,0),0),"none") -> none | CA28: 未入力 | CM28: None | CQ28: None | CW28: None | DC28: None | DK28: FALSE | DM28: None | EA28: =B28 | EB28: =D28 | EC28: =F28 | ED28: =CA28 -> 未入力 | EE28: =CE28 | EF28: ="SummonEnemy" -> SummonEnemy | EG28: =H28 | EI28: =CI28 | EJ28: =CG28 | EK28: =CM28 -> None | EL28: =CO28 | EM28: =CQ28 -> None | EN28: =CU28 | EO28: =CW28 -> None | EP28: =DA28 | EQ28: =DC28 -> None | ER28: =DG28 | ES28: =DI28 | ET28: =DK28 -> FALSE | EV28: =V28 -> Default | EW28: =X28 -> Normal | EX28: =AD28 -> 1 | EY28: =AH28 -> 1 | EZ28: ="1" -> 1 | FA28: =BS28 | FB28: 0 | FC28: =CK28 | FD28: =DM28 -> None | FE28: =DQ28
L29: =iferror(INDEX('ファントムマスター'!F:F,MATCH(H29,'ファントムマスター'!D:D,0),0),"none") -> none | P29: =iferror(INDEX('ファントムマスター'!H:H,MATCH(H29,'ファントムマスター'!D:D,0),0),"none") -> none | R29: =iferror(INDEX('ファントムマスター'!J:J,MATCH(H29,'ファントムマスター'!D:D,0),0),"none") -> none | T29: =iferror(INDEX('ファントムマスター'!I:I,MATCH(H29,'ファントムマスター'!D:D,0),0),"none") -> none | V29: Default | X29: Normal | AB29: =iferror(INDEX('ファントムマスター'!K:K,MATCH(H29,'ファントムマスター'!D:D,0),0)*AD29,"none") -> none | AD29: 1 | AF29: =iferror(INDEX('ファントムマスター'!O:O,MATCH(H29,'ファントムマスター'!D:D,0),0)*AH29,"none") -> none | AH29: 1 | AJ29: =iferror(right(INDEX('ファントムマスター'!T:T,MATCH(H29,'ファントムマスター'!D:D,0),0),4)*50,"none") -> none | AL29: =iferror(right(INDEX('ファントムマスター'!V:V,MATCH(H29,'ファントムマスター'!D:D,0),0),4),"none") -> none | AN29: =iferror(AF29*(50/(AJ29+AL29)),"攻撃力に数値を入力") -> 攻撃力に数値を入力 | AT29: =iferror(INDEX('ファントムマスター'!Y:Y,MATCH(H29,'ファントムマスター'!D:D,0),0),"none") -> none | AY29: =iferror(INDEX('ファントムマスター'!Z:Z,MATCH(H29,'ファントムマスター'!D:D,0),0),"none") -> none | BA29: =iferror(INDEX('ファントムマスター'!W:W,MATCH(H29,'ファントムマスター'!D:D,0),0)*50,"none") -> none | BC29: =iferror(INDEX('ファントムマスター'!AA:AA,MATCH(H29,'ファントムマスター'!D:D,0),0),"none") -> none | BE29: =iferror(INDEX('ファントムマスター'!M:M,MATCH(H29,'ファントムマスター'!D:D,0),0),"none") -> none | BG29: =iferror(INDEX('ファントムマスター'!N:N,MATCH(H29,'ファントムマスター'!D:D,0),0),"none") -> none | BI29: =iferror(INDEX('ファントムマスター'!P:P,MATCH(H29,'ファントムマスター'!D:D,0),0),"none") -> none | BK29: =iferror(INDEX('ファントムマスター'!Q:Q,MATCH(H29,'ファントムマスター'!D:D,0),0),"none") -> none | BM29: =iferror(INDEX('ファントムマスター'!R:R,MATCH(H29,'ファントムマスター'!D:D,0),0),"none") -> none | BO29: =iferror(INDEX('ファントムマスター'!L:L,MATCH(H29,'ファントムマスター'!D:D,0),0),"none") -> none | BQ29: =iferror(INDEX('ファントムマスター'!S:S,MATCH(H29,'ファントムマスター'!D:D,0),0),"none") -> none | CA29: 未入力 | CM29: None | CQ29: None | CW29: None | DC29: None | DK29: FALSE | DM29: None | EA29: =B29 | EB29: =D29 | EC29: =F29 | ED29: =CA29 -> 未入力 | EE29: =CE29 | EF29: ="SummonEnemy" -> SummonEnemy | EG29: =H29 | EI29: =CI29 | EJ29: =CG29 | EK29: =CM29 -> None | EL29: =CO29 | EM29: =CQ29 -> None | EN29: =CU29 | EO29: =CW29 -> None | EP29: =DA29 | EQ29: =DC29 -> None | ER29: =DG29 | ES29: =DI29 | ET29: =DK29 -> FALSE | EV29: =V29 -> Default | EW29: =X29 -> Normal | EX29: =AD29 -> 1 | EY29: =AH29 -> 1 | EZ29: ="1" -> 1 | FA29: =BS29 | FB29: 0 | FC29: =CK29 | FD29: =DM29 -> None | FE29: =DQ29
L30: =iferror(INDEX('ファントムマスター'!F:F,MATCH(H30,'ファントムマスター'!D:D,0),0),"none") -> none | P30: =iferror(INDEX('ファントムマスター'!H:H,MATCH(H30,'ファントムマスター'!D:D,0),0),"none") -> none | R30: =iferror(INDEX('ファントムマスター'!J:J,MATCH(H30,'ファントムマスター'!D:D,0),0),"none") -> none | T30: =iferror(INDEX('ファントムマスター'!I:I,MATCH(H30,'ファントムマスター'!D:D,0),0),"none") -> none | V30: Default | X30: Normal | AB30: =iferror(INDEX('ファントムマスター'!K:K,MATCH(H30,'ファントムマスター'!D:D,0),0)*AD30,"none") -> none | AD30: 1 | AF30: =iferror(INDEX('ファントムマスター'!O:O,MATCH(H30,'ファントムマスター'!D:D,0),0)*AH30,"none") -> none | AH30: 1 | AJ30: =iferror(right(INDEX('ファントムマスター'!T:T,MATCH(H30,'ファントムマスター'!D:D,0),0),4)*50,"none") -> none | AL30: =iferror(right(INDEX('ファントムマスター'!V:V,MATCH(H30,'ファントムマスター'!D:D,0),0),4),"none") -> none | AN30: =iferror(AF30*(50/(AJ30+AL30)),"攻撃力に数値を入力") -> 攻撃力に数値を入力 | AT30: =iferror(INDEX('ファントムマスター'!Y:Y,MATCH(H30,'ファントムマスター'!D:D,0),0),"none") -> none | AY30: =iferror(INDEX('ファントムマスター'!Z:Z,MATCH(H30,'ファントムマスター'!D:D,0),0),"none") -> none | BA30: =iferror(INDEX('ファントムマスター'!W:W,MATCH(H30,'ファントムマスター'!D:D,0),0)*50,"none") -> none | BC30: =iferror(INDEX('ファントムマスター'!AA:AA,MATCH(H30,'ファントムマスター'!D:D,0),0),"none") -> none | BE30: =iferror(INDEX('ファントムマスター'!M:M,MATCH(H30,'ファントムマスター'!D:D,0),0),"none") -> none | BG30: =iferror(INDEX('ファントムマスター'!N:N,MATCH(H30,'ファントムマスター'!D:D,0),0),"none") -> none | BI30: =iferror(INDEX('ファントムマスター'!P:P,MATCH(H30,'ファントムマスター'!D:D,0),0),"none") -> none | BK30: =iferror(INDEX('ファントムマスター'!Q:Q,MATCH(H30,'ファントムマスター'!D:D,0),0),"none") -> none | BM30: =iferror(INDEX('ファントムマスター'!R:R,MATCH(H30,'ファントムマスター'!D:D,0),0),"none") -> none | BO30: =iferror(INDEX('ファントムマスター'!L:L,MATCH(H30,'ファントムマスター'!D:D,0),0),"none") -> none | BQ30: =iferror(INDEX('ファントムマスター'!S:S,MATCH(H30,'ファントムマスター'!D:D,0),0),"none") -> none | CA30: 未入力 | CM30: None | CQ30: None | CW30: None | DC30: None | DK30: FALSE | DM30: None | EA30: =B30 | EB30: =D30 | EC30: =F30 | ED30: =CA30 -> 未入力 | EE30: =CE30 | EF30: ="SummonEnemy" -> SummonEnemy | EG30: =H30 | EI30: =CI30 | EJ30: =CG30 | EK30: =CM30 -> None | EL30: =CO30 | EM30: =CQ30 -> None | EN30: =CU30 | EO30: =CW30 -> None | EP30: =DA30 | EQ30: =DC30 -> None | ER30: =DG30 | ES30: =DI30 | ET30: =DK30 -> FALSE | EV30: =V30 -> Default | EW30: =X30 -> Normal | EX30: =AD30 -> 1 | EY30: =AH30 -> 1 | EZ30: ="1" -> 1 | FA30: =BS30 | FB30: 0 | FC30: =CK30 | FD30: =DM30 -> None | FE30: =DQ30
L31: =iferror(INDEX('ファントムマスター'!F:F,MATCH(H31,'ファントムマスター'!D:D,0),0),"none") -> none | P31: =iferror(INDEX('ファントムマスター'!H:H,MATCH(H31,'ファントムマスター'!D:D,0),0),"none") -> none | R31: =iferror(INDEX('ファントムマスター'!J:J,MATCH(H31,'ファントムマスター'!D:D,0),0),"none") -> none | T31: =iferror(INDEX('ファントムマスター'!I:I,MATCH(H31,'ファントムマスター'!D:D,0),0),"none") -> none | V31: Default | X31: Normal | AB31: =iferror(INDEX('ファントムマスター'!K:K,MATCH(H31,'ファントムマスター'!D:D,0),0)*AD31,"none") -> none | AD31: 1 | AF31: =iferror(INDEX('ファントムマスター'!O:O,MATCH(H31,'ファントムマスター'!D:D,0),0)*AH31,"none") -> none | AH31: 1 | AJ31: =iferror(right(INDEX('ファントムマスター'!T:T,MATCH(H31,'ファントムマスター'!D:D,0),0),4)*50,"none") -> none | AL31: =iferror(right(INDEX('ファントムマスター'!V:V,MATCH(H31,'ファントムマスター'!D:D,0),0),4),"none") -> none | AN31: =iferror(AF31*(50/(AJ31+AL31)),"攻撃力に数値を入力") -> 攻撃力に数値を入力 | AT31: =iferror(INDEX('ファントムマスター'!Y:Y,MATCH(H31,'ファントムマスター'!D:D,0),0),"none") -> none | AY31: =iferror(INDEX('ファントムマスター'!Z:Z,MATCH(H31,'ファントムマスター'!D:D,0),0),"none") -> none | BA31: =iferror(INDEX('ファントムマスター'!W:W,MATCH(H31,'ファントムマスター'!D:D,0),0)*50,"none") -> none | BC31: =iferror(INDEX('ファントムマスター'!AA:AA,MATCH(H31,'ファントムマスター'!D:D,0),0),"none") -> none | BE31: =iferror(INDEX('ファントムマスター'!M:M,MATCH(H31,'ファントムマスター'!D:D,0),0),"none") -> none | BG31: =iferror(INDEX('ファントムマスター'!N:N,MATCH(H31,'ファントムマスター'!D:D,0),0),"none") -> none | BI31: =iferror(INDEX('ファントムマスター'!P:P,MATCH(H31,'ファントムマスター'!D:D,0),0),"none") -> none | BK31: =iferror(INDEX('ファントムマスター'!Q:Q,MATCH(H31,'ファントムマスター'!D:D,0),0),"none") -> none | BM31: =iferror(INDEX('ファントムマスター'!R:R,MATCH(H31,'ファントムマスター'!D:D,0),0),"none") -> none | BO31: =iferror(INDEX('ファントムマスター'!L:L,MATCH(H31,'ファントムマスター'!D:D,0),0),"none") -> none | BQ31: =iferror(INDEX('ファントムマスター'!S:S,MATCH(H31,'ファントムマスター'!D:D,0),0),"none") -> none | CA31: 未入力 | CM31: None | CQ31: None | CW31: None | DC31: None | DK31: FALSE | DM31: None | EA31: =B31 | EB31: =D31 | EC31: =F31 | ED31: =CA31 -> 未入力 | EE31: =CE31 | EF31: ="SummonEnemy" -> SummonEnemy | EG31: =H31 | EI31: =CI31 | EJ31: =CG31 | EK31: =CM31 -> None | EL31: =CO31 | EM31: =CQ31 -> None | EN31: =CU31 | EO31: =CW31 -> None | EP31: =DA31 | EQ31: =DC31 -> None | ER31: =DG31 | ES31: =DI31 | ET31: =DK31 -> FALSE | EV31: =V31 -> Default | EW31: =X31 -> Normal | EX31: =AD31 -> 1 | EY31: =AH31 -> 1 | EZ31: ="1" -> 1 | FA31: =BS31 | FB31: 0 | FC31: =CK31 | FD31: =DM31 -> None | FE31: =DQ31
L32: =iferror(INDEX('ファントムマスター'!F:F,MATCH(H32,'ファントムマスター'!D:D,0),0),"none") -> none | P32: =iferror(INDEX('ファントムマスター'!H:H,MATCH(H32,'ファントムマスター'!D:D,0),0),"none") -> none | R32: =iferror(INDEX('ファントムマスター'!J:J,MATCH(H32,'ファントムマスター'!D:D,0),0),"none") -> none | T32: =iferror(INDEX('ファントムマスター'!I:I,MATCH(H32,'ファントムマスター'!D:D,0),0),"none") -> none | V32: Default | X32: Normal | AB32: =iferror(INDEX('ファントムマスター'!K:K,MATCH(H32,'ファントムマスター'!D:D,0),0)*AD32,"none") -> none | AD32: 1 | AF32: =iferror(INDEX('ファントムマスター'!O:O,MATCH(H32,'ファントムマスター'!D:D,0),0)*AH32,"none") -> none | AH32: 1 | AJ32: =iferror(right(INDEX('ファントムマスター'!T:T,MATCH(H32,'ファントムマスター'!D:D,0),0),4)*50,"none") -> none | AL32: =iferror(right(INDEX('ファントムマスター'!V:V,MATCH(H32,'ファントムマスター'!D:D,0),0),4),"none") -> none | AN32: =iferror(AF32*(50/(AJ32+AL32)),"攻撃力に数値を入力") -> 攻撃力に数値を入力 | AT32: =iferror(INDEX('ファントムマスター'!Y:Y,MATCH(H32,'ファントムマスター'!D:D,0),0),"none") -> none | AY32: =iferror(INDEX('ファントムマスター'!Z:Z,MATCH(H32,'ファントムマスター'!D:D,0),0),"none") -> none | BA32: =iferror(INDEX('ファントムマスター'!W:W,MATCH(H32,'ファントムマスター'!D:D,0),0)*50,"none") -> none | BC32: =iferror(INDEX('ファントムマスター'!AA:AA,MATCH(H32,'ファントムマスター'!D:D,0),0),"none") -> none | BE32: =iferror(INDEX('ファントムマスター'!M:M,MATCH(H32,'ファントムマスター'!D:D,0),0),"none") -> none | BG32: =iferror(INDEX('ファントムマスター'!N:N,MATCH(H32,'ファントムマスター'!D:D,0),0),"none") -> none | BI32: =iferror(INDEX('ファントムマスター'!P:P,MATCH(H32,'ファントムマスター'!D:D,0),0),"none") -> none | BK32: =iferror(INDEX('ファントムマスター'!Q:Q,MATCH(H32,'ファントムマスター'!D:D,0),0),"none") -> none | BM32: =iferror(INDEX('ファントムマスター'!R:R,MATCH(H32,'ファントムマスター'!D:D,0),0),"none") -> none | BO32: =iferror(INDEX('ファントムマスター'!L:L,MATCH(H32,'ファントムマスター'!D:D,0),0),"none") -> none | BQ32: =iferror(INDEX('ファントムマスター'!S:S,MATCH(H32,'ファントムマスター'!D:D,0),0),"none") -> none | CA32: 未入力 | CM32: None | CQ32: None | CW32: None | DC32: None | DK32: FALSE | DM32: None | EA32: =B32 | EB32: =D32 | EC32: =F32 | ED32: =CA32 -> 未入力 | EE32: =CE32 | EF32: ="SummonEnemy" -> SummonEnemy | EG32: =H32 | EI32: =CI32 | EJ32: =CG32 | EK32: =CM32 -> None | EL32: =CO32 | EM32: =CQ32 -> None | EN32: =CU32 | EO32: =CW32 -> None | EP32: =DA32 | EQ32: =DC32 -> None | ER32: =DG32 | ES32: =DI32 | ET32: =DK32 -> FALSE | EV32: =V32 -> Default | EW32: =X32 -> Normal | EX32: =AD32 -> 1 | EY32: =AH32 -> 1 | EZ32: ="1" -> 1 | FA32: =BS32 | FB32: 0 | FC32: =CK32 | FD32: =DM32 -> None | FE32: =DQ32
L33: =iferror(INDEX('ファントムマスター'!F:F,MATCH(H33,'ファントムマスター'!D:D,0),0),"none") -> none | P33: =iferror(INDEX('ファントムマスター'!H:H,MATCH(H33,'ファントムマスター'!D:D,0),0),"none") -> none | R33: =iferror(INDEX('ファントムマスター'!J:J,MATCH(H33,'ファントムマスター'!D:D,0),0),"none") -> none | T33: =iferror(INDEX('ファントムマスター'!I:I,MATCH(H33,'ファントムマスター'!D:D,0),0),"none") -> none | V33: Default | X33: Normal | AB33: =iferror(INDEX('ファントムマスター'!K:K,MATCH(H33,'ファントムマスター'!D:D,0),0)*AD33,"none") -> none | AD33: 1 | AF33: =iferror(INDEX('ファントムマスター'!O:O,MATCH(H33,'ファントムマスター'!D:D,0),0)*AH33,"none") -> none | AH33: 1 | AJ33: =iferror(right(INDEX('ファントムマスター'!T:T,MATCH(H33,'ファントムマスター'!D:D,0),0),4)*50,"none") -> none | AL33: =iferror(right(INDEX('ファントムマスター'!V:V,MATCH(H33,'ファントムマスター'!D:D,0),0),4),"none") -> none | AN33: =iferror(AF33*(50/(AJ33+AL33)),"攻撃力に数値を入力") -> 攻撃力に数値を入力 | AT33: =iferror(INDEX('ファントムマスター'!Y:Y,MATCH(H33,'ファントムマスター'!D:D,0),0),"none") -> none | AY33: =iferror(INDEX('ファントムマスター'!Z:Z,MATCH(H33,'ファントムマスター'!D:D,0),0),"none") -> none | BA33: =iferror(INDEX('ファントムマスター'!W:W,MATCH(H33,'ファントムマスター'!D:D,0),0)*50,"none") -> none | BC33: =iferror(INDEX('ファントムマスター'!AA:AA,MATCH(H33,'ファントムマスター'!D:D,0),0),"none") -> none | BE33: =iferror(INDEX('ファントムマスター'!M:M,MATCH(H33,'ファントムマスター'!D:D,0),0),"none") -> none | BG33: =iferror(INDEX('ファントムマスター'!N:N,MATCH(H33,'ファントムマスター'!D:D,0),0),"none") -> none | BI33: =iferror(INDEX('ファントムマスター'!P:P,MATCH(H33,'ファントムマスター'!D:D,0),0),"none") -> none | BK33: =iferror(INDEX('ファントムマスター'!Q:Q,MATCH(H33,'ファントムマスター'!D:D,0),0),"none") -> none | BM33: =iferror(INDEX('ファントムマスター'!R:R,MATCH(H33,'ファントムマスター'!D:D,0),0),"none") -> none | BO33: =iferror(INDEX('ファントムマスター'!L:L,MATCH(H33,'ファントムマスター'!D:D,0),0),"none") -> none | BQ33: =iferror(INDEX('ファントムマスター'!S:S,MATCH(H33,'ファントムマスター'!D:D,0),0),"none") -> none | CA33: 未入力 | CM33: None | CQ33: None | CW33: None | DC33: None | DK33: FALSE | DM33: None | EA33: =B33 | EB33: =D33 | EC33: =F33 | ED33: =CA33 -> 未入力 | EE33: =CE33 | EF33: ="SummonEnemy" -> SummonEnemy | EG33: =H33 | EI33: =CI33 | EJ33: =CG33 | EK33: =CM33 -> None | EL33: =CO33 | EM33: =CQ33 -> None | EN33: =CU33 | EO33: =CW33 -> None | EP33: =DA33 | EQ33: =DC33 -> None | ER33: =DG33 | ES33: =DI33 | ET33: =DK33 -> FALSE | EV33: =V33 -> Default | EW33: =X33 -> Normal | EX33: =AD33 -> 1 | EY33: =AH33 -> 1 | EZ33: ="1" -> 1 | FA33: =BS33 | FB33: 0 | FC33: =CK33 | FD33: =DM33 -> None | FE33: =DQ33
L34: =iferror(INDEX('ファントムマスター'!F:F,MATCH(H34,'ファントムマスター'!D:D,0),0),"none") -> none | P34: =iferror(INDEX('ファントムマスター'!H:H,MATCH(H34,'ファントムマスター'!D:D,0),0),"none") -> none | R34: =iferror(INDEX('ファントムマスター'!J:J,MATCH(H34,'ファントムマスター'!D:D,0),0),"none") -> none | T34: =iferror(INDEX('ファントムマスター'!I:I,MATCH(H34,'ファントムマスター'!D:D,0),0),"none") -> none | V34: Default | X34: Normal | AB34: =iferror(INDEX('ファントムマスター'!K:K,MATCH(H34,'ファントムマスター'!D:D,0),0)*AD34,"none") -> none | AD34: 1 | AF34: =iferror(INDEX('ファントムマスター'!O:O,MATCH(H34,'ファントムマスター'!D:D,0),0)*AH34,"none") -> none | AH34: 1 | AJ34: =iferror(right(INDEX('ファントムマスター'!T:T,MATCH(H34,'ファントムマスター'!D:D,0),0),4)*50,"none") -> none | AL34: =iferror(right(INDEX('ファントムマスター'!V:V,MATCH(H34,'ファントムマスター'!D:D,0),0),4),"none") -> none | AN34: =iferror(AF34*(50/(AJ34+AL34)),"攻撃力に数値を入力") -> 攻撃力に数値を入力 | AT34: =iferror(INDEX('ファントムマスター'!Y:Y,MATCH(H34,'ファントムマスター'!D:D,0),0),"none") -> none | AY34: =iferror(INDEX('ファントムマスター'!Z:Z,MATCH(H34,'ファントムマスター'!D:D,0),0),"none") -> none | BA34: =iferror(INDEX('ファントムマスター'!W:W,MATCH(H34,'ファントムマスター'!D:D,0),0)*50,"none") -> none | BC34: =iferror(INDEX('ファントムマスター'!AA:AA,MATCH(H34,'ファントムマスター'!D:D,0),0),"none") -> none | BE34: =iferror(INDEX('ファントムマスター'!M:M,MATCH(H34,'ファントムマスター'!D:D,0),0),"none") -> none | BG34: =iferror(INDEX('ファントムマスター'!N:N,MATCH(H34,'ファントムマスター'!D:D,0),0),"none") -> none | BI34: =iferror(INDEX('ファントムマスター'!P:P,MATCH(H34,'ファントムマスター'!D:D,0),0),"none") -> none | BK34: =iferror(INDEX('ファントムマスター'!Q:Q,MATCH(H34,'ファントムマスター'!D:D,0),0),"none") -> none | BM34: =iferror(INDEX('ファントムマスター'!R:R,MATCH(H34,'ファントムマスター'!D:D,0),0),"none") -> none | BO34: =iferror(INDEX('ファントムマスター'!L:L,MATCH(H34,'ファントムマスター'!D:D,0),0),"none") -> none | BQ34: =iferror(INDEX('ファントムマスター'!S:S,MATCH(H34,'ファントムマスター'!D:D,0),0),"none") -> none | CA34: 未入力 | CM34: None | CQ34: None | CW34: None | DC34: None | DK34: FALSE | DM34: None | EA34: =B34 | EB34: =D34 | EC34: =F34 | ED34: =CA34 -> 未入力 | EE34: =CE34 | EF34: ="SummonEnemy" -> SummonEnemy | EG34: =H34 | EI34: =CI34 | EJ34: =CG34 | EK34: =CM34 -> None | EL34: =CO34 | EM34: =CQ34 -> None | EN34: =CU34 | EO34: =CW34 -> None | EP34: =DA34 | EQ34: =DC34 -> None | ER34: =DG34 | ES34: =DI34 | ET34: =DK34 -> FALSE | EV34: =V34 -> Default | EW34: =X34 -> Normal | EX34: =AD34 -> 1 | EY34: =AH34 -> 1 | EZ34: ="1" -> 1 | FA34: =BS34 | FB34: 0 | FC34: =CK34 | FD34: =DM34 -> None | FE34: =DQ34
L35: =iferror(INDEX('ファントムマスター'!F:F,MATCH(H35,'ファントムマスター'!D:D,0),0),"none") -> none | P35: =iferror(INDEX('ファントムマスター'!H:H,MATCH(H35,'ファントムマスター'!D:D,0),0),"none") -> none | R35: =iferror(INDEX('ファントムマスター'!J:J,MATCH(H35,'ファントムマスター'!D:D,0),0),"none") -> none | T35: =iferror(INDEX('ファントムマスター'!I:I,MATCH(H35,'ファントムマスター'!D:D,0),0),"none") -> none | V35: Default | X35: Normal | AB35: =iferror(INDEX('ファントムマスター'!K:K,MATCH(H35,'ファントムマスター'!D:D,0),0)*AD35,"none") -> none | AD35: 1 | AF35: =iferror(INDEX('ファントムマスター'!O:O,MATCH(H35,'ファントムマスター'!D:D,0),0)*AH35,"none") -> none | AH35: 1 | AJ35: =iferror(right(INDEX('ファントムマスター'!T:T,MATCH(H35,'ファントムマスター'!D:D,0),0),4)*50,"none") -> none | AL35: =iferror(right(INDEX('ファントムマスター'!V:V,MATCH(H35,'ファントムマスター'!D:D,0),0),4),"none") -> none | AN35: =iferror(AF35*(50/(AJ35+AL35)),"攻撃力に数値を入力") -> 攻撃力に数値を入力 | AT35: =iferror(INDEX('ファントムマスター'!Y:Y,MATCH(H35,'ファントムマスター'!D:D,0),0),"none") -> none | AY35: =iferror(INDEX('ファントムマスター'!Z:Z,MATCH(H35,'ファントムマスター'!D:D,0),0),"none") -> none | BA35: =iferror(INDEX('ファントムマスター'!W:W,MATCH(H35,'ファントムマスター'!D:D,0),0)*50,"none") -> none | BC35: =iferror(INDEX('ファントムマスター'!AA:AA,MATCH(H35,'ファントムマスター'!D:D,0),0),"none") -> none | BE35: =iferror(INDEX('ファントムマスター'!M:M,MATCH(H35,'ファントムマスター'!D:D,0),0),"none") -> none | BG35: =iferror(INDEX('ファントムマスター'!N:N,MATCH(H35,'ファントムマスター'!D:D,0),0),"none") -> none | BI35: =iferror(INDEX('ファントムマスター'!P:P,MATCH(H35,'ファントムマスター'!D:D,0),0),"none") -> none | BK35: =iferror(INDEX('ファントムマスター'!Q:Q,MATCH(H35,'ファントムマスター'!D:D,0),0),"none") -> none | BM35: =iferror(INDEX('ファントムマスター'!R:R,MATCH(H35,'ファントムマスター'!D:D,0),0),"none") -> none | BO35: =iferror(INDEX('ファントムマスター'!L:L,MATCH(H35,'ファントムマスター'!D:D,0),0),"none") -> none | BQ35: =iferror(INDEX('ファントムマスター'!S:S,MATCH(H35,'ファントムマスター'!D:D,0),0),"none") -> none | CA35: 未入力 | CM35: None | CQ35: None | CW35: None | DC35: None | DK35: FALSE | DM35: None | EA35: =B35 | EB35: =D35 | EC35: =F35 | ED35: =CA35 -> 未入力 | EE35: =CE35 | EF35: ="SummonEnemy" -> SummonEnemy | EG35: =H35 | EI35: =CI35 | EJ35: =CG35 | EK35: =CM35 -> None | EL35: =CO35 | EM35: =CQ35 -> None | EN35: =CU35 | EO35: =CW35 -> None | EP35: =DA35 | EQ35: =DC35 -> None | ER35: =DG35 | ES35: =DI35 | ET35: =DK35 -> FALSE | EV35: =V35 -> Default | EW35: =X35 -> Normal | EX35: =AD35 -> 1 | EY35: =AH35 -> 1 | EZ35: ="1" -> 1 | FA35: =BS35 | FB35: 0 | FC35: =CK35 | FD35: =DM35 -> None | FE35: =DQ35
L36: =iferror(INDEX('ファントムマスター'!F:F,MATCH(H36,'ファントムマスター'!D:D,0),0),"none") -> none | P36: =iferror(INDEX('ファントムマスター'!H:H,MATCH(H36,'ファントムマスター'!D:D,0),0),"none") -> none | R36: =iferror(INDEX('ファントムマスター'!J:J,MATCH(H36,'ファントムマスター'!D:D,0),0),"none") -> none | T36: =iferror(INDEX('ファントムマスター'!I:I,MATCH(H36,'ファントムマスター'!D:D,0),0),"none") -> none | V36: Default | X36: Normal | AB36: =iferror(INDEX('ファントムマスター'!K:K,MATCH(H36,'ファントムマスター'!D:D,0),0)*AD36,"none") -> none | AD36: 1 | AF36: =iferror(INDEX('ファントムマスター'!O:O,MATCH(H36,'ファントムマスター'!D:D,0),0)*AH36,"none") -> none | AH36: 1 | AJ36: =iferror(right(INDEX('ファントムマスター'!T:T,MATCH(H36,'ファントムマスター'!D:D,0),0),4)*50,"none") -> none | AL36: =iferror(right(INDEX('ファントムマスター'!V:V,MATCH(H36,'ファントムマスター'!D:D,0),0),4),"none") -> none | AN36: =iferror(AF36*(50/(AJ36+AL36)),"攻撃力に数値を入力") -> 攻撃力に数値を入力 | AT36: =iferror(INDEX('ファントムマスター'!Y:Y,MATCH(H36,'ファントムマスター'!D:D,0),0),"none") -> none | AY36: =iferror(INDEX('ファントムマスター'!Z:Z,MATCH(H36,'ファントムマスター'!D:D,0),0),"none") -> none | BA36: =iferror(INDEX('ファントムマスター'!W:W,MATCH(H36,'ファントムマスター'!D:D,0),0)*50,"none") -> none | BC36: =iferror(INDEX('ファントムマスター'!AA:AA,MATCH(H36,'ファントムマスター'!D:D,0),0),"none") -> none | BE36: =iferror(INDEX('ファントムマスター'!M:M,MATCH(H36,'ファントムマスター'!D:D,0),0),"none") -> none | BG36: =iferror(INDEX('ファントムマスター'!N:N,MATCH(H36,'ファントムマスター'!D:D,0),0),"none") -> none | BI36: =iferror(INDEX('ファントムマスター'!P:P,MATCH(H36,'ファントムマスター'!D:D,0),0),"none") -> none | BK36: =iferror(INDEX('ファントムマスター'!Q:Q,MATCH(H36,'ファントムマスター'!D:D,0),0),"none") -> none | BM36: =iferror(INDEX('ファントムマスター'!R:R,MATCH(H36,'ファントムマスター'!D:D,0),0),"none") -> none | BO36: =iferror(INDEX('ファントムマスター'!L:L,MATCH(H36,'ファントムマスター'!D:D,0),0),"none") -> none | BQ36: =iferror(INDEX('ファントムマスター'!S:S,MATCH(H36,'ファントムマスター'!D:D,0),0),"none") -> none | CA36: 未入力 | CM36: None | CQ36: None | CW36: None | DC36: None | DK36: FALSE | DM36: None | EA36: =B36 | EB36: =D36 | EC36: =F36 | ED36: =CA36 -> 未入力 | EE36: =CE36 | EF36: ="SummonEnemy" -> SummonEnemy | EG36: =H36 | EI36: =CI36 | EJ36: =CG36 | EK36: =CM36 -> None | EL36: =CO36 | EM36: =CQ36 -> None | EN36: =CU36 | EO36: =CW36 -> None | EP36: =DA36 | EQ36: =DC36 -> None | ER36: =DG36 | ES36: =DI36 | ET36: =DK36 -> FALSE | EV36: =V36 -> Default | EW36: =X36 -> Normal | EX36: =AD36 -> 1 | EY36: =AH36 -> 1 | EZ36: ="1" -> 1 | FA36: =BS36 | FB36: 0 | FC36: =CK36 | FD36: =DM36 -> None | FE36: =DQ36
L37: =iferror(INDEX('ファントムマスター'!F:F,MATCH(H37,'ファントムマスター'!D:D,0),0),"none") -> none | P37: =iferror(INDEX('ファントムマスター'!H:H,MATCH(H37,'ファントムマスター'!D:D,0),0),"none") -> none | R37: =iferror(INDEX('ファントムマスター'!J:J,MATCH(H37,'ファントムマスター'!D:D,0),0),"none") -> none | T37: =iferror(INDEX('ファントムマスター'!I:I,MATCH(H37,'ファントムマスター'!D:D,0),0),"none") -> none | V37: Default | X37: Normal | AB37: =iferror(INDEX('ファントムマスター'!K:K,MATCH(H37,'ファントムマスター'!D:D,0),0)*AD37,"none") -> none | AD37: 1 | AF37: =iferror(INDEX('ファントムマスター'!O:O,MATCH(H37,'ファントムマスター'!D:D,0),0)*AH37,"none") -> none | AH37: 1 | AJ37: =iferror(right(INDEX('ファントムマスター'!T:T,MATCH(H37,'ファントムマスター'!D:D,0),0),4)*50,"none") -> none | AL37: =iferror(right(INDEX('ファントムマスター'!V:V,MATCH(H37,'ファントムマスター'!D:D,0),0),4),"none") -> none | AN37: =iferror(AF37*(50/(AJ37+AL37)),"攻撃力に数値を入力") -> 攻撃力に数値を入力 | AT37: =iferror(INDEX('ファントムマスター'!Y:Y,MATCH(H37,'ファントムマスター'!D:D,0),0),"none") -> none | AY37: =iferror(INDEX('ファントムマスター'!Z:Z,MATCH(H37,'ファントムマスター'!D:D,0),0),"none") -> none | BA37: =iferror(INDEX('ファントムマスター'!W:W,MATCH(H37,'ファントムマスター'!D:D,0),0)*50,"none") -> none | BC37: =iferror(INDEX('ファントムマスター'!AA:AA,MATCH(H37,'ファントムマスター'!D:D,0),0),"none") -> none | BE37: =iferror(INDEX('ファントムマスター'!M:M,MATCH(H37,'ファントムマスター'!D:D,0),0),"none") -> none | BG37: =iferror(INDEX('ファントムマスター'!N:N,MATCH(H37,'ファントムマスター'!D:D,0),0),"none") -> none | BI37: =iferror(INDEX('ファントムマスター'!P:P,MATCH(H37,'ファントムマスター'!D:D,0),0),"none") -> none | BK37: =iferror(INDEX('ファントムマスター'!Q:Q,MATCH(H37,'ファントムマスター'!D:D,0),0),"none") -> none | BM37: =iferror(INDEX('ファントムマスター'!R:R,MATCH(H37,'ファントムマスター'!D:D,0),0),"none") -> none | BO37: =iferror(INDEX('ファントムマスター'!L:L,MATCH(H37,'ファントムマスター'!D:D,0),0),"none") -> none | BQ37: =iferror(INDEX('ファントムマスター'!S:S,MATCH(H37,'ファントムマスター'!D:D,0),0),"none") -> none | CA37: 未入力 | CM37: None | CQ37: None | CW37: None | DC37: None | DK37: FALSE | DM37: None | EA37: =B37 | EB37: =D37 | EC37: =F37 | ED37: =CA37 -> 未入力 | EE37: =CE37 | EF37: ="SummonEnemy" -> SummonEnemy | EG37: =H37 | EI37: =CI37 | EJ37: =CG37 | EK37: =CM37 -> None | EL37: =CO37 | EM37: =CQ37 -> None | EN37: =CU37 | EO37: =CW37 -> None | EP37: =DA37 | EQ37: =DC37 -> None | ER37: =DG37 | ES37: =DI37 | ET37: =DK37 -> FALSE | EV37: =V37 -> Default | EW37: =X37 -> Normal | EX37: =AD37 -> 1 | EY37: =AH37 -> 1 | EZ37: ="1" -> 1 | FA37: =BS37 | FB37: 0 | FC37: =CK37 | FD37: =DM37 -> None | FE37: =DQ37
L38: =iferror(INDEX('ファントムマスター'!F:F,MATCH(H38,'ファントムマスター'!D:D,0),0),"none") -> none | P38: =iferror(INDEX('ファントムマスター'!H:H,MATCH(H38,'ファントムマスター'!D:D,0),0),"none") -> none | R38: =iferror(INDEX('ファントムマスター'!J:J,MATCH(H38,'ファントムマスター'!D:D,0),0),"none") -> none | T38: =iferror(INDEX('ファントムマスター'!I:I,MATCH(H38,'ファントムマスター'!D:D,0),0),"none") -> none | V38: Default | X38: Normal | AB38: =iferror(INDEX('ファントムマスター'!K:K,MATCH(H38,'ファントムマスター'!D:D,0),0)*AD38,"none") -> none | AD38: 1 | AF38: =iferror(INDEX('ファントムマスター'!O:O,MATCH(H38,'ファントムマスター'!D:D,0),0)*AH38,"none") -> none | AH38: 1 | AJ38: =iferror(right(INDEX('ファントムマスター'!T:T,MATCH(H38,'ファントムマスター'!D:D,0),0),4)*50,"none") -> none | AL38: =iferror(right(INDEX('ファントムマスター'!V:V,MATCH(H38,'ファントムマスター'!D:D,0),0),4),"none") -> none | AN38: =iferror(AF38*(50/(AJ38+AL38)),"攻撃力に数値を入力") -> 攻撃力に数値を入力 | AT38: =iferror(INDEX('ファントムマスター'!Y:Y,MATCH(H38,'ファントムマスター'!D:D,0),0),"none") -> none | AY38: =iferror(INDEX('ファントムマスター'!Z:Z,MATCH(H38,'ファントムマスター'!D:D,0),0),"none") -> none | BA38: =iferror(INDEX('ファントムマスター'!W:W,MATCH(H38,'ファントムマスター'!D:D,0),0)*50,"none") -> none | BC38: =iferror(INDEX('ファントムマスター'!AA:AA,MATCH(H38,'ファントムマスター'!D:D,0),0),"none") -> none | BE38: =iferror(INDEX('ファントムマスター'!M:M,MATCH(H38,'ファントムマスター'!D:D,0),0),"none") -> none | BG38: =iferror(INDEX('ファントムマスター'!N:N,MATCH(H38,'ファントムマスター'!D:D,0),0),"none") -> none | BI38: =iferror(INDEX('ファントムマスター'!P:P,MATCH(H38,'ファントムマスター'!D:D,0),0),"none") -> none | BK38: =iferror(INDEX('ファントムマスター'!Q:Q,MATCH(H38,'ファントムマスター'!D:D,0),0),"none") -> none | BM38: =iferror(INDEX('ファントムマスター'!R:R,MATCH(H38,'ファントムマスター'!D:D,0),0),"none") -> none | BO38: =iferror(INDEX('ファントムマスター'!L:L,MATCH(H38,'ファントムマスター'!D:D,0),0),"none") -> none | BQ38: =iferror(INDEX('ファントムマスター'!S:S,MATCH(H38,'ファントムマスター'!D:D,0),0),"none") -> none | CA38: 未入力 | CM38: None | CQ38: None | CW38: None | DC38: None | DK38: FALSE | DM38: None | EA38: =B38 | EB38: =D38 | EC38: =F38 | ED38: =CA38 -> 未入力 | EE38: =CE38 | EF38: ="SummonEnemy" -> SummonEnemy | EG38: =H38 | EI38: =CI38 | EJ38: =CG38 | EK38: =CM38 -> None | EL38: =CO38 | EM38: =CQ38 -> None | EN38: =CU38 | EO38: =CW38 -> None | EP38: =DA38 | EQ38: =DC38 -> None | ER38: =DG38 | ES38: =DI38 | ET38: =DK38 -> FALSE | EV38: =V38 -> Default | EW38: =X38 -> Normal | EX38: =AD38 -> 1 | EY38: =AH38 -> 1 | EZ38: ="1" -> 1 | FA38: =BS38 | FB38: 0 | FC38: =CK38 | FD38: =DM38 -> None | FE38: =DQ38
L39: =iferror(INDEX('ファントムマスター'!F:F,MATCH(H39,'ファントムマスター'!D:D,0),0),"none") -> none | P39: =iferror(INDEX('ファントムマスター'!H:H,MATCH(H39,'ファントムマスター'!D:D,0),0),"none") -> none | R39: =iferror(INDEX('ファントムマスター'!J:J,MATCH(H39,'ファントムマスター'!D:D,0),0),"none") -> none | T39: =iferror(INDEX('ファントムマスター'!I:I,MATCH(H39,'ファントムマスター'!D:D,0),0),"none") -> none | V39: Default | X39: Normal | AB39: =iferror(INDEX('ファントムマスター'!K:K,MATCH(H39,'ファントムマスター'!D:D,0),0)*AD39,"none") -> none | AD39: 1 | AF39: =iferror(INDEX('ファントムマスター'!O:O,MATCH(H39,'ファントムマスター'!D:D,0),0)*AH39,"none") -> none | AH39: 1 | AJ39: =iferror(right(INDEX('ファントムマスター'!T:T,MATCH(H39,'ファントムマスター'!D:D,0),0),4)*50,"none") -> none | AL39: =iferror(right(INDEX('ファントムマスター'!V:V,MATCH(H39,'ファントムマスター'!D:D,0),0),4),"none") -> none | AN39: =iferror(AF39*(50/(AJ39+AL39)),"攻撃力に数値を入力") -> 攻撃力に数値を入力 | AT39: =iferror(INDEX('ファントムマスター'!Y:Y,MATCH(H39,'ファントムマスター'!D:D,0),0),"none") -> none | AY39: =iferror(INDEX('ファントムマスター'!Z:Z,MATCH(H39,'ファントムマスター'!D:D,0),0),"none") -> none | BA39: =iferror(INDEX('ファントムマスター'!W:W,MATCH(H39,'ファントムマスター'!D:D,0),0)*50,"none") -> none | BC39: =iferror(INDEX('ファントムマスター'!AA:AA,MATCH(H39,'ファントムマスター'!D:D,0),0),"none") -> none | BE39: =iferror(INDEX('ファントムマスター'!M:M,MATCH(H39,'ファントムマスター'!D:D,0),0),"none") -> none | BG39: =iferror(INDEX('ファントムマスター'!N:N,MATCH(H39,'ファントムマスター'!D:D,0),0),"none") -> none | BI39: =iferror(INDEX('ファントムマスター'!P:P,MATCH(H39,'ファントムマスター'!D:D,0),0),"none") -> none | BK39: =iferror(INDEX('ファントムマスター'!Q:Q,MATCH(H39,'ファントムマスター'!D:D,0),0),"none") -> none | BM39: =iferror(INDEX('ファントムマスター'!R:R,MATCH(H39,'ファントムマスター'!D:D,0),0),"none") -> none | BO39: =iferror(INDEX('ファントムマスター'!L:L,MATCH(H39,'ファントムマスター'!D:D,0),0),"none") -> none | BQ39: =iferror(INDEX('ファントムマスター'!S:S,MATCH(H39,'ファントムマスター'!D:D,0),0),"none") -> none | CA39: 未入力 | CM39: None | CQ39: None | CW39: None | DC39: None | DK39: FALSE | DM39: None | EA39: =B39 | EB39: =D39 | EC39: =F39 | ED39: =CA39 -> 未入力 | EE39: =CE39 | EF39: ="SummonEnemy" -> SummonEnemy | EG39: =H39 | EI39: =CI39 | EJ39: =CG39 | EK39: =CM39 -> None | EL39: =CO39 | EM39: =CQ39 -> None | EN39: =CU39 | EO39: =CW39 -> None | EP39: =DA39 | EQ39: =DC39 -> None | ER39: =DG39 | ES39: =DI39 | ET39: =DK39 -> FALSE | EV39: =V39 -> Default | EW39: =X39 -> Normal | EX39: =AD39 -> 1 | EY39: =AH39 -> 1 | EZ39: ="1" -> 1 | FA39: =BS39 | FB39: 0 | FC39: =CK39 | FD39: =DM39 -> None | FE39: =DQ39
... L46: =iferror(INDEX('ファントムマスター'!F:F,MATCH(H46,'ファントムマスター'!D:D,0),0),"none") -> none | P46: =iferror(INDEX('ファントムマスター'!H:H,MATCH(H46,'ファントムマスター'!D:D,0),0),"none") -> none | R46: =iferror(INDEX('ファントムマスター'!J:J,MATCH(H46,'ファントムマスター'!D:D,0),0),"none") -> none | T46: =iferror(INDEX('ファントムマスター'!I:I,MATCH(H46,'ファントムマスター'!D:D,0),0),"none") -> none | V46: Default | X46: Normal | AB46: =iferror(INDEX('ファントムマスター'!K:K,MATCH(H46,'ファントムマスター'!D:D,0),0)*AD46,"none") -> none | AD46: 1 | AF46: =iferror(INDEX('ファントムマスター'!O:O,MATCH(H46,'ファントムマスター'!D:D,0),0)*AH46,"none") -> none | AH46: 1 | AJ46: =iferror(right(INDEX('ファントムマスター'!T:T,MATCH(H46,'ファントムマスター'!D:D,0),0),4)*50,"none") -> none | AL46: =iferror(right(INDEX('ファントムマスター'!V:V,MATCH(H46,'ファントムマスター'!D:D,0),0),4),"none") -> none | AN46: =iferror(AF46*(50/(AJ46+AL46)),"攻撃力に数値を入力") -> 攻撃力に数値を入力 | AT46: =iferror(INDEX('ファントムマスター'!Y:Y,MATCH(H46,'ファントムマスター'!D:D,0),0),"none") -> none | AY46: =iferror(INDEX('ファントムマスター'!Z:Z,MATCH(H46,'ファントムマスター'!D:D,0),0),"none") -> none | BA46: =iferror(INDEX('ファントムマスター'!W:W,MATCH(H46,'ファントムマスター'!D:D,0),0)*50,"none") -> none | BC46: =iferror(INDEX('ファントムマスター'!AA:AA,MATCH(H46,'ファントムマスター'!D:D,0),0),"none") -> none | BE46: =iferror(INDEX('ファントムマスター'!M:M,MATCH(H46,'ファントムマスター'!D:D,0),0),"none") -> none | BG46: =iferror(INDEX('ファントムマスター'!N:N,MATCH(H46,'ファントムマスター'!D:D,0),0),"none") -> none | BI46: =iferror(INDEX('ファントムマスター'!P:P,MATCH(H46,'ファントムマスター'!D:D,0),0),"none") -> none | BK46: =iferror(INDEX('ファントムマスター'!Q:Q,MATCH(H46,'ファントムマスター'!D:D,0),0),"none") -> none | BM46: =iferror(INDEX('ファントムマスター'!R:R,MATCH(H46,'ファントムマスター'!D:D,0),0),"none") -> none | BO46: =iferror(INDEX('ファントムマスター'!L:L,MATCH(H46,'ファントムマスター'!D:D,0),0),"none") -> none | BQ46: =iferror(INDEX('ファントムマスター'!S:S,MATCH(H46,'ファントムマスター'!D:D,0),0),"none") -> none | CA46: 未入力 | CM46: None | CQ46: None | CW46: None | DC46: None | DK46: FALSE | DM46: None | EA46: =B46 | EB46: =D46 | EC46: =F46 | ED46: =CA46 -> 未入力 | EE46: =CE46 | EF46: ="SummonEnemy" -> SummonEnemy | EG46: =H46 | EI46: =CI46 | EJ46: =CG46 | EK46: =CM46 -> None | EL46: =CO46 | EM46: =CQ46 -> None | EN46: =CU46 | EO46: =CW46 -> None | EP46: =DA46 | EQ46: =DC46 -> None | ER46: =DG46 | ES46: =DI46 | ET46: =DK46 -> FALSE | EV46: =V46 -> Default | EW46: =X46 -> Normal | EX46: =AD46 -> 1 | EY46: =AH46 -> 1 | EZ46: ="1" -> 1 | FA46: =BS46 | FB46: 0 | FC46: =CK46 | FD46: =DM46 -> None | FE46: =DQ46

Sheet ボスブロック
B1: ボスブロック_SPY×FAMILY
B3: ■基礎情報
B5: ステージコンセプト
B6: SPY×FAMILYの「ロイド」を強敵オーラを付けて登場させます。 体力は50000ほど、攻撃は15000、移動速度は少し速い、必殺ワザの使用はあり。
B10: BGM
B11: ファイル名
E12: ⇩チュートリアルの敵原画固定 | K12: ⇩100固定
B13: 味方ゲートID | E13: 敵ゲートID | H13: 敵ゲートasset | K13: 敵ゲートHP | N13: リリースキー
B14: default | E14: 入力してね | H14: 入力してね | K14: 1000 | N14: 入力してね
B16: ■コマ設計
B18: 行数 | D18: 行パターンID | F18: コマ数 | H18: コマ高さ | J18: コマ幅1 | L18: コマ幅2 | N18: コマ幅3 | P18: コマ幅4 | U18: コマ効果1 | Z18: 効果時間 | AB18: 効果数値 | AD18: コマ効果2 | AI18: 効果時間 | AK18: 効果数値 | AM18: コマ効果3 | AR18: 効果時間 | AT18: 効果数値 | AV18: コマ効果4 | BA18: 効果時間 | BC18: 効果数値
B19: 1行目 | D19: 1 | F19: =iferror(vlookup(D19,'行パターン'!$A$2:$C46,2,false),"error") -> error | H19: 0.55 | J19: {=iferror(INDEX('行パターン'!D:D,MATCH(D19,'行パターン'!A:A,0),0),"error")} -> error | L19: {=iferror(if(sum(J19)=1,"none",INDEX('行パターン'!E:E,MATCH($D19,'行パターン'!$A:$A,0),0)),"")} | N19: {=iferror(if(sum(J19:M19)=1,"none",INDEX('行パターン'!F:F,MATCH($D19,'行パターン'!$A:$A,0),0)),"")} | P19: {=iferror(if(sum(J19:O19)=1,"none",INDEX('行パターン'!G:G,MATCH($D19,'行パターン'!$A:$A,0),0)),"")}
B20: ※ボスブロックは1行(フロア)固定
B22: ■Enemyシーケンス | F22: ※コピペして使用
B24: sequence _group_id | D24: sequence_ element_id | F24: priority_sequence_element_id | H24: Enemy_ID | L24: ファントム名 | P24: unit_kind | R24: 属性 | T24: ロール | V24: オーラタイプ | X24: 死亡タイプ | Z24: 必殺ワザ有無 | AB24: 体力 | AD24: 体力係数 | AF24: 攻撃力 | AH24: 攻撃係数 | AJ24: 通常攻撃F | AL24: 通常攻撃CDF | AN24: 通常攻撃DPS | AP24: 通常攻撃備考 | AT24: 必殺技内容 | AY24: 必殺発動回数 | BA24: 必殺技F(秒) | BC24: 特性 | BE24: 移動速度 | BG24: well_distance | BI24: start_range | BK24: end_range | BM24: 攻撃範囲 | BO24: KB回数 | BQ24: 撃破p | BS24: 上書き撃破p | BU24: 変身先ID | BW24: 変身条件1 | BY24: 変身条件2 | CA24: 出撃条件 condition_type | CE24: 出撃開始値 condition_value | CG24: 出撃間隔値 summon_interval | CI24: 召喚回数 summon_count | CK24: アクション遅延 action_delay | CM24: 出撃 アニメーション | CO24: 召喚pos summon_position | CQ24: 移動開始条件 move_start_condition_type | CU24: 移動開始値 condition_value | CW24: 移動停止条件 move_stop_condition_type | DA24: 移動停止値 | DC24: 移動再スタート条件 move_restart_condition_type | DG24: 移動再スタート値 | DI24: 再スタート回数 move_loop_count | DK24: ゲート無敵化 | DM24: 出現停止条件 | DQ24: 停止条件値 | DS24: 備考 | EA24: sequence_group_id | EB24: sequence_element_id | EC24: priority_sequence_element_id | ED24: condition_type | EE24: condition_value | EF24: action_type | EG24: action_value | EH24: action_value2 | EI24: summon_count | EJ24: summon_interval | EK24: summon_animation_type | EL24: summon_position | EM24: move_start_condition_type | EN24: move_start_condition_value | EO24: move_stop_condition_type | EP24: move_stop_condition_value | EQ24: move_restart_condition_type | ER24: move_restart_condition_value | ES24: move_loop_count | ET24: is_summon_unit_outpost_damage_invalidation | EU24: last_boss_trigger | EV24: aura_type | EW24: death_type | EX24: enemy_hp_coef | EY24: enemy_attack_coef | EZ24: enemy_speed_coef | FA24: override_drop_battle_point | FB24: defeated_score | FC24: action_delay | FD24: deactivation_condition_type | FE24: deactivation_condition_value
D25: 1 | H25: c_spy_00101_general_n_Boss_Blue | L25: {=iferror(INDEX('ファントムマスター'!F:F,MATCH(H25,'ファントムマスター'!D:D,0),0),"error")} -> error | P25: =iferror(INDEX('ファントムマスター'!H:H,MATCH(H25,'ファントムマスター'!D:D,0),0),"none") -> none | R25: =iferror(INDEX('ファントムマスター'!J:J,MATCH(H25,'ファントムマスター'!D:D,0),0),"none") -> none | T25: =iferror(INDEX('ファントムマスター'!I:I,MATCH(H25,'ファントムマスター'!D:D,0),0),"none") -> none | V25: Default | X25: Normal | AB25: =iferror(INDEX('ファントムマスター'!K:K,MATCH(H25,'ファントムマスター'!D:D,0),0)*AD25,"none") -> none | AD25: 1 | AF25: =iferror(INDEX('ファントムマスター'!O:O,MATCH(H25,'ファントムマスター'!D:D,0),0)*AH25,"none") -> none | AH25: 1 | AJ25: =iferror(right(INDEX('ファントムマスター'!T:T,MATCH(H25,'ファントムマスター'!D:D,0),0),4)*50,"none") -> none | AL25: =iferror(right(INDEX('ファントムマスター'!V:V,MATCH(H25,'ファントムマスター'!D:D,0),0),4),"none") -> none | AN25: =iferror(AF25*(50/(AJ25+AL25)),"攻撃力に数値を入力") -> 攻撃力に数値を入力 | AT25: =iferror(INDEX('ファントムマスター'!Y:Y,MATCH(H25,'ファントムマスター'!D:D,0),0),"none") -> none | AY25: =iferror(INDEX('ファントムマスター'!Z:Z,MATCH(H25,'ファントムマスター'!D:D,0),0),"none") -> none | BA25: =iferror(INDEX('ファントムマスター'!W:W,MATCH(H25,'ファントムマスター'!D:D,0),0)*50,"none") -> none | BC25: =iferror(INDEX('ファントムマスター'!AA:AA,MATCH(H25,'ファントムマスター'!D:D,0),0),"none") -> none | BE25: =iferror(INDEX('ファントムマスター'!M:M,MATCH(H25,'ファントムマスター'!D:D,0),0),"none") -> none | BG25: =iferror(INDEX('ファントムマスター'!N:N,MATCH(H25,'ファントムマスター'!D:D,0),0),"none") -> none | BI25: =iferror(INDEX('ファントムマスター'!P:P,MATCH(H25,'ファントムマスター'!D:D,0),0),"none") -> none | BK25: =iferror(INDEX('ファントムマスター'!Q:Q,MATCH(H25,'ファントムマスター'!D:D,0),0),"none") -> none | BM25: =iferror(INDEX('ファントムマスター'!R:R,MATCH(H25,'ファントムマスター'!D:D,0),0),"none") -> none | BO25: =iferror(INDEX('ファントムマスター'!L:L,MATCH(H25,'ファントムマスター'!D:D,0),0),"none") -> none | BQ25: =iferror(INDEX('ファントムマスター'!S:S,MATCH(H25,'ファントムマスター'!D:D,0),0),"none") -> none | CA25: 未入力 | CE25: 1 | CG25: 10 | CI25: 99 | CM25: None | CQ25: None | CW25: None | DC25: None | DK25: FALSE | DM25: None | EA25: =B25 | EB25: =D25 -> 1 | EC25: =F25 | ED25: =CA25 -> 未入力 | EE25: =CE25 -> 1 | EF25: ="SummonEnemy" -> SummonEnemy | EG25: =H25 -> c_spy_00101_general_n_Boss_Blue | EI25: =CI25 -> 99 | EJ25: =CG25 -> 10 | EK25: =CM25 -> None | EL25: =CO25 | EM25: =CQ25 -> None | EN25: =CU25 | EO25: =CW25 -> None | EP25: =DA25 | EQ25: =DC25 -> None | ER25: =DG25 | ES25: =DI25 | ET25: =DK25 -> FALSE | EV25: =V25 -> Default | EW25: =X25 -> Normal | EX25: =AD25 -> 1 | EY25: =AH25 -> 1 | EZ25: ="1" -> 1 | FA25: =BS25 | FB25: 0 | FC25: =CK25 | FD25: =DM25 -> None | FE25: =DQ25
L26: =iferror(INDEX('ファントムマスター'!F:F,MATCH(H26,'ファントムマスター'!D:D,0),0),"none") -> none | P26: =iferror(INDEX('ファントムマスター'!H:H,MATCH(H26,'ファントムマスター'!D:D,0),0),"none") -> none | R26: =iferror(INDEX('ファントムマスター'!J:J,MATCH(H26,'ファントムマスター'!D:D,0),0),"none") -> none | T26: =iferror(INDEX('ファントムマスター'!I:I,MATCH(H26,'ファントムマスター'!D:D,0),0),"none") -> none | V26: Default | X26: Normal | AB26: =iferror(INDEX('ファントムマスター'!K:K,MATCH(H26,'ファントムマスター'!D:D,0),0)*AD26,"none") -> none | AD26: 1 | AF26: =iferror(INDEX('ファントムマスター'!O:O,MATCH(H26,'ファントムマスター'!D:D,0),0)*AH26,"none") -> none | AH26: 1 | AJ26: =iferror(right(INDEX('ファントムマスター'!T:T,MATCH(H26,'ファントムマスター'!D:D,0),0),4)*50,"none") -> none | AL26: =iferror(right(INDEX('ファントムマスター'!V:V,MATCH(H26,'ファントムマスター'!D:D,0),0),4),"none") -> none | AN26: =iferror(AF26*(50/(AJ26+AL26)),"攻撃力に数値を入力") -> 攻撃力に数値を入力 | AT26: =iferror(INDEX('ファントムマスター'!Y:Y,MATCH(H26,'ファントムマスター'!D:D,0),0),"none") -> none | AY26: =iferror(INDEX('ファントムマスター'!Z:Z,MATCH(H26,'ファントムマスター'!D:D,0),0),"none") -> none | BA26: =iferror(INDEX('ファントムマスター'!W:W,MATCH(H26,'ファントムマスター'!D:D,0),0)*50,"none") -> none | BC26: =iferror(INDEX('ファントムマスター'!AA:AA,MATCH(H26,'ファントムマスター'!D:D,0),0),"none") -> none | BE26: =iferror(INDEX('ファントムマスター'!M:M,MATCH(H26,'ファントムマスター'!D:D,0),0),"none") -> none | BG26: =iferror(INDEX('ファントムマスター'!N:N,MATCH(H26,'ファントムマスター'!D:D,0),0),"none") -> none | BI26: =iferror(INDEX('ファントムマスター'!P:P,MATCH(H26,'ファントムマスター'!D:D,0),0),"none") -> none | BK26: =iferror(INDEX('ファントムマスター'!Q:Q,MATCH(H26,'ファントムマスター'!D:D,0),0),"none") -> none | BM26: =iferror(INDEX('ファントムマスター'!R:R,MATCH(H26,'ファントムマスター'!D:D,0),0),"none") -> none | BO26: =iferror(INDEX('ファントムマスター'!L:L,MATCH(H26,'ファントムマスター'!D:D,0),0),"none") -> none | BQ26: =iferror(INDEX('ファントムマスター'!S:S,MATCH(H26,'ファントムマスター'!D:D,0),0),"none") -> none | CA26: 未入力 | CM26: None | CQ26: None | CW26: None | DC26: None | DK26: FALSE | DM26: None | EA26: =B26 | EB26: =D26 | EC26: =F26 | ED26: =CA26 -> 未入力 | EE26: =CE26 | EF26: ="SummonEnemy" -> SummonEnemy | EG26: =H26 | EI26: =CI26 | EJ26: =CG26 | EK26: =CM26 -> None | EL26: =CO26 | EM26: =CQ26 -> None | EN26: =CU26 | EO26: =CW26 -> None | EP26: =DA26 | EQ26: =DC26 -> None | ER26: =DG26 | ES26: =DI26 | ET26: =DK26 -> FALSE | EV26: =V26 -> Default | EW26: =X26 -> Normal | EX26: =AD26 -> 1 | EY26: =AH26 -> 1 | EZ26: ="1" -> 1 | FA26: =BS26 | FB26: 0 | FC26: =CK26 | FD26: =DM26 -> None | FE26: =DQ26
L27: =iferror(INDEX('ファントムマスター'!F:F,MATCH(H27,'ファントムマスター'!D:D,0),0),"none") -> none | P27: =iferror(INDEX('ファントムマスター'!H:H,MATCH(H27,'ファントムマスター'!D:D,0),0),"none") -> none | R27: =iferror(INDEX('ファントムマスター'!J:J,MATCH(H27,'ファントムマスター'!D:D,0),0),"none") -> none | T27: =iferror(INDEX('ファントムマスター'!I:I,MATCH(H27,'ファントムマスター'!D:D,0),0),"none") -> none | V27: Default | X27: Normal | AB27: =iferror(INDEX('ファントムマスター'!K:K,MATCH(H27,'ファントムマスター'!D:D,0),0)*AD27,"none") -> none | AD27: 1 | AF27: =iferror(INDEX('ファントムマスター'!O:O,MATCH(H27,'ファントムマスター'!D:D,0),0)*AH27,"none") -> none | AH27: 1 | AJ27: =iferror(right(INDEX('ファントムマスター'!T:T,MATCH(H27,'ファントムマスター'!D:D,0),0),4)*50,"none") -> none | AL27: =iferror(right(INDEX('ファントムマスター'!V:V,MATCH(H27,'ファントムマスター'!D:D,0),0),4),"none") -> none | AN27: =iferror(AF27*(50/(AJ27+AL27)),"攻撃力に数値を入力") -> 攻撃力に数値を入力 | AT27: =iferror(INDEX('ファントムマスター'!Y:Y,MATCH(H27,'ファントムマスター'!D:D,0),0),"none") -> none | AY27: =iferror(INDEX('ファントムマスター'!Z:Z,MATCH(H27,'ファントムマスター'!D:D,0),0),"none") -> none | BA27: =iferror(INDEX('ファントムマスター'!W:W,MATCH(H27,'ファントムマスター'!D:D,0),0)*50,"none") -> none | BC27: =iferror(INDEX('ファントムマスター'!AA:AA,MATCH(H27,'ファントムマスター'!D:D,0),0),"none") -> none | BE27: =iferror(INDEX('ファントムマスター'!M:M,MATCH(H27,'ファントムマスター'!D:D,0),0),"none") -> none | BG27: =iferror(INDEX('ファントムマスター'!N:N,MATCH(H27,'ファントムマスター'!D:D,0),0),"none") -> none | BI27: =iferror(INDEX('ファントムマスター'!P:P,MATCH(H27,'ファントムマスター'!D:D,0),0),"none") -> none | BK27: =iferror(INDEX('ファントムマスター'!Q:Q,MATCH(H27,'ファントムマスター'!D:D,0),0),"none") -> none | BM27: =iferror(INDEX('ファントムマスター'!R:R,MATCH(H27,'ファントムマスター'!D:D,0),0),"none") -> none | BO27: =iferror(INDEX('ファントムマスター'!L:L,MATCH(H27,'ファントムマスター'!D:D,0),0),"none") -> none | BQ27: =iferror(INDEX('ファントムマスター'!S:S,MATCH(H27,'ファントムマスター'!D:D,0),0),"none") -> none | CA27: 未入力 | CM27: None | CQ27: None | CW27: None | DC27: None | DK27: FALSE | DM27: None | EA27: =B27 | EB27: =D27 | EC27: =F27 | ED27: =CA27 -> 未入力 | EE27: =CE27 | EF27: ="SummonEnemy" -> SummonEnemy | EG27: =H27 | EI27: =CI27 | EJ27: =CG27 | EK27: =CM27 -> None | EL27: =CO27 | EM27: =CQ27 -> None | EN27: =CU27 | EO27: =CW27 -> None | EP27: =DA27 | EQ27: =DC27 -> None | ER27: =DG27 | ES27: =DI27 | ET27: =DK27 -> FALSE | EV27: =V27 -> Default | EW27: =X27 -> Normal | EX27: =AD27 -> 1 | EY27: =AH27 -> 1 | EZ27: ="1" -> 1 | FA27: =BS27 | FB27: 0 | FC27: =CK27 | FD27: =DM27 -> None | FE27: =DQ27
L28: =iferror(INDEX('ファントムマスター'!F:F,MATCH(H28,'ファントムマスター'!D:D,0),0),"none") -> none | P28: =iferror(INDEX('ファントムマスター'!H:H,MATCH(H28,'ファントムマスター'!D:D,0),0),"none") -> none | R28: =iferror(INDEX('ファントムマスター'!J:J,MATCH(H28,'ファントムマスター'!D:D,0),0),"none") -> none | T28: =iferror(INDEX('ファントムマスター'!I:I,MATCH(H28,'ファントムマスター'!D:D,0),0),"none") -> none | V28: Default | X28: Normal | AB28: =iferror(INDEX('ファントムマスター'!K:K,MATCH(H28,'ファントムマスター'!D:D,0),0)*AD28,"none") -> none | AD28: 1 | AF28: =iferror(INDEX('ファントムマスター'!O:O,MATCH(H28,'ファントムマスター'!D:D,0),0)*AH28,"none") -> none | AH28: 1 | AJ28: =iferror(right(INDEX('ファントムマスター'!T:T,MATCH(H28,'ファントムマスター'!D:D,0),0),4)*50,"none") -> none | AL28: =iferror(right(INDEX('ファントムマスター'!V:V,MATCH(H28,'ファントムマスター'!D:D,0),0),4),"none") -> none | AN28: =iferror(AF28*(50/(AJ28+AL28)),"攻撃力に数値を入力") -> 攻撃力に数値を入力 | AT28: =iferror(INDEX('ファントムマスター'!Y:Y,MATCH(H28,'ファントムマスター'!D:D,0),0),"none") -> none | AY28: =iferror(INDEX('ファントムマスター'!Z:Z,MATCH(H28,'ファントムマスター'!D:D,0),0),"none") -> none | BA28: =iferror(INDEX('ファントムマスター'!W:W,MATCH(H28,'ファントムマスター'!D:D,0),0)*50,"none") -> none | BC28: =iferror(INDEX('ファントムマスター'!AA:AA,MATCH(H28,'ファントムマスター'!D:D,0),0),"none") -> none | BE28: =iferror(INDEX('ファントムマスター'!M:M,MATCH(H28,'ファントムマスター'!D:D,0),0),"none") -> none | BG28: =iferror(INDEX('ファントムマスター'!N:N,MATCH(H28,'ファントムマスター'!D:D,0),0),"none") -> none | BI28: =iferror(INDEX('ファントムマスター'!P:P,MATCH(H28,'ファントムマスター'!D:D,0),0),"none") -> none | BK28: =iferror(INDEX('ファントムマスター'!Q:Q,MATCH(H28,'ファントムマスター'!D:D,0),0),"none") -> none | BM28: =iferror(INDEX('ファントムマスター'!R:R,MATCH(H28,'ファントムマスター'!D:D,0),0),"none") -> none | BO28: =iferror(INDEX('ファントムマスター'!L:L,MATCH(H28,'ファントムマスター'!D:D,0),0),"none") -> none | BQ28: =iferror(INDEX('ファントムマスター'!S:S,MATCH(H28,'ファントムマスター'!D:D,0),0),"none") -> none | CA28: 未入力 | CM28: None | CQ28: None | CW28: None | DC28: None | DK28: FALSE | DM28: None | EA28: =B28 | EB28: =D28 | EC28: =F28 | ED28: =CA28 -> 未入力 | EE28: =CE28 | EF28: ="SummonEnemy" -> SummonEnemy | EG28: =H28 | EI28: =CI28 | EJ28: =CG28 | EK28: =CM28 -> None | EL28: =CO28 | EM28: =CQ28 -> None | EN28: =CU28 | EO28: =CW28 -> None | EP28: =DA28 | EQ28: =DC28 -> None | ER28: =DG28 | ES28: =DI28 | ET28: =DK28 -> FALSE | EV28: =V28 -> Default | EW28: =X28 -> Normal | EX28: =AD28 -> 1 | EY28: =AH28 -> 1 | EZ28: ="1" -> 1 | FA28: =BS28 | FB28: 0 | FC28: =CK28 | FD28: =DM28 -> None | FE28: =DQ28
